Workbook
Name Marca: #REF!
Name Marca: #REF!
Name Marca1: #REF!
Name Marca1: #REF!
Name Marcas: #REF!
Name Marcas: #REF!
Name Valor: #REF!
Name Valor: #REF!
Name Value: #REF!
Name Value: #REF!
Name values: #REF!

Sheet DICIEMBRE
E1: 42400
D4: BANCOS | E4: =SUBTOTAL(9,E5:E5) -> 1.0260921e+09
D5: Bancos | E5: 1.0260921e+09
D6: FACTURACIÓN PENDIENTE POR MONETIZAR | E6: =SUBTOTAL(9,E7:E7) -> 3.9592753e+09
D7: Monetización - facturación y Offycycle Diciembre | E7: =171505293.6+294581581.61+43363251.75+75955982+3373869149.59 -> 3.9592753e+09
E8: =SUBTOTAL(9,E4:E7) -> 4.9853673e+09
C11: CUENTAS X PAGAR MES | E11: DICIEMBRE | F11: Fecha de Elaboración: | I11: 45992
C12: Factura | D12: PROVEEDOR | E12: VALOR | F12: Fecha vencimiento | G12: Estado | I12: KPI | J12: Objeto
D13: PAGOS ANTICIPADOS | E13: =SUBTOTAL(9,E14) -> 25041817
A14: =G14 -> Cancelado | B14: =IF(#REF!<=-1,1,IF(#REF!<=5,2,IF(#REF!<=15,3,IF(H14<=60,4)))) -> #REF! | C14: 1 registro | D14: Nómina Sergio Jimenez Belimo | E14: 25041817 | F14: 46020 | G14: Cancelado | H14: =IF(OR(G14="Sin pagar",G14="Pagar"),NETWORKDAYS($I$11,F14,'Festivos Colombia'!$A$3:$A$22),0) -> 0 | I14: =H14 -> 0
D15: SEGURIDAD SOCIAL | E15: =SUBTOTAL(9,E16:E16) -> 545064300
A16: =G16 -> Cancelado | B16: =IF(#REF!<=-1,1,IF(#REF!<=5,2,IF(#REF!<=15,3,IF(H16<=60,4)))) -> #REF! | D16: Pago seguridad social Global | E16: 545064300 | F16: 46003 | G16: Cancelado | H16: =IF(OR(G16="Sin pagar",G16="Pagar"),NETWORKDAYS($I$11,F16,'Festivos Colombia'!$A$3:$A$22),0) -> 0 | I16: =H16 -> 0
D17: AFC´S | E17: =SUBTOTAL(9,E18:E19) -> 80309295
A18: =G18 -> Cancelado | B18: =IF(#REF!<=-1,1,IF(#REF!<=5,2,IF(#REF!<=15,3,IF(H18<=60,4)))) -> #REF! | C18: 1 | D18: AFC y aportes voluntarios - Cheque | E18: =19400000+7900000 -> 27300000 | F18: 46017 | G18: Cancelado | H18: =IF(OR(G18="Sin pagar",G18="Pagar"),NETWORKDAYS($I$11,F18,'Festivos Colombia'!$A$3:$A$22),0) -> 0 | I18: =H18 -> 0
A19: =G19 -> Cancelado | B19: =IF(#REF!<=-1,1,IF(#REF!<=5,2,IF(#REF!<=15,3,IF(H19<=60,4)))) -> #REF! | C19: 1 | D19: AFC y aportes voluntarios -SOI y Aportes en Linea | E19: 53009295 | F19: 46017 | G19: Cancelado | H19: =IF(OR(G19="Sin pagar",G19="Pagar"),NETWORKDAYS($I$11,F19,'Festivos Colombia'!$A$3:$A$22),0) -> 0 | I19: =H19 -> 0
D20: IMPUESTOS | E20: =SUBTOTAL(9,E21:E21) -> 311877000 | H20: =IF(OR(G20="Sin pagar",G20="Pagar"),NETWORKDAYS($I$11,F20,'Festivos Colombia'!$A$3:$A$22),0) -> 0 | I20: =H20 -> 0
A21: =G21 -> Cancelado | B21: =IF(#REF!<=-1,1,IF(#REF!<=5,2,IF(#REF!<=15,3,IF(H21<=60,4)))) -> #REF! | D21: Retención en la fuente | E21: 311877000 | F21: 46003 | G21: Cancelado | H21: =IF(OR(G21="Sin pagar",G21="Pagar"),NETWORKDAYS($I$11,F21,'Festivos Colombia'!$A$3:$A$22),0) -> 0 | I21: =H21 -> 0
D22: PLANES COMPLEMENTARIOS Y PREPAGADAS | E22: =SUBTOTAL(9,E23:E25) -> 11402659 | H22: =IF(OR(G22="Sin pagar",G22="Pagar"),NETWORKDAYS($I$11,F22,'Festivos Colombia'!$A$3:$A$22),0) -> 0
A23: =G23 -> Cancelado | B23: =IF(#REF!<=-1,1,IF(#REF!<=5,2,IF(#REF!<=15,3,IF(H23<=60,4)))) -> #REF! | C23: 2091201744 | D23: Póliza suramericana # 091000808150 SALUD FAMILIAR | E23: 10359668 | F23: 46017 | G23: Cancelado | H23: =IF(OR(G23="Sin pagar",G23="Pagar"),NETWORKDAYS($I$11,F23,'Festivos Colombia'!$A$3:$A$22),0) -> 0 | I23: =H23 -> 0
A24: =G24 -> Cancelado | B24: =IF(#REF!<=-1,1,IF(#REF!<=5,2,IF(#REF!<=15,3,IF(H24<=60,4)))) -> #REF! | C24: 20911202787 | D24: Póliza suramericana # 091000808150 SALUD FAMILIAR | E24: 565363 | F24: 46017 | G24: Cancelado | H24: =IF(OR(G24="Sin pagar",G24="Pagar"),NETWORKDAYS($I$11,F24,'Festivos Colombia'!$A$3:$A$22),0) -> 0 | I24: =H24 -> 0
A25: =G25 -> Cancelado | B25: =IF(#REF!<=-1,1,IF(#REF!<=5,2,IF(#REF!<=15,3,IF(H25<=60,4)))) -> #REF! | C25: 20833316862 | D25: Póliza suramericana # 0904418894 SALUD FAMILIAR | E25: 477628 | F25: 46017 | G25: Cancelado | H25: =IF(OR(G25="Sin pagar",G25="Pagar"),NETWORKDAYS($I$11,F25,'Festivos Colombia'!$A$3:$A$22),0) -> 0 | I25: =H25 -> 0
D26: PÓLIZAS Y SEGUROS | E26: =SUBTOTAL(9,E27:E44) -> 36113797 | H26: =IF(OR(G26="Sin pagar",G26="Pagar"),NETWORKDAYS($I$11,F26,'Festivos Colombia'!$A$3:$A$22),0) -> 0
A27: =G27 -> Cancelado | B27: =IF(#REF!<=-1,1,IF(#REF!<=5,2,IF(#REF!<=15,3,IF(H27<=60,4)))) -> #REF! | C27: 1239806816 | D27: Plan grupo 10108069057 | E27: 12733350 | F27: 45995 | G27: Cancelado | H27: =IF(OR(G27="Sin pagar",G27="Pagar"),NETWORKDAYS($I$11,F27,'Festivos Colombia'!$A$3:$A$22),0) -> 0 | I27: =H27 -> 0
A28: =G28 -> Cancelado | B28: =IF(#REF!<=-1,1,IF(#REF!<=5,2,IF(#REF!<=15,3,IF(H28<=60,4)))) -> #REF! | C28: 1239781227 | D28: Plan grupo 103226992 - Aana Aguirre - GRAINGER SERVICES INTERNATIONA | E28: 193253 | F28: 45995 | G28: Cancelado | H28: =IF(OR(G28="Sin pagar",G28="Pagar"),NETWORKDAYS($I$11,F28,'Festivos Colombia'!$A$3:$A$22),0) -> 0 | I28: =H28 -> 0
A29: =G29 -> Cancelado | B29: =IF(#REF!<=-1,1,IF(#REF!<=5,2,IF(#REF!<=15,3,IF(H29<=60,4)))) -> #REF! | C29: 1239772460 | D29: Plan dental 103229130 Luna Rodriguez - LANO SOFTWARE GMBH | E29: 298337 | F29: 45995 | G29: Cancelado | H29: =IF(OR(G29="Sin pagar",G29="Pagar"),NETWORKDAYS($I$11,F29,'Festivos Colombia'!$A$3:$A$22),0) -> 0 | I29: =H29 -> 0
A30: =G30 -> Cancelado | B30: =IF(#REF!<=-1,1,IF(#REF!<=5,2,IF(#REF!<=15,3,IF(H30<=60,4)))) -> #REF! | C30: 1239773169 | D30: Plan dental 10325327 Ivonne Torres | E30: 295313 | F30: 45995 | G30: Cancelado | H30: =IF(OR(G30="Sin pagar",G30="Pagar"),NETWORKDAYS($I$11,F30,'Festivos Colombia'!$A$3:$A$22),0) -> 0 | I30: =H30 -> 0
A31: =G31 -> Cancelado | B31: =IF(#REF!<=-1,1,IF(#REF!<=5,2,IF(#REF!<=15,3,IF(H31<=60,4)))) -> #REF! | C31: 1239749107 | D31: Plan grupo 10108170475 - Sandra Barba - ALLEGIS GROUP INC | E31: 1642200 | F31: 45995 | G31: Cancelado | H31: =IF(OR(G31="Sin pagar",G31="Pagar"),NETWORKDAYS($I$11,F31,'Festivos Colombia'!$A$3:$A$22),0) -> 0 | I31: =H31 -> 0
A32: =G32 -> Cancelado | B32: =IF(#REF!<=-1,1,IF(#REF!<=5,2,IF(#REF!<=15,3,IF(H32<=60,4)))) -> #REF! | C32: 1239720449 | D32: Plan grupo 103225452 - Freddy Gomez - TITAN METER BIDCO CORPORATION | E32: 318465 | F32: 45995 | G32: Cancelado | H32: =IF(OR(G32="Sin pagar",G32="Pagar"),NETWORKDAYS($I$11,F32,'Festivos Colombia'!$A$3:$A$22),0) -> 0 | I32: =H32 -> 0
A33: =G33 -> Cancelado | B33: =IF(#REF!<=-1,1,IF(#REF!<=5,2,IF(#REF!<=15,3,IF(H33<=60,4)))) -> #REF! | C33: 1239803861 | D33: Plan grupo-103229134 - María Amaya Gomez - LANO SOFTWARE | E33: 68040 | F33: 45995 | G33: Cancelado | H33: =IF(OR(G33="Sin pagar",G33="Pagar"),NETWORKDAYS($I$11,F33,'Festivos Colombia'!$A$3:$A$22),0) -> 0 | I33: =H33 -> 0
A34: =G34 -> Cancelado | B34: =IF(#REF!<=-1,1,IF(#REF!<=5,2,IF(#REF!<=15,3,IF(H34<=60,4)))) -> #REF! | C34: 1239543181 | D34: Plan grupo 10108174837 - Freddy Gomez - TITAN METER BIDCO CORPORATION | E34: 1860600 | F34: 46000 | G34: Cancelado | H34: =IF(OR(G34="Sin pagar",G34="Pagar"),NETWORKDAYS($I$11,F34,'Festivos Colombia'!$A$3:$A$22),0) -> 0 | I34: =H34 -> 0
A35: =G35 -> Cancelado | B35: =IF(#REF!<=-1,1,IF(#REF!<=5,2,IF(#REF!<=15,3,IF(H35<=60,4)))) -> #REF! | C35: 1239817137 | D35: Plan grupo-103229134 - María Gabriela Acosta - LANO SOFTWARE | E35: 68040 | F35: 45995 | G35: Cancelado | H35: =IF(OR(G35="Sin pagar",G35="Pagar"),NETWORKDAYS($I$11,F35,'Festivos Colombia'!$A$3:$A$22),0) -> 0 | I35: =H35 -> 0
A36: =G36 -> Cancelado | B36: =IF(#REF!<=-1,1,IF(#REF!<=5,2,IF(#REF!<=15,3,IF(H36<=60,4)))) -> #REF! | C36: 12310058809 | D36: Plan grupo 10108069057 | E36: 13580700 | F36: 46028 | G36: Cancelado | H36: =IF(OR(G36="Sin pagar",G36="Pagar"),NETWORKDAYS($I$11,F36,'Festivos Colombia'!$A$3:$A$22),0) -> 0 | I36: =H36 -> 0
A37: =G37 -> Cancelado | B37: =IF(#REF!<=-1,1,IF(#REF!<=5,2,IF(#REF!<=15,3,IF(H37<=60,4)))) -> #REF! | C37: 1239964849 | D37: Plan grupo 103226992 - Aana Aguirre - GRAINGER SERVICES INTERNATIONA | E37: 205538 | F37: 46028 | G37: Cancelado | H37: =IF(OR(G37="Sin pagar",G37="Pagar"),NETWORKDAYS($I$11,F37,'Festivos Colombia'!$A$3:$A$22),0) -> 0 | I37: =H37 -> 0
A38: =G38 -> Cancelado | B38: =IF(#REF!<=-1,1,IF(#REF!<=5,2,IF(#REF!<=15,3,IF(H38<=60,4)))) -> #REF! | C38: 1239905171 | D38: Plan dental 103229130 Luna Rodriguez - LANO SOFTWARE GMBH | E38: 316953 | F38: 46028 | G38: Cancelado | H38: =IF(OR(G38="Sin pagar",G38="Pagar"),NETWORKDAYS($I$11,F38,'Festivos Colombia'!$A$3:$A$22),0) -> 0 | I38: =H38 -> 0
... A44: =G44 -> Cancelado | B44: =IF(#REF!<=-1,1,IF(#REF!<=5,2,IF(#REF!<=15,3,IF(H44<=60,4)))) -> #REF! | C44: 12310060492 | D44: Plan grupo-103229134 - María Gabriela Acosta - LANO SOFTWARE | E44: 71820 | F44: 46028 | G44: Cancelado | H44: =IF(OR(G44="Sin pagar",G44="Pagar"),NETWORKDAYS($I$11,F44,'Festivos Colombia'!$A$3:$A$22),0) -> 0 | I44: =H44 -> 0
D45: REEMBOLSO GASTOS VIAJE | E45: =SUBTOTAL(9,E46:E91) -> 1.3923323e+08
D46: Reembolso Cristhian Javier Gutierrez Torres-Sophos-CC020 | E46: 754854 | F46: 45995 | G46: Cancelado
D47: Reembolso Fabian Augusto Porto Dulcey cc020 - Sophos | E47: 224349.45 | F47: 45995 | G47: Cancelado
D48: Reembolso Howard Antonio Donado Padilla cc073- Zenio | E48: 380000 | F48: 45995 | G48: Cancelado
D49: Reembolso Edith johana pineda zapata cc020 - sophos | E49: 5720201.4 | F49: 45995 | G49: Cancelado
...

Sheet ENERO
E1: 42400
D4: BANCOS | E4: =SUBTOTAL(9,E5:E5) -> 1.8610213e+09
D5: Bancos | E5: =DICIEMBRE!E137 -> 1.8610213e+09
D6: FACTURACIÓN PENDIENTE POR MONETIZAR | E6: =SUBTOTAL(9,E7:E7) -> 2.5253478e+09
D7: Monetización - facturación y Offycycle enero | E7: =45000000+2477791585.72+2556216 -> 2.5253478e+09
E8: =SUBTOTAL(9,E4:E7) -> 4.3863691e+09
C11: CUENTAS X PAGAR MES | E11: ENERO | F11: Fecha de Elaboración: | I11: 46023
C12: Factura | D12: PROVEEDOR | E12: VALOR | F12: Fecha vencimiento | G12: Estado | I12: KPI | J12: Objeto
D13: PAGOS ANTICIPADOS | E13: =SUBTOTAL(9,E14) -> 26559341
A14: =G14 -> Cancelado | B14: =IF(#REF!<=-1,1,IF(#REF!<=5,2,IF(#REF!<=15,3,IF(H14<=60,4)))) -> #REF! | C14: 1 registro | D14: Nómina Sergio Jimenez Belimo | E14: 26559341 | F14: 46050 | G14: Cancelado | H14: =IF(OR(G14="Sin pagar",G14="Pagar"),NETWORKDAYS($I$11,F14,'Festivos Colombia'!$A$3:$A$22),0) -> 0 | I14: =H14 -> 0
D15: SEGURIDAD SOCIAL | E15: =SUBTOTAL(9,E16:E16) -> 564617800
A16: =G16 -> Cancelado | B16: =IF(#REF!<=-1,1,IF(#REF!<=5,2,IF(#REF!<=15,3,IF(H16<=60,4)))) -> #REF! | D16: Pago seguridad social Global | E16: 564617800 | F16: 46031 | G16: Cancelado | H16: =IF(OR(G16="Sin pagar",G16="Pagar"),NETWORKDAYS($I$11,F16,'Festivos Colombia'!$A$3:$A$22),0) -> 0 | I16: =H16 -> 0
D17: AFC´S | E17: =SUBTOTAL(9,E18:E20) -> 64815500
A18: =G18 -> Cancelado | B18: =IF(#REF!<=-1,1,IF(#REF!<=5,2,IF(#REF!<=15,3,IF(H18<=60,4)))) -> #REF! | C18: 1 | D18: AFC y aportes voluntarios - Cheque | E18: 21300000 | F18: 46050 | G18: Cancelado | H18: =IF(OR(G18="Sin pagar",G18="Pagar"),NETWORKDAYS($I$11,F18,'Festivos Colombia'!$A$3:$A$22),0) -> 0 | I18: =H18 -> 0
A19: =G19 -> Cancelado | B19: =IF(#REF!<=-1,1,IF(#REF!<=5,2,IF(#REF!<=15,3,IF(H19<=60,4)))) -> #REF! | C19: 1 | D19: AFC y aportes voluntarios -SOI y Aportes en Linea | E19: 39715500 | F19: 46050 | G19: Cancelado | H19: =IF(OR(G19="Sin pagar",G19="Pagar"),NETWORKDAYS($I$11,F19,'Festivos Colombia'!$A$3:$A$22),0) -> 0 | I19: =H19 -> 0
A20: =G20 -> Cancelado | B20: =IF(#REF!<=-1,1,IF(#REF!<=5,2,IF(#REF!<=15,3,IF(H20<=60,4)))) -> #REF! | C20: 1 | D20: AFC y aportes voluntarios Aportes en Linea adicional Skandia | E20: 3800000 | F20: 46057 | G20: Cancelado | H20: =IF(OR(G20="Sin pagar",G20="Pagar"),NETWORKDAYS($I$11,F20,'Festivos Colombia'!$A$3:$A$22),0) -> 0 | I20: =H20 -> 0
D21: IMPUESTOS | E21: =SUBTOTAL(9,E22:E24) -> 416605000 | H21: =IF(OR(G21="Sin pagar",G21="Pagar"),NETWORKDAYS($I$11,F21,'Festivos Colombia'!$A$3:$A$22),0) -> 0 | I21: =H21 -> 0
A22: =G22 -> Cancelado | B22: =IF(#REF!<=-1,1,IF(#REF!<=5,2,IF(#REF!<=15,3,IF(H22<=60,4)))) -> #REF! | D22: Retención en la fuente | E22: 411959000 | F22: 46037 | G22: Cancelado | H22: =IF(OR(G22="Sin pagar",G22="Pagar"),NETWORKDAYS($I$11,F22,'Festivos Colombia'!$A$3:$A$22),0) -> 0 | I22: =H22 -> 0
A23: =G23 -> Cancelado | B23: =IF(#REF!<=-1,1,IF(#REF!<=5,2,IF(#REF!<=15,3,IF(H23<=60,4)))) -> #REF! | D23: IVA tecer cuatrimestre | E23: 4352000 | F23: 46037 | G23: Cancelado | H23: =IF(OR(G23="Sin pagar",G23="Pagar"),NETWORKDAYS($I$11,F23,'Festivos Colombia'!$A$3:$A$22),0) -> 0 | I23: =H23 -> 0
A24: =G24 -> Cancelado | B24: =IF(#REF!<=-1,1,IF(#REF!<=5,2,IF(#REF!<=15,3,IF(H24<=60,4)))) -> #REF! | D24: Retención de ICA 6to bimestre 2025 | E24: 294000 | F24: 46036 | G24: Cancelado | H24: =IF(OR(G24="Sin pagar",G24="Pagar"),NETWORKDAYS($I$11,F24,'Festivos Colombia'!$A$3:$A$22),0) -> 0 | I24: =H24 -> 0
D25: PLANES COMPLEMENTARIOS Y PREPAGADAS | E25: =SUBTOTAL(9,E26:E28) -> 6780762 | H25: =IF(OR(G25="Sin pagar",G25="Pagar"),NETWORKDAYS($I$11,F25,'Festivos Colombia'!$A$3:$A$22),0) -> 0
A26: =G26 -> Cancelado | B26: =IF(#REF!<=-1,1,IF(#REF!<=5,2,IF(#REF!<=15,3,IF(H26<=60,4)))) -> #REF! | C26: 20911207746 | D26: Póliza suramericana # 091000808150 SALUD FAMILIAR | E26: 4265060 | F26: 46053 | G26: Cancelado | H26: =IF(OR(G26="Sin pagar",G26="Pagar"),NETWORKDAYS($I$11,F26,'Festivos Colombia'!$A$3:$A$22),0) -> 0 | I26: =H26 -> 0
A27: =G27 -> Cancelado | B27: =IF(#REF!<=-1,1,IF(#REF!<=5,2,IF(#REF!<=15,3,IF(H27<=60,4)))) -> #REF! | C27: 20833359623 | D27: Póliza suramericana # 0904418894 SALUD FAMILIAR | E27: 437176 | F27: 46058 | G27: Cancelado | H27: =IF(OR(G27="Sin pagar",G27="Pagar"),NETWORKDAYS($I$11,F27,'Festivos Colombia'!$A$3:$A$22),0) -> 0 | I27: =H27 -> 0
A28: =G28 -> Cancelado | B28: =IF(#REF!<=-1,1,IF(#REF!<=5,2,IF(#REF!<=15,3,IF(H28<=60,4)))) -> #REF! | C28: 20911209250 | D28: Póliza suramericana # 091000808150 SALUD FAMILIAR | E28: 2078526 | F28: 46052 | G28: Cancelado | H28: =IF(OR(G28="Sin pagar",G28="Pagar"),NETWORKDAYS($I$11,F28,'Festivos Colombia'!$A$3:$A$22),0) -> 0 | I28: =H28 -> 0
D29: PÓLIZAS Y SEGUROS | E29: =SUBTOTAL(9,E30:E38) -> 0 | H29: =IF(OR(G29="Sin pagar",G29="Pagar"),NETWORKDAYS($I$11,F29,'Festivos Colombia'!$A$3:$A$22),0) -> 0
A30: =G30 -> Cancelado | B30: =IF(#REF!<=-1,1,IF(#REF!<=5,2,IF(#REF!<=15,3,IF(H30<=60,4)))) -> #REF! | C30: 12310058809 | D30: Plan grupo 10108069057 | E30: =13580700*0 -> 0 | F30: 46028 | G30: Cancelado | H30: =IF(OR(G30="Sin pagar",G30="Pagar"),NETWORKDAYS($I$11,F30,'Festivos Colombia'!$A$3:$A$22),0) -> 0 | I30: =H30 -> 0
A31: =G31 -> Cancelado | B31: =IF(#REF!<=-1,1,IF(#REF!<=5,2,IF(#REF!<=15,3,IF(H31<=60,4)))) -> #REF! | C31: 1239964849 | D31: Plan grupo 103226992 - Aana Aguirre - GRAINGER SERVICES INTERNATIONA | E31: =205538*0 -> 0 | F31: 46028 | G31: Cancelado | H31: =IF(OR(G31="Sin pagar",G31="Pagar"),NETWORKDAYS($I$11,F31,'Festivos Colombia'!$A$3:$A$22),0) -> 0 | I31: =H31 -> 0
A32: =G32 -> Cancelado | B32: =IF(#REF!<=-1,1,IF(#REF!<=5,2,IF(#REF!<=15,3,IF(H32<=60,4)))) -> #REF! | C32: 1239905171 | D32: Plan dental 103229130 Luna Rodriguez - LANO SOFTWARE GMBH | E32: =316953*0 -> 0 | F32: 46028 | G32: Cancelado | H32: =IF(OR(G32="Sin pagar",G32="Pagar"),NETWORKDAYS($I$11,F32,'Festivos Colombia'!$A$3:$A$22),0) -> 0 | I32: =H32 -> 0
A33: =G33 -> Cancelado | B33: =IF(#REF!<=-1,1,IF(#REF!<=5,2,IF(#REF!<=15,3,IF(H33<=60,4)))) -> #REF! | C33: 1239956382 | D33: Plan dental 10325327 Ivonne Torres | E33: =314213*0 -> 0 | F33: 46028 | G33: Cancelado | H33: =IF(OR(G33="Sin pagar",G33="Pagar"),NETWORKDAYS($I$11,F33,'Festivos Colombia'!$A$3:$A$22),0) -> 0 | I33: =H33 -> 0
A34: =G34 -> Cancelado | B34: =IF(#REF!<=-1,1,IF(#REF!<=5,2,IF(#REF!<=15,3,IF(H34<=60,4)))) -> #REF! | C34: 1231040566 | D34: Plan grupo 10108170475 - Sandra Barba - ALLEGIS GROUP INC | E34: =1751400*0 -> 0 | F34: 46028 | G34: Cancelado | H34: =IF(OR(G34="Sin pagar",G34="Pagar"),NETWORKDAYS($I$11,F34,'Festivos Colombia'!$A$3:$A$22),0) -> 0 | I34: =H34 -> 0
A35: =G35 -> Cancelado | B35: =IF(#REF!<=-1,1,IF(#REF!<=5,2,IF(#REF!<=15,3,IF(H35<=60,4)))) -> #REF! | C35: 1239902938 | D35: Plan grupo 103225452 - Freddy Gomez - TITAN METER BIDCO CORPORATION | E35: =339255*0 -> 0 | F35: 46028 | G35: Cancelado | H35: =IF(OR(G35="Sin pagar",G35="Pagar"),NETWORKDAYS($I$11,F35,'Festivos Colombia'!$A$3:$A$22),0) -> 0 | I35: =H35 -> 0
A36: =G36 -> Cancelado | B36: =IF(#REF!<=-1,1,IF(#REF!<=5,2,IF(#REF!<=15,3,IF(H36<=60,4)))) -> #REF! | C36: 1239987772 | D36: Plan grupo-103229134 - María Amaya Gomez - LANO SOFTWARE | E36: =71820*0 -> 0 | F36: 46028 | G36: Cancelado | H36: =IF(OR(G36="Sin pagar",G36="Pagar"),NETWORKDAYS($I$11,F36,'Festivos Colombia'!$A$3:$A$22),0) -> 0 | I36: =H36 -> 0
A37: =G37 -> Cancelado | B37: =IF(#REF!<=-1,1,IF(#REF!<=5,2,IF(#REF!<=15,3,IF(H37<=60,4)))) -> #REF! | C37: 1239909226 | D37: Plan grupo 10108174837 - Freddy Gomez - TITAN METER BIDCO CORPORATION | E37: =1984500*0 -> 0 | F37: 46028 | G37: Cancelado | H37: =IF(OR(G37="Sin pagar",G37="Pagar"),NETWORKDAYS($I$11,F37,'Festivos Colombia'!$A$3:$A$22),0) -> 0 | I37: =H37 -> 0
A38: =G38 -> Cancelado | B38: =IF(#REF!<=-1,1,IF(#REF!<=5,2,IF(#REF!<=15,3,IF(H38<=60,4)))) -> #REF! | C38: 12310060492 | D38: Plan grupo-103229134 - María Gabriela Acosta - LANO SOFTWARE | E38: =71820*0 -> 0 | F38: 46028 | G38: Cancelado | H38: =IF(OR(G38="Sin pagar",G38="Pagar"),NETWORKDAYS($I$11,F38,'Festivos Colombia'!$A$3:$A$22),0) -> 0 | I38: =H38 -> 0
D39: REEMBOLSO GASTOS VIAJE | E39: =SUBTOTAL(9,E40:E72) -> 69701217
D40: Reembolso Cristian Javier Gutierrez Torres-cc020 - Sophos | E40: =467154*0 -> 0 | F40: 46024 | G40: Cancelado | H40: =IF(OR(G40="Sin pagar",G40="Pagar"),NETWORKDAYS($I$11,F40,'Festivos Colombia'!$A$3:$A$22),0) -> 0 | I40: =H40 -> 0
D41: Reembolso Jorge Daniel Ramos DUran cc040 - Environmental Dynamics INTL | E41: =1000226*0 -> 0 | F41: 46024 | G41: Cancelado | H41: =IF(OR(G41="Sin pagar",G41="Pagar"),NETWORKDAYS($I$11,F41,'Festivos Colombia'!$A$3:$A$22),0) -> 0 | I41: =H41 -> 0
D42: Reembolso Edwin fernando alonso castelblanco cc020 - sophos | E42: =255113.01*0 -> 0 | F42: 46024 | G42: Cancelado | H42: =IF(OR(G42="Sin pagar",G42="Pagar"),NETWORKDAYS($I$11,F42,'Festivos Colombia'!$A$3:$A$22),0) -> 0 | I42: =H42 -> 0
D43: Reembolso Howard Antonio Donado Padilla cc073- Zenio | E43: =468000*0 -> 0 | F43: 46024 | G43: Cancelado | H43: =IF(OR(G43="Sin pagar",G43="Pagar"),NETWORKDAYS($I$11,F43,'Festivos Colombia'!$A$3:$A$22),0) -> 0 | I43: =H43 -> 0
D44: Reembolso Ivonne Torres-cc012 - lifenet health | E44: =1546810.95*0 -> 0 | F44: 46024 | G44: Cancelado | H44: =IF(OR(G44="Sin pagar",G44="Pagar"),NETWORKDAYS($I$11,F44,'Festivos Colombia'!$A$3:$A$22),0) -> 0 | I44: =H44 -> 0
...

Sheet FEBRERO
E1: 42400
D4: BANCOS | E4: =SUBTOTAL(9,E5:E5) -> 1.6607035e+09
D5: Bancos | E5: =ENERO!$E$114 -> 1.6607035e+09
D6: FACTURACIÓN PENDIENTE POR MONETIZAR | E6: =SUBTOTAL(9,E7:E7) -> 2.8571378e+09
D7: Monetización - facturación y Offycycle Febrero | E7: =22812718.88+65000000+244115339.06+2385335023+116957872+22916818 -> 2.8571378e+09
E8: =SUBTOTAL(9,E4:E7) -> 4.5178413e+09
C11: CUENTAS X PAGAR MES | E11: FEBRERO | F11: Fecha de Elaboración: | I11: 46054
C12: Factura | D12: PROVEEDOR | E12: VALOR | F12: Fecha vencimiento | G12: Estado | I12: KPI | J12: Objeto
D13: PAGOS ANTICIPADOS | E13: =SUBTOTAL(9,E14) -> 25815079
A14: =G14 -> Cancelado | B14: =IF(#REF!<=-1,1,IF(#REF!<=5,2,IF(#REF!<=15,3,IF(H14<=60,4)))) -> #REF! | C14: 1 registro | D14: Nómina Sergio Jimenez Belimo | E14: 25815079 | F14: 46079 | G14: Cancelado | H14: =IF(OR(G14="Sin pagar",G14="Pagar"),NETWORKDAYS($I$11,F14,'Festivos Colombia'!$A$3:$A$22),0) -> 0 | I14: =H14 -> 0
D15: SEGURIDAD SOCIAL | E15: =SUBTOTAL(9,E16:E16) -> 553473400
A16: =G16 -> Cancelado | B16: =IF(#REF!<=-1,1,IF(#REF!<=5,2,IF(#REF!<=15,3,IF(H16<=60,4)))) -> #REF! | D16: Pago seguridad social Global | E16: 553473400 | F16: 46065 | G16: Cancelado | H16: =IF(OR(G16="Sin pagar",G16="Pagar"),NETWORKDAYS($I$11,F16,'Festivos Colombia'!$A$3:$A$22),0) -> 0 | I16: =H16 -> 0
D17: AFC´S | E17: =SUBTOTAL(9,E18:E19) -> 69505500
A18: =G18 -> Cancelado | B18: =IF(#REF!<=-1,1,IF(#REF!<=5,2,IF(#REF!<=15,3,IF(H18<=60,4)))) -> #REF! | C18: 1 | D18: AFC y aportes voluntarios - Cheque | E18: 19300000 | F18: 46080 | G18: Cancelado | H18: =IF(OR(G18="Sin pagar",G18="Pagar"),NETWORKDAYS($I$11,F18,'Festivos Colombia'!$A$3:$A$22),0) -> 0 | I18: =H18 -> 0
A19: =G19 -> Cancelado | B19: =IF(#REF!<=-1,1,IF(#REF!<=5,2,IF(#REF!<=15,3,IF(H19<=60,4)))) -> #REF! | C19: 1 | D19: AFC y aportes voluntarios -SOI y Aportes en Linea | E19: 50205500 | F19: 46077 | G19: Cancelado | H19: =IF(OR(G19="Sin pagar",G19="Pagar"),NETWORKDAYS($I$11,F19,'Festivos Colombia'!$A$3:$A$22),0) -> 0 | I19: =H19 -> 0
D20: IMPUESTOS | E20: =SUBTOTAL(9,E21:E22) -> 261448000 | H20: =IF(OR(G20="Sin pagar",G20="Pagar"),NETWORKDAYS($I$11,F20,'Festivos Colombia'!$A$3:$A$22),0) -> 0 | I20: =H20 -> 0
A21: =G21 -> Cancelado | B21: =IF(#REF!<=-1,1,IF(#REF!<=5,2,IF(#REF!<=15,3,IF(H21<=60,4)))) -> #REF! | D21: Retención en la fuente | E21: 258734000 | F21: 46065 | G21: Cancelado | H21: =IF(OR(G21="Sin pagar",G21="Pagar"),NETWORKDAYS($I$11,F21,'Festivos Colombia'!$A$3:$A$22),0) -> 0 | I21: =H21 -> 0
A22: =G22 -> Cancelado | B22: =IF(#REF!<=-1,1,IF(#REF!<=5,2,IF(#REF!<=15,3,IF(H22<=60,4)))) -> #REF! | D22: ICA anual | E22: 2714000 | F22: 46077 | G22: Cancelado | H22: =IF(OR(G22="Sin pagar",G22="Pagar"),NETWORKDAYS($I$11,F22,'Festivos Colombia'!$A$3:$A$22),0) -> 0 | I22: =H22 -> 0
D23: PLANES COMPLEMENTARIOS Y PREPAGADAS | E23: =SUBTOTAL(9,E24:E29) -> 14951682 | H23: =IF(OR(G23="Sin pagar",G23="Pagar"),NETWORKDAYS($I$11,F23,'Festivos Colombia'!$A$3:$A$22),0) -> 0
A24: =G24 -> Cancelado | B24: =IF(#REF!<=-1,1,IF(#REF!<=5,2,IF(#REF!<=15,3,IF(H24<=60,4)))) -> #REF! | C24: 20911209571 | D24: Póliza suramericana # 091000808150 SALUD FAMILIAR | E24: 576588 | F24: 46078 | G24: Cancelado | H24: =IF(OR(G24="Sin pagar",G24="Pagar"),NETWORKDAYS($I$11,F24,'Festivos Colombia'!$A$3:$A$22),0) -> 0 | I24: =H24 -> 0
A25: =G25 -> Cancelado | B25: =IF(#REF!<=-1,1,IF(#REF!<=5,2,IF(#REF!<=15,3,IF(H25<=60,4)))) -> #REF! | C25: 20911209572 | D25: Póliza suramericana # 091000808150 SALUD FAMILIAR | E25: 165038 | F25: 46078 | G25: Cancelado | H25: =IF(OR(G25="Sin pagar",G25="Pagar"),NETWORKDAYS($I$11,F25,'Festivos Colombia'!$A$3:$A$22),0) -> 0 | I25: =H25 -> 0
A26: =G26 -> Cancelado | B26: =IF(#REF!<=-1,1,IF(#REF!<=5,2,IF(#REF!<=15,3,IF(H26<=60,4)))) -> #REF! | C26: 20911209573 | D26: Póliza suramericana # 091000808150 SALUD FAMILIAR | E26: 169028 | F26: 46078 | G26: Cancelado | H26: =IF(OR(G26="Sin pagar",G26="Pagar"),NETWORKDAYS($I$11,F26,'Festivos Colombia'!$A$3:$A$22),0) -> 0 | I26: =H26 -> 0
A27: =G27 -> Cancelado | B27: =IF(#REF!<=-1,1,IF(#REF!<=5,2,IF(#REF!<=15,3,IF(H27<=60,4)))) -> #REF! | C27: 20911214073 | D27: Póliza suramericana # 091000808150 SALUD FAMILIAR | E27: 2196266 | F27: 46084 | G27: Cancelado | H27: =IF(OR(G27="Sin pagar",G27="Pagar"),NETWORKDAYS($I$11,F27,'Festivos Colombia'!$A$3:$A$22),0) -> 0 | I27: =H27 -> 0
A28: =G28 -> Cancelado | B28: =IF(#REF!<=-1,1,IF(#REF!<=5,2,IF(#REF!<=15,3,IF(H28<=60,4)))) -> #REF! | C28: 209833411130 | D28: Póliza suramericana # 0904418894 SALUD FAMILIAR | E28: 437176 | F28: 46084 | G28: Cancelado | H28: =IF(OR(G28="Sin pagar",G28="Pagar"),NETWORKDAYS($I$11,F28,'Festivos Colombia'!$A$3:$A$22),0) -> 0 | I28: =H28 -> 0
A29: =G29 -> Cancelado | B29: =IF(#REF!<=-1,1,IF(#REF!<=5,2,IF(#REF!<=15,3,IF(H29<=60,4)))) -> #REF! | C29: 20911213105 | D29: Póliza suramericana # 091000808150 SALUD FAMILIAR | E29: 11407586 | F29: 46084 | G29: Cancelado | H29: =IF(OR(G29="Sin pagar",G29="Pagar"),NETWORKDAYS($I$11,F29,'Festivos Colombia'!$A$3:$A$22),0) -> 0 | I29: =H29 -> 0
D30: PÓLIZAS Y SEGUROS | E30: =SUBTOTAL(9,E31:E40) -> 20743199 | H30: =IF(OR(G30="Sin pagar",G30="Pagar"),NETWORKDAYS($I$11,F30,'Festivos Colombia'!$A$3:$A$22),0) -> 0
A31: =G31 -> Cancelado | B31: =IF(#REF!<=-1,1,IF(#REF!<=5,2,IF(#REF!<=15,3,IF(H31<=60,4)))) -> #REF! | C31: 10175650 | D31: Plan grupo 10108069057 | E31: =13580700 -> 13580700 | F31: 46058 | G31: Cancelado | H31: =IF(OR(G31="Sin pagar",G31="Pagar"),NETWORKDAYS($I$11,F31,'Festivos Colombia'!$A$3:$A$22),0) -> 0 | I31: =H31 -> 0
A32: =G32 -> Cancelado | B32: =IF(#REF!<=-1,1,IF(#REF!<=5,2,IF(#REF!<=15,3,IF(H32<=60,4)))) -> #REF! | C32: 10226780 | D32: Plan grupo 103226992 - Aana Aguirre - GRAINGER SERVICES INTERNATIONA | E32: =205538 -> 205538 | F32: 46058 | G32: Cancelado | H32: =IF(OR(G32="Sin pagar",G32="Pagar"),NETWORKDAYS($I$11,F32,'Festivos Colombia'!$A$3:$A$22),0) -> 0 | I32: =H32 -> 0
A33: =G33 -> Cancelado | B33: =IF(#REF!<=-1,1,IF(#REF!<=5,2,IF(#REF!<=15,3,IF(H33<=60,4)))) -> #REF! | C33: 10090637 | D33: Plan dental 103229130 Luna Rodriguez - LANO SOFTWARE GMBH | E33: =316953 -> 316953 | F33: 46058 | G33: Cancelado | H33: =IF(OR(G33="Sin pagar",G33="Pagar"),NETWORKDAYS($I$11,F33,'Festivos Colombia'!$A$3:$A$22),0) -> 0 | I33: =H33 -> 0
A34: =G34 -> Cancelado | B34: =IF(#REF!<=-1,1,IF(#REF!<=5,2,IF(#REF!<=15,3,IF(H34<=60,4)))) -> #REF! | C34: 10238635 | D34: Plan dental 10325327 Ivonne Torres | E34: =314213 -> 314213 | F34: 46058 | G34: Cancelado | H34: =IF(OR(G34="Sin pagar",G34="Pagar"),NETWORKDAYS($I$11,F34,'Festivos Colombia'!$A$3:$A$22),0) -> 0 | I34: =H34 -> 0
A35: =G35 -> Cancelado | B35: =IF(#REF!<=-1,1,IF(#REF!<=5,2,IF(#REF!<=15,3,IF(H35<=60,4)))) -> #REF! | C35: 10225583 | D35: Plan grupo 10108170475 - Sandra Barba - ALLEGIS GROUP INC | E35: =1751400 -> 1751400 | F35: 46058 | G35: Cancelado | H35: =IF(OR(G35="Sin pagar",G35="Pagar"),NETWORKDAYS($I$11,F35,'Festivos Colombia'!$A$3:$A$22),0) -> 0 | I35: =H35 -> 0
A36: =G36 -> Cancelado | B36: =IF(#REF!<=-1,1,IF(#REF!<=5,2,IF(#REF!<=15,3,IF(H36<=60,4)))) -> #REF! | C36: 10230226 | D36: Plan grupo 103225452 - Freddy Gomez - TITAN METER BIDCO CORPORATION | E36: =339255 -> 339255 | F36: 46059 | G36: Cancelado | H36: =IF(OR(G36="Sin pagar",G36="Pagar"),NETWORKDAYS($I$11,F36,'Festivos Colombia'!$A$3:$A$22),0) -> 0 | I36: =H36 -> 0
A37: =G37 -> Cancelado | B37: =IF(#REF!<=-1,1,IF(#REF!<=5,2,IF(#REF!<=15,3,IF(H37<=60,4)))) -> #REF! | C37: 10173108 | D37: Plan grupo-103229134 - María Amaya Gomez - LANO SOFTWARE | E37: =71820 -> 71820 | F37: 46058 | G37: Cancelado | H37: =IF(OR(G37="Sin pagar",G37="Pagar"),NETWORKDAYS($I$11,F37,'Festivos Colombia'!$A$3:$A$22),0) -> 0 | I37: =H37 -> 0
A38: =G38 -> Cancelado | B38: =IF(#REF!<=-1,1,IF(#REF!<=5,2,IF(#REF!<=15,3,IF(H38<=60,4)))) -> #REF! | C38: 10094969 | D38: Plan grupo 10108174837 - Freddy Gomez - TITAN METER BIDCO CORPORATION | E38: =1984500 -> 1984500 | F38: 46058 | G38: Cancelado | H38: =IF(OR(G38="Sin pagar",G38="Pagar"),NETWORKDAYS($I$11,F38,'Festivos Colombia'!$A$3:$A$22),0) -> 0 | I38: =H38 -> 0
A39: =G39 -> Cancelado | B39: =IF(#REF!<=-1,1,IF(#REF!<=5,2,IF(#REF!<=15,3,IF(H39<=60,4)))) -> #REF! | C39: 10245676 | D39: Plan grupo-103229134 - María Gabriela Acosta - LANO SOFTWARE | E39: =71820 -> 71820 | F39: 46058 | G39: Cancelado | H39: =IF(OR(G39="Sin pagar",G39="Pagar"),NETWORKDAYS($I$11,F39,'Festivos Colombia'!$A$3:$A$22),0) -> 0 | I39: =H39 -> 0
A40: =G40 -> Cancelado | B40: =IF(#REF!<=-1,1,IF(#REF!<=5,2,IF(#REF!<=15,3,IF(H40<=60,4)))) -> #REF! | C40: 10245676 | D40: Póliza Sanitas Carlos Urrego | E40: 2107000 | F40: 46069 | G40: Cancelado | H40: =IF(OR(G40="Sin pagar",G40="Pagar"),NETWORKDAYS($I$11,F40,'Festivos Colombia'!$A$3:$A$22),0) -> 0 | I40: =H40 -> 0
D41: REEMBOLSO GASTOS VIAJE | E41: =SUBTOTAL(9,E42:E91) -> 1.2685418e+08
D42: Reembolso Maria Claudia Bohorquez cc020 - sophos | E42: 226425 | F42: 46059 | G42: Cancelado | H42: =IF(OR(G42="Sin pagar",G42="Pagar"),NETWORKDAYS($I$11,F42,'Festivos Colombia'!$A$3:$A$22),0) -> 0 | I42: =H42 -> 0
D43: Reembolso Fabian Augusto Porto Dulcey cc020 - Sophos | E43: 4250341 | F43: 46059 | G43: Cancelado | H43: =IF(OR(G43="Sin pagar",G43="Pagar"),NETWORKDAYS($I$11,F43,'Festivos Colombia'!$A$3:$A$22),0) -> 0 | I43: =H43 -> 0
D44: Reembolso Ivonne Torres-cc012 - lifenet health | E44: 298700 | F44: 46059 | G44: Cancelado | H44: =IF(OR(G44="Sin pagar",G44="Pagar"),NETWORKDAYS($I$11,F44,'Festivos Colombia'!$A$3:$A$22),0) -> 0 | I44: =H44 -> 0
...

Sheet MARZO
E1: 42400
D4: BANCOS | E4: =SUBTOTAL(9,E5:E5) -> 1.3036721e+09
D5: Bancos | E5: =FEBRERO!E129 -> 1.3036721e+09
D6: FACTURACIÓN PENDIENTE POR MONETIZAR | E6: =SUBTOTAL(9,E7:E7) -> 2.8172875e+09
D7: Monetización - facturación y Offycycle Marzo | E7: =2672864.02+7831260.8+47157848.5+71157372.72+2651028558.59+5475747+56288376-24324546.76 -> 2.8172875e+09
E8: =SUBTOTAL(9,E4:E7) -> 4.1209596e+09
C11: CUENTAS X PAGAR MES | E11: MARZO | F11: Fecha de Elaboración: | I11: 46082
C12: Factura | D12: PROVEEDOR | E12: VALOR | F12: Fecha vencimiento | G12: Estado | I12: KPI | J12: Objeto
D13: PAGOS ANTICIPADOS | E13: =SUBTOTAL(9,E14) -> 29793135
A14: =G14 -> Cancelado | B14: =IF(#REF!<=-1,1,IF(#REF!<=5,2,IF(#REF!<=15,3,IF(H14<=60,4)))) -> #REF! | C14: 1 registro | D14: Nómina Sergio Jimenez Belimo | E14: 29793135 | F14: 46108 | G14: Cancelado | H14: =IF(OR(G14="Sin pagar",G14="Pagar"),NETWORKDAYS($I$11,F14,'Festivos Colombia'!$A$3:$A$22),0) -> 0 | I14: =H14 -> 0
D15: SEGURIDAD SOCIAL | E15: =SUBTOTAL(9,E16:E16) -> 623291500
A16: =G16 -> Cancelado | B16: =IF(#REF!<=-1,1,IF(#REF!<=5,2,IF(#REF!<=15,3,IF(H16<=60,4)))) -> #REF! | D16: Pago seguridad social Global | E16: 623291500 | F16: 46091 | G16: Cancelado | H16: =IF(OR(G16="Sin pagar",G16="Pagar"),NETWORKDAYS($I$11,F16,'Festivos Colombia'!$A$3:$A$22),0) -> 0 | I16: =H16 -> 0
D17: AFC´S | E17: =SUBTOTAL(9,E18:E19) -> 67234163
A18: =G18 -> Cancelado | B18: =IF(#REF!<=-1,1,IF(#REF!<=5,2,IF(#REF!<=15,3,IF(H18<=60,4)))) -> #REF! | C18: 1 | D18: AFC y aportes voluntarios - Cheque | E18: 21300000 | F18: 46108 | G18: Cancelado | H18: =IF(OR(G18="Sin pagar",G18="Pagar"),NETWORKDAYS($I$11,F18,'Festivos Colombia'!$A$3:$A$22),0) -> 0 | I18: =H18 -> 0
A19: =G19 -> Cancelado | B19: =IF(#REF!<=-1,1,IF(#REF!<=5,2,IF(#REF!<=15,3,IF(H19<=60,4)))) -> #REF! | C19: 1 | D19: AFC y aportes voluntarios -SOI y Aportes en Linea | E19: 45934163 | F19: 46111 | G19: Cancelado | H19: =IF(OR(G19="Sin pagar",G19="Pagar"),NETWORKDAYS($I$11,F19,'Festivos Colombia'!$A$3:$A$22),0) -> 0 | I19: =H19 -> 0
D20: IMPUESTOS | E20: =SUBTOTAL(9,E21:E22) -> 332839000 | H20: =IF(OR(G20="Sin pagar",G20="Pagar"),NETWORKDAYS($I$11,F20,'Festivos Colombia'!$A$3:$A$22),0) -> 0 | I20: =H20 -> 0
A21: =G21 -> Cancelado | B21: =IF(#REF!<=-1,1,IF(#REF!<=5,2,IF(#REF!<=15,3,IF(H21<=60,4)))) -> #REF! | D21: Retención en la fuente | E21: 332523000 | F21: 46093 | G21: Cancelado | H21: =IF(OR(G21="Sin pagar",G21="Pagar"),NETWORKDAYS($I$11,F21,'Festivos Colombia'!$A$3:$A$22),0) -> 0 | I21: =H21 -> 0
A22: =G22 -> Cancelado | B22: =IF(#REF!<=-1,1,IF(#REF!<=5,2,IF(#REF!<=15,3,IF(H22<=60,4)))) -> #REF! | D22: Reteica 1er bimestre 2026 | E22: 316000 | F22: 46100 | G22: Cancelado | H22: =IF(OR(G22="Sin pagar",G22="Pagar"),NETWORKDAYS($I$11,F22,'Festivos Colombia'!$A$3:$A$22),0) -> 0 | I22: =H22 -> 0
D23: PLANES COMPLEMENTARIOS Y PREPAGADAS | E23: =SUBTOTAL(9,E24:E29) -> 15400832 | H23: =IF(OR(G23="Sin pagar",G23="Pagar"),NETWORKDAYS($I$11,F23,'Festivos Colombia'!$A$3:$A$22),0) -> 0
A24: =G24 -> Cancelado | B24: =IF(#REF!<=-1,1,IF(#REF!<=5,2,IF(#REF!<=15,3,IF(H24<=60,4)))) -> #REF! | C24: 20911217888 | D24: Póliza suramericana # 091000808150 SALUD FAMILIAR | E24: 14963656 | F24: 46111 | G24: Cancelado | H24: =IF(OR(G24="Sin pagar",G24="Pagar"),NETWORKDAYS($I$11,F24,'Festivos Colombia'!$A$3:$A$22),0) -> 0 | I24: =H24 -> 0
A25: =G25 -> Cancelado | B25: =IF(#REF!<=-1,1,IF(#REF!<=5,2,IF(#REF!<=15,3,IF(H25<=60,4)))) -> #REF! | C25: 20833457861 | D25: Póliza suramericana # 0904418894 SALUD FAMILIAR | E25: 437176 | F25: 46111 | G25: Cancelado | H25: =IF(OR(G25="Sin pagar",G25="Pagar"),NETWORKDAYS($I$11,F25,'Festivos Colombia'!$A$3:$A$22),0) -> 0 | I25: =H25 -> 0
A26: =G26 -> Sin Pagar | B26: =IF(#REF!<=-1,1,IF(#REF!<=5,2,IF(#REF!<=15,3,IF(H26<=60,4)))) -> #REF! | C26: 20911209572 | D26: Póliza suramericana # 091000808150 SALUD FAMILIAR | E26: =576588*0 -> 0 | F26: 46122 | G26: Sin Pagar | H26: =IF(OR(G26="Sin pagar",G26="Pagar"),NETWORKDAYS($I$11,F26,'Festivos Colombia'!$A$3:$A$22),0) -> 27 | I26: =H26 -> 27 | J26: Sin radicar
A27: =G27 -> Sin Pagar | B27: =IF(#REF!<=-1,1,IF(#REF!<=5,2,IF(#REF!<=15,3,IF(H27<=60,4)))) -> #REF! | C27: 20911209573 | D27: Póliza suramericana # 091000808150 SALUD FAMILIAR | E27: =576588*0 -> 0 | F27: 46122 | G27: Sin Pagar | H27: =IF(OR(G27="Sin pagar",G27="Pagar"),NETWORKDAYS($I$11,F27,'Festivos Colombia'!$A$3:$A$22),0) -> 27 | I27: =H27 -> 27 | J27: Sin radicar
A28: =G28 -> Sin Pagar | B28: =IF(#REF!<=-1,1,IF(#REF!<=5,2,IF(#REF!<=15,3,IF(H28<=60,4)))) -> #REF! | C28: 20911214073 | D28: Póliza suramericana # 091000808150 SALUD FAMILIAR | E28: =576588*0 -> 0 | F28: 46122 | G28: Sin Pagar | H28: =IF(OR(G28="Sin pagar",G28="Pagar"),NETWORKDAYS($I$11,F28,'Festivos Colombia'!$A$3:$A$22),0) -> 27 | I28: =H28 -> 27 | J28: Sin radicar
A29: =G29 -> Sin Pagar | B29: =IF(#REF!<=-1,1,IF(#REF!<=5,2,IF(#REF!<=15,3,IF(H29<=60,4)))) -> #REF! | C29: 20911213105 | D29: Póliza suramericana # 091000808150 SALUD FAMILIAR | E29: =576588*0 -> 0 | F29: 46122 | G29: Sin Pagar | H29: =IF(OR(G29="Sin pagar",G29="Pagar"),NETWORKDAYS($I$11,F29,'Festivos Colombia'!$A$3:$A$22),0) -> 27 | I29: =H29 -> 27 | J29: Sin radicar
D30: PÓLIZAS Y SEGUROS | E30: =SUBTOTAL(9,E34:E36) -> 18535234 | H30: =IF(OR(G30="Sin pagar",G30="Pagar"),NETWORKDAYS($I$11,F30,'Festivos Colombia'!$A$3:$A$22),0) -> 0
A31: =G31 -> Cancelado | B31: =IF(#REF!<=-1,1,IF(#REF!<=5,2,IF(#REF!<=15,3,IF(H31<=60,4)))) -> #REF! | C31: 10304561 | D31: Plan grupo 10108170475 - Sandra Barba - ALLEGIS GROUP INC | E31: =1751400 -> 1751400 | F31: 46091 | G31: Cancelado | H31: =IF(OR(G31="Sin pagar",G31="Pagar"),NETWORKDAYS($I$11,F31,'Festivos Colombia'!$A$3:$A$22),0) -> 0 | I31: =H31 -> 0
A32: =G32 -> Cancelado | B32: =IF(#REF!<=-1,1,IF(#REF!<=5,2,IF(#REF!<=15,3,IF(H32<=60,4)))) -> #REF! | C32: 12310455687 | D32: Plan Dental 103232083 | E32: 1080034 | F32: 46097 | G32: Cancelado | H32: =IF(OR(G32="Sin pagar",G32="Pagar"),NETWORKDAYS($I$11,F32,'Festivos Colombia'!$A$3:$A$22),0) -> 0 | I32: =H32 -> 0
A33: =G33 -> Cancelado | B33: =IF(#REF!<=-1,1,IF(#REF!<=5,2,IF(#REF!<=15,3,IF(H33<=60,4)))) -> #REF! | C33: 12310455690 | D33: Plan salud 10108211747 | E33: 15703800 | F33: 46097 | G33: Cancelado | H33: =IF(OR(G33="Sin pagar",G33="Pagar"),NETWORKDAYS($I$11,F33,'Festivos Colombia'!$A$3:$A$22),0) -> 0 | I33: =H33 -> 0
A34: =G34 -> Cancelado | B34: =IF(#REF!<=-1,1,IF(#REF!<=5,2,IF(#REF!<=15,3,IF(H34<=60,4)))) -> #REF! | C34: 12310603651 | D34: Plan grupo 10108170475 - Sandra Barba - ALLEGIS GROUP INC | E34: =1751400 -> 1751400 | F34: 46119 | G34: Cancelado | H34: =IF(OR(G34="Sin pagar",G34="Pagar"),NETWORKDAYS($I$11,F34,'Festivos Colombia'!$A$3:$A$22),0) -> 0 | I34: =H34 -> 0
A35: =G35 -> Cancelado | B35: =IF(#REF!<=-1,1,IF(#REF!<=5,2,IF(#REF!<=15,3,IF(H35<=60,4)))) -> #REF! | C35: 12310458522 | D35: Plan Dental 103232083 | E35: 1080034 | F35: 46123 | G35: Cancelado | H35: =IF(OR(G35="Sin pagar",G35="Pagar"),NETWORKDAYS($I$11,F35,'Festivos Colombia'!$A$3:$A$22),0) -> 0 | I35: =H35 -> 0
A36: =G36 -> Cancelado | B36: =IF(#REF!<=-1,1,IF(#REF!<=5,2,IF(#REF!<=15,3,IF(H36<=60,4)))) -> #REF! | C36: 12310459539 | D36: Plan salud 10108211747 | E36: 15703800 | F36: 46123 | G36: Cancelado | H36: =IF(OR(G36="Sin pagar",G36="Pagar"),NETWORKDAYS($I$11,F36,'Festivos Colombia'!$A$3:$A$22),0) -> 0 | I36: =H36 -> 0
D37: REEMBOLSO GASTOS VIAJE | E37: =SUBTOTAL(9,E38:E84) -> 1.8858256e+08
D38: Reembolso Camila Marin Melo cc020 - sophos | E38: 197477 | F38: 46093 | G38: Cancelado | H38: =IF(OR(G38="Sin pagar",G38="Pagar"),NETWORKDAYS($I$11,F38,'Festivos Colombia'!$A$3:$A$22),0) -> 0 | I38: =H38 -> 0
D39: Reembolso Cristiam Silva cc020 - sophos | E39: 368769 | F39: 46093 | G39: Cancelado | H39: =IF(OR(G39="Sin pagar",G39="Pagar"),NETWORKDAYS($I$11,F39,'Festivos Colombia'!$A$3:$A$22),0) -> 0 | I39: =H39 -> 0
D40: Reembolso Cristian Javier Gutierrez Torres-cc020 - Sophos | E40: 2459151 | F40: 46093 | G40: Cancelado | H40: =IF(OR(G40="Sin pagar",G40="Pagar"),NETWORKDAYS($I$11,F40,'Festivos Colombia'!$A$3:$A$22),0) -> 0 | I40: =H40 -> 0
D41: Reembolso Daniel Alberto Ramos Duran cc040 - Environmental Dynamics INTL | E41: 575750 | F41: 46093 | G41: Cancelado | H41: =IF(OR(G41="Sin pagar",G41="Pagar"),NETWORKDAYS($I$11,F41,'Festivos Colombia'!$A$3:$A$22),0) -> 0 | I41: =H41 -> 0
D42: Reembolso Ivonne Torres-cc012 - lifenet health | E42: 7661306.2 | F42: 46093 | G42: Cancelado | H42: =IF(OR(G42="Sin pagar",G42="Pagar"),NETWORKDAYS($I$11,F42,'Festivos Colombia'!$A$3:$A$22),0) -> 0 | I42: =H42 -> 0
D43: Reembolso Jhon Jairo Garzon Beleño cc020 - Sophos | E43: 6469600 | F43: 46093 | G43: Cancelado | H43: =IF(OR(G43="Sin pagar",G43="Pagar"),NETWORKDAYS($I$11,F43,'Festivos Colombia'!$A$3:$A$22),0) -> 0 | I43: =H43 -> 0
D44: Reembolso Lina Marcela Gomez Nuñez cc083 - Acaps | E44: 54300 | F44: 46093 | G44: Cancelado | H44: =IF(OR(G44="Sin pagar",G44="Pagar"),NETWORKDAYS($I$11,F44,'Festivos Colombia'!$A$3:$A$22),0) -> 0 | I44: =H44 -> 0
...

Sheet ABRIL
E1: 42400
D4: BANCOS | E4: =SUBTOTAL(9,E5:E5) -> 1.2068599e+09
D5: Bancos | E5: =MARZO!$E$121 -> 1.2068599e+09
D6: FACTURACIÓN PENDIENTE POR MONETIZAR | E6: =SUBTOTAL(9,E7:E7) -> 3.1908855e+09
D7: Monetización - facturación y Offycycle Abril | E7: =5553553.2+8903168.4+54058.69+279638141.4+2657714938.49+106046819.2+33451228+30169695.15+69353897 -> 3.1908855e+09
E8: =SUBTOTAL(9,E4:E7) -> 4.3977454e+09
C11: CUENTAS X PAGAR MES | E11: ABRIL | F11: Fecha de Elaboración: | I11: 46113
C12: Factura | D12: PROVEEDOR | E12: VALOR | F12: Fecha vencimiento | G12: Estado | I12: KPI | J12: Objeto
D13: PAGOS ANTICIPADOS | E13: =SUBTOTAL(9,E14) -> 25815079
A14: =G14 -> Cancelado | B14: =IF(#REF!<=-1,1,IF(#REF!<=5,2,IF(#REF!<=15,3,IF(H14<=60,4)))) -> #REF! | C14: 1 registro | D14: Nómina Sergio Jimenez Belimo | E14: 25815079 | F14: 46140 | G14: Cancelado | H14: =IF(OR(G14="Sin pagar",G14="Pagar"),NETWORKDAYS($I$11,F14,'Festivos Colombia'!$A$3:$A$22),0) -> 0 | I14: =H14 -> 0
D15: SEGURIDAD SOCIAL | E15: =SUBTOTAL(9,E16:E16) -> 648657500
A16: =G16 -> Cancelado | B16: =IF(#REF!<=-1,1,IF(#REF!<=5,2,IF(#REF!<=15,3,IF(H16<=60,4)))) -> #REF! | D16: Pago seguridad social Global | E16: 648657500 | F16: 46128 | G16: Cancelado | H16: =IF(OR(G16="Sin pagar",G16="Pagar"),NETWORKDAYS($I$11,F16,'Festivos Colombia'!$A$3:$A$22),0) -> 0 | I16: =H16 -> 0 | J16: 648217000 | K16: =+J16-E16 -> -440500
D17: AFC´S | E17: =SUBTOTAL(9,E18:E19) -> 77581011
A18: =G18 -> Cancelado | B18: =IF(#REF!<=-1,1,IF(#REF!<=5,2,IF(#REF!<=15,3,IF(H18<=60,4)))) -> #REF! | C18: 1 | D18: AFC y aportes voluntarios - Cheque | E18: 18566667 | F18: 46139 | G18: Cancelado | H18: =IF(OR(G18="Sin pagar",G18="Pagar"),NETWORKDAYS($I$11,F18,'Festivos Colombia'!$A$3:$A$22),0) -> 0 | I18: =H18 -> 0
A19: =G19 -> Cancelado | B19: =IF(#REF!<=-1,1,IF(#REF!<=5,2,IF(#REF!<=15,3,IF(H19<=60,4)))) -> #REF! | C19: 1 | D19: AFC y aportes voluntarios -SOI y Aportes en Linea | E19: 59014344 | F19: 46140 | G19: Cancelado | H19: =IF(OR(G19="Sin pagar",G19="Pagar"),NETWORKDAYS($I$11,F19,'Festivos Colombia'!$A$3:$A$22),0) -> 0 | I19: =H19 -> 0
D20: IMPUESTOS | E20: =SUBTOTAL(9,E21:E21) -> 340661000 | H20: =IF(OR(G20="Sin pagar",G20="Pagar"),NETWORKDAYS($I$11,F20,'Festivos Colombia'!$A$3:$A$22),0) -> 0 | I20: =H20 -> 0
A21: =G21 -> Cancelado | B21: =IF(#REF!<=-1,1,IF(#REF!<=5,2,IF(#REF!<=15,3,IF(H21<=60,4)))) -> #REF! | D21: Retención en la fuente | E21: 340661000 | F21: 46126 | G21: Cancelado | H21: =IF(OR(G21="Sin pagar",G21="Pagar"),NETWORKDAYS($I$11,F21,'Festivos Colombia'!$A$3:$A$22),0) -> 0 | I21: =H21 -> 0
D22: PLANES COMPLEMENTARIOS Y PREPAGADAS | E22: =SUBTOTAL(9,E23:E26) -> 17294698 | H22: =IF(OR(G22="Sin pagar",G22="Pagar"),NETWORKDAYS($I$11,F22,'Festivos Colombia'!$A$3:$A$22),0) -> 0
A23: =G23 -> Cancelado | B23: =IF(#REF!<=-1,1,IF(#REF!<=5,2,IF(#REF!<=15,3,IF(H23<=60,4)))) -> #REF! | C23: 20833471824 | D23: Póliza suramericana # 0904418894 SALUD FAMILIAR | E23: 15052 | F23: 46135 | G23: Cancelado | H23: =IF(OR(G23="Sin pagar",G23="Pagar"),NETWORKDAYS($I$11,F23,'Festivos Colombia'!$A$3:$A$22),0) -> 0 | I23: =H23 -> 0
A24: =G24 -> Cancelado | B24: =IF(#REF!<=-1,1,IF(#REF!<=5,2,IF(#REF!<=15,3,IF(H24<=60,4)))) -> #REF! | C24: 12310363886 | D24: Póliza suramericana # 091000808150 SALUD FAMILIAR | E24: 1864800 | F24: 46139 | G24: Cancelado | H24: =IF(OR(G24="Sin pagar",G24="Pagar"),NETWORKDAYS($I$11,F24,'Festivos Colombia'!$A$3:$A$22),0) -> 0 | I24: =H24 -> 0
A25: =G25 -> Cancelado | B25: =IF(#REF!<=-1,1,IF(#REF!<=5,2,IF(#REF!<=15,3,IF(H25<=60,4)))) -> #REF! | C25: 20911224616 | D25: Póliza suramericana # 091000808150 SALUD FAMILIAR | E25: 14963656 | F25: 46141 | G25: Cancelado | H25: =IF(OR(G25="Sin pagar",G25="Pagar"),NETWORKDAYS($I$11,F25,'Festivos Colombia'!$A$3:$A$22),0) -> 0 | I25: =H25 -> 0
A26: =G26 -> Cancelado | B26: =IF(#REF!<=-1,1,IF(#REF!<=5,2,IF(#REF!<=15,3,IF(H26<=60,4)))) -> #REF! | C26: 20833497839 | D26: Póliza suramericana # 0904418894 SALUD FAMILIAR | E26: 451190 | F26: 46141 | G26: Cancelado | H26: =IF(OR(G26="Sin pagar",G26="Pagar"),NETWORKDAYS($I$11,F26,'Festivos Colombia'!$A$3:$A$22),0) -> 0 | I26: =H26 -> 0
D27: PÓLIZAS Y SEGUROS | E27: =SUBTOTAL(9,E28:E30) -> 0 | H27: =IF(OR(G27="Sin pagar",G27="Pagar"),NETWORKDAYS($I$11,F27,'Festivos Colombia'!$A$3:$A$22),0) -> 0
A28: =G28 -> Cancelado | B28: =IF(#REF!<=-1,1,IF(#REF!<=5,2,IF(#REF!<=15,3,IF(H28<=60,4)))) -> #REF! | C28: 12310603651 | D28: Plan grupo 10108170475 - Sandra Barba - ALLEGIS GROUP INC | E28: =1751400*0 -> 0 | F28: 46119 | G28: Cancelado | H28: =IF(OR(G28="Sin pagar",G28="Pagar"),NETWORKDAYS($I$11,F28,'Festivos Colombia'!$A$3:$A$22),0) -> 0 | I28: =H28 -> 0
A29: =G29 -> Cancelado | B29: =IF(#REF!<=-1,1,IF(#REF!<=5,2,IF(#REF!<=15,3,IF(H29<=60,4)))) -> #REF! | C29: 12310458522 | D29: Plan Dental 103232083 | E29: =1080034*0 -> 0 | F29: 46119 | G29: Cancelado | H29: =IF(OR(G29="Sin pagar",G29="Pagar"),NETWORKDAYS($I$11,F29,'Festivos Colombia'!$A$3:$A$22),0) -> 0 | I29: =H29 -> 0
A30: =G30 -> Cancelado | B30: =IF(#REF!<=-1,1,IF(#REF!<=5,2,IF(#REF!<=15,3,IF(H30<=60,4)))) -> #REF! | C30: 12310459539 | D30: Plan salud 10108211747 | E30: =15703800*0 -> 0 | F30: 46119 | G30: Cancelado | H30: =IF(OR(G30="Sin pagar",G30="Pagar"),NETWORKDAYS($I$11,F30,'Festivos Colombia'!$A$3:$A$22),0) -> 0 | I30: =H30 -> 0
D31: REEMBOLSO GASTOS VIAJE | E31: =SUBTOTAL(9,E32:E83) -> 1.0005003e+08
D32: Reembolso Cristiam Silva cc020 - sophos | E32: =3861857*0 -> 0 | F32: 46113 | G32: Cancelado | H32: =IF(OR(G32="Sin pagar",G32="Pagar"),NETWORKDAYS($I$11,F32,'Festivos Colombia'!$A$3:$A$22),0) -> 0 | I32: =H32 -> 0
D33: Reembolso Carla Georgina Arcia - CC083 - ACAPS | E33: =531900*0 -> 0 | F33: 46113 | G33: Cancelado | H33: =IF(OR(G33="Sin pagar",G33="Pagar"),NETWORKDAYS($I$11,F33,'Festivos Colombia'!$A$3:$A$22),0) -> 0 | I33: =H33 -> 0
D34: Reembolso Maria Claudia Bohorquez cc020 - sophos | E34: =51272*0 -> 0 | F34: 46113 | G34: Cancelado | H34: =IF(OR(G34="Sin pagar",G34="Pagar"),NETWORKDAYS($I$11,F34,'Festivos Colombia'!$A$3:$A$22),0) -> 0 | I34: =H34 -> 0
D35: Reembolso Cristian Javier Gutierrez Torres-cc020 - Sophos | E35: =433968*0 -> 0 | F35: 46113 | G35: Cancelado | H35: =IF(OR(G35="Sin pagar",G35="Pagar"),NETWORKDAYS($I$11,F35,'Festivos Colombia'!$A$3:$A$22),0) -> 0 | I35: =H35 -> 0
D36: Reembolso Daniel Alberto Ramos Duran cc040 - Environmental Dynamics INTL | E36: =4848643*0 -> 0 | F36: 46113 | G36: Cancelado | H36: =IF(OR(G36="Sin pagar",G36="Pagar"),NETWORKDAYS($I$11,F36,'Festivos Colombia'!$A$3:$A$22),0) -> 0 | I36: =H36 -> 0
D37: Reembolso Ivonne Torres-cc012 - lifenet health | E37: =104600*0 -> 0 | F37: 46113 | G37: Cancelado | H37: =IF(OR(G37="Sin pagar",G37="Pagar"),NETWORKDAYS($I$11,F37,'Festivos Colombia'!$A$3:$A$22),0) -> 0 | I37: =H37 -> 0
D38: Reembolso Jhon Jairo Garzon Beleño cc020 - Sophos | E38: =4669650*0 -> 0 | F38: 46113 | G38: Cancelado | H38: =IF(OR(G38="Sin pagar",G38="Pagar"),NETWORKDAYS($I$11,F38,'Festivos Colombia'!$A$3:$A$22),0) -> 0 | I38: =H38 -> 0
D39: Reembolso Lina Marcela Gomez Nuñez cc083 - Acaps | E39: =906118*0 -> 0 | F39: 46113 | G39: Cancelado | H39: =IF(OR(G39="Sin pagar",G39="Pagar"),NETWORKDAYS($I$11,F39,'Festivos Colombia'!$A$3:$A$22),0) -> 0 | I39: =H39 -> 0
D40: Reembolso Milagro del Vallle Sanchez cc020 - sophos | E40: =4672644*0 -> 0 | F40: 46113 | G40: Cancelado | H40: =IF(OR(G40="Sin pagar",G40="Pagar"),NETWORKDAYS($I$11,F40,'Festivos Colombia'!$A$3:$A$22),0) -> 0 | I40: =H40 -> 0
D41: Reembolso Monica Martinez CC082 - CHRISTEL HOUSE INTERNATIONAL | E41: =5157482*0 -> 0 | F41: 46113 | G41: Cancelado | H41: =IF(OR(G41="Sin pagar",G41="Pagar"),NETWORKDAYS($I$11,F41,'Festivos Colombia'!$A$3:$A$22),0) -> 0 | I41: =H41 -> 0
D42: Reembolso Paula Andrea Alba Grajales CC077 - LANO SOFTWARE GMBH | E42: =4756267*0 -> 0 | F42: 46113 | G42: Cancelado | H42: =IF(OR(G42="Sin pagar",G42="Pagar"),NETWORKDAYS($I$11,F42,'Festivos Colombia'!$A$3:$A$22),0) -> 0 | I42: =H42 -> 0
D43: Reembolso Cristiam Silva cc020 - sophos | E43: 278017 | F43: 46122 | G43: Cancelado | H43: =IF(OR(G43="Sin pagar",G43="Pagar"),NETWORKDAYS($I$11,F43,'Festivos Colombia'!$A$3:$A$22),0) -> 0 | I43: =H43 -> 0
D44: Reembolso Daniel Alberto Ramos Duran cc040 - Environmental Dynamics INTL | E44: 8438461 | F44: 46122 | G44: Cancelado | H44: =IF(OR(G44="Sin pagar",G44="Pagar"),NETWORKDAYS($I$11,F44,'Festivos Colombia'!$A$3:$A$22),0) -> 0 | I44: =H44 -> 0
...

Sheet MAYO
E1: 42400
D4: BANCOS | E4: =SUBTOTAL(9,E5:E5) -> 1.2837765e+09
D5: Bancos | E5: =ABRIL!$F$146 -> 1.2837765e+09
D6: FACTURACIÓN PENDIENTE POR MONETIZAR | E6: =SUBTOTAL(9,E7:E7) -> 10328391
D7: Monetización - facturación y Offycycle mayo | E7: 10328391
E8: =SUBTOTAL(9,E4:E7) -> 1.2941049e+09
C11: CUENTAS X PAGAR MES | E11: MAYO | F11: Fecha de Elaboración: | I11: 46143
C12: Factura | D12: PROVEEDOR | E12: VALOR | F12: Fecha vencimiento | G12: Estado | I12: KPI | J12: Objeto
D13: PAGOS ANTICIPADOS | E13: =SUBTOTAL(9,E14) -> 25815079
A14: =G14 -> Sin Pagar | B14: =IF(#REF!<=-1,1,IF(#REF!<=5,2,IF(#REF!<=15,3,IF(H14<=60,4)))) -> #REF! | C14: 1 registro | D14: Nómina Sergio Jimenez Belimo | E14: 25815079 | F14: 46170 | G14: Sin Pagar | H14: =IF(OR(G14="Sin pagar",G14="Pagar"),NETWORKDAYS($I$11,F14,'Festivos Colombia'!$A$3:$A$22),0) -> 18 | I14: =H14 -> 18
D15: SEGURIDAD SOCIAL | E15: =SUBTOTAL(9,E16:E16) -> 652981100
A16: =G16 -> Cancelado | B16: =IF(#REF!<=-1,1,IF(#REF!<=5,2,IF(#REF!<=15,3,IF(H16<=60,4)))) -> #REF! | D16: Pago seguridad social Global | E16: 652981100 | F16: 46155 | G16: Cancelado | H16: =IF(OR(G16="Sin pagar",G16="Pagar"),NETWORKDAYS($I$11,F16,'Festivos Colombia'!$A$3:$A$22),0) -> 0 | I16: =H16 -> 0
D17: AFC´S | E17: =SUBTOTAL(9,E18:E20) -> 81747678
A18: =G18 -> Cancelado | B18: =IF(#REF!<=-1,1,IF(#REF!<=5,2,IF(#REF!<=15,3,IF(H18<=60,4)))) -> #REF! | C18: 1 | D18: AFC Bancolombia Carlos de real de Abril por devolución | E18: 4166667 | F18: 46154 | G18: Cancelado | H18: =IF(OR(G18="Sin pagar",G18="Pagar"),NETWORKDAYS($I$11,F18,'Festivos Colombia'!$A$3:$A$22),0) -> 0 | I18: =H18 -> 0
A19: =G19 -> Sin Pagar | B19: =IF(#REF!<=-1,1,IF(#REF!<=5,2,IF(#REF!<=15,3,IF(H19<=60,4)))) -> #REF! | C19: 1 | D19: AFC y aportes voluntarios - Cheque | E19: 18566667 | F19: 46171 | G19: Sin Pagar | H19: =IF(OR(G19="Sin pagar",G19="Pagar"),NETWORKDAYS($I$11,F19,'Festivos Colombia'!$A$3:$A$22),0) -> 19 | I19: =H19 -> 19
A20: =G20 -> Sin Pagar | B20: =IF(#REF!<=-1,1,IF(#REF!<=5,2,IF(#REF!<=15,3,IF(H20<=60,4)))) -> #REF! | C20: 1 | D20: AFC y aportes voluntarios -SOI y Aportes en Linea | E20: 59014344 | F20: 46171 | G20: Sin Pagar | H20: =IF(OR(G20="Sin pagar",G20="Pagar"),NETWORKDAYS($I$11,F20,'Festivos Colombia'!$A$3:$A$22),0) -> 19 | I20: =H20 -> 19
D21: IMPUESTOS | E21: =SUBTOTAL(9,E22:E24) -> 437515000 | H21: =IF(OR(G21="Sin pagar",G21="Pagar"),NETWORKDAYS($I$11,F21,'Festivos Colombia'!$A$3:$A$22),0) -> 0 | I21: =H21 -> 0
A22: =G22 -> Cancelado | B22: =IF(#REF!<=-1,1,IF(#REF!<=5,2,IF(#REF!<=15,3,IF(H22<=60,4)))) -> #REF! | D22: Retención en la fuente | E22: 400001000 | F22: 46156 | G22: Cancelado | H22: =IF(OR(G22="Sin pagar",G22="Pagar"),NETWORKDAYS($I$11,F22,'Festivos Colombia'!$A$3:$A$22),0) -> 0 | I22: =H22 -> 0 | J22: =E22+E23 -> 437109000
A23: =G23 -> Cancelado | B23: =IF(#REF!<=-1,1,IF(#REF!<=5,2,IF(#REF!<=15,3,IF(H23<=60,4)))) -> #REF! | D23: Renta año 2025 | E23: 37108000 | F23: 46156 | G23: Cancelado | H23: =IF(OR(G23="Sin pagar",G23="Pagar"),NETWORKDAYS($I$11,F23,'Festivos Colombia'!$A$3:$A$22),0) -> 0 | I23: =H23 -> 0
A24: =G24 -> Sin Pagar | B24: =IF(#REF!<=-1,1,IF(#REF!<=5,2,IF(#REF!<=15,3,IF(H24<=60,4)))) -> #REF! | D24: Retención de ICA | E24: 406000 | F24: 46164 | G24: Sin Pagar | H24: =IF(OR(G24="Sin pagar",G24="Pagar"),NETWORKDAYS($I$11,F24,'Festivos Colombia'!$A$3:$A$22),0) -> 14 | I24: =H24 -> 14
D25: PLANES COMPLEMENTARIOS Y PREPAGADAS | E25: =SUBTOTAL(9,E26:E28) -> 1712130 | H25: =IF(OR(G25="Sin pagar",G25="Pagar"),NETWORKDAYS($I$11,F25,'Festivos Colombia'!$A$3:$A$22),0) -> 0
A26: =G26 -> Cancelado | B26: =IF(#REF!<=-1,1,IF(#REF!<=5,2,IF(#REF!<=15,3,IF(H26<=60,4)))) -> #REF! | C26: 20911226831 | D26: Póliza suramericana # 091000808150 SALUD FAMILIAR | E26: 471136 | F26: 46159 | G26: Cancelado | H26: =IF(OR(G26="Sin pagar",G26="Pagar"),NETWORKDAYS($I$11,F26,'Festivos Colombia'!$A$3:$A$22),0) -> 0 | I26: =H26 -> 0
A27: =G27 -> Cancelado | B27: =IF(#REF!<=-1,1,IF(#REF!<=5,2,IF(#REF!<=15,3,IF(H27<=60,4)))) -> #REF! | C27: 20911226518 | D27: Póliza suramericana # 091000808150 SALUD FAMILIAR | E27: 828400 | F27: 46155 | G27: Cancelado | H27: =IF(OR(G27="Sin pagar",G27="Pagar"),NETWORKDAYS($I$11,F27,'Festivos Colombia'!$A$3:$A$22),0) -> 0 | I27: =H27 -> 0
A28: =G28 -> Cancelado | B28: =IF(#REF!<=-1,1,IF(#REF!<=5,2,IF(#REF!<=15,3,IF(H28<=60,4)))) -> #REF! | C28: 20911226519 | D28: Póliza suramericana # 091000808150 SALUD FAMILIAR | E28: 412594 | F28: 46155 | G28: Cancelado | H28: =IF(OR(G28="Sin pagar",G28="Pagar"),NETWORKDAYS($I$11,F28,'Festivos Colombia'!$A$3:$A$22),0) -> 0 | I28: =H28 -> 0
D29: PÓLIZAS Y SEGUROS | E29: =SUBTOTAL(9,E30:E31) -> 16795651 | H29: =IF(OR(G29="Sin pagar",G29="Pagar"),NETWORKDAYS($I$11,F29,'Festivos Colombia'!$A$3:$A$22),0) -> 0
A30: =G30 -> Cancelado | B30: =IF(#REF!<=-1,1,IF(#REF!<=5,2,IF(#REF!<=15,3,IF(H30<=60,4)))) -> #REF! | C30: 12310648205 | D30: Plan Dental 103232083 | E30: 1081351 | F30: 46154 | G30: Cancelado | H30: =IF(OR(G30="Sin pagar",G30="Pagar"),NETWORKDAYS($I$11,F30,'Festivos Colombia'!$A$3:$A$22),0) -> 0 | I30: =H30 -> 0
A31: =G31 -> Cancelado | B31: =IF(#REF!<=-1,1,IF(#REF!<=5,2,IF(#REF!<=15,3,IF(H31<=60,4)))) -> #REF! | C31: 12310649246 | D31: Plan salud 10108211747 | E31: 15714300 | F31: 46154 | G31: Cancelado | H31: =IF(OR(G31="Sin pagar",G31="Pagar"),NETWORKDAYS($I$11,F31,'Festivos Colombia'!$A$3:$A$22),0) -> 0 | I31: =H31 -> 0
D32: REEMBOLSO GASTOS VIAJE | E32: =SUBTOTAL(9,E33:E52) -> 1.3134604e+08
D33: Reembolso Camila Marin Melo cc020 - sophos | E33: 7658879 | F33: 46149 | G33: Cancelado | H33: =IF(OR(G33="Sin pagar",G33="Pagar"),NETWORKDAYS($I$11,F33,'Festivos Colombia'!$A$3:$A$22),0) -> 0 | I33: =H33 -> 0
D34: Reembolso Cristiam Silva cc020 - sophos | E34: 1337160 | F34: 46149 | G34: Cancelado | H34: =IF(OR(G34="Sin pagar",G34="Pagar"),NETWORKDAYS($I$11,F34,'Festivos Colombia'!$A$3:$A$22),0) -> 0 | I34: =H34 -> 0
D35: Reembolso Cristian Javier Gutierrez Torres-cc020 - Sophos | E35: 518478 | F35: 46149 | G35: Cancelado | H35: =IF(OR(G35="Sin pagar",G35="Pagar"),NETWORKDAYS($I$11,F35,'Festivos Colombia'!$A$3:$A$22),0) -> 0 | I35: =H35 -> 0
D36: Reembolso Daniel Alberto Ramos Duran cc040 - Environmental Dynamics INTL | E36: 5242497.6 | F36: 46149 | G36: Cancelado | H36: =IF(OR(G36="Sin pagar",G36="Pagar"),NETWORKDAYS($I$11,F36,'Festivos Colombia'!$A$3:$A$22),0) -> 0 | I36: =H36 -> 0
D37: Reembolso Genesis Coromoto Marchena Gómez - cc081 - go - global outsourcing inc | E37: 1944281 | F37: 46149 | G37: Cancelado | H37: =IF(OR(G37="Sin pagar",G37="Pagar"),NETWORKDAYS($I$11,F37,'Festivos Colombia'!$A$3:$A$22),0) -> 0 | I37: =H37 -> 0
D38: Reembolso Milagro del Vallle Sanchez cc020 - sophos | E38: 1270939 | F38: 46149 | G38: Cancelado | H38: =IF(OR(G38="Sin pagar",G38="Pagar"),NETWORKDAYS($I$11,F38,'Festivos Colombia'!$A$3:$A$22),0) -> 0 | I38: =H38 -> 0
D39: Reembolso Paula Andrea Alba Grajales CC077 - LANO SOFTWARE GMBH | E39: 9648516 | F39: 46149 | G39: Cancelado | H39: =IF(OR(G39="Sin pagar",G39="Pagar"),NETWORKDAYS($I$11,F39,'Festivos Colombia'!$A$3:$A$22),0) -> 0 | I39: =H39 -> 0
D40: Reembolso Monica Martinez Martinez-cc012 - lifenet health | E40: 9022977 | F40: 46149 | G40: Cancelado | H40: =IF(OR(G40="Sin pagar",G40="Pagar"),NETWORKDAYS($I$11,F40,'Festivos Colombia'!$A$3:$A$22),0) -> 0 | I40: =H40 -> 0
D41: Reembolso Camila Marin Melo cc020 - sophos | E41: 2214750 | F41: 46157 | G41: Cancelado | H41: =IF(OR(G41="Sin pagar",G41="Pagar"),NETWORKDAYS($I$11,F41,'Festivos Colombia'!$A$3:$A$22),0) -> 0 | I41: =H41 -> 0
D42: Reembolso Cristiam Silva cc020 - sophos | E42: 63900 | F42: 46157 | G42: Cancelado | H42: =IF(OR(G42="Sin pagar",G42="Pagar"),NETWORKDAYS($I$11,F42,'Festivos Colombia'!$A$3:$A$22),0) -> 0 | I42: =H42 -> 0
D43: Reembolso Maria Claudia Bohorquez cc020 - sophos | E43: 1679100 | F43: 46157 | G43: Cancelado | H43: =IF(OR(G43="Sin pagar",G43="Pagar"),NETWORKDAYS($I$11,F43,'Festivos Colombia'!$A$3:$A$22),0) -> 0 | I43: =H43 -> 0
D44: Reembolso Cristian Javier Gutierrez Torres-cc020 - Sophos | E44: 79400 | F44: 46157 | G44: Cancelado | H44: =IF(OR(G44="Sin pagar",G44="Pagar"),NETWORKDAYS($I$11,F44,'Festivos Colombia'!$A$3:$A$22),0) -> 0 | I44: =H44 -> 0
...

Sheet RESUMEN
B2: 46023
E3: Trm ref 7/1/26 | F3: 3730.26
B5: INGRESOS
E7: Valores COPS | F7: Valor USD
D8: Saldo Banco Santander 07/01/2026 | E8: =ENERO!F137 -> 1.6607852e+09 | F8: =E8/F3 -> 445219.69
B10: PAGOS
B12: Desde | C12: Hasta | D12: Descripción | E12: Valores COPS | F12: Valor USD
B13: 46027 | C13: 46034 | D13: Polizas de salud, Reembolsos y tiquetes | E13: 53914058 | F13: =E13/$F$3 -> 14453.164
B14: 46037 | C14: 46037 | D14: Seguridad social, Rte fte e IVA tercer cuatrimestre | E14: 9.8949618e+08 | F14: =E14/$F$3 -> 265261.99
B15: 46038 | C15: 46038 | D15: Retención ICA, liquidacion prevista, reembolso y tiquetes | E15: 252438422 | F15: =E15/$F$3 -> 67673.144
B16: 46041 | C16: 46047 | D16: Reembolsos | E16: 55000000 | F16: =E16/$F$3 -> 14744.281
B17: 46048 | C17: 46053 | D17: Nómina, Libranzas, AFC, Reembolsos,pagos terceros | E17: 1.8667865e+09 | F17: =E17/$F$3 -> 500444.07
B18: TOTAL EGRESOS DEL MES | E18: =SUM(E13:E17) -> 3.2176352e+09 | F18: =SUM(F13:F17) -> 862576.65
D20: Pagos del 01 al 25 de enero | E20: =SUM(E13:E16) -> 1.3508487e+09 | F20: =SUM(F13:F16) -> 362132.58
D21: Impuesto 4 x mil por transacciones | E21: =E20*4/1000 -> 5403394.6 | F21: =F20*4/1000 -> 1448.5303
D22: Gran total | E22: =SUM(E20:E21) -> 1.3562521e+09 | F22: =SUM(F20:F21) -> 363581.11
D24: Superavit o Deficit | E24: =E8-E22 -> 3.0453313e+08 | F24: =F8-F22 -> 81638.58

Sheet Prioridades de pago
C2: Ingreso
B3: 44612 | C3: Saldo Banco | D3: 37331755 | E3: 5.5935868e+08
C4: Dnero pendiente por llegar | D4: =E4*F4 -> #REF! | E4: =#REF! -> #REF! | F4: 4760 | H4: =F4*#REF! -> #REF!
C5: Total | D5: =SUM(D3:D4) -> #REF!
B8: Pagos Urgentes
B10: 44965 | C10: Correción retención en la fuente Diciembre | D10: =#REF!*0 -> #REF!
B11: 44966 | C11: Rte Fte | D11: =#REF!*0 -> #REF!
B12: 44970 | C12: Seguridad social | D12: =#REF!*0 -> #REF!
B13: 44966 | C13: IVA diciembre | D13: =#REF!*0 -> #REF!
B14: 44971 | C14: Cesantías | D14: =#REF!*0 -> #REF!
B15: 44978 | C15: ICA | D15: =#REF!*0 -> #REF!
B16: Total | D16: =SUM(D10:D15) -> #REF!
B18: Otros pagos y proveedores a realizar mes de febrero
B20: 44965 | C20: Póliza suramericana 090001175163 SALUD FAMILIAR | D20: =#REF!*0 -> #REF!
B21: 44968 | C21: Póliza suramericana 090001175195 SALUD FAMILIAR | D21: =#REF!*0 -> #REF!
B22: 44969 | C22: Emasoc Fra #4340 | D22: =#REF! -> #REF! | E22: Final mes
B23: 44977 | C23: Emasoc Fra #4368 | D23: =#REF! -> #REF! | E23: Final mes
B24: 44977 | C24: Anticipo nómina Ivonne Torres | D24: =#REF! -> #REF!
B25: 44977 | C25: AFC Ivonne Torres | D25: =#REF!*0 -> #REF! | E25: Ya se pago 01 de febrero
B26: Total | D26: =SUM(D20:D25) -> #REF!
B28: Total Pagos urgentes + otros pagos | D28: =D16+D26 -> #REF!
B29: 4 x mil | C29: 4 x mil | D29: =(D28*4)/1000 -> #REF!
B30: Gran total | D30: =SUM(D28:D29) -> #REF!
C32: Diferencia | D32: =D5-D30 -> #REF!
B35: Nota: No se tiene en cuenta los valores por reembolos, tiquetes
B36: Nóminas y AFC para pagar el 28 de febrero
D40: 5.5935868e+08
D42: 2133830
D43: 2633022
D44: 264022000
D45: =SUM(D42:D44) -> 268788852
D46: =(D45*4)/1000 -> 1075155.4
D47: =SUM(D45:D46) -> 2.6986401e+08
D49: =D40-D47 -> 2.8949467e+08
D50: 2.9056485e+08
D51: =+D50-D49 -> 1070177.4

Sheet Pagos realiDiferencia 2022
B2: INVOICES | L2: PAYMENTS | P2: BALANCE
B4: Number | C4: TRM Factura | D4: Client | E4: Description | F4: Invoice Amount USD | G4: Invoice Amount COPS | I4: Total Payment | J4: partial payments COPS | L4: Date | M4: traded value | N4: TRM | O4: traded value | P4: Difference
B5: FV-4-3521 | C5: 4922.7 | D5: GLOBAL PEO SERVICES LLC | E5: EO Third parties service Client: GLOBAL CS COLOMBIA -November | F5: 330717.95 | G5: =F5*C5 -> 1.6280253e+09 | I5: 0 | J5: =280218.95*C5 -> 1.3794338e+09 | L5: 44896 | M5: 280218.95 | N5: 4821 | O5: =N5*M5 -> 1.3509356e+09 | P5: =O5-J5 -> -28498267
I6: 0 | J6: =50499*C5 -> 2.4859143e+08 | L6: 44904 | M6: 50499 | N6: 4816.3485 | O6: =N6*M6 -> 2.4322078e+08 | P6: =O6-J6+19.92 -> -5370627
B7: FV-4-3522 | C7: 4922.7 | D7: GLOBAL PEO SERVICES LLC | E7: Employer of Record Service - November | F7: 5358 | G7: =F7*C7 -> 26375827 | I7: =F7*C7 -> 26375827 | J7: 0 | L7: 44896 | M7: 5358.57 | N7: 4821 | O7: =N7*M7 -> 25833666 | P7: =O7-I7 -> -542160.63
B8: FV-4-3523 | C8: 4922.7 | D8: GLOBAL PEO SERVICES LLC | E8: Banking Taxes - November (4x1000) | F8: 1579.96 | G8: =F8*C8 -> 7777669.1 | I8: =F8*C8 -> 7777669.1 | J8: 0 | L8: 44896 | M8: 1579.96 | N8: 4821 | O8: =N8*M8 -> 7616987.2 | P8: =O8-I8 -> -160681.93
B9: FV-4-3528 | C9: 4922.7 | D9: GLOBAL PEO SERVICES LLC | E9: EO Third parties service Client: GLOBAL CS COLOMBIA -November (Paola Romero) | F9: 1207.19 | G9: =F9*C9 -> 5942634.2 | I9: =C9*F9 -> 5942634.2 | J9: 0 | L9: 44896 | M9: 1207.19 | N9: 4821 | O9: =N9*M9 -> 5819863 | P9: =O9-I9 -> -122771.22
B10: FV-4-3579 | C10: 4737.19 | D10: GLOBAL PEO SERVICES LLC | E10: Employer of Record Service - December | F10: 4543.43 | G10: =F10*C10 -> 21523091 | I10: 21523091 | J10: 0 | L10: 44917 | M10: 4543.43 | N10: 4746.3 | O10: =N10*M10 -> 21564482 | P10: =O10-I10 -> 41390.647
B11: FV-4-3580 | C11: 4737.19 | D11: GLOBAL PEO SERVICES LLC | E11: EO Third parties service Client: GLOBAL CS COLOMBIA -December | F11: 467025.04 | G11: =F11*C11 -> 2.2123863e+09 | I11: 2.2123863e+09 | J11: 0 | L11: 44917 | M11: 467025.04 | N11: 4746.3 | O11: =N11*M11 -> 2.2166409e+09 | P11: =O11-I11 -> 4254598.1
B12: FV-4-3581 | C12: 4737.19 | D12: GLOBAL PEO SERVICES LLC | E12: Banking Taxes - December (4x1000) | F12: 2242.17 | G12: =F12*C12 -> 10621585 | I12: 10621585 | J12: 0 | L12: 44917 | M12: 2242.17 | N12: 4746.3 | O12: =N12*M12 -> 10642011 | P12: =O12-I12 -> 20426.169
B13: FV-4-3582 | C13: 4737.19 | D13: GLOBAL PEO SERVICES LLC | E13: PEO Third parties service Client: GLOBAL CS COLOMBIA -December (Paola Romero) | F13: 4021.16 | G13: =F13*C13 -> 19048999 | I13: 19048999 | J13: 0 | L13: 44914 | M13: 4021.16 | N13: 4767.22 | O13: =N13*M13 -> 19169754 | P13: =O13-I13 -> 120755.43
F14: =SUM(F5:F13) -> 816694.9 | G14: =SUM(G5:G13) -> 3.9317014e+09 | I14: =SUM(I5:I13) -> 2.3036762e+09 | J14: =SUM(J5:J13) -> 1.6280253e+09 | M14: =SUM(M5:M13) -> 816695.47 | O14: =SUM(O5:O13) -> 3.901444e+09 | P14: =SUM(P5:P13) -> -30257338

Sheet Festivos Colombia
A2: FESTIVOS COLOMBIA
A3: 46023
A4: 46034
A5: 46104
A6: 46110
A7: 46114
A8: 46115
A9: 46117
A10: 46143
A11: 46160
A12: 46181
A13: 46188
A14: 46202
... A22: 46381
