Workbook
Name Fact: DISTRIBUCIÓN!#REF!
Name Fact: 'DISTRIBUCIÓN (2)'!#REF!
Name Fact: #REF!
Name Marca: #REF!
Name Marca1: #REF!
Name Marcas: #REF!
Name Valor: #REF!
Name Value: #REF!
Name values: #REF!

Sheet Festivos Colombia
A2: FESTIVOS COLOMBIA
A3: 46023
A4: 46034
A5: 46104
A6: 46110
A7: 46114
A8: 46115
A9: 46117
A10: 46143
A11: 46160
A12: 46181
A13: 46188
A14: 46202
... A22: 46381

Sheet DICIEMBRE
E1: 42400
I2: 1
I3: 2
D4: BANCOS | E4: =SUBTOTAL(9,E5:E11) -> 1.339387e+09 | I4: 3
D5: Bancos | E5: 1.1397443e+09 | I5: 4
D6: Devolucion tiquete Cristian Ferney Parada Cabrera | E6: 139474
D7: Ingreso Bancolombia Panamá Pago primas | E7: 183919680
D8: Ingreso Banco Finandina | E8: 5000000
D9: Pago intereses PM | E9: 4808596
D10: devolucion saldo caja menor | E10: 215700
D11: Suramericana Incapacidad | E11: 5559334
D12: CLIENTES | E12: =SUBTOTAL(9,E13:E58) -> 3.4220209e+08
C13: Pagado | D13: ACT&J Consultores Factura 6472-6337-6423 y saldo Factura 6182 $ 77,525 | E13: 4524531.5 | F13: ***
C14: Pagado | D14: ACT&J Consultores Factura 6502-Noviembre Pretalires | E14: 1549380 | F14: ***
C15: Pagado | D15: AECID Factura # 6533-Octubre y noviembre | E15: 51544069
C16: Pagado | D16: AECID Factura #5-132-Octubre y noviembre | E16: 5260000
C17: Pagado | D17: AECID Factura # 6574 | E17: 34362713
C18: Pagado | D18: Clarke Modet factura # 6459 | E18: 2455029.2 | F18: ***
C19: Pagado | D19: Compassion international factura # 6542 | E19: 6563937.3
C20: Pagado | D20: Consorcio HL-AB Factura # 6107-6205 | E20: 9784261
C21: Pagado | D21: Consorcio HL-AB Factura # 6107-6205 | E21: 1880863 | J21: =E20+E21+E23+E40+E41+E42+E43 -> 87943892
C22: Sin Pagar | D22: Consorcio HL-A&D Factura 6478 | E22: =1341880.13*0 -> 0
C23: Pagado | D23: Consorcio HL Gisaico Factura 6432 | E23: =605371 -> 605371
C24: Pagado | D24: Consorcio SK-HL facturas 6422 | E24: =229392 -> 229392 | F24: ***
C25: Pagado | D25: Consorcio SK-HL facturas 6501 | E25: =229392 -> 229392
C26: Sin Pagar | D26: Corporación punto azul factura # 6424 | E26: =1692717.2*0 -> 0 | F26: ***
C27: Sin Pagar | D27: Dinterweb factura # 5646-5725-5805-5892-5974-6061 | E27: =7528323*0 -> 0
C28: Sin Pagar | D28: Distritech facturas # 6235 Llega por Panamá | E28: =5391183.76*0 -> 0
C29: Sin Pagar | D29: Dream Tyme resort Factura # 1-27 | E29: =9781142.24*0 -> 0
C30: Sin Pagar | D30: Dream Tyme resort Factura # 6437 | E30: =1007999.64*0 -> 0
C31: Sin Pagar | D31: Dream Tyme Primera y segunda quincena Diciembre | E31: =9781142.24*2*0 -> 0
C32: Sin Pagar | D32: Dream Tyme Primera y segunda quincena Diciembre | E32: =4713074*0 -> 0
C33: Sin Pagar | D33: Ecohl factura # 6373-6375 | E33: =1228866.62*0 -> 0
C34: Pagado | D34: Gilead Scense Colombia Factura # 5-154 | E34: 821905.26
C35: Pagado | D35: Global CS Colombia SAS -Solutions & payroll-Servicio Noviembre 2025 Factura 6467 | E35: 17406804 | F35: ***
C36: Pagado | D36: Global CS Colombia SAS -Solutions & payroll-Factura 5-93 Reembolso Gastos Nov | E36: 359994 | F36: ***
C37: Pagado | D37: Global Projects service AG facturas # 6268 | E37: 2455134.4 | F37: 2676011 | G37: =(E37-F37) -> -220876.55
C38: Sin Pagar | D38: Global Projects service AG facturas # 6315 | E38: =2709294*0 -> 0
C39: Sin Pagar | D39: HL Gestiones factura # 6395 | E39: =597907.31*0 -> 0 | I39: 4
C40: Pagado | D40: HL Ingenieros factura # 6127 a 6226 | E40: 2568994
...

Sheet ENERO
E1: 42400
I2: 1
I3: 2
D4: BANCOS | E4: =SUBTOTAL(9,E5:E14) -> 1.0939477e+09 | I4: 3
D5: Bancos | E5: =DICIEMBRE!$E$345 -> 1.0574441e+09 | I5: 4
D6: Incapacidad pendiente por identificar | E6: 800040
D7: Incapacidad pendiente por identificar | E7: 400475
D8: Incapacidad pagada Sandra Milena Bello | E8: 64397
D9: Pago intereses PM | E9: 22670000
D10: Devolución Camara de comercio | E10: 190000
D11: Devolución Camara de comercio | E11: 69000
D12: Transferencia de fondos por Saldo de anticipo People Pass Root capital | E12: 284009
D13: Devolución dinero Root capital | E13: 12000000
D14: Devolución de retención IVA – Factura FEG 1344 Gelcon | E14: 25650
D15: CLIENTES | E15: =SUBTOTAL(9,E16:E55) -> 1.2653437e+08
C16: Pagado | D16: ACT&J Consultores Factura 6555 | E16: 1572392.3
C17: Pagado | D17: ACT&J Consultores Factura 6612 | E17: 1549380
C18: Sin Pagar | D18: AECID Factura # 6640 | E18: =34362712.65*0 -> 0
C19: Sin Pagar | D19: AECID Factura # 5-200 | E19: =2104000*0 -> 0
C20: Pagado | D20: Clarke Modet factura # 6564 | E20: 2373194.9
C21: Pagado | D21: Compassion international factura # 6360 | E21: =6898752.51 -> 6898752.5 | G21: =E22+E23+E24+E30+E37+E38 -> 33574449
C22: Pagado | D22: Consorcio A&D Factura # 6478-6508-6545 | E22: 3254917
C23: Pagado | D23: Consorcio HL-AB Factura # 6357 - 6358 | E23: 498186
C24: Pagado | D24: Consorcio HL Gisaico Factura 6532-6534 | E24: 1568049
C25: Pagado | D25: Monica Londoño Factura 6396 | E25: 177905
C26: Pagado | D26: Corporación punto azul factura # 6424 | E26: =1692717.2 -> 1692717.2
C27: Sin Pagar | D27: Dinterweb factura # 5646-5725-5805-5892-5974-6061 | E27: =7528323*0 -> 0
C28: Sin Pagar | D28: Distritech facturas # 6235 Llega por Panamá | E28: =5391183.76*0 -> 0
C29: Sin Pagar | D29: Dream Tyme resort | E29: =23310881.53*0 -> 0
C30: Pagado | D30: Ecohl facturas 6373-6474-6375 | E30: 1228867
C31: Pagado | D31: Funeravet factura # 6599 | E31: 771364.8
C32: Pagado | D32: Gilead Scense Colombia Factura # 6628 | E32: 915290.76
C33: Sin Pagar | D33: Global CS Colombia SAS factura # 6443 | E33: =17406803.72*0 -> 0
C34: Pagado | D34: Global CS Colombia SAS -factura # 6554 - 163 | E34: 19282040
C35: Sin Pagar | D35: Global Projects service AG facturas # 6315-27-45 (Pendiente monetizar) | E35: =15456075.3468*0 -> 0
C36: Sin Pagar | D36: HL Gestiones factura # 6395 | E36: =1121157.31*0 -> 0 | I36: 4
C37: Pagado | D37: HL Ingenieros factura # 6355 | E37: 217212
C38: Pagado | D38: Hl Infraestructura factura # 6366 -6368 - 6369 - 6371 - 6372 - 6386 - 6387 - 6402 | E38: 26807218
C39: Pagado | D39: Inversiones el Bosque factura # 6391 | E39: 2049073
C40: Pagado | D40: Inversiones el Bosque factura # 6627 | E40: 2013009
...

Sheet FEBRERO
E1: 42400
I2: 1
I3: 2
D4: BANCOS | E4: =SUBTOTAL(9,E5:E12) -> 9.2277668e+08 | I4: 3
D5: Bancos | E5: =ENERO!E329+900255200.74 -> 9.0048942e+08 | I5: 4
C6: Pagado | D6: Punto medical | E6: 2670000
C7: Pagado | D7: Devolución de dinero a cuenta BAC panamá para prestamo Nomina global PA USD 2000 | E7: 7200000 | I7: 4
C8: Pagado | D8: Pago incapacidad Suramericana Lina Guio | E8: 539025
C9: Pagado | D9: Pago incapacidad Suramericana Ricardo Arambulo | E9: 10920122
C10: Pagado | D10: Pago Devolución saldo a favor suramericana | E10: 432545
C11: Pagado | D11: Pago Devolución pago tiquete Aereo Ana Guitierrez | E11: 525570
C12: Pagado | D12: Devolucion de dinero de Global Peo Services Panamá para el envio del pago SIPE Enero
D13: CLIENTES | E13: =SUBTOTAL(9,E14:E52) -> 6.3206884e+08
C14: Sin Pagar | D14: ACT&J Consultores Factura 1682 | E14: =1572392.28307*0 -> 0
C15: Pagado | D15: AECID Factura # 6640 | E15: =34362712.65 -> 34362713
C16: Pagado | D16: AECID Factura # 5-200 | E16: =2104000 -> 2104000
C17: Pagado | D17: Clarke Modet factura # 6618 | E17: 2629357.6
C18: Pagado | D18: Compassion international factura # 6717 | E18: 6766084.2
C19: Pagado | D19: Consorcio HL-AB Factura # 6454 | E19: 318616.52
C20: Pagado | D20: Monica Londoño Factura 6719 | E20: =190536 -> 190536
C21: Pagado | D21: Corporación punto azul factura # 6503-6528 | E21: 3808077
C22: Pagado | D22: Deel Facturas # 6407-6408-6409-6410-6411-6412-6413-6491-6492-6493-6494-6495 | E22: 39020834 | F22: 41322268 | G22: =(E22-F22) -> -2301434.4
C23: Pagado | D23: Deel Facturas # 6415-6416-6417-6496-6497-6498-6499-126 | E23: 14229202 | F23: 14859058 | G23: =(E23-F23) -> -629856
C24: Pagado | D24: Deel Facturas #6165-6166-6167-6168-6169-6170-6171-6172-6173-6174-6249-6250-6251-6252-6253-6254-6255-6256-6257-6486-6487-6488-6489-6490-6581-6582-6583-6586-6587-6588-6589 | E24: 1.3794203e+08 | F24: 1.4618867e+08 | G24: =(E24-F24) -> -8246639.2
C25: Pagado | D25: Deel Facturas # 6175-6176-6177-6178-6179-6258-6259-6260-6261-6262-6500-6592-164-6593-6594 | E25: 1.0584899e+08 | F25: 1.1213237e+08 | G25: =(E25-F25) -> -6283381.3 | K25: =E19+E33+E39+E40 -> 35007675
C26: Pagado | D26: Deel Facturas # 6584-6585 | E26: 7843526.4 | F26: 7981254.7 | G26: =(E26-F26) -> -137728.29
C27: Pagado | D27: Deel Facturas # 6590-6591 | E27: 2747269.2 | F27: 2782525.8 | G27: =(E27-F27) -> -35256.621
C28: Pagado | D28: Deel Facturas #6654-6655-6656-201-6657-6658 | E28: 13980796 | F28: 14014539 | G28: =(E28-F28) -> -33743.01
C29: Pagado | D29: Deel Facturas # 6645-6647-6648-6650-6651-6652-6653 | E29: 31640804 | F29: 31747485 | G29: =(E29-F29) -> -106681.36
C30: Sin Pagar | D30: Dinterweb factura # 5646-5725-5805-5892-5974-6061 | E30: =7528323*0 -> 0
C31: Sin Pagar | D31: Distritech facturas # 6631 Llega por Panamá | E31: =5391183.76*0 -> 0
C32: Sin Pagar | D32: Dream Tyme resort | E32: =23310882*0 -> 0
C33: Pagado | D33: Ecohl facturas 6428-6429-6430 | E33: 1276724
C34: Pagado | D34: Gilead Scense Colombia Factura # 6715 | E34: 1359917.2
C35: Pagado | D35: Global CS Colombia SAS -factura # 6605-5-197 | E35: 20139314
C36: Pagado | D36: Global Projects service AG facturas # 6315-27-45 | E36: 14472628 | F36: 15456075 | G36: =(E36-F36) -> -983447.15
C37: Pagado | D37: Global Projects service AG facturas # 6534 | E37: 2543700 | F37: 2739268 | G37: =(E37-F37) -> -195568
C38: Pagado | D38: HL Gestiones factura # 6718 | E38: 1200756 | I38: 4
C39: Pagado | D39: HL Ingenieros factura # 6441-6531-6548 | E39: 1088426
C40: Pagado | D40: Hl Infraestructura factura # 6427-6431-6438-6444-6471-6476-6477 | E40: 32323908
...

Sheet MARZO
E1: 42400
I2: 1
I3: 2
D4: BANCOS | E4: =SUBTOTAL(9,E5:E9) -> 6.9897103e+08 | I4: 3
D5: Bancos | E5: =FEBRERO!E330 -> 6.5971468e+08 | I5: 4
C6: Pagado | D6: Devolucion de dinero de Peo global services | E6: 59698832 | F6: 59489365 | G6: =E6-F6 -> 209466.82
C7: Pagado | D7: Pago Advancio 6644 | E7: 311941
D8: Menos devolución de Panamá para enviarle dinero a Yadira para el pago de SIPE Marzo | E8: =-(6145*3704.87) -> -22766426
C9: Pagado | D9: Por identificar | E9: 2012000
D10: CLIENTES | E10: =SUBTOTAL(9,E11:E45) -> 2.3801491e+08
C11: Pagado | D11: ACT&J Consultores Factura 6695-6792-6598 ( abono) | E11: 4870966.4
C12: Pagado | D12: AECID Factura # 6720 | E12: 34362713
C13: Pagado | D13: AECID Factura # 5-233 | E13: 2104000
C14: Pagado | D14: Clarke Modet factura # 6704 | E14: 2717002.9
C15: Pagado | D15: Compassion international factura # 6799 | E15: 6766084.2
C16: Sin Pagar | D16: Consorcio HL-Gisaico # 6668-6669 | E16: =2503090.56*0 -> 0
C17: Sin Pagar | D17: Monica Londoño Factura 6573 | E17: =177905*0 -> 0
C18: Sin Pagar | D18: Consorcio Gisaico facturas # 6668-6669 | E18: 2015276.2
C19: Sin Pagar | D19: Consorcio SK - HL 6615 - 6659 | E19: 504664
C20: Pagado | D20: Corporación punto azul factura # 6601 | E20: 2015276.2
C21: Pagado | D21: Deel factura # 6658 | E21: 42535444 | F21: 41874833 | G21: =(E21-F21) -> 660611.52
C22: Pagado | D22: Deel facturas # 6646-6649 | E22: 39759248 | F22: 39196672 | G22: =(E22-F22) -> 562575.48
C23: Sin Pagar | D23: Dinterweb factura # 5646-5725-5805-5892-5974-6061 | E23: =7528323*0 -> 0
C24: Sin Pagar | D24: Distritech facturas # 6631 Llega por Panamá | E24: =5391183.76*0 -> 0
C25: Sin Pagar | D25: Dream Tyme resort | E25: =23310882*0 -> 0
C26: Pagado | D26: Ecohl facturas 6509 a 6511-6552-6553 | E26: 3312381
C27: Pagado | D27: Evoluzion talent abono a la factura 6742 | E27: 560489
C28: Pagado | D28: Funeravet Factura # 6699 | E28: 405352
C29: Pagado | D29: Gilead Scense Colombia Factura # 6802 | E29: 920132.14
C30: Pagado | D30: Global CS Colombia SAS -factura # 6696-5-235 | E30: 18921371
C31: Pagado | D31: Global Projects service AG facturas # FV-4-6403-FV-4-6505-FV-5-85-FV-5-123-FV-5-158-FV-5-198 | E31: 30962053 | F31: 31750578 | G31: =+E31-F31 -> -788524.88
C32: Sin Pagar | D32: HL Gestiones factura # 6395-6572 | E32: =1719065*0 -> 0 | I32: 4
C33: Sin Pagar | D33: HL Ingenieros factura # 6441-6531 | E33: =723071*0 -> 0
C34: Pagado | D34: Hl Infraestructura factura # 6515 - 6544 | E34: =7328987 -> 7328987
C35: Sin Pagar | D35: Inversiones el Bosque factura # 6797 | E35: =2013039*0 -> 0
C36: Sin Pagar | D36: Live Systems technology factura # 6626 | E36: =1264316.04*0 -> 0
C37: Pagado | D37: Ortho Clinical Diagnostics # 6705 | E37: 1451213.8
C38: Pagado | D38: Petrobras colombia Factura # 6697 | E38: 18182068
C39: Pagado | D39: Petrobras baspetro Factura # 6660 | E39: 7948929
C40: Pagado | D40: Petrobras baspetro Factura # 6746 | E40: 7402389
...

Sheet ABRIL
E1: 42400
I2: 1
I3: 2
D4: BANCOS | E4: =SUBTOTAL(9,E5:E5) -> 7.7277487e+08 | I4: 3
D5: Bancos | E5: =MARZO!E294 -> 7.7277487e+08 | I5: 4
D6: CLIENTES | E6: =SUBTOTAL(9,E7:E36) -> 2.771425e+08
C7: Sin Pagar | D7: ACT&J Consultores Factura 6598 | E7: 2031584.6
C8: Sin Pagar | D8: AECID Factura # 6789 | E8: 34362713
C9: Sin Pagar | D9: AECID Factura # 5-262 | E9: 2104000
C10: Pagado | D10: Clarke Modet factura # 6790 | E10: 2804648.1
C11: Sin Pagar | D11: Compassion international factura # XXXX | E11: 6766084.2
C12: Sin Pagar | D12: Consorcio HL-Gisaico # 6785 | E12: =3646434.25*0 -> 0
C13: Sin Pagar | D13: Consorcio SK - HL 6745 | E13: 252331.2
C14: Sin Pagar | D14: Corporación punto azul factura # 6661 | E14: 2015276.2
C15: Sin Pagar | D15: Deel Facturas # 6728-6729-6730-6731-6732-6733-6734-6735-6736 ( Por monetizar) | E15: ='MONETIZACIONES PEND'!$R$14 -> 41243759
C16: Sin Pagar | D16: Deel Facturas # 6737-6738-6739-6740-6741 ( Por monetizar) | E16: ='MONETIZACIONES PEND'!$R$15 -> 21043637
C17: Sin Pagar | D17: Deel Facturas # 6325 ( Por monetizar) | E17: ='MONETIZACIONES PEND'!$R$16 -> 5300165
C18: Sin Pagar | D18: Dinterweb factura # 5646-5725-5805-5892-5974-6061 | E18: =7528323*0 -> 0
C19: Sin Pagar | D19: Distritech facturas # 6631 Llega por Panamá | E19: 987674.51
C20: Sin Pagar | D20: Dream Tyme resort | E20: 12075001
C21: Sin Pagar | D21: Ecohl facturas 6690-6691-6692-6723-6724-6780-6781-6782 | E21: =3182508.68*0 -> 0
C22: Sin Pagar | D22: Gilead Scense Colombia Factura # XXXX | E22: 920132.14
C23: Sin Pagar | D23: Global CS Colombia SAS -factura # 6778-5-272 | E23: 20244754
C24: Sin Pagar | D24: Global Projects service AG facturas factura 6597-6663-6694-6758-221-256 | E24: 24139258
C25: Sin Pagar | D25: Global Upside Factura # 6750 | E25: ='MONETIZACIONES PEND'!$R$12 -> 6825500
C26: Sin Pagar | D26: HL Gestiones factura # 6395-6572 | E26: =1719065*0 -> 0 | I26: 4
C27: Sin Pagar | D27: HL Ingenieros factura # 6678-6757 | E27: =667948.35*0 -> 0
C28: Sin Pagar | D28: Hl Infraestructura factura # 6507-6512-6513-6514-6519 | E28: =24527869*0 -> 0
C29: Sin Pagar | D29: Inversiones el Bosque factura # 6797 | E29: =2013039 -> 2013039
C30: Pagado | D30: Live Systems technology factura # 6626 | E30: =1264316.04 -> 1264316
C31: Sin Pagar | D31: Monica Londoño Factura 6573 | E31: =177905 -> 177905
C32: Sin Pagar | D32: Ortho Clinical Diagnostics # 6794 | E32: 1451213.8
C33: Sin Pagar | D33: Petrobras colombia Factura # 6752 | E33: 18093866
C34: Sin Pagar | D34: TPL Logistics factura # 6796 | E34: =2033960.42 -> 2033960.4
C35: Sin Pagar | D35: Safeguard World Inter Ltd Factura # 6575 a 6577 | E35: =SUM('MONETIZACIONES PEND'!$R$9:$R$11) -> 21070830
C36: Sin Pagar | D36: Solutions ingreso dinero de Panamá | E36: ='MONETIZACIONES PEND'!$R$13 -> 47920850
D37: EOR | E37: =SUBTOTAL(9,E38:E86) -> 2.8285125e+09 | F37: 1
C38: Sin Pagar | D38: Action Factura # XXXX | E38: 1570694.5
C39: Sin Pagar | D39: Action Factura # X-XXX | E39: 14278927
C40: Sin Pagar | D40: Bubble BPM Factura # 6815 | E40: ='MONETIZACIONES PEND'!$Q$18 -> 470071.35
...

Sheet DISTRIBUCIÓN
H1: Sin Pagar | I1: Cancelado
B2: Distribución de dinero
B4: Semana | C4: Fecha Inicial | D4: Fecha Final | E4: Descripción | F4: Valor | H4: Sin pagar | I4: Cancelado | J4: Total
B5: 1 | C5: 46113 | D5: 46124 | E5: Pagos a Realizar | F5: =SUMIFS(ABRIL!$E$92:$E$1917,ABRIL!$F$92:$F$1917,">="&C5,ABRIL!$F$92:$F$1917,"<="&D5,ABRIL!$G$92:$G$1917,$H$1) -> 7941408.5 | G5: Proveedores
B6: 2 | C6: 46125 | D6: 46125 | E6: Pagos a Realizar | F6: =SUMIFS(ABRIL!$E$92:$E$1917,ABRIL!$F$92:$F$1917,">="&C6,ABRIL!$F$92:$F$1917,"<="&D6,ABRIL!$G$92:$G$1917,$H$1) -> 0 | G6: - | H6: =SUMIFS(ABRIL!$E$92:$E$1926,ABRIL!$F$92:$F$1926,">="&C5,ABRIL!$F$92:$F$1926,"<="&D13,ABRIL!$G$92:$G$1926,$H$1) -> 3.1346752e+09 | I6: =SUMIFS(ABRIL!$E$92:$E$1926,ABRIL!$F$92:$F$1926,">="&C5,ABRIL!$F$92:$F$1926,"<="&D13,ABRIL!$G$92:$G$1926,$I$1) -> 166600 | J6: =SUM(H6:I6) -> 3.1348418e+09 | L6: =J6-#REF! -> #REF!
B7: 3 | C7: 46126 | D7: 46126 | E7: Pagos a Realizar | F7: =SUMIFS(ABRIL!$E$92:$E$1917,ABRIL!$F$92:$F$1917,">="&C7,ABRIL!$F$92:$F$1917,"<="&D7,ABRIL!$G$92:$G$1917,$H$1) -> 15620964 | G7: Anticipo nómina Nazdar y Action
B8: 4 | C8: 46127 | D8: 46127 | E8: Pagos a Realizar | F8: =SUMIFS(ABRIL!$E$92:$E$1917,ABRIL!$F$92:$F$1917,">="&C8,ABRIL!$F$92:$F$1917,"<="&D8,ABRIL!$G$92:$G$1917,$H$1) -> 530117800 | G8: Seguridad social | I8: Comprobación | J8: =ABRIL!E203 -> 3.1348418e+09
B9: 5 | C9: 46128 | D9: 46128 | E9: Pagos a Realizar | F9: =SUMIFS(ABRIL!$E$92:$E$1917,ABRIL!$F$92:$F$1917,">="&C9,ABRIL!$F$92:$F$1917,"<="&D9,ABRIL!$G$92:$G$1917,$H$1) -> 21127878 | G9: TC Endrington
B10: 6 | C10: 46129 | D10: 46131 | E10: Pagos a Realizar | F10: =SUMIFS(ABRIL!$E$92:$E$1917,ABRIL!$F$92:$F$1917,">="&C10,ABRIL!$F$92:$F$1917,"<="&D10,ABRIL!$G$92:$G$1917,$H$1) -> 85525370 | G10: Proveedores | J10: =J6-J8 -> 0
B11: 7 | C11: 46132 | D11: 46132 | E11: Pagos a Realizar | F11: =SUMIFS(ABRIL!$E$92:$E$1917,ABRIL!$F$92:$F$1917,">="&C11,ABRIL!$F$92:$F$1917,"<="&D11,ABRIL!$G$92:$G$1917,$H$1) -> 239676790 | G11: Rte FTE
B12: 8 | C12: 46133 | D12: 46138 | E12: Pagos a Realizar | F12: =SUMIFS(ABRIL!$E$92:$E$1917,ABRIL!$F$92:$F$1917,">="&C12,ABRIL!$F$92:$F$1917,"<="&D12,ABRIL!$G$92:$G$1917,$H$1) -> 43684726 | G12: Proveedores
B13: 9 | C13: 46139 | D13: 46142 | E13: Pagos a Realizar | F13: =SUMIFS(ABRIL!$E$92:$E$1917,ABRIL!$F$92:$F$1917,">="&C13,ABRIL!$F$92:$F$1917,"<="&D13,ABRIL!$G$92:$G$1917,$H$1) -> 2.1909803e+09 | G13: Nómina-Pagos a tercero-Proveedores
B14: TOTAL | F14: =SUM(F5:F13) -> 3.1346752e+09
E16: Escenario 1
E17: Gastos y costos Periodo 01 al 26 abril | F17: =SUM($F$5:$F$12) -> 9.4369494e+08
E18: 4 X mil | F18: =($F$17*4)/1000 -> 3774779.7
E19: Total | F19: =SUM(F17:F18) -> 9.4746972e+08
E21: Bancos | F21: =ABRIL!$E$221 -> 7.7365012e+08
E22: Bubble Do Brasil | F22: ='MONETIZACIONES PEND'!$Q$18+'MONETIZACIONES PEND'!$Q$19 -> 4743457.2
E23: Action AD | F23: 12600000
E24: AECID | F24: =ABRIL!$E$8+ABRIL!$E$9 -> 36466713
E25: Global Colombia | F25: =ABRIL!E23 -> 20244754
E26: Proveedores Nacionales | F26: =ABRIL!$E$7+ABRIL!$E$10+ABRIL!$E$29+ABRIL!$E$33+ABRIL!$E$34 -> 26977098 | G26: 0
E27: Facturas por monetizar Deel | F27: =ABRIL!$E$15+ABRIL!$E$16+ABRIL!$E$17 -> 67587561
E28: Facturas por monetizar Safeguard | F28: =ABRIL!$E$35+ABRIL!$E$36 -> 68991680
E29: Sobregiro | F29: 0
E30: Total | F30: =SUM(F21:F29) -> 1.0112614e+09
E31: Saldo | F31: =F30-$F$19 -> 63791669
E39: FORECAST MAYO 2026 | H39: FORECAST JUNIO 2026
E41: INGRESO | F41: =SUBTOTAL(9,F42:F50) -> 1.0164382e+09 | H41: INGRESO | I41: =SUBTOTAL(9,I42:I50) -> 1.314082e+09
E42: Bancos Valor previsto | F42: =ABRIL!$E$205 -> 7.4358807e+08 | H42: Bancos Valor previsto | I42: =F111 -> 1.1428106e+09
E43: Safeguard Back office 360 | F43: 63005792 | G43: 1 | H43: Safeguard Back office 360 | I43: 35000000 | J43: 1
E44: Action XXXX | F44: 13000000 | H44: Deel | I44: =15303.2*3650 -> 55856680
E45: Clientes nacionales Previsto -Global Project | F45: 52000000 | H45: Action XXXX | I45: 12500000
E46: Global CS Colombia | F46: 18500000 | H46: Clientes nacionales Previsto -Global Project | I46: 45000000
E47: Deel | F47: =18542.14* 3703.69 -> 68674338 | H47: Grupo HL | I47: 0
E48: Grupo HL | F48: 55000000 | H48: Global CS Colombia | I48: 20244754
E49: Intereses PM | F49: =2670000 -> 2670000 | H49: Intereses PM | I49: =2670000 -> 2670000
E50: Sobregiro | F50: 0 | H50: Sobregiro | I50: 0
E51: PAGOS DEL 1 AL 24 MAYO | F51: =SUM(F52:F82) -> 1.0112007e+09 | H51: PAGOS DEL 1 AL 25 Junio | I51: =SUM(I52:I79) -> 9.6160339e+08
...

Sheet MONETIZACIONES PEND
O1: 0
B2: ID | C2: Client | D2: Invoice | E2: Incoming resources | F2: Maximum Date for Monetization | G2: Día | H2: Mes | I2: Días | J2: Progress | K2: Invoiced | L2: Received | M2: Banking taxes | N2: TRM Invoice Cops | O2: TRM Bank (Average) Cops | P2: Difference in exchange rates | Q2: invoicing in COPS | R2: negotiated COPS | S2: difference | T2: KPI | U2: Color KPI
B3: 1 | C3: Safeguard World Inter Ltd | D3: FV-4-6246 | E3: 46085 | F3: 46145 | G3: =(TEXT(F3,"ddd")) -> dom | H3: =(TEXT(F3,"mmm")) -> may | I3: =F3-E3 -> 60 | J3: =IFERROR(IF(TODAY()>=E3,(TODAY()-E3)/I3,0),0) -> 0.6 | K3: 600 | L3: 599.18805 | M3: =K3-L3 -> 0.81194602 | N3: 4019.9 | Q3: =K3*N3 -> 2411940 | R3: =L3*O3 -> 0 | S3: =R3-Q3 -> -2411940 | T3: =IF(R3<= Q3,"No Monetizar","Monetizar") -> No Monetizar
B4: 2 | C4: Safeguard World Inter Ltd | D4: FV-4-6248 | E4: 46085 | F4: 46145 | G4: =(TEXT(F4,"ddd")) -> dom | H4: =(TEXT(F4,"mmm")) -> may | I4: =F4-E4 -> 60 | J4: =IFERROR(IF(TODAY()>=E4,(TODAY()-E4)/I4,0),0) -> 0.6 | K4: 3380 | L4: 3375.426 | M4: =K4-L4 -> 4.5739626 | N4: 4019.09 | Q4: =K4*N4 -> 13584524 | R4: =L4*O4 -> 0 | S4: =R4-Q4 -> -13584524 | T4: =IF(R4<= Q4,"No Monetizar","Monetizar") -> No Monetizar
B5: 3 | C5: Safeguard World Inter Ltd | D5: FV-4-6312 | E5: 46085 | F5: 46145 | G5: =(TEXT(F5,"ddd")) -> dom | H5: =(TEXT(F5,"mmm")) -> may | I5: =F5-E5 -> 60 | J5: =IFERROR(IF(TODAY()>=E5,(TODAY()-E5)/I5,0),0) -> 0.6 | K5: 780 | L5: 778.94447 | M5: =K5-L5 -> 1.0555298 | N5: 3844.47 | Q5: =K5*N5 -> 2998686.6 | R5: =L5*O5 -> 0 | S5: =R5-Q5 -> -2998686.6 | T5: =IF(R5<= Q5,"No Monetizar","Monetizar") -> No Monetizar
B6: 4 | C6: Safeguard World Inter Ltd | D6: FV-4-6620 | E6: 46085 | F6: 46145 | G6: =(TEXT(F6,"ddd")) -> dom | H6: =(TEXT(F6,"mmm")) -> may | I6: =F6-E6 -> 60 | J6: =IFERROR(IF(TODAY()>=E6,(TODAY()-E6)/I6,0),0) -> 0.6 | K6: 2003.42 | L6: 2000.7089 | M6: =K6-L6 -> 2.7111148 | N6: 3682.97 | Q6: =K6*N6 -> 7378535.8 | R6: =L6*O6 -> 0 | S6: =R6-Q6 -> -7378535.8 | T6: =IF(R6<= Q6,"No Monetizar","Monetizar") -> No Monetizar
B7: 5 | C7: Safeguard World Inter Ltd | D7: FV-4-6622 | E7: 46085 | F7: 46145 | G7: =(TEXT(F7,"ddd")) -> dom | H7: =(TEXT(F7,"mmm")) -> may | I7: =F7-E7 -> 60 | J7: =IFERROR(IF(TODAY()>=E7,(TODAY()-E7)/I7,0),0) -> 0.6 | K7: 2280 | L7: 2276.9146 | M7: =K7-L7 -> 3.0853949 | N7: 3682.97 | Q7: =K7*N7 -> 8397171.6 | R7: =L7*O7 -> 0 | S7: =R7-Q7 -> -8397171.6 | T7: =IF(R7<= Q7,"No Monetizar","Monetizar") -> No Monetizar
B8: 6 | C8: Safeguard World Inter Ltd | D8: FV-4-6707 | E8: 46085 | F8: 46145 | G8: =(TEXT(F8,"ddd")) -> dom | H8: =(TEXT(F8,"mmm")) -> may | I8: =F8-E8 -> 60 | J8: =IFERROR(IF(TODAY()>=E8,(TODAY()-E8)/I8,0),0) -> 0.6 | K8: 2055.84 | L8: 2053.0579 | M8: =K8-L8 -> 2.7820518 | N8: 3691.34 | Q8: =K8*N8 -> 7588804.4 | R8: =L8*O8 -> 0 | S8: =R8-Q8 -> -7588804.4 | T8: =IF(R8<= Q8,"No Monetizar","Monetizar") -> No Monetizar
B9: 7 | C9: Safeguard World Inter Ltd | D9: FV-4-6575 | E9: 46080 | F9: 46140 | G9: =(TEXT(F9,"ddd")) -> mar | H9: =(TEXT(F9,"mmm")) -> abr | I9: =F9-E9 -> 60 | J9: =IFERROR(IF(TODAY()>=E9,(TODAY()-E9)/I9,0),0) -> 0.68333333 | K9: 1969.45 | L9: 1969.45 | M9: =K9-L9 -> 0 | N9: 3817.93 | O9: 3650 | Q9: =K9*N9 -> 7519222.2 | R9: =L9*O9 -> 7188492.5 | S9: =R9-Q9 -> -330729.74 | T9: =IF(R9<= Q9,"No Monetizar","Monetizar") -> No Monetizar
B10: 8 | C10: Safeguard World Inter Ltd | D10: FV-4-6576 | E10: 46080 | F10: 46140 | G10: =(TEXT(F10,"ddd")) -> mar | H10: =(TEXT(F10,"mmm")) -> abr | I10: =F10-E10 -> 60 | J10: =IFERROR(IF(TODAY()>=E10,(TODAY()-E10)/I10,0),0) -> 0.68333333 | K10: 1523.38 | L10: 1523.38 | M10: =K10-L10 -> 0 | N10: 3817.93 | O10: 3650 | Q10: =K10*N10 -> 5816158.2 | R10: =L10*O10 -> 5560337 | S10: =R10-Q10 -> -255821.2 | T10: =IF(R10<= Q10,"No Monetizar","Monetizar") -> No Monetizar
B11: 9 | C11: Safeguard World Inter Ltd | D11: FV-4-6577 | E11: 46080 | F11: 46140 | G11: =(TEXT(F11,"ddd")) -> mar | H11: =(TEXT(F11,"mmm")) -> abr | I11: =F11-E11 -> 60 | J11: =IFERROR(IF(TODAY()>=E11,(TODAY()-E11)/I11,0),0) -> 0.68333333 | K11: 2280 | L11: 2280 | M11: =K11-L11 -> 0 | N11: 3817.93 | O11: 3650 | Q11: =K11*N11 -> 8704880.4 | R11: =L11*O11 -> 8322000 | S11: =R11-Q11 -> -382880.4 | T11: =IF(R11<= Q11,"No Monetizar","Monetizar") -> No Monetizar
B12: 10 | C12: Global Upside LLC | D12: 6750 | E12: 46100 | F12: 46160 | G12: =(TEXT(F12,"ddd")) -> lun | H12: =(TEXT(F12,"mmm")) -> may | I12: =F12-E12 -> 60 | J12: =IFERROR(IF(TODAY()>=E12,(TODAY()-E12)/I12,0),0) -> 0.35 | K12: 1870 | L12: 1870 | M12: =K12-L12 -> 0 | N12: 3767.94 | O12: 3650 | Q12: =K12*N12 -> 7046047.8 | R12: =L12*O12 -> 6825500 | S12: =R12-Q12 -> -220547.8 | T12: =IF(R12<= Q12,"No Monetizar","Monetizar") -> No Monetizar
B13: 11 | C13: Solutions & Payroll SAS | D13: Giros Western Union | E13: 46105 | F13: 46165 | G13: =(TEXT(F13,"ddd")) -> sáb | H13: =(TEXT(F13,"mmm")) -> may | I13: =F13-E13 -> 60 | J13: =IFERROR(IF(TODAY()>=E13,(TODAY()-E13)/I13,0),0) -> 0.26666667 | K13: 13129 | L13: 13129 | M13: =K13-L13 -> 0 | N13: 3704.87 | O13: 3650 | Q13: =K13*N13 -> 48641238 | R13: =L13*O13 -> 47920850 | S13: =R13-Q13 -> -720388.23 | T13: =IF(R13<= Q13,"No Monetizar","Monetizar") -> No Monetizar
B14: 12 | C14: Deel | D14: 6728-6729-6730-6731-6732-6733-6734-6735-6736 | E14: 46105 | F14: 46165 | G14: =(TEXT(F14,"ddd")) -> sáb | H14: =(TEXT(F14,"mmm")) -> may | I14: =F14-E14 -> 60 | J14: =IFERROR(IF(TODAY()>=E14,(TODAY()-E14)/I14,0),0) -> 0.26666667 | K14: 11314.66 | L14: 11299.66 | M14: =K14-L14 -> 15 | N14: 3703.69 | O14: 3650 | Q14: =K14*N14 -> 41905993 | R14: =L14*O14 -> 41243759 | S14: =R14-Q14 -> -662234.1 | T14: =IF(R14<= Q14,"No Monetizar","Monetizar") -> No Monetizar
B15: 13 | C15: Deel | D15: 6737-6738-6739-6740-6741 | E15: 46105 | F15: 46165 | G15: =(TEXT(F15,"ddd")) -> sáb | H15: =(TEXT(F15,"mmm")) -> may | I15: =F15-E15 -> 60 | J15: =IFERROR(IF(TODAY()>=E15,(TODAY()-E15)/I15,0),0) -> 0.26666667 | K15: 5765.38 | L15: 5765.38 | M15: =K15-L15 -> 0 | N15: 3703.69 | O15: 3650 | Q15: =K15*N15 -> 21353180 | R15: =L15*O15 -> 21043637 | S15: =R15-Q15 -> -309543.25 | T15: =IF(R15<= Q15,"No Monetizar","Monetizar") -> No Monetizar
B16: 14 | C16: Deel | D16: FV-4-6325 | E16: 46105 | F16: 46165 | G16: =(TEXT(F16,"ddd")) -> sáb | H16: =(TEXT(F16,"mmm")) -> may | I16: =F16-E16 -> 60 | J16: =IFERROR(IF(TODAY()>=E16,(TODAY()-E16)/I16,0),0) -> 0.26666667 | K16: 1462.1 | L16: 1452.1 | M16: =K16-L16 -> 10 | N16: 3901.29 | O16: 3650 | Q16: =K16*N16 -> 5704076.1 | R16: =L16*O16 -> 5300165 | S16: =R16-Q16 -> -403911.11 | T16: =IF(R16<= Q16,"No Monetizar","Monetizar") -> No Monetizar
B18: 4 | C18: Bubble do Brasil | D18: FV-4-6815 | E18: 46112 | F18: 46172 | G18: =(TEXT(F18,"ddd")) -> sáb | H18: =(TEXT(F18,"mmm")) -> may | I18: =F18-E18 -> 60 | J18: =IFERROR(IF(TODAY()>=E18,(TODAY()-E18)/I18,0),0) -> 0.15 | K18: 129.22 | L18: 128.22901 | M18: =K18-L18 -> 0.99098892 | N18: 3637.76 | O18: 3750 | Q18: =K18*N18 -> 470071.35 | R18: =L18*O18 -> 480858.79 | S18: =R18-Q18 -> 10787.444 | T18: =IF(R18<= Q18,"No Monetizar","Monetizar") -> Monetizar
B19: 5 | C19: Bubble do Brasil | D19: FV-5-273 | E19: 46112 | F19: 46172 | G19: =(TEXT(F19,"ddd")) -> sáb | H19: =(TEXT(F19,"mmm")) -> may | I19: =F19-E19 -> 60 | J19: =IFERROR(IF(TODAY()>=E19,(TODAY()-E19)/I19,0),0) -> 0.15 | K19: 1174.73 | L19: 1165.721 | M19: =K19-L19 -> 9.0090111 | N19: 3637.76 | O19: 3750 | Q19: =K19*N19 -> 4273385.8 | R19: =L19*O19 -> 4371453.7 | S19: =R19-Q19 -> 98067.904 | T19: =IF(R19<= Q19,"No Monetizar","Monetizar") -> Monetizar
J20: =IFERROR(IF(TODAY()>=E20,(TODAY()-E20)/I20,0),0) -> 0
J21: =IFERROR(IF(TODAY()>=E21,(TODAY()-E21)/I21,0),0) -> 0 | Q21: =K21*N21 -> 0 | R21: =L21*O21 -> 0 | S21: =R21-Q21 -> 0 | T21: =IF(R21<= Q21,"No Monetizar","Monetizar") -> No Monetizar
Q22: =K22*N22 -> 0 | R22: =L22*O22 -> 0 | S22: =R22-Q22 -> 0 | T22: =IF(R22<= Q22,"No Monetizar","Monetizar") -> No Monetizar
B23: TOTAL | K23: =SUBTOTAL(9,K3:K22) -> 51717.18 | L23: =SUBTOTAL(9,L3:L22) -> 51667.16 | M23: =SUBTOTAL(9,M3:M22) -> 50.02 | Q23: =SUBTOTAL(9,Q3:Q22) -> 1.9379392e+08 | R23: =SUBTOTAL(9,R3:R22) -> 148257053 | S23: =SUBTOTAL(9,S3:S22) -> -45536863 | T23: =S23/Q23 -> -0.23497571
J25: Trm 9/3/2026
K26: 3741.47
Q29: CASH FLOW | Z29: ACCOUNTANT
B31: ID | C31: Client | D31: Invoice | E31: Incoming resources | F31: Maximum Date for Monetization | I31: Días | J31: Progress | K31: Invoiced | L31: Received | M31: Banking taxes | N31: TRm Invoice Cops | O31: TRM Bank (Average) Cops | P31: Difference in exchange rates | Q31: invoicing in COPS | R31: negotiated COPS | S31: difference | T31: KPI | U31: Color KPI | V31: Transaction date | W31: Propuesto | X31: Aprobado | Y31: Observaciones | Z31: negotiated COPS | AA31: difference
B32: 1 | C32: Action AD | D32: 5618 | E32: 45670 | F32: 45730 | J32: =IFERROR(IF(TODAY()>=E32,(TODAY()-E32)/I32,0),0)*0 -> 0 | K32: 6950.93 | L32: 6950.93 | M32: =K32-L32 -> 0 | N32: 4252.31 | O32: 4290.5 | P32: =O32-N32 -> 38.19 | Q32: =K32*N32 -> 29557509 | R32: =L32*O32 -> 29822965 | S32: =R32-Q32 -> 265456.02 | T32: =IF(R32<= Q32,"No Monetizar","Monetizar") -> Monetizar | V32: 45684 | W32: Alfonso Fonseca A | X32: Alfonso Fonseca A | Y32: Se monetiza ya que el valor ofrecido por el banco en cada divisa es superior al valor facturado | Z32: =K32*O32 -> 29822965 | AA32: =Z32-Q32 -> 265456.02
B33: 2 | C33: Remofirst | D33: 5619 | E33: 45684 | F33: 45744 | J33: =IFERROR(IF(TODAY()>=E33,(TODAY()-E33)/I33,0),0)*0 -> 0 | K33: 152785.56 | L33: 152785.56 | M33: =K33-L33 -> 0 | N33: 4235.51 | O33: 4303.83 | P33: =O33-N33 -> 68.32 | Q33: =K33*N33 -> 6.4712477e+08 | R33: =L33*O33 -> 6.5756308e+08 | S33: =R33-Q33 -> 10438309 | T33: =IF(R33<= Q33,"No Monetizar","Monetizar") -> Monetizar | V33: 45684 | W33: Alfonso Fonseca A | X33: Alfonso Fonseca A | Y33: Se monetiza ya que el valor ofrecido por el banco en cada divisa es superior al valor facturado | Z33: =K33*O33 -> 6.5756308e+08 | AA33: =Z33-Q33 -> 10438309
B34: 3 | C34: Endrington | D34: 5629 | E34: 45684 | F34: 45744 | J34: =IFERROR(IF(TODAY()>=E34,(TODAY()-E34)/I34,0),0)*0 -> 0 | K34: 22896.82 | L34: 22896.82 | M34: =K34-L34 -> 0 | N34: 4251.23 | O34: 4303.83 | P34: =O34-N34 -> 52.6 | Q34: =K34*N34 -> 97339648 | R34: =L34*O34 -> 98544021 | S34: =R34-Q34 -> 1204372.7 | T34: =IF(R34<= Q34,"No Monetizar","Monetizar") -> Monetizar | V34: 45684 | W34: Alfonso Fonseca A | X34: Alfonso Fonseca A | Y34: Se monetiza ya que el valor ofrecido por el banco en cada divisa es superior al valor facturado | Z34: =K34*O34 -> 98544021 | AA34: =Z34-Q34 -> 1204372.7
B35: 4 | C35: Marketing Doctors | D35: 5622 | E35: 45684 | F35: 45744 | J35: =IFERROR(IF(TODAY()>=E35,(TODAY()-E35)/I35,0),0)*0 -> 0 | K35: 2660.37 | L35: 2660.37 | M35: =K35-L35 -> 0 | N35: 4231.23 | O35: 4303.83 | P35: =O35-N35 -> 72.6 | Q35: =K35*N35 -> 11256637 | R35: =L35*O35 -> 11449780 | S35: =R35-Q35 -> 193142.86 | T35: =IF(R35<= Q35,"No Monetizar","Monetizar") -> Monetizar | V35: 45684 | W35: Alfonso Fonseca A | X35: Alfonso Fonseca A | Y35: Se monetiza ya que el valor ofrecido por el banco en cada divisa es superior al valor facturado | Z35: =K35*O35 -> 11449780 | AA35: =Z35-Q35 -> 193142.86
B36: 5 | C36: Flexco | D36: 5630 | E36: 45684 | F36: 45744 | J36: =IFERROR(IF(TODAY()>=E36,(TODAY()-E36)/I36,0),0)*0 -> 0 | K36: 12800.27 | L36: 12785.27 | M36: =K36-L36 -> 15 | N36: 4194.11 | O36: 4303.83 | P36: =O36-N36 -> 109.72 | Q36: =K36*N36 -> 53685740 | R36: =L36*O36 -> 55025629 | S36: =R36-Q36 -> 1339888.2 | T36: =IF(R36<= Q36,"No Monetizar","Monetizar") -> Monetizar | V36: 45684 | W36: Alfonso Fonseca A | X36: Alfonso Fonseca A | Y36: Se monetiza ya que el valor ofrecido por el banco en cada divisa es superior al valor facturado | Z36: =K36*O36 -> 55090186 | AA36: =Z36-Q36 -> 1404445.6
B37: 6 | C37: Nazdar ink technologies | D37: 5623 | E37: 45684 | F37: 45744 | J37: =IFERROR(IF(TODAY()>=E37,(TODAY()-E37)/I37,0),0)*0 -> 0 | K37: 18062.89 | L37: 18047.89 | M37: =K37-L37 -> 15 | N37: 4251.23 | O37: 4303.83 | P37: =O37-N37 -> 52.6 | Q37: =K37*N37 -> 76789500 | R37: =L37*O37 -> 77675050 | S37: =R37-Q37 -> 885550.56 | T37: =IF(R37<= Q37,"No Monetizar","Monetizar") -> Monetizar | V37: 45684 | W37: Alfonso Fonseca A | X37: Alfonso Fonseca A | Y37: Se monetiza ya que el valor ofrecido por el banco en cada divisa es superior al valor facturado | Z37: =K37*O37 -> 77739608 | AA37: =Z37-Q37 -> 950108.01
B38: 7 | C38: Oncehub | D38: 5631 | E38: 45684 | F38: 45744 | J38: =IFERROR(IF(TODAY()>=E38,(TODAY()-E38)/I38,0),0)*0 -> 0 | K38: 2833.35 | L38: 2813.35 | M38: =K38-L38 -> 20 | N38: 4231.53 | O38: 4303.83 | P38: =O38-N38 -> 72.3 | Q38: =K38*N38 -> 11989406 | R38: =L38*O38 -> 12108180 | S38: =R38-Q38 -> 118774.61 | T38: =IF(R38<= Q38,"No Monetizar","Monetizar") -> Monetizar | V38: 45684 | W38: Alfonso Fonseca A | X38: Alfonso Fonseca A | Y38: Se monetiza ya que el valor ofrecido por el banco en cada divisa es superior al valor facturado | Z38: =K38*O38 -> 12194257 | AA38: =Z38-Q38 -> 204851.21
B39: 8 | C39: Insider | D39: 5655 | E39: 45685 | F39: 45745 | J39: =IFERROR(IF(TODAY()>=E39,(TODAY()-E39)/I39,0),0)*0 -> 0 | K39: 106150.36 | L39: 106135.36 | M39: =K39-L39 -> 15 | N39: 4070.86 | O39: 4177.7 | P39: =O39-N39 -> 106.84 | Q39: =K39*N39 -> 4.3212325e+08 | R39: =L39*O39 -> 4.4340169e+08 | S39: =R39-Q39 -> 11278439 | T39: =IF(R39<= Q39,"No Monetizar","Monetizar") -> Monetizar | V39: 45686 | W39: Alfonso Fonseca A | X39: Alfonso Fonseca A | Y39: Se monetiza ya que el valor ofrecido por el banco en cada divisa es superior al valor facturado | Z39: =K39*O39 -> 4.4346436e+08 | AA39: =Z39-Q39 -> 11341104
B40: 9 | C40: Safeguard Payroll | D40: 5389 a 5406 | E40: 45680 | F40: 45740 | J40: =IFERROR(IF(TODAY()>=E40,(TODAY()-E40)/I40,0),0)*0 -> 0 | K40: 17192.43 | L40: 17177.43 | M40: =K40-L40 -> 15 | N40: 4367.39 | O40: 4441.62 | P40: =O40-N40 -> 74.23 | Q40: =K40*N40 -> 75086047 | R40: =L40*O40 -> 76295617 | S40: =R40-Q40 -> 1209569.8 | T40: =IF(R40<= Q40,"No Monetizar","Monetizar") -> Monetizar | V40: 45687 | W40: Alfonso Fonseca A | X40: Alfonso Fonseca A | Y40: Se monetiza ya que el valor ofrecido por el banco en cada divisa es superior al valor facturado | Z40: =K40*O40 -> 76362241 | AA40: =Z40-Q40 -> 1276194.1
B41: 10 | C41: Remofirst-Abono | D41: 5656 | E41: 45691 | F41: 45751 | J41: =IFERROR(IF(TODAY()>=E41,(TODAY()-E41)/I41,0),0)*0 -> 0 | K41: 1459.33 | L41: 1459.33 | M41: =K41-L41 -> 0 | N41: 4100.86 | O41: 4136.07 | P41: =O41-N41 -> 35.21 | Q41: =K41*N41 -> 5984508 | R41: =L41*O41 -> 6035891 | S41: =R41-Q41 -> 51383.009 | T41: =IF(R41<= Q41,"No Monetizar","Monetizar") -> Monetizar | V41: 45692 | W41: Alfonso Fonseca A | X41: Alfonso Fonseca A | Y41: Se monetiza ya que el valor ofrecido por el banco en cada divisa es superior al valor facturado | Z41: =K41*O41 -> 6035891 | AA41: =Z41-Q41 -> 51383.009
B42: 11 | C42: Remofirst-Saldo final | D42: 5656 | E42: 45700 | F42: 45760 | J42: =IFERROR(IF(TODAY()>=E42,(TODAY()-E42)/I42,0),0)*0 -> 0 | K42: 593.48 | L42: 593.48 | M42: =K42-L42 -> 0 | N42: 4100.86 | O42: 4147.5 | P42: =O42-N42 -> 46.64 | Q42: =K42*N42 -> 2433778.4 | R42: =L42*O42 -> 2461458.3 | S42: =R42-Q42 -> 27679.907 | T42: =IF(R42<= Q42,"No Monetizar","Monetizar") -> Monetizar | V42: 45700 | W42: Alfonso Fonseca A | X42: Alfonso Fonseca A | Y42: Se monetiza ya que el valor ofrecido por el banco en cada divisa es superior al valor facturado | Z42: =K42*O42 -> 2461458.3 | AA42: =Z42-Q42 -> 27679.907
B43: 12 | C43: Hong kong yonyou xinfushe cloud technology co | D43: 5628 | E43: 45679 | F43: 45739 | J43: =IFERROR(IF(TODAY()>=E43,(TODAY()-E43)/I43,0),0)*0 -> 0 | K43: 4737.5 | L43: 4737.5 | M43: =K43-L43 -> 0 | N43: 4231.23 | O43: 4143.44 | P43: =O43-N43 -> -87.79 | Q43: =K43*N43 -> 20045452 | R43: =L43*O43 -> 19629547 | S43: =R43-Q43 -> -415905.12 | T43: =IF(R43<= Q43,"No Monetizar","Monetizar") -> No Monetizar | V43: 45700 | W43: Alfonso Fonseca A | X43: Eduard Forero | Y43: Se monetizaron estas divisas por debajo del valor facturado debido a que, por el comportamiento del mercado, la TRM ha presentado una reducción notable desde el pasado 25 de enero, producto de factores externos de carácter económico. Desde el 07 de enero se realizó un monitoreo constante del comportamiento de esta divisa. En dicho período, el máximo crecimiento registrado fue el 12 de febrero frente al 07 de febrero, con un incremento de $15,99, alcanzando un valor máximo de $4,143,44. Entre el valor facturado y lo finalmente negociado, se tenía previsto un ingreso de $174 millones, pero el ingreso real fue de $173 millones, reflejando una desviación del 0,9 %. Adicionalmente, era necesario disponer de los recursos para cumplir con obligaciones financieras urgentes, como el pago de seguridad social, impuestos de retención en la fuente y cesantías, programados para el jueves 13 y viernes 14 de febrero. Por esta razón, no era viable esperar un aumento del valor de la divisa por encima del rango facturado, estimado entre $4,251 y $4,294. | Z43: =K43*O43 -> 19629547 | AA43: =Z43-Q43 -> -415905.12
B44: 13 | C44: Hemmebarsch GMBH & Co KG | D44: 5586 | E44: 45679 | F44: 45739 | J44: =IFERROR(IF(TODAY()>=E44,(TODAY()-E44)/I44,0),0)*0 -> 0 | K44: 867.66 | L44: 867.66 | M44: =K44-L44 -> 0 | N44: 4294.64 | O44: 4143.44 | P44: =O44-N44 -> -151.2 | Q44: =K44*N44 -> 3726287.3 | R44: =L44*O44 -> 3595097.2 | S44: =R44-Q44 -> -131190.19 | T44: =IF(R44<= Q44,"No Monetizar","Monetizar") -> No Monetizar | V44: 45700 | W44: Alfonso Fonseca A | X44: Eduard Forero | Y44: Se monetizaron estas divisas por debajo del valor facturado debido a que, por el comportamiento del mercado, la TRM ha presentado una reducción notable desde el pasado 25 de enero, producto de factores externos de carácter económico. Desde el 07 de enero se realizó un monitoreo constante del comportamiento de esta divisa. En dicho período, el máximo crecimiento registrado fue el 12 de febrero frente al 07 de febrero, con un incremento de $15,99, alcanzando un valor máximo de $4,143,44. Entre el valor facturado y lo finalmente negociado, se tenía previsto un ingreso de $174 millones, pero el ingreso real fue de $173 millones, reflejando una desviación del 0,9 %. Adicionalmente, era necesario disponer de los recursos para cumplir con obligaciones financieras urgentes, como el pago de seguridad social, impuestos de retención en la fuente y cesantías, programados para el jueves 13 y viernes 14 de febrero. Por esta razón, no era viable esperar un aumento del valor de la divisa por encima del rango facturado, estimado entre $4,251 y $4,294. | Z44: =K44*O44 -> 3595097.2 | AA44: =Z44-Q44 -> -131190.19
B45: 14 | C45: Neo | D45: 5624 | E45: 45680 | F45: 45740 | J45: =IFERROR(IF(TODAY()>=E45,(TODAY()-E45)/I45,0),0)*0 -> 0 | K45: 22499.23 | L45: 22453.23 | M45: =K45-L45 -> 46 | N45: 4216.23 | O45: 4143.44 | P45: =O45-N45 -> -72.79 | Q45: =K45*N45 -> 94861929 | R45: =L45*O45 -> 93033611 | S45: =R45-Q45 -> -1828317.2 | T45: =IF(R45<= Q45,"No Monetizar","Monetizar") -> No Monetizar | V45: 45700 | W45: Alfonso Fonseca A | X45: Eduard Forero | Y45: Se monetizaron estas divisas por debajo del valor facturado debido a que, por el comportamiento del mercado, la TRM ha presentado una reducción notable desde el pasado 25 de enero, producto de factores externos de carácter económico. Desde el 07 de enero se realizó un monitoreo constante del comportamiento de esta divisa. En dicho período, el máximo crecimiento registrado fue el 12 de febrero frente al 07 de febrero, con un incremento de $15,99, alcanzando un valor máximo de $4,143,44. Entre el valor facturado y lo finalmente negociado, se tenía previsto un ingreso de $174 millones, pero el ingreso real fue de $173 millones, reflejando una desviación del 0,9 %. Adicionalmente, era necesario disponer de los recursos para cumplir con obligaciones financieras urgentes, como el pago de seguridad social, impuestos de retención en la fuente y cesantías, programados para el jueves 13 y viernes 14 de febrero. Por esta razón, no era viable esperar un aumento del valor de la divisa por encima del rango facturado, estimado entre $4,251 y $4,294. | Z45: =K45*O45 -> 93224210 | AA45: =Z45-Q45 -> -1637719
...

Sheet DISTRIBUCIÓN (2)
H1: Sin Pagar | I1: Cancelado
B2: Distribución de dinero
B4: Semana | C4: Fecha Inicial | D4: Fecha Final | E4: Descripción | F4: Valor | H4: Sin pagar | I4: Cancelado | J4: Total
B5: 1 | C5: 45992 | D5: 45999 | E5: Pagos a Realizar | F5: =SUMIFS(DICIEMBRE!$E$115:$E$1613,DICIEMBRE!$F$115:$F$1613,">="&C5,DICIEMBRE!$F$115:$F$1613,"<="&D5,DICIEMBRE!$G$115:$G$1613,$H$1) -> 0 | G5: Proveedores
B6: 2 | C6: 46000 | D6: 46002 | E6: Pagos a Realizar | F6: =SUMIFS(DICIEMBRE!$E$115:$E$1613,DICIEMBRE!$F$115:$F$1613,">="&C6,DICIEMBRE!$F$115:$F$1613,"<="&D6,DICIEMBRE!$G$115:$G$1613,$H$1) -> 0 | G6: Proveedores | H6: =SUMIFS(DICIEMBRE!$E$115:$E$1613,DICIEMBRE!$F$115:$F$1613,">="&C5,DICIEMBRE!$F$115:$F$1613,"<="&$D$15,DICIEMBRE!$G$115:$G$1613,$H$1) -> 0 | I6: =SUMIFS(DICIEMBRE!$E$115:$E$1613,DICIEMBRE!$F$115:$F$1613,">="&C5,DICIEMBRE!$F$115:$F$1613,"<="&$D$15,DICIEMBRE!$G$115:$G$1613,$I$1) -> 2.8215259e+09 | J6: =SUM(H6:I6) -> 2.8215259e+09 | L6: =J6-#REF! -> #REF!
B7: 3 | C7: 46003 | D7: 46003 | E7: Pagos a Realizar | F7: =SUMIFS(DICIEMBRE!$E$115:$E$1613,DICIEMBRE!$F$115:$F$1613,">="&C7,DICIEMBRE!$F$115:$F$1613,"<="&D7,DICIEMBRE!$G$115:$G$1613,$H$1) -> 0 | G7: Seguridad social-Anticipo nómina Nazdar y Action
B8: 4 | C8: 46004 | D8: 46005 | E8: Pagos a Realizar | F8: =SUMIFS(DICIEMBRE!$E$115:$E$1613,DICIEMBRE!$F$115:$F$1613,">="&C8,DICIEMBRE!$F$115:$F$1613,"<="&D8,DICIEMBRE!$G$115:$G$1613,$H$1) -> 0 | I8: Comprobación | J8: =DICIEMBRE!E325 -> 2.8872815e+09
B9: 5 | C9: 46006 | D9: 46006 | E9: Pagos a Realizar | F9: =SUMIFS(DICIEMBRE!$E$115:$E$1613,DICIEMBRE!$F$115:$F$1613,">="&C9,DICIEMBRE!$F$115:$F$1613,"<="&D9,DICIEMBRE!$G$115:$G$1613,$H$1) -> 0 | G9: Primas EOR-S&P y Nómina Time Resort
C10: 46007 | D10: 46007 | E10: Pagos a Realizar | F10: =SUMIFS(DICIEMBRE!$E$115:$E$1613,DICIEMBRE!$F$115:$F$1613,">="&C10,DICIEMBRE!$F$115:$F$1613,"<="&D10,DICIEMBRE!$G$115:$G$1613,$H$1) -> 0 | G10: Impuestos Nacionales-TC Endrington
B11: 6 | C11: 46008 | D11: 46012 | E11: Pagos a Realizar | F11: =SUMIFS(DICIEMBRE!$E$115:$E$1613,DICIEMBRE!$F$115:$F$1613,">="&C11,DICIEMBRE!$F$115:$F$1613,"<="&D11,DICIEMBRE!$G$115:$G$1613,$H$1) -> 0
B12: 7 | C12: 46013 | D12: 46016 | E12: Pagos a Realizar | F12: =SUMIFS(DICIEMBRE!$E$115:$E$1613,DICIEMBRE!$F$115:$F$1613,">="&C12,DICIEMBRE!$F$115:$F$1613,"<="&D12,DICIEMBRE!$G$115:$G$1613,$H$1) -> 0 | G12: Proveedores
B13: 8 | C13: 46017 | D13: 46017 | E13: Pagos a Realizar | F13: =SUMIFS(DICIEMBRE!$E$115:$E$1613,DICIEMBRE!$F$115:$F$1613,">="&C13,DICIEMBRE!$F$115:$F$1613,"<="&D13,DICIEMBRE!$G$115:$G$1613,$H$1) -> 0 | G13: Nómina-Pagos a tercero-Proveedores
B14: 9 | C14: 46018 | D14: 46019 | E14: Pagos a Realizar | F14: =SUMIFS(DICIEMBRE!$E$115:$E$1613,DICIEMBRE!$F$115:$F$1613,">="&C14,DICIEMBRE!$F$115:$F$1613,"<="&D14,DICIEMBRE!$G$115:$G$1613,$H$1) -> 0
B15: 10 | C15: 46020 | D15: 46022 | E15: Pagos a Realizar | F15: =SUMIFS(DICIEMBRE!$E$115:$E$1613,DICIEMBRE!$F$115:$F$1613,">="&C15,DICIEMBRE!$F$115:$F$1613,"<="&D15,DICIEMBRE!$G$115:$G$1613,$H$1) -> 0 | G15: Proveedores
B16: TOTAL | F16: =SUM(F5:F15) -> 0
E18: Escenario 1
E19: Gastos y costos Periodo 01 al 17 Diciembre | F19: =SUM($F$5:$F$11) -> 0
E20: 4 X mil | F20: =($F$19*4)/1000 -> 0
E21: Total | F21: =SUM(F19:F20) -> 0
E23: Bancos | F23: =DICIEMBRE!$E$343 -> 1.0574441e+09
E24: Action AD | F24: 13000000
E25: Safeguard -Endrington-Noviembre | F25: ='MONETIZACIONES PEND'!#REF!*3700 -> #REF!
E26: Safeguard por identificar servicios de centro américa | F26: =('MONETIZACIONES PEND'!#REF!)*3700 -> #REF!
E27: Safeguard LTD x identificar | F27: =('MONETIZACIONES PEND'!#REF!)*3700 -> #REF!
E28: Global Project | F28: ='MONETIZACIONES PEND'!#REF!*3700 -> #REF!
E29: Remofirst | F29: ='MONETIZACIONES PEND'!#REF!*3700 -> #REF!
E30: Global CS Colombia SAS factura # 5-61 Reembolso Celulares | F30: 359994
E31: Global CS Colombia SAS -Solutions & payroll-Servicio Noviembre 2025 Factura 2-257 | F31: 19334755
E32: Clientes nacionales | F32: =DICIEMBRE!$E$14+DICIEMBRE!$E$15+DICIEMBRE!$E$26+DICIEMBRE!$E$24+DICIEMBRE!$E$29+DICIEMBRE!$E$30+DICIEMBRE!$E$47+DICIEMBRE!$E$57 -> 72533124
E33: Safeguard Payroll | F33: =SUM(DICIEMBRE!$E$51:$E$53) -> 0
E34: Insider | F34: =DICIEMBRE!$E$85 -> 1.4449483e+08
E35: Sobregiro | F35: 0
E36: Total | F36: =SUM(F23:F35) -> #REF!
E37: Saldo | F37: =F36-$F$21 -> #REF!
E39: Escenario 2
E41: Gastos y costos Periodo 01 al 17 Diciembre | F41: =SUM($F$5:$F$11)-DICIEMBRE!$E$267 -> -144223182
E42: 4 X mil | F42: =($F$19*4)/1000 -> 0
E43: Total | F43: =SUM(F41:F42) -> -144223182
E45: Bancos | F45: =DICIEMBRE!$E$343 -> 1.0574441e+09
E46: Action AD | F46: 13000000
...

Sheet Balanza DF
D3: Concepto | E3: Ene | F3: Feb | G3: Marzo | H3: Abril | I3: Mayo | J3: Junio | K3: Julio | L3: Agosto | M3: Septiembre | N3: Octubre | O3: Noviembre | P3: Diciembre | Q3: Acumulado
C4: 421020 | D4: Diferencia en cambio ( Ingreso) | E4: 26960712 | F4: 93771698 | G4: 57438103 | H4: =#REF!+#REF!+#REF!+#REF!+#REF!+#REF!+#REF!+#REF!+#REF!+#REF!+#REF!+#REF!+#REF!+#REF!+#REF!+#REF!+#REF!+#REF!+#REF!+#REF!+#REF!+#REF! -> #REF! | Q4: =SUM(E4:P4) -> #REF!
C5: 530525 | D5: Diferencia en cambio ( Gasto) | E5: 19562974 | F5: 6983301 | G5: 1320422 | H5: 2775771 | Q5: =SUM(E5:P5) -> 30642468
D6: Balanza 25 | E6: =E4-E5 -> 7397737.6 | F6: =F4-F5 -> 86788397 | G6: =G4-G5 -> 56117681 | H6: =H4-H5 -> #REF! | I6: =I4-I5 -> 0 | J6: =J4-J5 -> 0 | K6: =K4-K5 -> 0 | L6: =L4-L5 -> 0 | ... Q6: =Q4-Q5 -> #REF!
D8: Diferencia en cambio ( Ingreso) | E8: 20456548 | F8: 20805960 | G8: 2493777 | H8: 52141246 | Q8: =SUM(E8:P8) -> 95897531
D9: Diferencia en cambio ( Gasto) | E9: 593328 | F9: 9336021.7 | G9: 12371550 | H9: 1819382.6 | Q9: =SUM(E9:P9) -> 24120282
D10: Balanza 24 | E10: =E8-E9 -> 19863220 | F10: =F8-F9 -> 11469938 | G10: =G8-G9 -> -9877772.7 | H10: =H8-H9 -> 50321864 | I10: =I8-I9 -> 0 | J10: =J8-J9 -> 0 | K10: =K8-K9 -> 0 | L10: =L8-L9 -> 0 | ... Q10: =Q8-Q9 -> 71777249

Sheet Hoja2
B2: Seguridad social | E2: Retención en la fuente
B3: Enero | C3: 326365300 | E3: Enero | F3: 132004000
B4: Febrero | C4: 366144100 | E4: Febrero | F4: 114838000
B5: Marzo | C5: 336362300 | E5: Marzo | F5: 122963000
B6: Abril | C6: 356100200 | E6: Abril | F6: 121740150
B7: Total | C7: =AVERAGE(C3:C6) -> 346242975 | E7: Total | F7: =AVERAGE(F3:F6) -> 1.2288629e+08

Sheet Análisis
B2: Semana | C2: Fecha Inicial | D2: Fecha Final | E2: Descripción | F2: Valor
B3: 1 | C3: 45689 | D3: 45697 | E3: Proveedores | F3: 4927863.5
B4: 2 | C4: 45698 | D4: 45701 | E4: SS-Movistar | F4: 366472412
B5: 2 | C5: 45702 | D5: 45702 | E5: Cesantías-Anticipo NZD ACT | F5: 497926761
B6: 4 | C6: 45705 | D6: 45711 | E6: RTE FTE-TC Endrington-Proveedores | F6: 151400713
B7: SUBTOTAL | F7: =SUM(F3:F6) -> 1.0207277e+09
B8: 4 x MIL | F8: =(F7*4)/1000 -> 4082911
B9: TOTAL | F9: =SUM(F7:F8) -> 1.0248107e+09
E11: Bancos | F11: =#REF! -> #REF!
E12: Action # 5678 | F12: =#REF! -> #REF!
E13: Monetizaciones | F13: ='MONETIZACIONES PEND'!$R$23 -> 148257053 | J13: Facturado | K13: ='MONETIZACIONES PEND'!Q23 -> 1.9379392e+08 | L13: Monetizado | M13: =F13 -> 148257053 | N13: =F13-K13 -> -45536863
E14: Endrington | F14: =#REF! -> #REF!
E15: Payroll Safeguard | F15: =#REF! -> #REF! | H15: 13791.26 | I15: 4406.16 | J15: Facturado | K15: =H15*I15 -> 60766498 | L15: Monetizado | M15: =$H$15*$I$16 -> #REF! | N15: =K16-K15 -> #REF!
E16: Gran Total | F16: =SUM(F11:F15) -> #REF! | I16: ='MONETIZACIONES PEND'!#REF! -> #REF! | K16: =$H$15*$I$16 -> #REF!
E18: Deficit | F18: =F16-F9 -> #REF! | J18: Total | K18: =K13+K15 -> 2.5456041e+08 | M18: =M13+M15 -> #REF! | N18: =N13+N15 -> #REF!
N19: =N18/K18 -> #REF!

Sheet Hoja1
B2: Nazdar | C2: 13336.33 | D2: 1
B3: Flexco | C3: 6784.5 | D3: 2 | K3: 288.62 | L3: =K3/K5 -> 0.013950321 | M3: =G7*L3 -> 177.21916
B4: MKD | C4: 2103.98 | D4: 3 | K4: 20400.51 | L4: =K4/K5 -> 0.98604968 | M4: =G7*L4 -> 12526.371
B5: Remotefirst | C5: 106335.63 | K5: =SUM(K3:K4) -> 20689.13
B6: Remotefisrt | C6: 33144.18
B7: Neo | C7: 20628.13 | D7: 4 | F7: ='MONETIZACIONES PEND'!K239+'MONETIZACIONES PEND'!K240 -> 7924.54 | G7: =C7-F7 -> 12703.59
B8: Oncehub | C8: 2866.23 | D8: 5
B9: Total | C9: =SUM(C2:C8) -> 185198.98
H11: Mayor valor
B12: Forward 1 | C12: 133605.5 | E12: 4294.81 | G12: =C5+C6 -> 139479.81 | H12: =G12-C12 -> 5874.31
B13: Forward 2 | C13: 49487.77 | E13: 4239.77 | G13: =C2+C3+C4+C7+C8 -> 45719.17 | H13: =G13-C13 -> -3768.6
F38: Pendiente | G38: 33144.18
F40: Saldo | G40: 3768.6
F41: Saldo | G41: 27269.87
F42: Negocie | G42: 2105.71
G43: =SUM(G40:G42) -> 33144.18 | I43: =G43*4278.77 -> 1.4181632e+08
G45: =G38-G43 -> 0

Sheet Proyectado Moneti 
B2: ID | C2: Client | D2: Invoice | E2: Incoming resources | F2: Maximum Date for Monetization | G2: Días | H2: Progress | J2: Invoiced | L2: Received | M2: Banking taxes | N2: TRM Invoice Cops | O2: TRM Bank (Average) Cops | P2: Difference in exchange rates | Q2: invoicing in COPS | R2: negotiated COPS | S2: difference | T2: KPI | U2: Color KPI
B3: 1 | C3: Remofirst-10AK | D3: 4820 | E3: 45443 | F3: 45503 | G3: =F3-E3 -> 60 | H3: =IFERROR(IF(TODAY()>=E3,(TODAY()-E3)/G3,0),0) -> 11.3 | I3: 1 | J3: 9692.05 | K3: =J3/$J$23 -> 0.088543303 | L3: =J3-M3 -> 9688.0656 | M3: =K3*$K$23 -> 3.9844486 | N3: 3864.23 | O3: 3882.9 | P3: =O3-N3 -> 18.67 | Q3: =J3*N3 -> 37452310 | R3: =L3*O3 -> 37617790 | S3: =R3-Q3 -> 165479.36 | T3: =IF(O3<= N3,"No Monetizar","Monetizar") -> Monetizar | W3: Remofirst-10AK Factura # 4820
B4: 2 | C4: Remofirst-Ferrous | D4: 4821 | E4: 45443 | F4: 45503 | G4: =F4-E4 -> 60 | H4: =IFERROR(IF(TODAY()>=E4,(TODAY()-E4)/G4,0),0) -> 11.3 | I4: 1 | J4: 8127.7 | K4: =J4/$J$23 -> 0.074251929 | L4: =J4-M4 -> 8124.3587 | M4: =K4*$K$23 -> 3.3413368 | N4: 3864.23 | O4: 3882.9 | P4: =O4-N4 -> 18.67 | Q4: =J4*N4 -> 31407302 | R4: =L4*O4 -> 31546072 | S4: =R4-Q4 -> 138770.08 | T4: =IF(O4<= N4,"No Monetizar","Monetizar") -> Monetizar | W4: Remofirst-Ferrous Factura # 4821
B5: 3 | C5: Remofirst Bluleadz | D5: 4822 | E5: 45443 | F5: 45503 | G5: =F5-E5 -> 60 | H5: =IFERROR(IF(TODAY()>=E5,(TODAY()-E5)/G5,0),0) -> 11.3 | I5: 1 | J5: 5392.67 | K5: =J5/$J$23 -> 0.049265616 | L5: =J5-M5 -> 5390.453 | M5: =K5*$K$23 -> 2.2169527 | N5: 3864.23 | O5: 3882.9 | P5: =O5-N5 -> 18.67 | Q5: =J5*N5 -> 20838517 | R5: =L5*O5 -> 20930590 | S5: =R5-Q5 -> 92072.943 | T5: =IF(O5<= N5,"No Monetizar","Monetizar") -> Monetizar | W5: Remofirst Bluleadz Factura # 4822
B6: 4 | C6: Remofirst TC1 Corporation SAC | D6: 4823 | E6: 45443 | F6: 45503 | G6: =F6-E6 -> 60 | H6: =IFERROR(IF(TODAY()>=E6,(TODAY()-E6)/G6,0),0) -> 11.3 | I6: 1 | J6: 6167.93 | K6: =J6/$J$23 -> 0.05634813 | L6: =J6-M6 -> 6165.3943 | M6: =K6*$K$23 -> 2.5356659 | N6: 3864.23 | O6: 3882.9 | P6: =O6-N6 -> 18.67 | Q6: =J6*N6 -> 23834300 | R6: =L6*O6 -> 23939610 | S6: =R6-Q6 -> 105309.52 | T6: =IF(O6<= N6,"No Monetizar","Monetizar") -> Monetizar | W6: Remofirst TC1 Corporation SAC Factura # 4823
B7: 5 | C7: Remofirst BGB Comunications | D7: 4824 | E7: 45443 | F7: 45503 | G7: =F7-E7 -> 60 | H7: =IFERROR(IF(TODAY()>=E7,(TODAY()-E7)/G7,0),0) -> 11.3 | I7: 1 | J7: 2914.59 | K7: =J7/$J$23 -> 0.026626712 | L7: =J7-M7 -> 2913.3918 | M7: =K7*$K$23 -> 1.198202 | N7: 3864.23 | O7: 3882.9 | P7: =O7-N7 -> 18.67 | Q7: =J7*N7 -> 11262646 | R7: =L7*O7 -> 11312409 | S7: =R7-Q7 -> 49762.897 | T7: =IF(O7<= N7,"No Monetizar","Monetizar") -> Monetizar | W7: Remofirst BGB Comunications Factura # 4824
B8: 6 | C8: Remofirst Hypatos | D8: 4835 | E8: 45443 | F8: 45503 | G8: =F8-E8 -> 60 | H8: =IFERROR(IF(TODAY()>=E8,(TODAY()-E8)/G8,0),0) -> 11.3 | I8: 1 | J8: 3873.2 | K8: =J8/$J$23 -> 0.03538425 | L8: =J8-M8 -> 3871.6077 | M8: =K8*$K$23 -> 1.5922913 | N8: 3864.23 | O8: 3882.9 | P8: =O8-N8 -> 18.67 | Q8: =J8*N8 -> 14966936 | R8: =L8*O8 -> 15033066 | S8: =R8-Q8 -> 66129.936 | T8: =IF(O8<= N8,"No Monetizar","Monetizar") -> Monetizar | W8: Remofirst Hypatos Factura # 4835
B9: 7 | C9: Remofirst R&R Windows | D9: 4825 | E9: 45443 | F9: 45503 | G9: =F9-E9 -> 60 | H9: =IFERROR(IF(TODAY()>=E9,(TODAY()-E9)/G9,0),0) -> 11.3 | I9: 1 | J9: 7033.16 | K9: =J9/$J$23 -> 0.06425258 | L9: =J9-M9 -> 7030.2686 | M9: =K9*$K$23 -> 2.8913661 | N9: 3864.23 | O9: 3882.9 | P9: =O9-N9 -> 18.67 | Q9: =J9*N9 -> 27177748 | R9: =L9*O9 -> 27297830 | S9: =R9-Q9 -> 120082.21 | T9: =IF(O9<= N9,"No Monetizar","Monetizar") -> Monetizar | W9: Remofirst R&R Windows Factura # 4825
B10: 8 | C10: Remofirst Velo3D | D10: 4826 | E10: 45443 | F10: 45503 | G10: =F10-E10 -> 60 | H10: =IFERROR(IF(TODAY()>=E10,(TODAY()-E10)/G10,0),0) -> 11.3 | I10: 1 | J10: 3625.59 | K10: =J10/$J$23 -> 0.033122169 | L10: =J10-M10 -> 3624.0995 | M10: =K10*$K$23 -> 1.4904976 | N10: 3864.23 | O10: 3882.9 | P10: =O10-N10 -> 18.67 | Q10: =J10*N10 -> 14010114 | R10: =L10*O10 -> 14072016 | S10: =R10-Q10 -> 61902.312 | T10: =IF(O10<= N10,"No Monetizar","Monetizar") -> Monetizar | W10: Remofirst Velo3D Factura # 4826
B11: 9 | C11: Remofirst Starlight Software Solutions | D11: 4827 | E11: 45443 | F11: 45503 | G11: =F11-E11 -> 60 | H11: =IFERROR(IF(TODAY()>=E11,(TODAY()-E11)/G11,0),0) -> 11.3 | I11: 1 | J11: 5792.08 | K11: =J11/$J$23 -> 0.052914491 | L11: =J11-M11 -> 5789.6988 | M11: =K11*$K$23 -> 2.3811521 | N11: 3864.23 | O11: 3882.9 | P11: =O11-N11 -> 18.67 | Q11: =J11*N11 -> 22381929 | R11: =L11*O11 -> 22480822 | S11: =R11-Q11 -> 98892.358 | T11: =IF(O11<= N11,"No Monetizar","Monetizar") -> Monetizar | W11: Remofirst Starlight Software Solutions Factura # 4827
B12: 10 | C12: Remofirst One firefly | D12: 4828 | E12: 45443 | F12: 45503 | G12: =F12-E12 -> 60 | H12: =IFERROR(IF(TODAY()>=E12,(TODAY()-E12)/G12,0),0) -> 11.3 | I12: 1 | J12: 2779.95 | K12: =J12/$J$23 -> 0.025396686 | L12: =J12-M12 -> 2778.8071 | M12: =K12*$K$23 -> 1.1428509 | N12: 3864.23 | O12: 3882.9 | P12: =O12-N12 -> 18.67 | Q12: =J12*N12 -> 10742366 | R12: =L12*O12 -> 10789830 | S12: =R12-Q12 -> 47464.091 | T12: =IF(O12<= N12,"No Monetizar","Monetizar") -> Monetizar | W12: Remofirst One firefly Factura # 4828
B13: 11 | C13: Remofirst Search Wizards | D13: 4829 | E13: 45443 | F13: 45503 | G13: =F13-E13 -> 60 | H13: =IFERROR(IF(TODAY()>=E13,(TODAY()-E13)/G13,0),0) -> 11.3 | I13: 1 | J13: 1838.65 | K13: =J13/$J$23 -> 0.016797287 | L13: =J13-M13 -> 1837.8941 | M13: =K13*$K$23 -> 0.75587791 | N13: 3864.23 | O13: 3882.9 | P13: =O13-N13 -> 18.67 | Q13: =J13*N13 -> 7104966.5 | R13: =L13*O13 -> 7136359.1 | S13: =R13-Q13 -> 31392.597 | T13: =IF(O13<= N13,"No Monetizar","Monetizar") -> Monetizar | W13: Remofirst Search Wizards Factura # 4829
B14: 12 | C14: Remofirst Search Insighful | D14: 4830 | E14: 45443 | F14: 45503 | G14: =F14-E14 -> 60 | H14: =IFERROR(IF(TODAY()>=E14,(TODAY()-E14)/G14,0),0) -> 11.3 | I14: 1 | J14: 19928.19 | K14: =J14/$J$23 -> 0.18205723 | L14: =J14-M14 -> 19919.997 | M14: =K14*$K$23 -> 8.1925753 | N14: 3864.23 | O14: 3882.9 | P14: =O14-N14 -> 18.67 | Q14: =J14*N14 -> 77007110 | R14: =L14*O14 -> 77347358 | S14: =R14-Q14 -> 340248.36 | T14: =IF(O14<= N14,"No Monetizar","Monetizar") -> Monetizar | W14: Remofirst Search Insighful Factura # 4830
... B16: 14 | C16: Remofirst Coop Edgar | D16: 4832 | E16: 45443 | F16: 45503 | G16: =F16-E16 -> 60 | H16: =IFERROR(IF(TODAY()>=E16,(TODAY()-E16)/G16,0),0) -> 11.3 | I16: 1 | J16: 4054.74 | K16: =J16/$J$23 -> 0.037042738 | L16: =J16-M16 -> 4053.0731 | M16: =K16*$K$23 -> 1.6669232 | N16: 3864.23 | O16: 3882.9 | P16: =O16-N16 -> 18.67 | Q16: =J16*N16 -> 15668448 | R16: =L16*O16 -> 15737677 | S16: =R16-Q16 -> 69229.5 | T16: =IF(O16<= N16,"No Monetizar","Monetizar") -> Monetizar | W16: Remofirst Coop Edgar Factura # 4832
B17: 15 | C17: Remofirst Search AMG Global Distribution | D17: 4833 | E17: 45443 | F17: 45503 | G17: =F17-E17 -> 60 | H17: =IFERROR(IF(TODAY()>=E17,(TODAY()-E17)/G17,0),0) -> 11.3 | I17: 1 | J17: =16965.69 -> 16965.69 | K17: =J17/$J$23 -> 0.15499283 | L17: =J17-M17 -> 16958.715 | M17: =K17*$K$23 -> 6.9746772 | N17: 3864.23 | O17: 3882.9 | P17: =O17-N17 -> 18.67 | Q17: =J17*N17 -> 65559328 | R17: =L17*O17 -> 65848996 | S17: =R17-Q17 -> 289667.46 | T17: =IF(O17<= N17,"No Monetizar","Monetizar") -> Monetizar | W17: Remofirst Search AMG Global Distribution Factura # 4833
B18: 16 | C18: Remofirst Search Carbon better | D18: 4834 | E18: 45443 | F18: 45503 | G18: =F18-E18 -> 60 | H18: =IFERROR(IF(TODAY()>=E18,(TODAY()-E18)/G18,0),0) -> 11.3 | I18: 1 | J18: =1712.33 -> 1712.33 | K18: =J18/$J$23 -> 0.01564327 | L18: =J18-M18 -> 1711.6261 | M18: =K18*$K$23 -> 0.70394715 | N18: 3864.23 | O18: 3882.9 | P18: =O18-N18 -> 18.67 | Q18: =J18*N18 -> 6616837 | R18: =L18*O18 -> 6646072.8 | S18: =R18-Q18 -> 29235.845 | T18: =IF(O18<= N18,"No Monetizar","Monetizar") -> Monetizar | W18: Remofirst Search Carbon better Factura # 4834
B19: 17 | C19: Remofirst CPaT Global LLC | D19: 4879 | E19: 45443 | F19: 45503 | G19: =F19-E19 -> 60 | H19: =IFERROR(IF(TODAY()>=E19,(TODAY()-E19)/G19,0),0) -> 11.3 | J19: 4772 | K19: =J19/$J$23 -> 0.043595384 | L19: =J19-M19 -> 4770.0382 | M19: =K19*$K$23 -> 1.9617923 | N19: 3864.23 | O19: 3882.9 | P19: =O19-N19 -> 18.67 | Q19: =J19*N19 -> 18440106 | R19: =L19*O19 -> 18521581 | S19: =R19-Q19 -> 81475.797 | T19: =IF(O19<= N19,"No Monetizar","Monetizar") -> Monetizar | W19: Remofirst CPaT Global LLC Factura # 4879
B20: 18 | C20: Remofirst CPaT Global LLC | D20: 4880 | E20: 45443 | F20: 45503 | G20: =F20-E20 -> 60 | H20: =IFERROR(IF(TODAY()>=E20,(TODAY()-E20)/G20,0),0) -> 11.3 | J20: 3016.51 | K20: =J20/$J$23 -> 0.027557819 | L20: =J20-M20 -> 3015.2699 | M20: =K20*$K$23 -> 1.2401019 | N20: 3864.23 | O20: 3882.9 | P20: =O20-N20 -> 18.67 | Q20: =J20*N20 -> 11656488 | R20: =L20*O20 -> 11707991 | S20: =R20-Q20 -> 51503.05 | T20: =IF(O20<= N20,"No Monetizar","Monetizar") -> Monetizar | W20: Remofirst CPaT Global LLC Factura # 4880
B21: TOTAL | J21: =SUM(J3:J20) -> 109461.13 | L21: =SUM(L3:L20) -> 109416.13 | M21: =SUM(M3:M20) -> 45 | Q21: =SUM(Q3:Q20) -> 4.2298298e+08 | R21: =SUM(R3:R20) -> 4.2485189e+08 | S21: =SUM(S3:S20) -> 1868908.8 | T21: =S21/Q21 -> 0.0044184019
H23: Remotefirst | J23: =SUM(J3:J20) -> 109461.13 | K23: 45
J26: Diferencia Cambio
J28: Diferencia en cambio ( Ingreso) | M28: =#REF!+#REF!+#REF! -> #REF!
J29: Diferencia en cambio ( Gasto) | M29: =S21+'MONETIZACIONES PEND'!S23 -> -43667954
J30: Balanza | M30: =SUM(M28:M29) -> #REF!
