Workbook

Sheet BAC SAN JOSE COLONES  
D1: BAC SAN JOSE COLONES | E1: INGRESO | F1: SALIDA | G1: SALDO
A2: FECHA | D2: CUENTA S&P | G2: 0
D3: BENEFICIARIO - CLIENTE DETALLES
A5: 44926 | D5: SALDO 31 DE DICIEMBRE 2021 | G5: 84354.37
A6: 44927 | E6: 0 | F6: 0 | G6: =G5+E6-F6 -> 84354.37
A7: 44937 | D7: TRANSFER DE FONDOS CTA USD A COLONES $ 300 USD | E7: 172500 | G7: =G6+E7-F7 -> 256854.37
A8: 44937 | D8: SERVICIOS ADM MES DE ENERO ALEJANDRO ECHAVARRIA | F8: 105000 | G8: =G7+E8-F8 -> 151854.37
A9: 44937 | D9: PAGO DE COMPRA DE CAFÉ VB ED FORERO | F9: 77000 | G9: =G8+E9-F9 -> 74854.37
A10: 44937 | D10: PAGO DE TRANSFERENCIA SINPE BAC SAN JOSE | F10: 1767 | G10: =G9+E10-F10 -> 73087.37
A11: 44946 | D11: PAGO DE RECARGA DE FACTURAS ELECTRONICAS A GTI | F11: 13560 | G11: =G10+E11-F11 -> 59527.37
A12: 44957 | G12: =G11+E12-F12 -> 59527.37
A13: 44958 | D13: TRANSFER DE FONDOS CTA USD A COLONES $ 700 USD | E13: 384300 | G13: =G12+E13-F13 -> 443827.37
A14: 44958 | D14: SERVICIOS ADM MES DE ENERO ALEJANDRO ECHAVARRIA | F14: 105000 | G14: =G13+E14-F14 -> 338827.37
A15: 44958 | D15: PAGO DE COMPRA DE CAFÉ VB ED FORERO | F15: 77000 | G15: =G14+E15-F15 -> 261827.37
A16: 44958 | D16: PAGO DE TRANSFERENCIA SINPE BAC SAN JOSE | F16: 422.25 | G16: =G15+E16-F16 -> 261405.12
A17: 44958 | D17: MINISTERIO DE HACIENDA IMP DE SOCIEDADES 2023 | F17: 231173 | G17: =G16+E17-F17 -> 30232.12
A18: 44985 | G18: =G17+E18-F18 -> 30232.12
A19: 44987 | D19: TRANSFER DE FONDOS CTA USD A COLONES $ 300 USD | E19: 165600 | G19: =G18+E19-F19 -> 195832.12
A20: 44987 | D20: SERVICIOS ADM MES DE ENERO ALEJANDRO ECHAVARRIA | F20: 105000 | G20: =G19+E20-F20 -> 90832.12
A21: 44987 | D21: PAGO DE COMPRA DE CAFÉ VB ED FORERO | F21: 77000 | G21: =G20+E21-F21 -> 13832.12
A22: 44987 | D22: PAGO DE TRANSFERENCIA SINPE BAC SAN JOSE | F22: 424.5 | G22: =G21+E22-F22 -> 13407.62
A23: 45016 | D23: COMISION SALDO MINIMO | F23: 3000 | G23: =G22+E23-F23 -> 10407.62
A24: 45016 | G24: =G23+E24-F24 -> 10407.62
A25: 45040 | D25: TRANSFER DE FONDOS CTA USD A COLONES $ 200 USD | E25: 105200 | G25: =G24+E25-F25 -> 115607.62
A26: 45040 | D26: PAGO DE COMPRA DE CAFÉ VB ED FORERO | F26: 77000 | G26: =G25+E26-F26 -> 38607.62
A27: 45040 | D27: PAGO DE TRANSFERENCIA SINPE BAC SAN JOSE | F27: 1620 | G27: =G26+E27-F27 -> 36987.62
A28: 45046 | D28: COMISION SALDO MINIMO | F28: 3000 | G28: =G27+E28-F28 -> 33987.62
A29: 45046 | G29: =G28+E29-F29 -> 33987.62
A30: 45047 | D30: TRANSFER DE FONDOS CTA USD A COLONES $ 200 USD | E30: 107600 | G30: =G29+E30-F30 -> 141587.62
A31: 45048 | D31: PAGO DE COMPRA DE CAFÉ VB ED FORERO | F31: 77000 | G31: =G30+E31-F31 -> 64587.62
A32: 45049 | D32: PAGO DE TRANSFERENCIA SINPE BAC SAN JOSE | F32: 414 | G32: =G31+E32-F32 -> 64173.62
A33: 45077 | G33: =G32+E33-F33 -> 64173.62
A34: 45082 | D34: TRANSFER DE FONDOS CTA USD A COLONES $ 300 USD | E34: 160800 | G34: =G33+E34-F34 -> 224973.62
A35: 45082 | D35: SERVICIOS ADM MES DE JUNIO ALEJANDRO ECHAVARRIA | F35: 105000 | G35: =G34+E35-F35 -> 119973.62
A36: 45082 | D36: PAGO DE COMPRA DE CAFÉ VB ED FORERO | F36: 77000 | G36: =G35+E36-F36 -> 42973.62
A37: 45082 | D37: PAGO DE TRANSFERENCIA SINPE BAC SAN JOSE | F37: 412.5 | G37: =G36+E37-F37 -> 42561.12
A38: 45105 | D38: TRANSFER DE FONDOS CTA USD A COLONES $ 1400 USD TC 540 | E38: 756000 | G38: =G37+E38-F38 -> 798561.12
A39: 45105 | D39: NOMINA PRISCILLA POLSON MES DE JUNIO | F39: 752248 | G39: =G38+E39-F39 -> 46313.12
A40: 45107 | G40: =G39+E40-F40 -> 46313.12
A41: 45110 | D41: TRANSFER DE FONDOS CTA USD A COLONES $ 300 USD | E41: 161700 | G41: =G40+E41-F41 -> 208013.12
...

Sheet BAC SAN JOSE USD
A1: FECHA | D1: BAC SAN JOSE DOLARES | E1: INGRESO | F1: SALIDA | G1: SALDO
D2: CUENTA S&P | G2: 0
D3: BENEFICIARIO - CLIENTE DETALLES
D5: SALDO 31 DE DICIEMBRE 2022 | G5: 4726.85
A6: 44937 | D6: TRANSFERENCIA CUENTA COLONES | E6: 0 | F6: 300 | G6: =G5+E6-F6 -> 4426.85
A7: 44957 | G7: =G6+E7-F7 -> 4426.85
A8: 44958 | D8: TRANSFER DE FONDOS A CUENTA COLONES | F8: 700 | G8: =G7+E8-F8 -> 3726.85
A9: 44985 | G9: =G8+E9-F9 -> 3726.85
A10: 44986 | D10: TRANSFERENCIA CUENTA COLONES | F10: 300 | G10: =G9+E10-F10 -> 3426.85
A11: 44988 | D11: TRANSFERENCIA COMPRA DE COMPUTADORA GUATEMALA VB RICARDO ARAMBULO | F11: 2640 | G11: =G10+E11-F11 -> 786.85
A12: 44988 | D12: COMISION TRANSFER INTERNACIONAL | F12: 30 | G12: =G11+E12-F12 -> 756.85
A13: 45016 | D13: TRANSFER DE FONDOS A CUENTA COLONES | G13: =G12+E13-F13 -> 756.85
A14: 45040 | D14: TRANSFERENCIA CUENTA COLONES | F14: 200 | G14: =G13+E14-F14 -> 556.85
A15: 45046 | G15: =G14+E15-F15 -> 556.85
A16: 45047 | G16: =G15+E16-F16 -> 556.85
A17: 45051 | D17: TRANSFERENCIA CUENTA COLONES | F17: 200 | G17: =G16+E17-F17 -> 356.85
A18: 45076 | D18: TRANSFER SOLUTIONS AND PAYRROL COLOMBIA | E18: 980 | G18: =G17+E18-F18 -> 1336.85
A19: 45076 | D19: COMISION TRANSFERENCIA INTERNACIONAL | F19: 20 | G19: =G18+E19-F19 -> 1316.85
A20: 45077 | G20: =G19+E20-F20 -> 1316.85
A21: 45078 | D21: NOMINA JONATHAN SALAZAR GARCIA MES DE MAYO | F21: 1243.06 | G21: =G20+E21-F21 -> 73.79
A22: 45079 | D22: REMORFIST FACT 082 | E22: 1931.89 | G22: =G21+E22-F22 -> 2005.68
A23: 45079 | D23: COMISION TRANSFERENCIA INTERNACIONAL | F23: 20 | G23: =G22+E23-F23 -> 1985.68
A24: 45104 | D24: TRANSFERENCIA CUENTA COLONES | F24: 300 | G24: =G23+E24-F24 -> 1685.68
A25: 45104 | D25: REMORFIST FACT 083 | E25: 5473.67 | G25: =G24+E25-F25 -> 7159.35
A26: 45104 | D26: REMORFIST FACT 084 | E26: 2117.21 | G26: =G25+E26-F26 -> 9276.56
A27: 45104 | D27: COMISION TRANSFERENCIA INTERNACIONAL | F27: 20 | G27: =G26+E27-F27 -> 9256.56
A28: 45104 | D28: COMISION TRANSFERENCIA INTERNACIONAL | F28: 20 | G28: =G27+E28-F28 -> 9236.56
A29: 45105 | D29: NOMINA JONATHAN SALAZAR GARCIA MES DE JUNIO | F29: 3407.11 | G29: =G28+E29-F29 -> 5829.45
A30: 45105 | D30: TRANSFERENCIA CUENTA COLONES | F30: 1400 | G30: =G29+E30-F30 -> 4429.45
A31: 45107 | D31: COMISION SALDO MINIMO | F31: 6 | G31: =G30+E31-F31 -> 4423.45
A32: 45107 | G32: =G31+E32-F32 -> 4423.45
A33: 45110 | D33: TRANSFERENCIA CUENTA COLONES | F33: 300 | G33: =G32+E33-F33 -> 4123.45
A34: 45124 | D34: TRANSFERENCIA CUENTA COLONES | F34: 300 | G34: =G33+E34-F34 -> 3823.45
A35: 45128 | D35: REMORFIST FACT 085 | E35: 4076.02 | G35: =G34+E35-F35 -> 7899.47
A36: 45128 | D36: REMORFIST FACT 086 | E36: 5473.67 | G36: =G35+E36-F36 -> 13373.14
A37: 45128 | D37: COMISION TRANSFERENCIA INTERNACIONAL | F37: 20 | G37: =G36+E37-F37 -> 13353.14
A38: 45128 | D38: COMISION TRANSFERENCIA INTERNACIONAL | F38: 20 | G38: =G37+E38-F38 -> 13333.14
A39: 45135 | D39: TRANSFERENCIA CUENTA COLONES | F39: 3000 | G39: =G38+E39-F39 -> 10333.14
A40: 45135 | D40: NOMINA JONATHAN SALAZAR GARCIA MES DE JULIO | F40: 3407.11 | G40: =G39+E40-F40 -> 6926.03
A41: 45138 | G41: =G40+E41-F41 -> 6926.03
...

Sheet FLUJO CAJA ABRIL
D1: 42400
D4: Fecha de Elaboración: | E4: 45385
C6: Tasa de cambio: | D6: 501
D7: ABRIL
D8: VALOR ₡ CRC | E8: VALOR USD
C9: BANCOS | D9: =SUBTOTAL(9,D10:D11) -> 9666655.2 | E9: =SUBTOTAL(9,E10:E11) -> 19294.721
C10: Bancos ₡ CRC | D10: ='BAC SAN JOSE COLONES '!$G$155 -> 5804661.6 | E10: =D10/$D$6 -> 11586.151
C11: Bancos USD | D11: ='BAC SAN JOSE USD'!$G$162*'FLUJO CAJA ABRIL'!$D$6 -> 3861993.6 | E11: =D11/$D$6 -> 7708.57
C12: CLIENTES | D12: =SUBTOTAL(9,D13:D16) -> 16450881 | E12: =SUBTOTAL(9,E13:E16) -> 32836.09
C13: Client: Remorfist-Client-Starlight SS | D13: =E13*$D$6 -> 5099608.9 | E13: 10178.86
C14: Client: Remorfist-Client: Aluminati | D14: =E14*$D$6 -> 4506364.7 | E14: 8994.74
C15: Client: Remorfist - Client: TC1SS | D15: =E15*$D$6 -> 1239904.9 | E15: 2474.86
C16: Remorfist - Client: CZ SS | D16: =E16*$D$6 -> 5605002.6 | E16: 11187.63
C17: TOTAL INGRESOS | D17: =SUBTOTAL(9,D9:D16) -> 26117536 | E17: =SUBTOTAL(9,E9:E16) -> 52130.811
B20: CUENTAS X PAGAR MES | D20: ABRIL
B21: Factura | C21: PROVEEDOR | D21: VALOR ₡ CRC | E21: VALOR USD | F21: Fecha vencimiento | G21: Estado | J21: KPI
C22: SEGURIDAD IGSS | D22: =SUBTOTAL(9,D23:D23) -> 4490553 | E22: =SUBTOTAL(9,E23:E23) -> 8963.1796
B23: 176206200 | C23: Pago CCSS marzo | D23: 4490553 | E23: =D23/$D$6 -> 8963.1796 | F23: 45406 | G23: Cancelado | H23: =IF(OR(G23="Sin pagar",G23="Pagar"),_xlfn.SINGLE(NETWORKDAYS($E$4,F23,'Festivos CR'!$A$3:$A$15)),0) -> 0 | I23: =NETWORKDAYS($E$4,F23,'Festivos CR'!$A$3:$A$15) -> 15 | J23: =H23 -> 0
C24: IMPUESTOS | D24: =SUBTOTAL(9,D25:D26) -> 1096496 | E24: =SUBTOTAL(9,E25:E26) -> 2188.6148 | J24: =H24 -> 0
C25: Retención en la fuente | D25: 985183 | E25: =D25/$D$6 -> 1966.4331 | F25: 45393 | G25: Cancelado | H25: =IF(OR(G25="Sin pagar",G25="Pagar"),_xlfn.SINGLE(NETWORKDAYS($E$4,F25,'Festivos CR'!$A$3:$A$15)),0) -> 0 | I25: =NETWORKDAYS($E$4,F25,'Festivos CR'!$A$3:$A$15) -> 6 | J25: =H25 -> 0
C26: Rte fte por declaración de remesas al exterior Facturación S&P Colombia a S&P CR | D26: 111313 | E26: =D26/$D$6 -> 222.18164 | F26: 45393 | G26: Cancelado | H26: =IF(OR(G26="Sin pagar",G26="Pagar"),_xlfn.SINGLE(NETWORKDAYS($E$4,F26,'Festivos CR'!$A$3:$A$15)),0) -> 0 | I26: =NETWORKDAYS($E$4,F26,'Festivos CR'!$A$3:$A$15) -> 6 | J26: =H26 -> 0
C27: SERVICIOS PROFESIONALES -REPRESENTACIÓN LEGAL | D27: =SUBTOTAL(9,D28:D29) -> 365700 | E27: =SUBTOTAL(9,E28:E29) -> 729.94012 | J27: =H27 -> 0
B28: 55 | C28: Fabian Leonardo Ulloa -Certificación de cuenta BAC | D28: 178500 | E28: =D28/$D$6 -> 356.28743 | F28: 45390 | G28: Cancelado | H28: =IF(OR(G28="Sin pagar",G28="Pagar"),_xlfn.SINGLE(NETWORKDAYS($E$4,F28,'Festivos CR'!$A$3:$A$15)),0) -> 0 | I28: =NETWORKDAYS($E$4,F28,'Festivos CR'!$A$3:$A$15) -> 4 | J28: =H28 -> 0
B29: 14 | C29: Alejandro Echavarria apoyo admon Febrero, Marzo y abril | D29: 187200 | E29: =D29/$D$6 -> 373.65269 | F29: 45406 | G29: Cancelado | H29: =IF(OR(G29="Sin pagar",G29="Pagar"),_xlfn.SINGLE(NETWORKDAYS($E$4,F29,'Festivos CR'!$A$3:$A$15)),0) -> 0 | I29: =NETWORKDAYS($E$4,F29,'Festivos CR'!$A$3:$A$15) -> 15 | J29: =H29 -> 0
C30: GASTOS DE OFICINA | D30: =SUBTOTAL(9,D31:D31) -> 77000 | E30: =SUBTOTAL(9,E31:E31) -> 153.69261
B31: 54 | C31: Compra de café | D31: 77000 | E31: =D31/$D$6 -> 153.69261 | F31: 45383 | G31: Cancelado | H31: =IF(OR(G31="Sin pagar",G31="Pagar"),_xlfn.SINGLE(NETWORKDAYS($E$4,F31,'Festivos CR'!$A$3:$A$15)),0) -> 0 | I31: =NETWORKDAYS($E$4,F31,'Festivos CR'!$A$3:$A$15) -> -3 | J31: =H31 -> 0
C32: COBROS ENTRE SUCURSALES | D32: =SUBTOTAL(9,D33:D34) -> 0 | E32: =SUBTOTAL(9,E33:E34) -> 0
B33: 4699 | C33: Cobro S&P a sucursal Enero a marzo | D33: =E33*$D$6*0 -> 0 | E33: =880*0 -> 0 | F33: 45443 | G33: Sin Pagar | H33: =IF(OR(G33="Sin pagar",G33="Pagar"),_xlfn.SINGLE(NETWORKDAYS($E$4,F33,'Festivos CR'!$A$3:$A$15)),0) -> 41 | I33: =NETWORKDAYS($E$4,F33,'Festivos CR'!$A$3:$A$15) -> 41 | J33: =H33 -> 41
B34: 4777 | C34: Cobro S&P a sucursal Abril | D34: =E34*$D$6*0 -> 0 | E34: =720*0 -> 0 | F34: 45496 | G34: Sin Pagar | H34: =IF(OR(G34="Sin pagar",G34="Pagar"),_xlfn.SINGLE(NETWORKDAYS($E$4,F34,'Festivos CR'!$A$3:$A$15)),0) -> 78 | I34: =NETWORKDAYS($E$4,F34,'Festivos CR'!$A$3:$A$15) -> 78 | J34: =H34 -> 78
C35: COSTOS FINANCIEROS | D35: =SUBTOTAL(9,D36:D36) -> 0.071197605 | E35: =SUBTOTAL(9,E36:E36) -> 35.67
C36: COSTOS FINANCIEROS | D36: =E36/$D$6 -> 0.071197605 | E36: 35.67 | F36: 45412 | G36: Cancelado | H36: =IF(OR(G36="Sin pagar",G36="Pagar"),_xlfn.SINGLE(NETWORKDAYS($E$4,F36,'Festivos CR'!$A$3:$A$15)),0) -> 0 | I36: =NETWORKDAYS($E$4,F36,'Festivos CR'!$A$3:$A$15) -> 19 | J36: =H36 -> 0
C37: NÓMINAS | D37: =SUBTOTAL(9,D38:D43) -> 10255109 | E37: =SUBTOTAL(9,E38:E43) -> 20482.591
C38: Jhoel González González-Starlight-CR003 | D38: 1612916.3 | E38: =D38/500 -> 3225.8327 | F38: 45412 | G38: Cancelado | H38: =IF(OR(G38="Sin pagar",G38="Pagar"),_xlfn.SINGLE(NETWORKDAYS($E$4,F38,'Festivos CR'!$A$3:$A$15)),0) -> 0 | I38: =NETWORKDAYS($E$4,F38,'Festivos CR'!$A$3:$A$15) -> 19 | J38: =H38 -> 0
C39: Jonathan Salazar García -Starlight-CR003 | D39: =E39*500 -> 1721625 | E39: 3443.25 | F39: 45412 | G39: Cancelado | H39: =IF(OR(G39="Sin pagar",G39="Pagar"),_xlfn.SINGLE(NETWORKDAYS($E$4,F39,'Festivos CR'!$A$3:$A$15)),0) -> 0 | I39: =NETWORKDAYS($E$4,F39,'Festivos CR'!$A$3:$A$15) -> 19 | J39: =H39 -> 0
C40: Priscilla Grace Polson -Aluminati-CR004 | D40: 1410537.3 | E40: =D40/501 -> 2815.4437 | F40: 45412 | G40: Cancelado | H40: =IF(OR(G40="Sin pagar",G40="Pagar"),_xlfn.SINGLE(NETWORKDAYS($E$4,F40,'Festivos CR'!$A$3:$A$15)),0) -> 0 | I40: =NETWORKDAYS($E$4,F40,'Festivos CR'!$A$3:$A$15) -> 19 | J40: =H40 -> 0
C41: José Roberto Aguilar Barrante-Aluminati-CR004 | D41: 1410537.3 | E41: =D41/501 -> 2815.4437 | F41: 45412 | G41: Cancelado | H41: =IF(OR(G41="Sin pagar",G41="Pagar"),_xlfn.SINGLE(NETWORKDAYS($E$4,F41,'Festivos CR'!$A$3:$A$15)),0) -> 0 | I41: =NETWORKDAYS($E$4,F41,'Festivos CR'!$A$3:$A$15) -> 19 | J41: =H41 -> 0
C42: Sebastían Gerardo Salazar, -TC1SS | D42: 803970 | E42: =D42/501 -> 1604.7305 | F42: 45412 | G42: Cancelado | H42: =IF(OR(G42="Sin pagar",G42="Pagar"),_xlfn.SINGLE(NETWORKDAYS($E$4,F42,'Festivos CR'!$A$3:$A$15)),0) -> 0 | I42: =NETWORKDAYS($E$4,F42,'Festivos CR'!$A$3:$A$15) -> 19 | J42: =H42 -> 0
C43: Tatiana Araya Pochet-CZ-CR006 | D43: =E43*501 -> 3295522.9 | E43: 6577.89 | F43: 45412 | G43: Cancelado | H43: =IF(OR(G43="Sin pagar",G43="Pagar"),_xlfn.SINGLE(NETWORKDAYS($E$4,F43,'Festivos CR'!$A$3:$A$15)),0) -> 0 | I43: =NETWORKDAYS($E$4,F43,'Festivos CR'!$A$3:$A$15) -> 19 | J43: =H43 -> 0
C44: IMPREVISTO | D44: =SUBTOTAL(9,D45:D45) -> 0 | E44: =SUBTOTAL(9,E45:E45) -> 0
D45: 0 | E45: =D45/$D$6 -> 0 | F45: 45412 | G45: Cancelado | H45: =IF(OR(G45="Sin pagar",G45="Pagar"),_xlfn.SINGLE(NETWORKDAYS($E$4,F45,'Festivos CR'!$A$3:$A$15)),0) -> 0 | I45: =NETWORKDAYS($E$4,F45,'Festivos CR'!$A$3:$A$15) -> 19 | J45: =H45 -> 0
...

Sheet FLUJO CAJA MAYO
D1: 42400
D4: Fecha de Elaboración: | E4: 45415
C6: Tasa de cambio: | D6: 521
D7: MAYO
D8: VALOR ₡ CRC | E8: VALOR USD
C9: BANCOS | D9: =SUBTOTAL(9,D10:D11) -> 10199679 | E9: =SUBTOTAL(9,E10:E11) -> 19577.119
C10: Bancos ₡ CRC | D10: ='BAC SAN JOSE COLONES '!$G$174 -> 5275416 | E10: =D10/$D$6 -> 10125.559
C11: Bancos USD | D11: ='BAC SAN JOSE USD'!$G$172*'FLUJO CAJA MAYO'!$D$6 -> 4924262.8 | E11: =D11/$D$6 -> 9451.56
C12: CLIENTES | D12: =SUBTOTAL(9,D13:D17) -> 17809249 | E12: =SUBTOTAL(9,E13:E17) -> 34182.819
C13: Client: Remorfist-Client-Starlight SS -Factura Nro 126 | D13: =E13*$D$6 -> 5566149.5 | E13: =CONVERSIONES!$C$87+CONVERSIONES!$D$87 -> 10683.588
C14: Client: Remorfist-Client: Aluminati-Factura Nro 127 | D14: =E14*$D$6 -> 4621343.3 | E14: =(CONVERSIONES!$E$87+CONVERSIONES!$F$87-142) -> 8870.1407
C15: Client: Remorfist - Client: TC1SS-Factura Nro 128 | D15: =E15*$D$6 -> 520854.12 | E15: =CONVERSIONES!$G$87 -> 999.72
C16: Remorfist - Client: CZ SS-Factura Nro 131 | D16: =E16*$D$6 -> 5833282.7 | E16: =CONVERSIONES!$H$87 -> 11196.32
C17: Remorfist - Client: PLLC- Factura Nro 130 | D17: =E17*$D$6 -> 1267619.1 | E17: =CONVERSIONES!$I$87 -> 2433.05
C18: TOTAL INGRESOS | D18: =SUBTOTAL(9,D9:D17) -> 28008927 | E18: =SUBTOTAL(9,E9:E17) -> 53759.938
B21: CUENTAS X PAGAR MES | D21: MAYO
B22: Factura | C22: PROVEEDOR | D22: VALOR ₡ CRC | E22: VALOR USD | F22: Fecha vencimiento | G22: Estado | J22: KPI
C23: SEGURIDAD IGSS | D23: =SUBTOTAL(9,D24:D24) -> 4718443 | E23: =SUBTOTAL(9,E24:E24) -> 9056.5125
B24: 176206200 | C24: Pago CCSS abril | D24: 4718443 | E24: =D24/$D$6 -> 9056.5125 | F24: 45422 | G24: Cancelado | H24: =IF(OR(G24="Sin pagar",G24="Pagar"),_xlfn.SINGLE(NETWORKDAYS($E$4,F24,'Festivos CR'!$A$3:$A$15)),0) -> 0 | I24: =NETWORKDAYS($E$4,F24,'Festivos CR'!$A$3:$A$15) -> 6 | J24: =H24 -> 0
C25: IMPUESTOS | D25: =SUBTOTAL(9,D26:D27) -> 1139287.6 | E25: =SUBTOTAL(9,E26:E27) -> 2186.7325 | J25: =H25 -> 0
C26: Retención en la fuente | D26: 1029558.6 | E26: =D26/$D$6 -> 1976.1202 | F26: 45422 | G26: Cancelado | H26: =IF(OR(G26="Sin pagar",G26="Pagar"),_xlfn.SINGLE(NETWORKDAYS($E$4,F26,'Festivos CR'!$A$3:$A$15)),0) -> 0 | I26: =NETWORKDAYS($E$4,F26,'Festivos CR'!$A$3:$A$15) -> 6 | J26: =H26 -> 0
C27: Rte fte por declaración de remesas al exterior Facturación S&P Colombia a S&P CR | D27: 109729 | E27: =D27/$D$6 -> 210.61228 | F27: 45422 | G27: Cancelado | H27: =IF(OR(G27="Sin pagar",G27="Pagar"),_xlfn.SINGLE(NETWORKDAYS($E$4,F27,'Festivos CR'!$A$3:$A$15)),0) -> 0 | I27: =NETWORKDAYS($E$4,F27,'Festivos CR'!$A$3:$A$15) -> 6 | J27: =H27 -> 0
C28: SERVICIOS PROFESIONALES -REPRESENTACIÓN LEGAL | D28: =SUBTOTAL(9,D29:D29) -> 62400 | E28: =SUBTOTAL(9,E29:E29) -> 119.76967 | J28: =H28 -> 0
C29: Servicios profesionales Alejandro Echavarria Mayo | D29: 62400 | E29: =D29/$D$6 -> 119.76967 | F29: 45440 | G29: Cancelado | H29: =IF(OR(G29="Sin pagar",G29="Pagar"),_xlfn.SINGLE(NETWORKDAYS($E$4,F29,'Festivos CR'!$A$3:$A$15)),0) -> 0 | I29: =NETWORKDAYS($E$4,F29,'Festivos CR'!$A$3:$A$15) -> 18 | J29: =H29 -> 0
C30: GASTOS DE OFICINA | D30: =SUBTOTAL(9,D31:D31) -> 77000 | E30: =SUBTOTAL(9,E31:E31) -> 147.79271
B31: 54 | C31: Compra de café | D31: 77000 | E31: =D31/$D$6 -> 147.79271 | F31: 45415 | G31: Cancelado | H31: =IF(OR(G31="Sin pagar",G31="Pagar"),_xlfn.SINGLE(NETWORKDAYS($E$4,F31,'Festivos CR'!$A$3:$A$15)),0) -> 0 | I31: =NETWORKDAYS($E$4,F31,'Festivos CR'!$A$3:$A$15) -> 1 | J31: =H31 -> 0
C32: COBROS ENTRE SUCURSALES | D32: =SUBTOTAL(9,D33:D35) -> 0 | E32: =SUBTOTAL(9,E33:E35) -> 0
B33: 4699 | C33: Cobro S&P a sucursal Enero a marzo | D33: =E33*$D$6*0 -> 0 | E33: =880*0 -> 0 | F33: 45443 | G33: Cancelado | H33: =IF(OR(G33="Sin pagar",G33="Pagar"),_xlfn.SINGLE(NETWORKDAYS($E$4,F33,'Festivos CR'!$A$3:$A$15)),0) -> 0 | I33: =NETWORKDAYS($E$4,F33,'Festivos CR'!$A$3:$A$15) -> 21 | J33: =H33 -> 0
B34: 4777 | C34: Cobro S&P a sucursal Abril | D34: =E34*$D$6*0 -> 0 | E34: =720*0 -> 0 | F34: 45443 | G34: Cancelado | H34: =IF(OR(G34="Sin pagar",G34="Pagar"),_xlfn.SINGLE(NETWORKDAYS($E$4,F34,'Festivos CR'!$A$3:$A$15)),0) -> 0 | I34: =NETWORKDAYS($E$4,F34,'Festivos CR'!$A$3:$A$15) -> 21 | J34: =H34 -> 0
B35: 4777 | C35: Cobro S&P a sucursal Mayo | D35: =E35*$D$6*0 -> 0 | E35: =720*0 -> 0 | H35: =IF(OR(G47="Sin pagar",G47="Pagar"),_xlfn.SINGLE(NETWORKDAYS($E$4,F47,'Festivos CR'!$A$3:$A$15)),0) -> 0 | I35: =NETWORKDAYS($E$4,F47,'Festivos CR'!$A$3:$A$15) -> 21 | J35: =H35 -> 0
C36: COSTOS FINANCIEROS | D36: =SUBTOTAL(9,D37:D37) -> 430.47 | E36: =SUBTOTAL(9,E37:E37) -> 0.826238
C37: COSTOS FINANCIEROS | D37: =(386.25+386.25)-342.03 -> 430.47 | E37: =D37/D6 -> 0.826238 | F37: 45443 | G37: Cancelado | H37: =IF(OR(G37="Sin pagar",G37="Pagar"),_xlfn.SINGLE(NETWORKDAYS($E$4,F37,'Festivos CR'!$A$3:$A$15)),0) -> 0 | I37: =NETWORKDAYS($E$4,F37,'Festivos CR'!$A$3:$A$15) -> 21 | J37: =H37 -> 0
C38: NÓMINAS | D38: =SUBTOTAL(9,D39:D45) -> 10824358 | E38: =SUBTOTAL(9,E39:E45) -> 20776.119
C39: Jhoel González González-Starlight-CR003 | D39: 1612916.3 | E39: =D39/$D$6 -> 3095.8087 | F39: 45440 | G39: Cancelado | H39: =IF(OR(G39="Sin pagar",G39="Pagar"),_xlfn.SINGLE(NETWORKDAYS($E$4,F39,'Festivos CR'!$A$3:$A$15)),0) -> 0 | I39: =NETWORKDAYS($E$4,F39,'Festivos CR'!$A$3:$A$15) -> 18 | J39: =H39 -> 0
C40: Jonathan Salazar García -Starlight-CR003 | D40: =E40*$D$6 -> 1771728.2 | E40: 3400.63 | F40: 45440 | G40: Cancelado | H40: =IF(OR(G40="Sin pagar",G40="Pagar"),_xlfn.SINGLE(NETWORKDAYS($E$4,F40,'Festivos CR'!$A$3:$A$15)),0) -> 0 | I40: =NETWORKDAYS($E$4,F40,'Festivos CR'!$A$3:$A$15) -> 18 | J40: =H40 -> 0
C41: Priscilla Grace Polson -Aluminati-CR004 | D41: 1410537.3 | E41: =D41/$D$6 -> 2707.3653 | F41: 45440 | G41: Cancelado | H41: =IF(OR(G41="Sin pagar",G41="Pagar"),_xlfn.SINGLE(NETWORKDAYS($E$4,F41,'Festivos CR'!$A$3:$A$15)),0) -> 0 | I41: =NETWORKDAYS($E$4,F41,'Festivos CR'!$A$3:$A$15) -> 18 | J41: =H41 -> 0
C42: José Roberto Aguilar Barrante-Aluminati-CR004 | D42: 1410537.3 | E42: =D42/$D$6 -> 2707.3653 | F42: 45440 | G42: Cancelado | H42: =IF(OR(G42="Sin pagar",G42="Pagar"),_xlfn.SINGLE(NETWORKDAYS($E$4,F42,'Festivos CR'!$A$3:$A$15)),0) -> 0 | I42: =NETWORKDAYS($E$4,F42,'Festivos CR'!$A$3:$A$15) -> 18 | J42: =H42 -> 0
C43: Sebastían Gerardo Salazar, -Liquidación -TC1 Corp | D43: 417000 | E43: =D43/$D$6 -> 800.38388 | F43: 45440 | G43: Cancelado | H43: =IF(OR(G43="Sin pagar",G43="Pagar"),_xlfn.SINGLE(NETWORKDAYS($E$4,F43,'Festivos CR'!$A$3:$A$15)),0) -> 0 | I43: =NETWORKDAYS($E$4,F43,'Festivos CR'!$A$3:$A$15) -> 18 | J43: =H43 -> 0
C44: Sheryl Gertrudiz Cambronero Estrada-lorez & Prada PPLC | D44: 786551.54 | E44: =D44/$D$6 -> 1509.6959 | F44: 45440 | G44: Cancelado | H44: =IF(OR(G44="Sin pagar",G44="Pagar"),_xlfn.SINGLE(NETWORKDAYS($E$4,F44,'Festivos CR'!$A$3:$A$15)),0) -> 0 | I44: =NETWORKDAYS($E$4,F44,'Festivos CR'!$A$3:$A$15) -> 18 | J44: =H44 -> 0
C45: Tatiana Araya Pochet-CZ-CR006 | D45: =E45*$D$6 -> 3415087.3 | E45: 6554.87 | F45: 45440 | G45: Cancelado | H45: =IF(OR(G45="Sin pagar",G45="Pagar"),_xlfn.SINGLE(NETWORKDAYS($E$4,F45,'Festivos CR'!$A$3:$A$15)),0) -> 0 | I45: =NETWORKDAYS($E$4,F45,'Festivos CR'!$A$3:$A$15) -> 18 | J45: =H45 -> 0
...

Sheet FLUJO CAJA JUNIO 
D1: 42400
D4: Fecha de Elaboración: | E4: 45448
C6: Tasa de cambio: | D6: 519
D7: JUNIO
D8: VALOR ₡ CRC | E8: VALOR USD
C9: BANCOS | D9: =SUBTOTAL(9,D10:D11) -> 11184425 | E9: =SUBTOTAL(9,E10:E11) -> 21549.952
C10: Bancos ₡ CRC | D10: ='BAC SAN JOSE COLONES '!$G$191 -> 7003070.3 | E10: =D10/$D$6 -> 13493.392
C11: Bancos USD | D11: ='BAC SAN JOSE USD'!$G$180*'FLUJO CAJA JUNIO '!$D$6 -> 4181354.6 | E11: =D11/$D$6 -> 8056.56
C12: CLIENTES | D12: =SUBTOTAL(9,D13:D17) -> 17395560 | E12: =SUBTOTAL(9,E13:E17) -> 33473.042
C13: Client: Remorfist-Client-Starlight SS -Factura Nro 131 | D13: =E13*519 -> 5409010.8 | E13: =CONVERSIONES!$C$106+CONVERSIONES!$D$106 -> 10421.986
C14: Client: Remorfist-Client: Aluminati-Factura Nro 132 | D14: =E14*520 -> 4455235.7 | E14: =CONVERSIONES!$E$106+CONVERSIONES!$F$106 -> 8567.7609
C15: Remorfist - Client: CZ SS-Factura Nro 133 | D15: =E15*520 -> 5814099.2 | E15: =CONVERSIONES!$G$106 -> 11180.96
C16: Remorfist - Client: PLLC- Factura Nro 134 | D16: =E16*520 -> 1197801.6 | E16: =CONVERSIONES!$H$106 -> 2303.4646
C17: Client: Remorfist-Client-Starlight SS -Factura Nro 135 | D17: =E17*520 -> 519412.4 | E17: =CONVERSIONES!$I$106 -> 998.87
C18: TOTAL INGRESOS | D18: =SUBTOTAL(9,D9:D17) -> 28579985 | E18: =SUBTOTAL(9,E9:E17) -> 55022.993
B21: CUENTAS X PAGAR MES | D21: JUNIO
B22: Factura | C22: PROVEEDOR | D22: VALOR ₡ CRC | E22: VALOR USD | F22: Fecha vencimiento | G22: Estado | J22: KPI
C23: SEGURIDAD IGSS | D23: =SUBTOTAL(9,D24:D24) -> 4806878 | E23: =SUBTOTAL(9,E24:E24) -> 9261.8073
B24: 176206200 | C24: Pago CCSS Mayo | D24: 4806878 | E24: =D24/$D$6 -> 9261.8073 | F24: 45450 | G24: Cancelado | H24: =IF(OR(G24="Sin pagar",G24="Pagar"),_xlfn.SINGLE(NETWORKDAYS($E$4,F24,'Festivos CR'!$A$3:$A$15)),0) -> 0 | I24: =NETWORKDAYS($E$4,F24,'Festivos CR'!$A$3:$A$15) -> 3 | J24: =H24 -> 0
C25: IMPUESTOS | D25: =SUBTOTAL(9,D26:D27) -> 1174829.7 | E25: =SUBTOTAL(9,E26:E27) -> 2263.641 | J25: =H25 -> 0
C26: Retención en la fuente | D26: 1092316.7 | E26: =D26/$D$6 -> 2104.6564 | F26: 45457 | G26: Cancelado | H26: =IF(OR(G26="Sin pagar",G26="Pagar"),_xlfn.SINGLE(NETWORKDAYS($E$4,F26,'Festivos CR'!$A$3:$A$15)),0) -> 0 | I26: =NETWORKDAYS($E$4,F26,'Festivos CR'!$A$3:$A$15) -> 8 | J26: =H26 -> 0
C27: Rte fte por declaración de remesas al exterior Facturación S&P Colombia a S&P CR | D27: 82513 | E27: =D27/$D$6 -> 158.98459 | F27: 45457 | G27: Cancelado | H27: =IF(OR(G27="Sin pagar",G27="Pagar"),_xlfn.SINGLE(NETWORKDAYS($E$4,F27,'Festivos CR'!$A$3:$A$15)),0) -> 0 | I27: =NETWORKDAYS($E$4,F27,'Festivos CR'!$A$3:$A$15) -> 8 | J27: =H27 -> 0
C28: SERVICIOS PROFESIONALES -REPRESENTACIÓN LEGAL | D28: =SUBTOTAL(9,D29:D29) -> 62400 | E28: =SUBTOTAL(9,E29:E29) -> 120.23121 | J28: =H28 -> 0
B29: 16 | C29: Servicios profesionales Alejandro Echavarria Junio | D29: 62400 | E29: =D29/$D$6 -> 120.23121 | F29: 45471 | G29: Cancelado | H29: =IF(OR(G29="Sin pagar",G29="Pagar"),_xlfn.SINGLE(NETWORKDAYS($E$4,F29,'Festivos CR'!$A$3:$A$15)),0) -> 0 | I29: =NETWORKDAYS($E$4,F29,'Festivos CR'!$A$3:$A$15) -> 18 | J29: =H29 -> 0
C30: GASTOS DE OFICINA | D30: =SUBTOTAL(9,D31:D31) -> 77000 | E30: =SUBTOTAL(9,E31:E31) -> 148.36224
B31: 55 | C31: Compra de café | D31: 77000 | E31: =D31/$D$6 -> 148.36224 | F31: 45447 | G31: Cancelado | H31: =IF(OR(G31="Sin pagar",G31="Pagar"),_xlfn.SINGLE(NETWORKDAYS($E$4,F31,'Festivos CR'!$A$3:$A$15)),0) -> 0 | I31: =NETWORKDAYS($E$4,F31,'Festivos CR'!$A$3:$A$15) -> -2 | J31: =H31 -> 0
C32: COBROS ENTRE SUCURSALES | D32: =SUBTOTAL(9,D33:D36) -> 0 | E32: =SUBTOTAL(9,E33:E36) -> 0
B33: 4699 | C33: Cobro S&P a sucursal Enero a marzo | D33: =E33*$D$6*0 -> 0 | E33: =880*0 -> 0 | F33: 45504 | G33: Cancelado | H33: =IF(OR(G33="Sin pagar",G33="Pagar"),_xlfn.SINGLE(NETWORKDAYS($E$4,F33,'Festivos CR'!$A$3:$A$15)),0) -> 0 | I33: =NETWORKDAYS($E$4,F33,'Festivos CR'!$A$3:$A$15) -> 40 | J33: =H33 -> 0
B34: 4777 | C34: Cobro S&P a sucursal Abril | D34: =E34*$D$6*0 -> 0 | E34: =720*0 -> 0 | F34: 45504 | G34: Cancelado | H34: =IF(OR(G34="Sin pagar",G34="Pagar"),_xlfn.SINGLE(NETWORKDAYS($E$4,F34,'Festivos CR'!$A$3:$A$15)),0) -> 0 | I34: =NETWORKDAYS($E$4,F34,'Festivos CR'!$A$3:$A$15) -> 40 | J34: =H34 -> 0
B35: 4878 | C35: Cobro S&P a sucursal Mayo | D35: =E35*$D$6*0 -> 0 | E35: =720*0 -> 0 | F35: 45504 | G35: Cancelado | H35: =IF(OR(G48="Sin pagar",G48="Pagar"),_xlfn.SINGLE(NETWORKDAYS($E$4,F48,'Festivos CR'!$A$3:$A$15)),0) -> 0 | I35: =NETWORKDAYS($E$4,F48,'Festivos CR'!$A$3:$A$15) -> 18 | J35: =H35 -> 0
B36: XXXX | C36: Cobro S&P a sucursal Junio | D36: =E36*$D$6*0 -> 0 | E36: =720*0 -> 0 | F36: 45504 | G36: Cancelado | H36: =IF(OR(G49="Sin pagar",G49="Pagar"),_xlfn.SINGLE(NETWORKDAYS($E$4,F49,'Festivos CR'!$A$3:$A$15)),0) -> 0 | I36: =NETWORKDAYS($E$4,F49,'Festivos CR'!$A$3:$A$15) -> -32458 | J36: =H36 -> 0
C37: COSTOS FINANCIEROS | D37: =SUBTOTAL(9,D38:D38) -> 403.5 | E37: =SUBTOTAL(9,E38:E38) -> 0.77745665
C38: COSTOS FINANCIEROS | D38: 403.5 | E38: =D38/D6 -> 0.77745665 | F38: 45473 | G38: Cancelado | H38: =IF(OR(G38="Sin pagar",G38="Pagar"),_xlfn.SINGLE(NETWORKDAYS($E$4,F38,'Festivos CR'!$A$3:$A$15)),0) -> 0 | I38: =NETWORKDAYS($E$4,F38,'Festivos CR'!$A$3:$A$15) -> 18 | J38: =H38 -> 0
C39: NÓMINAS | D39: =SUBTOTAL(9,D40:D46) -> 10706121 | E39: =SUBTOTAL(9,E40:E46) -> 20628.365
B40: CRC | C40: Jhoel González González-Starlight-CR003 | D40: 1612916.3 | E40: =D40/$D$6 -> 3107.7386 | F40: 45471 | G40: Cancelado | H40: =IF(OR(G40="Sin pagar",G40="Pagar"),_xlfn.SINGLE(NETWORKDAYS($E$4,F40,'Festivos CR'!$A$3:$A$15)),0) -> 0 | I40: =NETWORKDAYS($E$4,F40,'Festivos CR'!$A$3:$A$15) -> 18 | J40: =H40 -> 0
B41: USD | C41: Jonathan Salazar García -Starlight-CR003 | D41: =E41*$D$6 -> 1768653.4 | E41: 3407.81 | F41: 45471 | G41: Cancelado | H41: =IF(OR(G41="Sin pagar",G41="Pagar"),_xlfn.SINGLE(NETWORKDAYS($E$4,F41,'Festivos CR'!$A$3:$A$15)),0) -> 0 | I41: =NETWORKDAYS($E$4,F41,'Festivos CR'!$A$3:$A$15) -> 18 | J41: =H41 -> 0
B42: CRC | C42: Daniel Nazario Casto Vindas-Starlight-CR003 | D42: 326417.87 | E42: =D42/$D$6 -> 628.93617 | F42: 45471 | G42: Cancelado | H42: =IF(OR(G42="Sin pagar",G42="Pagar"),_xlfn.SINGLE(NETWORKDAYS($E$4,F42,'Festivos CR'!$A$3:$A$15)),0) -> 0 | I42: =NETWORKDAYS($E$4,F42,'Festivos CR'!$A$3:$A$15) -> 18 | J42: =H42 -> 0
B43: CRC | C43: Priscilla Grace Polson -Aluminati-CR004 | D43: 1410537.3 | E43: =D43/$D$6 -> 2717.7983 | F43: 45471 | G43: Cancelado | H43: =IF(OR(G43="Sin pagar",G43="Pagar"),_xlfn.SINGLE(NETWORKDAYS($E$4,F43,'Festivos CR'!$A$3:$A$15)),0) -> 0 | I43: =NETWORKDAYS($E$4,F43,'Festivos CR'!$A$3:$A$15) -> 18 | J43: =H43 -> 0
B44: CRC | C44: José Roberto Aguilar Barrante-Aluminati-CR004 | D44: 1410537.3 | E44: =D44/$D$6 -> 2717.7983 | F44: 45471 | G44: Cancelado | H44: =IF(OR(G44="Sin pagar",G44="Pagar"),_xlfn.SINGLE(NETWORKDAYS($E$4,F44,'Festivos CR'!$A$3:$A$15)),0) -> 0 | I44: =NETWORKDAYS($E$4,F44,'Festivos CR'!$A$3:$A$15) -> 18 | J44: =H44 -> 0
B45: CRC | C45: Sheryl Gertrudiz Cambronero Estrada-lorez & Prada PPLC | D45: 786551.54 | E45: =D45/$D$6 -> 1515.5136 | F45: 45471 | G45: Cancelado | H45: =IF(OR(G45="Sin pagar",G45="Pagar"),_xlfn.SINGLE(NETWORKDAYS($E$4,F45,'Festivos CR'!$A$3:$A$15)),0) -> 0 | I45: =NETWORKDAYS($E$4,F45,'Festivos CR'!$A$3:$A$15) -> 18 | J45: =H45 -> 0
...

Sheet FLUJO CAJA JULIO 
D1: 42400
D4: Fecha de Elaboración: | E4: 45474
C6: Tasa de cambio: | D6: 522
D7: JULIO
D8: VALOR ₡ CRC | E8: VALOR USD
C9: BANCOS | D9: =SUBTOTAL(9,D10:D11) -> 11779308 | E9: =SUBTOTAL(9,E10:E11) -> 22565.724
C10: Bancos ₡ CRC | D10: ='BAC SAN JOSE COLONES '!G207 -> 7080494.5 | E10: =D10/$D$6 -> 13564.166
C11: Bancos USD | D11: ='BAC SAN JOSE USD'!G190*$D$6 -> 4698813.5 | E11: =D11/$D$6 -> 9001.5584
C12: CLIENTES | D12: =SUBTOTAL(9,D13:D16) -> 19014768 | E12: =SUBTOTAL(9,E13:E16) -> 36426.759
C13: Client: Remorfist-Client-Starlight SS -Factura Nro 140 | D13: =E13*$D$6 -> 7515256.3 | E13: =CONVERSIONES!$C$124+CONVERSIONES!$D$124+CONVERSIONES!$E$124 -> 14397.043
C14: Client: Remorfist-Client: Aluminati-Factura Nro 141 | D14: =E14*$D$6 -> 4454090.3 | E14: =CONVERSIONES!$F$124+CONVERSIONES!$G$124 -> 8532.74
C15: Remorfist - Client: CZ SS-Factura Nro 138 | D15: =E15*$D$6 -> 5842986.1 | E15: =CONVERSIONES!$H$124 -> 11193.46
C16: Remorfist - Client: PLLC- Factura Nro 139 | D16: =E16*$D$6 -> 1202435.6 | E16: =CONVERSIONES!$I$124 -> 2303.5165
C17: TOTAL INGRESOS | D17: =SUBTOTAL(9,D9:D16) -> 30794076 | E17: =SUBTOTAL(9,E9:E16) -> 58992.483
B20: CUENTAS X PAGAR MES | D20: JULIO
B21: Factura | C21: PROVEEDOR | D21: VALOR ₡ CRC | E21: VALOR USD | F21: Fecha vencimiento | G21: Estado | J21: KPI
C22: SEGURIDAD IGSS | D22: =SUBTOTAL(9,D23:D23) -> 5040051.5 | E22: =SUBTOTAL(9,E23:E23) -> 9655.271
B23: 176206200 | C23: Pago CCSS Junio | D23: 5040051.5 | E23: =D23/$D$6 -> 9655.271 | F23: 45482 | G23: Cancelado | H23: =IF(OR(G23="Sin pagar",G23="Pagar"),_xlfn.SINGLE(NETWORKDAYS($E$4,F23,'Festivos CR'!$A$3:$A$15)),0) -> 0 | I23: =NETWORKDAYS($E$4,F23,'Festivos CR'!$A$3:$A$15) -> 7 | J23: =H23 -> 0
C24: IMPUESTOS | D24: =SUBTOTAL(9,D25:D26) -> 1121832.4 | E24: =SUBTOTAL(9,E25:E26) -> 2149.1043 | J24: =H24 -> 0
C25: Retención en la fuente | D25: 1098581.4 | E25: =D25/$D$6 -> 2104.5622 | F25: 45482 | G25: Cancelado | H25: =IF(OR(G25="Sin pagar",G25="Pagar"),_xlfn.SINGLE(NETWORKDAYS($E$4,F25,'Festivos CR'!$A$3:$A$15)),0) -> 0 | I25: =NETWORKDAYS($E$4,F25,'Festivos CR'!$A$3:$A$15) -> 7 | J25: =H25 -> 0
C26: Rte fte por declaración de remesas al exterior Facturación S&P Colombia a S&P CR | D26: 23251 | E26: =D26/$D$6 -> 44.542146 | F26: 45482 | G26: Cancelado | H26: =IF(OR(G26="Sin pagar",G26="Pagar"),_xlfn.SINGLE(NETWORKDAYS($E$4,F26,'Festivos CR'!$A$3:$A$15)),0) -> 0 | I26: =NETWORKDAYS($E$4,F26,'Festivos CR'!$A$3:$A$15) -> 7 | J26: =H26 -> 0
C27: SERVICIOS PROFESIONALES -REPRESENTACIÓN LEGAL | D27: =SUBTOTAL(9,D28:D28) -> 62400 | E27: =SUBTOTAL(9,E28:E28) -> 119.54023 | J27: =H27 -> 0
B28: 17 | C28: Servicios profesionales Alejandro Echavarria Junio | D28: 62400 | E28: =D28/$D$6 -> 119.54023 | F28: 45499 | G28: Cancelado | H28: =IF(OR(G28="Sin pagar",G28="Pagar"),_xlfn.SINGLE(NETWORKDAYS($E$4,F28,'Festivos CR'!$A$3:$A$15)),0) -> 0 | I28: =NETWORKDAYS($E$4,F28,'Festivos CR'!$A$3:$A$15) -> 19 | J28: =H28 -> 0
C29: GASTOS DE OFICINA | D29: =SUBTOTAL(9,D30:D30) -> 77000 | E29: =SUBTOTAL(9,E30:E30) -> 147.50958
B30: 57 | C30: Compra de café | D30: 77000 | E30: =D30/$D$6 -> 147.50958 | F30: 45475 | G30: Cancelado | H30: =IF(OR(G30="Sin pagar",G30="Pagar"),_xlfn.SINGLE(NETWORKDAYS($E$4,F30,'Festivos CR'!$A$3:$A$15)),0) -> 0 | I30: =NETWORKDAYS($E$4,F30,'Festivos CR'!$A$3:$A$15) -> 2 | J30: =H30 -> 0
C31: COBROS ENTRE SUCURSALES | D31: =SUBTOTAL(9,D32:D35) -> 0 | E31: =SUBTOTAL(9,E32:E35) -> 0
B32: 4699 | C32: Cobro S&P a sucursal Enero a marzo | D32: =E32*$D$6*0 -> 0 | E32: =880*0 -> 0 | F32: 45504 | G32: Cancelado | H32: =IF(OR(G32="Sin pagar",G32="Pagar"),_xlfn.SINGLE(NETWORKDAYS($E$4,F32,'Festivos CR'!$A$3:$A$15)),0) -> 0 | I32: =NETWORKDAYS($E$4,F32,'Festivos CR'!$A$3:$A$15) -> 22 | J32: =H32 -> 0
B33: 4777 | C33: Cobro S&P a sucursal Abril | D33: =E33*$D$6*0 -> 0 | E33: =720*0 -> 0 | F33: 45504 | G33: Cancelado | H33: =IF(OR(G33="Sin pagar",G33="Pagar"),_xlfn.SINGLE(NETWORKDAYS($E$4,F33,'Festivos CR'!$A$3:$A$15)),0) -> 0 | I33: =NETWORKDAYS($E$4,F33,'Festivos CR'!$A$3:$A$15) -> 22 | J33: =H33 -> 0
B34: 4878 | C34: Cobro S&P a sucursal Mayo | D34: =E34*$D$6*0 -> 0 | E34: =720*0 -> 0 | F34: 45504 | G34: Cancelado | H34: =IF(OR(G47="Sin pagar",G47="Pagar"),_xlfn.SINGLE(NETWORKDAYS($E$4,F47,'Festivos CR'!$A$3:$A$15)),0) -> 0 | I34: =NETWORKDAYS($E$4,F47,'Festivos CR'!$A$3:$A$15) -> 21 | J34: =H34 -> 0
B35: 4957 | C35: Cobro S&P a sucursal Junio | D35: =E35*$D$6*0 -> 0 | E35: =330*0 -> 0 | F35: 45504 | G35: Cancelado | H35: =IF(OR(G48="Sin pagar",G48="Pagar"),_xlfn.SINGLE(NETWORKDAYS($E$4,F48,'Festivos CR'!$A$3:$A$15)),0) -> 0 | I35: =NETWORKDAYS($E$4,F48,'Festivos CR'!$A$3:$A$15) -> -32476 | J35: =H35 -> 0
C36: COSTOS FINANCIEROS | D36: =SUBTOTAL(9,D37:D37) -> 399.75 | E36: =SUBTOTAL(9,E37:E37) -> 0.7658046
C37: COSTOS FINANCIEROS | D37: 399.75 | E37: =D37/D6 -> 0.7658046 | F37: 45504 | G37: Cancelado | H37: =IF(OR(G37="Sin pagar",G37="Pagar"),_xlfn.SINGLE(NETWORKDAYS($E$4,F37,'Festivos CR'!$A$3:$A$15)),0) -> 0 | I37: =NETWORKDAYS($E$4,F37,'Festivos CR'!$A$3:$A$15) -> 22 | J37: =H37 -> 0
C38: NÓMINAS | D38: =SUBTOTAL(9,D39:D45) -> 11737204 | E38: =SUBTOTAL(9,E39:E45) -> 22485.065
B39: CRC | C39: Jhoel González González-Starlight-CR003 | D39: 1612916.3 | E39: =D39/$D$6 -> 3089.878 | F39: 45499 | G39: Cancelado | H39: =IF(OR(G39="Sin pagar",G39="Pagar"),_xlfn.SINGLE(NETWORKDAYS($E$4,F39,'Festivos CR'!$A$3:$A$15)),0) -> 0 | I39: =NETWORKDAYS($E$4,F39,'Festivos CR'!$A$3:$A$15) -> 19 | J39: =H39 -> 0
B40: USD | C40: Jonathan Salazar García -Starlight-CR003 | D40: =E40*$D$6 -> 1779832.1 | E40: 3409.64 | F40: 45499 | G40: Cancelado | H40: =IF(OR(G40="Sin pagar",G40="Pagar"),_xlfn.SINGLE(NETWORKDAYS($E$4,F40,'Festivos CR'!$A$3:$A$15)),0) -> 0 | I40: =NETWORKDAYS($E$4,F40,'Festivos CR'!$A$3:$A$15) -> 19 | J40: =H40 -> 0
B41: CRC | C41: Daniel Nazario Casto Vindas-Starlight-CR003 | D41: 1325079.4 | E41: =D41/$D$6 -> 2538.4662 | F41: 45499 | G41: Cancelado | H41: =IF(OR(G41="Sin pagar",G41="Pagar"),_xlfn.SINGLE(NETWORKDAYS($E$4,F41,'Festivos CR'!$A$3:$A$15)),0) -> 0 | I41: =NETWORKDAYS($E$4,F41,'Festivos CR'!$A$3:$A$15) -> 19 | J41: =H41 -> 0
B42: CRC | C42: Priscilla Grace Polson -Aluminati-CR004 | D42: 1410537.3 | E42: =D42/$D$6 -> 2702.1787 | F42: 45499 | G42: Cancelado | H42: =IF(OR(G42="Sin pagar",G42="Pagar"),_xlfn.SINGLE(NETWORKDAYS($E$4,F42,'Festivos CR'!$A$3:$A$15)),0) -> 0 | I42: =NETWORKDAYS($E$4,F42,'Festivos CR'!$A$3:$A$15) -> 19 | J42: =H42 -> 0
B43: CRC | C43: José Roberto Aguilar Barrante-Aluminati-CR004 | D43: 1410537.3 | E43: =D43/$D$6 -> 2702.1787 | F43: 45499 | G43: Cancelado | H43: =IF(OR(G43="Sin pagar",G43="Pagar"),_xlfn.SINGLE(NETWORKDAYS($E$4,F43,'Festivos CR'!$A$3:$A$15)),0) -> 0 | I43: =NETWORKDAYS($E$4,F43,'Festivos CR'!$A$3:$A$15) -> 19 | J43: =H43 -> 0
B44: CRC | C44: Sheryl Gertrudiz Cambronero Estrada-lorez & Prada PPLC | D44: 786551.54 | E44: =D44/$D$6 -> 1506.8037 | F44: 45499 | G44: Cancelado | H44: =IF(OR(G44="Sin pagar",G44="Pagar"),_xlfn.SINGLE(NETWORKDAYS($E$4,F44,'Festivos CR'!$A$3:$A$15)),0) -> 0 | I44: =NETWORKDAYS($E$4,F44,'Festivos CR'!$A$3:$A$15) -> 19 | J44: =H44 -> 0
B45: USD | C45: Tatiana Araya Pochet-CZ-CR006 | D45: =E45*$D$6 -> 3411750.2 | E45: 6535.92 | F45: 45499 | G45: Cancelado | H45: =IF(OR(G45="Sin pagar",G45="Pagar"),_xlfn.SINGLE(NETWORKDAYS($E$4,F45,'Festivos CR'!$A$3:$A$15)),0) -> 0 | I45: =NETWORKDAYS($E$4,F45,'Festivos CR'!$A$3:$A$15) -> 19 | J45: =H45 -> 0
...

Sheet FLUJO CAJA AGOSTO
D1: 42400
D4: Fecha de Elaboración: | E4: 45505
C6: Tasa de cambio: | D6: 518
D7: AGOSTO
D8: VALOR ₡ CRC | E8: VALOR USD
C9: BANCOS | D9: =SUBTOTAL(9,D10:D11) -> 12715370 | E9: =SUBTOTAL(9,E10:E11) -> 24547.046
C10: Bancos ₡ CRC | D10: ='BAC SAN JOSE COLONES '!$G$221 -> 7563057.3 | E10: =D10/$D$6 -> 14600.497
C11: Bancos USD | D11: =E11*$D$6 -> 5152312.5 | E11: ='BAC SAN JOSE USD'!$G$196 -> 9946.5492
C12: CLIENTES | D12: =SUBTOTAL(9,D13:D17) -> 19822836 | E12: =SUBTOTAL(9,E13:E17) -> 38716.476
C13: Client: Remorfist-Client-Starlight SS -Factura Nro 142 | D13: =E13*CONVERSIONES!$C$146 -> 7402756.9 | E13: =CONVERSIONES!$C$142+CONVERSIONES!$D$142+CONVERSIONES!$E$142 -> 14458.51
C14: Client: Remorfist-Client: Aluminati-Factura Nro 143 | D14: =E14*CONVERSIONES!$C$146 -> 4401268 | E14: =CONVERSIONES!$F$142+CONVERSIONES!$G$142 -> 8596.2266
C15: Remorfist - Client: CZ SS-Factura Nro 144 | D15: =E15*CONVERSIONES!$C$146 -> 5733611.5 | E15: =CONVERSIONES!$H$142 -> 11198.46
C16: Remorfist - Client: PLLC- Factura Nro 145 | D16: =E16*CONVERSIONES!$C$146 -> 1190476.8 | E16: =CONVERSIONES!$I$142 -> 2325.15
C17: Client: Remorfist-Client-Starlight SS -Factura Nro 146-Offcycle | D17: =E17*CONVERSIONES!$C$146 -> 1094722.6 | E17: =CONVERSIONES!$J$142 -> 2138.13
C18: TOTAL INGRESOS | D18: =SUBTOTAL(9,D9:D17) -> 32538206 | E18: =SUBTOTAL(9,E9:E17) -> 63263.522
B21: CUENTAS X PAGAR MES | D21: AGOSTO
B22: Factura | C22: PROVEEDOR | D22: VALOR ₡ CRC | E22: VALOR USD | F22: Fecha vencimiento | G22: Estado | J22: KPI
C23: SEGURIDAD IGSS | D23: =SUBTOTAL(9,D24:D24) -> 5377274 | E23: =SUBTOTAL(9,E24:E24) -> 10380.838
B24: 202407-3102766975-1 | C24: Pago CCSS Julio | D24: 5377274 | E24: =D24/$D$6 -> 10380.838 | F24: 45513 | G24: Cancelado | H24: =IF(OR(G24="Sin pagar",G24="Pagar"),_xlfn.SINGLE(NETWORKDAYS($E$4,F24,'Festivos CR'!$A$3:$A$15)),0) -> 0 | I24: =NETWORKDAYS($E$4,F24,'Festivos CR'!$A$3:$A$15) -> 6 | J24: =H24 -> 0
C25: IMPUESTOS | D25: =SUBTOTAL(9,D26:D27) -> 1235035 | E25: =SUBTOTAL(9,E26:E27) -> 2384.2375 | J25: =H25 -> 0
C26: Retención en la fuente | D26: 1166839 | E26: =D26/$D$6 -> 2252.5849 | F26: 45516 | G26: Cancelado | H26: =IF(OR(G26="Sin pagar",G26="Pagar"),_xlfn.SINGLE(NETWORKDAYS($E$4,F26,'Festivos CR'!$A$3:$A$15)),0) -> 0 | I26: =NETWORKDAYS($E$4,F26,'Festivos CR'!$A$3:$A$15) -> 7 | J26: =H26 -> 0
C27: Rte fte por declaración de remesas al exterior Facturación S&P Colombia a S&P CR | D27: 68196 | E27: =D27/$D$6 -> 131.65251 | F27: 45516 | G27: Cancelado | H27: =IF(OR(G27="Sin pagar",G27="Pagar"),_xlfn.SINGLE(NETWORKDAYS($E$4,F27,'Festivos CR'!$A$3:$A$15)),0) -> 0 | I27: =NETWORKDAYS($E$4,F27,'Festivos CR'!$A$3:$A$15) -> 7 | J27: =H27 -> 0
C28: SERVICIOS PROFESIONALES -REPRESENTACIÓN LEGAL | D28: =SUBTOTAL(9,D29:D29) -> 62400 | E28: =SUBTOTAL(9,E29:E29) -> 120.46332 | J28: =H28 -> 0
B29: 18 | C29: Servicios profesionales Alejandro Echavarria Agosto | D29: 62400 | E29: =D29/$D$6 -> 120.46332 | F29: 45531 | G29: Cancelado | H29: =IF(OR(G29="Sin pagar",G29="Pagar"),_xlfn.SINGLE(NETWORKDAYS($E$4,F29,'Festivos CR'!$A$3:$A$15)),0) -> 0 | I29: =NETWORKDAYS($E$4,F29,'Festivos CR'!$A$3:$A$15) -> 17 | J29: =H29 -> 0
C30: GASTOS DE OFICINA | D30: =SUBTOTAL(9,D31:D31) -> 77000 | E30: =SUBTOTAL(9,E31:E31) -> 148.64865
B31: 58 | C31: Compra de café | D31: 77000 | E31: =D31/$D$6 -> 148.64865 | F31: 45512 | G31: Cancelado | H31: =IF(OR(G31="Sin pagar",G31="Pagar"),_xlfn.SINGLE(NETWORKDAYS($E$4,F31,'Festivos CR'!$A$3:$A$15)),0) -> 0 | I31: =NETWORKDAYS($E$4,F31,'Festivos CR'!$A$3:$A$15) -> 5 | J31: =H31 -> 0
C32: COBROS ENTRE SUCURSALES | D32: =SUBTOTAL(9,D33:D38) -> 0 | E32: =SUBTOTAL(9,E33:E38) -> 0 | M32: Facturado | N32: Cruzado | O32: 0
B33: 4699 | C33: Cobro S&P a sucursal Enero a marzo | D33: =E33*$D$6 -> 0 | E33: =(228818/3888.02)*$O$32 -> 0 | F33: 45535 | G33: Cancelado | H33: =IF(OR(G33="Sin pagar",G33="Pagar"),_xlfn.SINGLE(NETWORKDAYS($E$4,F33,'Festivos CR'!$A$3:$A$15)),0) -> 0 | I33: =NETWORKDAYS($E$4,F33,'Festivos CR'!$A$3:$A$15) -> 20 | J33: =H33 -> 0 | M33: 880 | N33: =M33-E33 -> 880
B34: 4777 | C34: Cobro S&P a sucursal Abril | D34: =E34*$D$6 -> 0 | E34: =(160718/3924.82)*$O$32 -> 0 | F34: 45535 | G34: Cancelado | H34: =IF(OR(G34="Sin pagar",G34="Pagar"),_xlfn.SINGLE(NETWORKDAYS($E$4,F34,'Festivos CR'!$A$3:$A$15)),0) -> 0 | I34: =NETWORKDAYS($E$4,F34,'Festivos CR'!$A$3:$A$15) -> 20 | J34: =H34 -> 0 | M34: 720 | N34: =M34-E34 -> 720
B35: 4878 | C35: Cobro S&P a sucursal Mayo | D35: =E35*$D$6 -> 0 | E35: =(205400/3829.59)*$O$32 -> 0 | F35: 45535 | G35: Cancelado | H35: =IF(OR(G50="Sin pagar",G50="Pagar"),_xlfn.SINGLE(NETWORKDAYS($E$4,F50,'Festivos CR'!$A$3:$A$15)),0) -> 0 | I35: =NETWORKDAYS($E$4,F50,'Festivos CR'!$A$3:$A$15) -> -3 | J35: =H35 -> 0 | M35: 645 | N35: =M35-E35 -> 645
B36: 4957 | C36: Cobro S&P a sucursal Junio | D36: =E36*$D$6 -> 0 | E36: 0 | F36: 45535 | G36: Cancelado | H36: =IF(OR(G51="Sin pagar",G51="Pagar"),_xlfn.SINGLE(NETWORKDAYS($E$4,F51,'Festivos CR'!$A$3:$A$15)),0) -> 0 | I36: =NETWORKDAYS($E$4,F51,'Festivos CR'!$A$3:$A$15) -> -32498 | J36: =H36 -> 0 | M36: 330 | N36: 330
B37: 4957 | C37: Cobro S&P a sucursal Julio | D37: =E37*$D$6 -> 0 | E37: =515*$O$32 -> 0 | F37: 45535 | G37: Cancelado | H37: =IF(OR(G52="Sin pagar",G52="Pagar"),_xlfn.SINGLE(NETWORKDAYS($E$4,F52,'Festivos CR'!$A$3:$A$15)),0) -> 0 | I37: =NETWORKDAYS($E$4,F52,'Festivos CR'!$A$3:$A$15) -> -32498 | J37: =H37 -> 0 | M37: 550 | N37: 0
B38: 5160 | C38: Cobro S&P a sucursal Agosto | D38: =E38*$D$6 -> 0 | E38: =755*0 -> 0 | F38: 45535 | G38: Cancelado | H38: =IF(OR(G53="Sin pagar",G53="Pagar"),_xlfn.SINGLE(NETWORKDAYS($E$4,F53,'Festivos CR'!$A$3:$A$15)),0) -> 0 | I38: =NETWORKDAYS($E$4,F53,'Festivos CR'!$A$3:$A$15) -> -32498 | J38: =H38 -> 0 | M38: 550 | N38: 0
C39: COSTOS FINANCIEROS | D39: =SUBTOTAL(9,D40:D40) -> 59521.68 | E39: =SUBTOTAL(9,E40:E40) -> 114.90672 | M39: =SUM(M33:M37) -> 3125 | N39: =SUM(N33:N37) -> 2575 | O39: Saldo | P39: =M39-N39 -> 550
C40: COSTOS FINANCIEROS | D40: 59521.68 | E40: =D40/D6 -> 114.90672 | F40: 45534 | G40: Cancelado | H40: =IF(OR(G40="Sin pagar",G40="Pagar"),_xlfn.SINGLE(NETWORKDAYS($E$4,F40,'Festivos CR'!$A$3:$A$15)),0) -> 0 | I40: =NETWORKDAYS($E$4,F40,'Festivos CR'!$A$3:$A$15) -> 20 | J40: =H40 -> 0
C41: NÓMINAS | D41: =SUBTOTAL(9,D42:D48) -> 12225663 | E41: =SUBTOTAL(9,E42:E48) -> 23878.248
B42: CRC | C42: Jhoel González González-Starlight-CR003 | D42: 1612916.3 | E42: =D42/CONVERSIONES!$C$146 -> 3150.2272 | F42: 45532 | G42: Cancelado | H42: =IF(OR(G42="Sin pagar",G42="Pagar"),_xlfn.SINGLE(NETWORKDAYS($E$4,F42,'Festivos CR'!$A$3:$A$15)),0) -> 0 | I42: =NETWORKDAYS($E$4,F42,'Festivos CR'!$A$3:$A$15) -> 18 | J42: =H42 -> 0
B43: USD | C43: Jonathan Salazar García -Starlight-CR003 | D43: =E43*CONVERSIONES!$C$146 -> 2333562.9 | E43: 4557.74 | F43: 45532 | G43: Cancelado | H43: =IF(OR(G43="Sin pagar",G43="Pagar"),_xlfn.SINGLE(NETWORKDAYS($E$4,F43,'Festivos CR'!$A$3:$A$15)),0) -> 0 | I43: =NETWORKDAYS($E$4,F43,'Festivos CR'!$A$3:$A$15) -> 18 | J43: =H43 -> 0
B44: CRC | C44: Daniel Nazario Casto Vindas-Starlight-CR003 | D44: 1325079.4 | E44: =D44/CONVERSIONES!$C$146 -> 2588.0456 | F44: 45532 | G44: Cancelado | H44: =IF(OR(G44="Sin pagar",G44="Pagar"),_xlfn.SINGLE(NETWORKDAYS($E$4,F44,'Festivos CR'!$A$3:$A$15)),0) -> 0 | I44: =NETWORKDAYS($E$4,F44,'Festivos CR'!$A$3:$A$15) -> 18 | J44: =H44 -> 0
B45: CRC | C45: Priscilla Grace Polson -Aluminati-CR004 | D45: 1410537.3 | E45: =D45/CONVERSIONES!$C$146 -> 2754.9557 | F45: 45532 | G45: Cancelado | H45: =IF(OR(G45="Sin pagar",G45="Pagar"),_xlfn.SINGLE(NETWORKDAYS($E$4,F45,'Festivos CR'!$A$3:$A$15)),0) -> 0 | I45: =NETWORKDAYS($E$4,F45,'Festivos CR'!$A$3:$A$15) -> 18 | J45: =H45 -> 0
...

Sheet FLUJO CAJA SEPTIEMBRE
D1: 42400
D4: Fecha de Elaboración: | E4: 45536
C6: Tasa de cambio: | D6: 522
D7: SEPTIEMBRE
D8: VALOR ₡ CRC | E8: VALOR USD
C9: BANCOS | D9: =SUBTOTAL(9,D10:D11) -> 13534196 | E9: =SUBTOTAL(9,E10:E11) -> 25927.578
C10: Bancos ₡ CRC | D10: ='BAC SAN JOSE COLONES '!$G$239 -> 7778335.2 | E10: =D10/$D$6 -> 14901.025
C11: Bancos USD | D11: =E11*$D$6 -> 5755860.7 | E11: ='BAC SAN JOSE USD'!G203 -> 11026.553
C12: CLIENTES | D12: =SUBTOTAL(9,D13:D16) -> 20839583 | E12: =SUBTOTAL(9,E13:E16) -> 40543.935
C13: Client: Remorfist-Client-Starlight SS -Factura Nro 147 | D13: =E13*CONVERSIONES!$C$165 -> 9387150.2 | E13: =CONVERSIONES!$C$161+CONVERSIONES!$D$161+CONVERSIONES!$E$161 -> 18262.938
C14: Client: Remorfist-Client: Aluminati-Factura Nro 148 | D14: =E14*CONVERSIONES!$F$165 -> 4484535.9 | E14: =CONVERSIONES!F161+CONVERSIONES!G161 -> 8724.7781
C15: Remorfist - Client: CZ SS-Factura Nro 149 | D15: =$E$15*CONVERSIONES!$H$165 -> 5755641.3 | E15: =CONVERSIONES!H161 -> 11197.746
C16: Remorfist - Client: PLLC- Factura Nro 150 | D16: =$E$16*CONVERSIONES!$I$165 -> 1212255.2 | E16: =CONVERSIONES!$I$161 -> 2358.4732
C17: TOTAL INGRESOS | D17: =SUBTOTAL(9,D9:D16) -> 34373779 | E17: =SUBTOTAL(9,E9:E16) -> 66471.513
B20: CUENTAS X PAGAR MES | D20: AGOSTO
B21: Factura | C21: PROVEEDOR | D21: VALOR ₡ CRC | E21: VALOR USD | F21: Fecha vencimiento | G21: Estado | J21: KPI
C22: SEGURIDAD IGSS | D22: =SUBTOTAL(9,D23:D23) -> 5659227 | E22: =SUBTOTAL(9,E23:E23) -> 10841.431
B23: 202408-3102766975-1 | C23: Pago CCSS Agosto | D23: 5659227 | E23: =D23/$D$6 -> 10841.431 | F23: 45548 | G23: Cancelado | H23: =IF(OR(G23="Sin pagar",G23="Pagar"),_xlfn.SINGLE(NETWORKDAYS($E$4,F23,'Festivos CR'!$A$3:$A$15)),0) -> 0 | I23: =NETWORKDAYS($E$4,F23,'Festivos CR'!$A$3:$A$15) -> 10 | J23: =H23 -> 0
C24: IMPUESTOS | D24: =SUBTOTAL(9,D25:D26) -> 1412173.9 | E24: =SUBTOTAL(9,E25:E26) -> 2705.314 | J24: =H24 -> 0
C25: Retención en la fuente | D25: 1313132.9 | E25: =D25/$D$6 -> 2515.5803 | F25: 45548 | G25: Cancelado | H25: =IF(OR(G25="Sin pagar",G25="Pagar"),_xlfn.SINGLE(NETWORKDAYS($E$4,F25,'Festivos CR'!$A$3:$A$15)),0) -> 0 | I25: =NETWORKDAYS($E$4,F25,'Festivos CR'!$A$3:$A$15) -> 10 | J25: =H25 -> 0
C26: Rte fte por declaración de remesas al exterior Facturación S&P Colombia a S&P CR | D26: 99041 | E26: =D26/$D$6 -> 189.73372 | F26: 45548 | G26: Cancelado | H26: =IF(OR(G26="Sin pagar",G26="Pagar"),_xlfn.SINGLE(NETWORKDAYS($E$4,F26,'Festivos CR'!$A$3:$A$15)),0) -> 0 | I26: =NETWORKDAYS($E$4,F26,'Festivos CR'!$A$3:$A$15) -> 10 | J26: =H26 -> 0
C27: SERVICIOS PROFESIONALES -REPRESENTACIÓN LEGAL | D27: =SUBTOTAL(9,D28:D28) -> 62400 | E27: =SUBTOTAL(9,E28:E28) -> 119.54023 | J27: =H27 -> 0
B28: 19 | C28: Servicios profesionales Alejandro Echavarria Agosto | D28: 62400 | E28: =D28/$D$6 -> 119.54023 | F28: 45561 | G28: Cancelado | H28: =IF(OR(G28="Sin pagar",G28="Pagar"),_xlfn.SINGLE(NETWORKDAYS($E$4,F28,'Festivos CR'!$A$3:$A$15)),0) -> 0 | I28: =NETWORKDAYS($E$4,F28,'Festivos CR'!$A$3:$A$15) -> 19 | J28: =H28 -> 0
C29: GASTOS DE OFICINA | D29: =SUBTOTAL(9,D30:D31) -> 628208 | E29: =SUBTOTAL(9,E30:E31) -> 1203.4636
B30: 58 | C30: Compra de café | D30: 77000 | E30: =D30/$D$6 -> 147.50958 | F30: 45538 | G30: Cancelado | H30: =IF(OR(G30="Sin pagar",G30="Pagar"),_xlfn.SINGLE(NETWORKDAYS($E$4,F30,'Festivos CR'!$A$3:$A$15)),0) -> 0 | I30: =NETWORKDAYS($E$4,F30,'Festivos CR'!$A$3:$A$15) -> 2 | J30: =H30 -> 0
B31: 4024882 | C31: Renovación seguro Riesgo de trabajo del INS | D31: 551208 | E31: =D31/$D$6 -> 1055.954 | F31: 45548 | G31: Cancelado | H31: =IF(OR(G31="Sin pagar",G31="Pagar"),_xlfn.SINGLE(NETWORKDAYS($E$4,F31,'Festivos CR'!$A$3:$A$15)),0) -> 0 | I31: =NETWORKDAYS($E$4,F31,'Festivos CR'!$A$3:$A$15) -> 10 | J31: =H31 -> 0
C32: COBROS ENTRE SUCURSALES | D32: =SUBTOTAL(9,D33:D39) -> 0 | E32: =SUBTOTAL(9,E33:E39) -> 0 | M32: Facturado | N32: Cruzado | O32: 0
B33: 4699 | C33: Cobro S&P a sucursal Enero a marzo | D33: =E33*$D$6 -> 0 | E33: =(228818/3888.02)*$O$32 -> 0 | F33: 45565 | G33: Cancelado | H33: =IF(OR(G33="Sin pagar",G33="Pagar"),_xlfn.SINGLE(NETWORKDAYS($E$4,F33,'Festivos CR'!$A$3:$A$15)),0) -> 0 | I33: =NETWORKDAYS($E$4,F33,'Festivos CR'!$A$3:$A$15) -> 21 | J33: =H33 -> 0 | M33: 880 | N33: =M33-E33 -> 880
B34: 4777 | C34: Cobro S&P a sucursal Abril | D34: =E34*$D$6 -> 0 | E34: =(160718/3924.82)*$O$32 -> 0 | F34: 45565 | G34: Cancelado | H34: =IF(OR(G34="Sin pagar",G34="Pagar"),_xlfn.SINGLE(NETWORKDAYS($E$4,F34,'Festivos CR'!$A$3:$A$15)),0) -> 0 | I34: =NETWORKDAYS($E$4,F34,'Festivos CR'!$A$3:$A$15) -> 21 | J34: =H34 -> 0 | M34: 720 | N34: =M34-E34 -> 720
B35: 4878 | C35: Cobro S&P a sucursal Mayo | D35: =E35*$D$6 -> 0 | E35: =(205400/3829.59)*$O$32 -> 0 | F35: 45565 | G35: Cancelado | H35: =IF(OR(G51="Sin pagar",G51="Pagar"),_xlfn.SINGLE(NETWORKDAYS($E$4,F51,'Festivos CR'!$A$3:$A$15)),0) -> 0 | I35: =NETWORKDAYS($E$4,F51,'Festivos CR'!$A$3:$A$15) -> 21 | J35: =H35 -> 0 | M35: 645 | N35: =M35-E35 -> 645
B36: 4957 | C36: Cobro S&P a sucursal Junio | D36: =E36*$D$6 -> 0 | E36: 0 | F36: 45565 | G36: Cancelado | H36: =IF(OR(G52="Sin pagar",G52="Pagar"),_xlfn.SINGLE(NETWORKDAYS($E$4,F52,'Festivos CR'!$A$3:$A$15)),0) -> 0 | I36: =NETWORKDAYS($E$4,F52,'Festivos CR'!$A$3:$A$15) -> -32517 | J36: =H36 -> 0 | M36: 330 | N36: 330
B37: 4957 | C37: Cobro S&P a sucursal Julio | D37: =E37*$D$6 -> 0 | E37: =515*$O$32 -> 0 | F37: 45565 | G37: Cancelado | H37: =IF(OR(G53="Sin pagar",G53="Pagar"),_xlfn.SINGLE(NETWORKDAYS($E$4,F53,'Festivos CR'!$A$3:$A$15)),0) -> 0 | I37: =NETWORKDAYS($E$4,F53,'Festivos CR'!$A$3:$A$15) -> -32517 | J37: =H37 -> 0 | M37: 550 | N37: 0
B38: 5160 | C38: Cobro S&P a sucursal Agosto | D38: =E38*$D$6 -> 0 | E38: =755*0 -> 0 | F38: 45565 | G38: Cancelado | H38: =IF(OR(G54="Sin pagar",G54="Pagar"),_xlfn.SINGLE(NETWORKDAYS($E$4,F54,'Festivos CR'!$A$3:$A$15)),0) -> 0 | I38: =NETWORKDAYS($E$4,F54,'Festivos CR'!$A$3:$A$15) -> -32517 | J38: =H38 -> 0 | M38: 550 | N38: 0
B39: 5283 | C39: Cobro S&P a sucursal Agosto | D39: =E39*$D$6 -> 0 | E39: =515*0 -> 0 | F39: 45565 | G39: Cancelado | H39: =IF(OR(G55="Sin pagar",G55="Pagar"),_xlfn.SINGLE(NETWORKDAYS($E$4,F55,'Festivos CR'!$A$3:$A$15)),0) -> 0 | I39: =NETWORKDAYS($E$4,F55,'Festivos CR'!$A$3:$A$15) -> -32517 | J39: =H39 -> 0 | M39: 550 | N39: 0
C40: COSTOS FINANCIEROS | D40: =SUBTOTAL(9,D41:D41) -> 11279.25 | E40: =SUBTOTAL(9,E41:E41) -> 21.607759 | M40: =SUM(M33:M37) -> 3125 | N40: =SUM(N33:N37) -> 2575 | O40: Saldo | P40: =M40-N40 -> 550
C41: COSTOS FINANCIEROS | D41: =(('BAC SAN JOSE COLONES '!$F$239+'BAC SAN JOSE COLONES '!$F$244)+(CONVERSIONES!$J$160*CONVERSIONES!$H$155))-9909 -> 11279.25 | E41: =D41/D6 -> 21.607759 | F41: 45565 | G41: Cancelado | H41: =IF(OR(G41="Sin pagar",G41="Pagar"),_xlfn.SINGLE(NETWORKDAYS($E$4,F41,'Festivos CR'!$A$3:$A$15)),0) -> 0 | I41: =NETWORKDAYS($E$4,F41,'Festivos CR'!$A$3:$A$15) -> 21 | J41: =H41 -> 0
C42: NÓMINAS | D42: =SUBTOTAL(9,D43:D49) -> 12697662 | E42: =SUBTOTAL(9,E43:E49) -> 14538.95
B43: CRC | C43: Jhoel González González-Starlight-CR003 | D43: 1612916.3 | E43: =CONVERSIONES!$C$165 -> 514 | F43: 45562 | G43: Cancelado | H43: =IF(OR(G43="Sin pagar",G43="Pagar"),_xlfn.SINGLE(NETWORKDAYS($E$4,F43,'Festivos CR'!$A$3:$A$15)),0) -> 0 | I43: =NETWORKDAYS($E$4,F43,'Festivos CR'!$A$3:$A$15) -> 20 | J43: =H43 -> 0
B44: USD | C44: Jonathan Salazar García -Starlight-CR003 | D44: =E44*CONVERSIONES!$C$165 -> 2790315.8 | E44: 5428.63 | F44: 45562 | G44: Cancelado | H44: =IF(OR(G44="Sin pagar",G44="Pagar"),_xlfn.SINGLE(NETWORKDAYS($E$4,F44,'Festivos CR'!$A$3:$A$15)),0) -> 0 | I44: =NETWORKDAYS($E$4,F44,'Festivos CR'!$A$3:$A$15) -> 20 | J44: =H44 -> 0
B45: CRC | C45: Daniel Nazario Casto Vindas-Starlight-CR003 | D45: 1325079.4 | E45: =CONVERSIONES!$C$165 -> 514 | F45: 45562 | G45: Cancelado | H45: =IF(OR(G45="Sin pagar",G45="Pagar"),_xlfn.SINGLE(NETWORKDAYS($E$4,F45,'Festivos CR'!$A$3:$A$15)),0) -> 0 | I45: =NETWORKDAYS($E$4,F45,'Festivos CR'!$A$3:$A$15) -> 20 | J45: =H45 -> 0
...

Sheet FLUJO CAJA OCTUBRE 
D1: 42400
D4: Fecha de Elaboración: | E4: 45601
C6: Tasa de cambio: | D6: 511
D7: OCTUBRE
D8: VALOR ₡ CRC | E8: VALOR USD
C9: BANCOS | D9: =SUBTOTAL(9,D10:D11) -> 13869749 | E9: =SUBTOTAL(9,E10:E12) -> 32689.246
C10: Bancos ₡ CRC | D10: ='BAC SAN JOSE COLONES '!$G$253 -> 8235183 | E10: =D10/$D$6 -> 16115.818
C11: Bancos USD | D11: =E11*$D$6 -> 5634566.1 | E11: ='BAC SAN JOSE USD'!G210 -> 11026.548
C12: Ingreso | D12: =E12*$D$6 -> 2834455.6 | E12: 5546.8799
C13: CLIENTES | D13: =SUBTOTAL(9,D14:D18) -> 21438410 | E13: =SUBTOTAL(9,E14:E18) -> 42368.399
B14: Pagado | C14: Client: Remorfist-Client-Starlight SS -Factura Nro 151 | D14: =E14*CONVERSIONES!$C$183 -> 7392526.7 | E14: =CONVERSIONES!$C$179+CONVERSIONES!$D$179+CONVERSIONES!$E$179 -> 14609.737
B15: Pagado | C15: Client: Remorfist-Client: Aluminati-Factura Nro 152 | D15: =E15*CONVERSIONES!$C$183 -> 4423104.3 | E15: =CONVERSIONES!$F$179+CONVERSIONES!$G$179 -> 8741.3129
B16: Pagado | C16: Remorfist - Client: CZ SS-Factura Nro 153 | D16: =E16*CONVERSIONES!$C$183 -> 5666059.3 | E16: =CONVERSIONES!$H$179 -> 11197.746
B17: Pagado | C17: Remorfist - Client: PLLC- Factura Nro 154 | D17: =E17*CONVERSIONES!$C$183 -> 1195578.6 | E17: =CONVERSIONES!$I$179 -> 2362.8037
B18: Pagado | C18: Advancio - Client: PLLC- Factura Nro 155 | D18: =E18*CONVERSIONES!$J$183 -> 2761140.8 | E18: =CONVERSIONES!$J$179 -> 5456.8
C19: TOTAL INGRESOS | D19: =SUBTOTAL(9,D9:D17) -> 35381474 | E19: =SUBTOTAL(9,E9:E17) -> 69600.845
B22: CUENTAS X PAGAR MES | D22: AGOSTO
B23: Factura | C23: PROVEEDOR | D23: VALOR ₡ CRC | E23: VALOR USD | F23: Fecha vencimiento | G23: Estado | J23: KPI
C24: SEGURIDAD IGSS | D24: =SUBTOTAL(9,D25:D25) -> 5909923 | E24: =SUBTOTAL(9,E25:E25) -> 11565.407
B25: 202408-3102766975-1 | C25: Pago CCSS Agosto | D25: 5909923 | E25: =D25/$D$6 -> 11565.407 | F25: 45579 | G25: Cancelado | H25: =IF(OR(G25="Sin pagar",G25="Pagar"),_xlfn.SINGLE(NETWORKDAYS($E$4,F25,'Festivos CR'!$A$3:$A$15)),0) -> 0 | I25: =NETWORKDAYS($E$4,F25,'Festivos CR'!$A$3:$A$15) -> -17 | J25: =H25 -> 0
C26: IMPUESTOS | D26: =SUBTOTAL(9,D27:D28) -> 1508002 | E26: =SUBTOTAL(9,E27:E28) -> 2951.0802 | F26: , | J26: =H26 -> 0
C27: Retención en la fuente | D27: 1440883 | E27: =D27/$D$6 -> 2819.7319 | F27: 45579 | G27: Cancelado | H27: =IF(OR(G27="Sin pagar",G27="Pagar"),_xlfn.SINGLE(NETWORKDAYS($E$4,F27,'Festivos CR'!$A$3:$A$15)),0) -> 0 | I27: =NETWORKDAYS($E$4,F27,'Festivos CR'!$A$3:$A$15) -> -17 | J27: =H27 -> 0
C28: Rte fte por declaración de remesas al exterior Facturación S&P Colombia a S&P CR | D28: 67119 | E28: =D28/$D$6 -> 131.34834 | F28: 45579 | G28: Cancelado | H28: =IF(OR(G28="Sin pagar",G28="Pagar"),_xlfn.SINGLE(NETWORKDAYS($E$4,F28,'Festivos CR'!$A$3:$A$15)),0) -> 0 | I28: =NETWORKDAYS($E$4,F28,'Festivos CR'!$A$3:$A$15) -> -17 | J28: =H28 -> 0
C29: SERVICIOS PROFESIONALES -REPRESENTACIÓN LEGAL | D29: =SUBTOTAL(9,D30:D30) -> 62400 | E29: =SUBTOTAL(9,E30:E30) -> 122.1135 | J29: =H29 -> 0
B30: 20 | C30: Servicios profesionales Alejandro Echavarria Octubre | D30: 62400 | E30: =D30/$D$6 -> 122.1135 | F30: 45590 | G30: Cancelado | H30: =IF(OR(G30="Sin pagar",G30="Pagar"),_xlfn.SINGLE(NETWORKDAYS($E$4,F30,'Festivos CR'!$A$3:$A$15)),0) -> 0 | I30: =NETWORKDAYS($E$4,F30,'Festivos CR'!$A$3:$A$15) -> -8 | J30: =H30 -> 0
C31: GASTOS DE OFICINA | D31: =SUBTOTAL(9,D32:D32) -> 77000 | E31: =SUBTOTAL(9,E32:E32) -> 150.68493
B32: 58 | C32: Compra de café | D32: 77000 | E32: =D32/$D$6 -> 150.68493 | F32: 45567 | G32: Cancelado | H32: =IF(OR(G32="Sin pagar",G32="Pagar"),_xlfn.SINGLE(NETWORKDAYS($E$4,F32,'Festivos CR'!$A$3:$A$15)),0) -> 0 | I32: =NETWORKDAYS($E$4,F32,'Festivos CR'!$A$3:$A$15) -> -25 | J32: =H32 -> 0
C33: COBROS ENTRE SUCURSALES | D33: =SUBTOTAL(9,D34:D36) -> 0 | E33: =SUBTOTAL(9,E34:E36) -> 0
B34: 5059 | C34: Cobro S&P a sucursal Julio | D34: =E34*$D$6 -> 0 | E34: =515*0 -> 0 | F34: 45596 | G34: Sin Pagar | H34: =IF(OR(G34="Sin pagar",G34="Pagar"),_xlfn.SINGLE(NETWORKDAYS($E$4,F34,'Festivos CR'!$A$3:$A$15)),0) -> -4 | I34: =NETWORKDAYS($E$4,F34,'Festivos CR'!$A$3:$A$15) -> -4 | J34: =H34 -> -4
B35: 5160 | C35: Cobro S&P a sucursal Agosto | D35: =E35*$D$6 -> 0 | E35: =755*0 -> 0 | F35: 45596 | G35: Sin Pagar | H35: =IF(OR(G35="Sin pagar",G35="Pagar"),_xlfn.SINGLE(NETWORKDAYS($E$4,F35,'Festivos CR'!$A$3:$A$15)),0) -> -4 | I35: =NETWORKDAYS($E$4,F35,'Festivos CR'!$A$3:$A$15) -> -4 | J35: =H35 -> -4
B36: 5283 | C36: Cobro S&P a sucursal Septiembre | D36: =E36*$D$6 -> 0 | E36: =515*0 -> 0 | F36: 45596 | G36: Sin Pagar | H36: =IF(OR(G36="Sin pagar",G36="Pagar"),_xlfn.SINGLE(NETWORKDAYS($E$4,F36,'Festivos CR'!$A$3:$A$15)),0) -> -4 | I36: =NETWORKDAYS($E$4,F36,'Festivos CR'!$A$3:$A$15) -> -4 | J36: =H36 -> -4
C37: COSTOS FINANCIEROS | D37: =SUBTOTAL(9,D38:D38) -> 172870 | E37: =SUBTOTAL(9,E38:E38) -> 77.054795
C38: COSTOS FINANCIEROS | D38: =39375+133495 -> 172870 | E38: =39375/D6 -> 77.054795 | F38: 45595 | G38: Cancelado | H38: =IF(OR(G38="Sin pagar",G38="Pagar"),_xlfn.SINGLE(NETWORKDAYS($E$4,F38,'Festivos CR'!$A$3:$A$15)),0) -> 0 | I38: =NETWORKDAYS($E$4,F38,'Festivos CR'!$A$3:$A$15) -> -5 | J38: =H38 -> 0
C39: NÓMINAS | D39: =SUBTOTAL(9,D40:D47) -> 13203900 | E39: =SUBTOTAL(9,E40:E47) -> 26182.392
B40: CRC | C40: Jhoel González González-Starlight-CR003 | D40: 1612916.3 | E40: =D40/CONVERSIONES!$C$183 -> 3187.5817 | F40: 45593 | G40: Cancelado | H40: =IF(OR(G40="Sin pagar",G40="Pagar"),_xlfn.SINGLE(NETWORKDAYS($E$4,F40,'Festivos CR'!$A$3:$A$15)),0) -> 0 | I40: =NETWORKDAYS($E$4,F40,'Festivos CR'!$A$3:$A$15) -> -7 | J40: =H40 -> 0
B41: USD | C41: Jonathan Salazar García -Starlight-CR003 | D41: =$E$41*CONVERSIONES!$C$83 -> 1683392.9 | E41: 3414.59 | F41: 45593 | G41: Cancelado | H41: =IF(OR(G41="Sin pagar",G41="Pagar"),_xlfn.SINGLE(NETWORKDAYS($E$4,F41,'Festivos CR'!$A$3:$A$15)),0) -> 0 | I41: =NETWORKDAYS($E$4,F41,'Festivos CR'!$A$3:$A$15) -> -7 | J41: =H41 -> 0
B42: CRC | C42: Daniel Nazario Casto Vindas-Starlight-CR003 | D42: 1325079.4 | E42: =D42/CONVERSIONES!$C$183 -> 2618.7339 | F42: 45593 | G42: Cancelado | H42: =IF(OR(G42="Sin pagar",G42="Pagar"),_xlfn.SINGLE(NETWORKDAYS($E$4,F42,'Festivos CR'!$A$3:$A$15)),0) -> 0 | I42: =NETWORKDAYS($E$4,F42,'Festivos CR'!$A$3:$A$15) -> -7 | J42: =H42 -> 0
B43: CRC | C43: Priscilla Grace Polson -Aluminati-CR004 | D43: 1410537.3 | E43: =$D$43/CONVERSIONES!$C$183 -> 2787.6231 | F43: 45593 | G43: Cancelado | H43: =IF(OR(G43="Sin pagar",G43="Pagar"),_xlfn.SINGLE(NETWORKDAYS($E$4,F43,'Festivos CR'!$A$3:$A$15)),0) -> 0 | I43: =NETWORKDAYS($E$4,F43,'Festivos CR'!$A$3:$A$15) -> -7 | J43: =H43 -> 0
B44: CRC | C44: José Roberto Aguilar Barrante-Aluminati-CR004 | D44: 1410537.3 | E44: =$D$44/CONVERSIONES!$C$183 -> 2787.6231 | F44: 45593 | G44: Cancelado | H44: =IF(OR(G44="Sin pagar",G44="Pagar"),_xlfn.SINGLE(NETWORKDAYS($E$4,F44,'Festivos CR'!$A$3:$A$15)),0) -> 0 | I44: =NETWORKDAYS($E$4,F44,'Festivos CR'!$A$3:$A$15) -> -7 | J44: =H44 -> 0
B45: CRC | C45: Sheryl Gertrudiz Cambronero Estrada-lorez & Prada PPLC | D45: 786551.54 | E45: =$D$45/CONVERSIONES!$C$183 -> 1554.4497 | F45: 45593 | G45: Cancelado | H45: =IF(OR(G45="Sin pagar",G45="Pagar"),_xlfn.SINGLE(NETWORKDAYS($E$4,F45,'Festivos CR'!$A$3:$A$15)),0) -> 0 | I45: =NETWORKDAYS($E$4,F45,'Festivos CR'!$A$3:$A$15) -> -7 | J45: =H45 -> 0
...

Sheet FLUJO CAJA NOVIEMBRE
D1: 42400
D4: Fecha de Elaboración: | E4: 45598
C6: Tasa de cambio: | D6: 506
D7: NOVIEMBRE
D8: VALOR ₡ CRC | E8: VALOR USD
C9: BANCOS | D9: =SUBTOTAL(9,D10:D11) -> 14369981 | E9: =SUBTOTAL(9,E10:E11) -> 28399.173
C10: Bancos ₡ CRC | D10: ='BAC SAN JOSE COLONES '!$G$269-'BAC SAN JOSE COLONES '!$F$271-'BAC SAN JOSE COLONES '!$F$272 -> 8722237.9 | E10: =D10/$D$6 -> 17237.624
C11: Bancos USD | D11: =E11*$D$6 -> 5647743.4 | E11: ='BAC SAN JOSE USD'!$G$221 -> 11161.548
C12: CLIENTES | D12: =SUBTOTAL(9,D13:D17) -> 20430754 | E12: =SUBTOTAL(9,E13:E17) -> 37183.073
B13: Pagado | C13: Client: Remorfist-Client-Starlight SS -Factura Nro 156 | D13: =E13*CONVERSIONES!$C$191 -> 4647993.2 | E13: =CONVERSIONES!$C$197+CONVERSIONES!$D$197 -> 9258.9505
B14: Pagado | C14: Client: Remorfist-Client: Aluminati-Factura Nro 157 | D14: =E14*CONVERSIONES!$F$191 -> 7195053.9 | E14: =CONVERSIONES!$E$197+CONVERSIONES!$F$197+CONVERSIONES!$G$197 -> 14332.777
B15: Pagado | C15: Remorfist - Client: CZ SS-Factura Nro 158 | D15: =E15*CONVERSIONES!$H$191 -> 5621268.3 | E15: =CONVERSIONES!$H$197 -> 11197.746
B16: Pagado | C16: Remorfist - Client: PLLC- Factura Nro 159 | D16: =$E$16*CONVERSIONES!$I$191 -> 1201587.1 | E16: =CONVERSIONES!$I$197 -> 2393.5997
B17: Sin Pagar | C17: Advancio - Client: PLLC- Factura Nro 160 | D17: 1764852 | E17: =CONVERSIONES!$J$193*0 -> 0
C18: TOTAL INGRESOS | D18: =SUBTOTAL(9,D9:D17) -> 34800736 | E18: =SUBTOTAL(9,E9:E17) -> 65582.245
