Workbook

Sheet BBVA SOLES
D2: BCP SOLES
A4: FECHA | D4: DESCRIPCIÓN | E4: INGRESO | F4: SALIDA | G4: SALDO
A5: 45901
A6: 45926 | D6: Transferencia de fondos por apertura de cuenta | E6: 1500 | G6: =G5+E6-F6 -> 1500
A7: 45927 | D7: Bastanteo poderes y escrituras | F7: 45 | G7: =G6+E7-F7 -> 1455
A8: 45930 | D8: Comisión de mantenimiento | F8: 15 | G8: =G7+E8-F8 -> 1440
A9: 45930 | D9: Saldo | G9: =G8+E9-F9 -> 1440
A10: 45566 | D10: Inicio mes | G10: =G9+E10-F10 -> 1440
A11: 45596 | D11: Comisión de mantenimiento | F11: 15 | G11: =G10+E11-F11 -> 1425
A12: 45596 | D12: Saldo | G12: =G11+E12-F12 -> 1425
A13: 45597 | D13: Inicio mes | G13: =G12+E13-F13 -> 1425
A14: 45973 | D14: Transferencia a la cuenta BBVA de S&P para pagos CTS Safeguard interbank | E14: 23650 | G14: =G13+E14-F14 -> 25075
A15: 45973 | D15: Transferencia a la cuenta BBVA de S&P para pagos CTS Safeguard interbank | E15: 23650 | G15: =G14+E15-F15 -> 48725
A16: 45973 | D16: Pago CTS Interbank Safeguard | F16: 37652.9 | G16: =G15+E16-F16 -> 11072.1
A17: 45973 | D17: Impuesto ITF | F17: 1.85 | G17: =G16+E17-F17 -> 11070.25
A18: 45973 | D18: Comisión CTS | F18: 6 | G18: =G17+E18-F18 -> 11064.25
A19: 45973 | D19: Transferencia de la cuenta de Avanza para pago AFP Habitat Safeguard | E19: 9530.3 | G19: =G18+E19-F19 -> 20594.55
A20: 45973 | D20: Impuesto ITF | F20: 0.45 | G20: =G19+E20-F20 -> 20594.1
A21: 45973 | D21: Pago AFP Habitat Safeguard | F21: 9530.3 | G21: =G20+E21-F21 -> 11063.8
A22: 45973 | D22: Impuesto ITF | F22: 0.45 | G22: =G21+E22-F22 -> 11063.35
A23: 45974 | D23: Transferencia a la cuenta BBVA de S&P para pagos CTS Safeguard y S&P | E23: 13318.7 | G23: =G22+E23-F23 -> 24382.05
A24: 45974 | D24: Pago CTS Olga Paredes Interbank y Melissa Guadalupe Caja piura-Safeguard-Noviembre | F24: 21063.69 | G24: =G23+E24-F24 -> 3318.36
A25: 45974 | D25: Impuesto ITF | F25: 1.05 | G25: =G24+E25-F25 -> 3317.31
A26: 45974 | D26: Comisión CTS | F26: 2 | G26: =G25+E26-F26 -> 3315.31
A27: 45975 | D27: Devolución CTS Fiorella Chavez Noviembre -Safeguard | E27: 1591.01 | G27: =G26+E27-F27 -> 4906.32
A28: 45975 | D28: Impuesto ITF | F28: 0.05 | G28: =G27+E28-F28 -> 4906.27
A29: 45975 | D29: Pago CTS Andrés Felipe Uribe BBVA S&P | F29: 1533.34 | G29: =G28+E29-F29 -> 3372.93
A30: 45975 | D30: Impuesto ITF | F30: =0.05+0.05 -> 0.1 | G30: =G29+E30-F30 -> 3372.83
A31: 45975 | D31: Impuesto ITF | F31: 0.05 | G31: =G30+E31-F31 -> 3372.78
A32: 45975 | D32: Pago CTS Fiorella Chavez Noviembre -Safeguard | F32: 1591.01 | G32: =G31+E32-F32 -> 1781.77
A33: 45975 | D33: Comisión CTS | F33: 1 | G33: =G32+E33-F33 -> 1780.77
A34: 45987 | D34: Pago CTS Andrés Felipe Uribe BBVA S&P-Ajuste | F34: 170.36 | G34: =G33+E34-F34 -> 1610.41
A35: 45988 | D35: Pago CTS Christiam Valle BBVA Noviembre- USD S&P-Ajuste | F35: 1046.08 | G35: =G34+E35-F35 -> 564.33
A36: 45989 | D36: Comisión de mantenimiento | F36: 15 | G36: =G35+E36-F36 -> 549.33
A37: 45991 | G37: =G36+E37-F37 -> 549.33
A38: 45992 | G38: =G37+E38-F38 -> 549.33
A39: 45995 | D39: Transferencia de fondos a cuenta BBVA para pago Planilla de declaración y pago de aportes previsional SG | E39: 30000 | G39: =G38+E39-F39 -> 30549.33
A40: 45996 | D40: Pago AFP Habitat Safeguard | F40: 6615.13 | G40: =G39+E40-F40 -> 23934.2
A41: 45996 | D41: Pago AFP Integra Safeguard | F41: 6050.25 | G41: =G40+E41-F41 -> 17883.95
A42: 45996 | D42: Pago AFP Prima Safeguard | F42: 11925.06 | G42: =G41+E42-F42 -> 5958.89
...

Sheet BBVA USD
D2: BCP USD
A4: FECHA | D4: DESCRIPCIÓN | E4: INGRESO | F4: SALIDA | G4: SALDO
A5: 45901 | G5: 0
A6: 45925 | D6: Transferencia de fondos para apertura de cuenta | E6: 500 | G6: =G5+E6-F6 -> 500
A7: 45930 | D7: Comisión de mantenimiento | F7: 5.4 | G7: =G6+E7-F7 -> 494.6
A8: 45930 | G8: =G7+E8-F8 -> 494.6
A9: 45931 | G9: =G8+E9-F9 -> 494.6
A10: 45961 | D10: Comisión de mantenimiento | F10: 5.4 | G10: =G9+E10-F10 -> 489.2
A11: 45961 | G11: =G10+E11-F11 -> 489.2
A12: 45962 | G12: =G11+E12-F12 -> 489.2
A13: 45610 | D13: Transferencia de fondos de la cuenta BBVA para pago CTS Christiam Valle BBVA Noviembre- USD S&P | E13: 1602.78 | G13: =G12+E13-F13 -> 2091.98
A14: 45610 | D14: Pago CTS Christiam Valle BBVA Noviembre- USD S&P | F14: 1602.78 | G14: =G13+E14-F14 -> 489.2
A15: 45610 | D15: Impuesto ITF | F15: 0.05 | G15: =G14+E15-F15 -> 489.15
A16: 45622 | D16: Comisión de mantenimiento | F16: 5.4 | G16: =G15+E16-F16 -> 483.75
A17: 45991 | G17: =G16+E17-F17 -> 483.75
A18: 45992 | G18: =G17+E18-F18 -> 483.75
A19: 46007 | D19: Transferencia de la cuenta BBVA de USD a la cuenta BCP USD para pago IGV SG | F19: 450 | G19: =G18+E19-F19 -> 33.75
A20: 46007 | D20: Comisión por transferencia de dinero SG | F20: 2.01 | G20: =G19+E20-F20 -> 31.74
A21: 46022 | D21: Comisión de mantenimiento | F21: 5.4 | G21: =G20+E21-F21 -> 26.34
A22: 46022 | G22: =G21+E22-F22 -> 26.34
A23: 46023 | D23: Comisión de mantenimiento | F23: 5.4 | G23: =G22+E23-F23 -> 20.94
A24: 46053 | G24: =G23+E24-F24 -> 20.94
A25: 46080 | D25: Comisión de mantenimiento | F25: 5.4 | G25: =G24+E25-F25 -> 15.54
A26: 46081 | G26: =G25+E26-F26 -> 15.54
A27: 46112 | D27: Comisión de mantenimiento | F27: 5.4 | G27: =G26+E27-F27 -> 10.14
A28: 46112 | G28: =G27+E28-F28 -> 10.14
G29: =G28+E29-F29 -> 10.14
G30: =G29+E30-F30 -> 10.14
G31: =G30+E31-F31 -> 10.14
G32: =G31+E32-F32 -> 10.14
G33: =G32+E33-F33 -> 10.14
G34: =G33+E34-F34 -> 10.14
G35: =G34+E35-F35 -> 10.14
G36: =G35+E36-F36 -> 10.14
G37: =G36+E37-F37 -> 10.14
G38: =G37+E38-F38 -> 10.14
G39: =G38+E39-F39 -> 10.14
G40: =G39+E40-F40 -> 10.14
... G50: =G49+E50-F50 -> 10.14

Sheet BCP SOLES BCP
D2: BCP SOLES
A4: FECHA | D4: DESCRIPCIÓN | E4: INGRESO | F4: SALIDA | G4: SALDO
A5: 45536
A6: 45558 | D6: Transferencia de fondos por apertura de cuenta | E6: 500 | G6: =G5+E6-F6 -> 500
A7: 45548 | D7: Gestion pago del token | F7: 25 | G7: =G6+E7-F7 -> 475
A8: 45562 | D8: Envio estado de cuenta | F8: 5.5 | G8: =G7+E8-F8 -> 469.5
A9: 45562 | D9: Costo por uso de pagina bancaria | F9: 35 | G9: =G8+E9-F9 -> 434.5
A10: 45562 | D10: Cierre | G10: =G9+E10-F10 -> 434.5
A11: 45565 | D11: Saldo | G11: =G10+E11-F11 -> 434.5
A12: 45566 | D12: Inicio mes | G12: =G11+E12-F12 -> 434.5
A13: 45575 | D13: Mantenimiento TD | F13: 10 | G13: =G12+E13-F13 -> 424.5
A14: 45596 | D14: Envio estado de cuenta | F14: 5.5 | G14: =G13+E14-F14 -> 419
A15: 45596 | D15: Costo por uso de pagina bancaria | F15: 35 | G15: =G14+E15-F15 -> 384
A16: 45596 | D16: Saldo | G16: =G15+E16-F16 -> 384
A17: 45597 | D17: Inicio mes | G17: =G16+E17-F17 -> 384
A18: 45611 | D18: Mantenimiento TD | F18: 10 | G18: =G17+E18-F18 -> 374
A19: 45623 | D19: Transferencia de fondos desde la cuenta de USD a Soles para pago pólizas | E19: 300 | G19: =G18+E19-F19 -> 674
A20: 45623 | D20: Pago póliza vida seguro RUC 20613146360 | F20: 629.51 | G20: =G19+E20-F20 -> 44.49
A21: 45624 | D21: Transferencia de fondos de la cuenta de USD a Soles para pago de nómina | E21: 6600 | G21: =G20+E21-F21 -> 6644.49
A22: 45624 | D22: Pago Nómina Noviembre Gonzalo Gabriel Armas-Remofisrt | F22: 6536.4 | G22: =G21+E22-F22 -> 108.09
A23: 45624 | D23: Comisión interbancaria por transferencia pago nómina | F23: 4.8 | G23: =G22+E23-F23 -> 103.29
A24: 45624 | D24: Impuesto ITF | F24: 0.3 | G24: =G23+E24-F24 -> 102.99
A25: 45626 | D25: Envio estado de cuenta | F25: 5.5 | G25: =G24+E25-F25 -> 97.49
A26: 45626 | D26: Costo por uso de pagina bancaria | F26: 35 | G26: =G25+E26-F26 -> 62.49
A27: 45626 | D27: Saldo | G27: =G26+E27-F27 -> 62.49
A28: 45627 | D28: Inicio mes | G28: =G27+E28-F28 -> 62.49
A29: 45637 | D29: Transferencia de fondos de la cuenta de USD a Soles para pago de seguridad social de noviembre | E29: 3000 | G29: =G28+E29-F29 -> 3062.49
A30: 45637 | D30: Transferencia de fondos de la cuenta de USD a Soles para gastos empleado Noviembre | E30: 1239.32 | G30: =G29+E30-F30 -> 4301.81
A31: 45637 | D31: Transferencia de fondos de la cuenta de USD a Soles para gastos empleado Noviembre | E31: 3323.19 | G31: =G30+E31-F31 -> 7625
A32: 45638 | D32: Pago de seguridad social noviembre | F32: 914.43 | G32: =G31+E32-F32 -> 6710.57
A33: 45638 | D33: Pago Gratificaciones y Bonificación de Perú Gonzalo Gabriel Armas-Remofisrt | F33: 3270 | G33: =G32+E33-F33 -> 3440.57
A34: 45638 | D34: Comisión Gratificaciones y Bonificación de Perú Gonzalo Gabriel Armas-Remofisrt | F34: 4.3 | G34: =G33+E34-F34 -> 3436.27
A35: 45642 | D35: Transferencia de fondos de la cuenta de USD a Soles para Salarios, Seguridad social e impuestos de Diciembre | E35: 22167.95 | G35: =G34+E35-F35 -> 25604.22
A36: 45642 | D36: Transferencia de fondos de la cuenta de USD a Soles para Salarios, Seguridad social e impuestos de Diciembre | E36: 113.76 | G36: =G35+E36-F36 -> 25717.98
A37: 45642 | D37: Devolución de dinero Gratificaciones y Bonificación de Perú Gonzalo Gabriel Armas-Remofisrt | E37: 3270 | G37: =G36+E37-F37 -> 28987.98
A38: 45642 | D38: Impuesto ITF | F38: 0.15 | G38: =G37+E38-F38 -> 28987.83
A39: 45642 | D39: Mantenimiento Adic Neg | F39: 10 | G39: =G38+E39-F39 -> 28977.83
A40: 45643 | D40: Pago EESSALUD Seguridad regular trabajador Gonzalo Gabrile Armas-Remotefirst | F40: 702 | G40: =G39+E40-F40 -> 28275.83
A41: 45646 | D41: Pago Gratificaciones y Bonificación de Perú Gonzalo Gabriel Armas-Remofisrt | F41: 3270 | G41: =G40+E41-F41 -> 25005.83
A42: 45646 | D42: Comisión Gratificaciones y Bonificación de Perú Gonzalo Gabriel Armas-Remofisrt | F42: 4.8 | G42: =G41+E42-F42 -> 25001.03
...

Sheet BCP USD BCP
D2: BCP USD
A4: FECHA | D4: DESCRIPCIÓN | E4: INGRESO | F4: SALIDA | G4: SALDO
A5: 45566 | G5: 0
A6: 45575 | D6: Mantenimiento TD | F6: 15.84 | G6: =G5+E6-F6 -> -15.84
A7: 45596 | D7: Envio estado de cuenta | F7: 2 | G7: =G6+E7-F7 -> -17.84
A8: 45596 | G8: =G7+E8-F8 -> -17.84
A9: 45597 | G9: =G8+E9-F9 -> -17.84
A10: 45607 | D10: Devolución Mantenimiento TD | E10: 15.84 | G10: =G9+E10-F10 -> -2
A11: 45608 | D11: Envío de recursos desde casa matriz S&P col a Sucursal Perú para fondeo cuenta y pago Proveedor | E11: 2595 | G11: =G10+E11-F11 -> 2593
A12: 45608 | D12: Impuesto ITF | F12: 0.1 | G12: =G11+E12-F12 -> 2592.9
A13: 45610 | D13: Pago de facturas Nro. 4734 servicio de octubre y 4853 servicios de noviembre- Estudio Fuentes | F13: 1338.8 | G13: =G12+E13-F13 -> 1254.1
A14: 45610 | D14: Impuesto ITF | F14: 0.05 | G14: =G13+E14-F14 -> 1254.05
A15: 45614 | D15: Portes autosobre | F15: 1.32 | G15: =G14+E15-F15 -> 1252.73
A16: 45621 | D16: Pago servicios mes de noviembre Remotefisrt SIL | E16: 3833.74 | G16: =G15+E16-F16 -> 5086.47
A17: 45621 | D17: Impuesto ITF | F17: 0.15 | G17: =G16+E17-F17 -> 5086.32
A18: 45623 | D18: Transferencia de fondos desde la cuenta de USD a Soles para pago pólizas | F18: 81.06 | G18: =G17+E18-F18 -> 5005.26
A19: 45624 | D19: Transferencia de fondos de la cuenta de USD a Soles para pago nómina Gonzalo Gabriel Armas-Remotefisrt | F19: 1778.98 | G19: =G18+E19-F19 -> 3226.28
A20: 45626 | D20: Envio estado de cuenta | F20: 2 | G20: =G19+E20-F20 -> 3224.28
A21: 45626 | D21: Intereses deudores | F21: 0.15 | G21: =G20+E21-F21 -> 3224.13
A22: 45626 | D22: Mantenimiento TD | F22: 13 | G22: =G21+E22-F22 -> 3211.13
A23: 45626 | G23: =G22+E23-F23 -> 3211.13
A24: 45627 | G24: =G23+E24-F24 -> 3211.13
A25: 45628 | D25: Portes autosobre | F25: 1.32 | G25: =G24+E25-F25 -> 3209.81
A26: 45628 | D26: Porte extracto Numer | F26: 1.32 | G26: =G25+E26-F26 -> 3208.49
A27: 45637 | D27: Transferencia de fondos de la cuenta de USD a Soles para Seguridad social de noviembre | F27: 815.44 | G27: =G26+E27-F27 -> 2393.05
A28: 45637 | D28: Transferencia de fondos de la cuenta de USD a Soles para pagos | F28: 336.77 | G28: =G27+E28-F28 -> 2056.28
A29: 45637 | D29: Transferencia de fondos de la cuenta de USD a Soles para pagos | F29: 902.55 | G29: =G28+E29-F29 -> 1153.73
A30: 45639 | D30: Pago servicios mes de diciembre Remotefisrt SIL | E30: 6017.36 | G30: =G29+E30-F30 -> 7171.09
A31: 45639 | D31: Impuesto ITF | F31: 0.3 | G31: =G30+E31-F31 -> 7170.79
A32: 45639 | D32: Transferencia de fondos de la cuenta de USD a Soles para Salarios, Seguridad social e impuestos de Diciembre | F32: 5986.48 | G32: =G31+E32-F32 -> 1184.31
A33: 45639 | D33: Transferencia de fondos de la cuenta de USD a Soles para Salarios, Seguridad social e impuestos de Diciembre | F33: 30.88 | G33: =G32+E33-F33 -> 1153.43
A34: 45642 | D34: Portes autosobre | F34: 1.32 | G34: =G33+E34-F34 -> 1152.11
A35: 45645 | D35: Pago de facturas Nro.5107 servicio de Diciembre- Estudio Fuentes | F35: 938.1 | G35: =G34+E35-F35 -> 214.01
A36: 45657 | D36: Envio estado de cuenta | F36: 2 | G36: =G35+E36-F36 -> 212.01
A37: 45657 | D37: Mantenimiento TD | F37: 13 | G37: =G36+E37-F37 -> 199.01
A38: 45657 | G38: =G37+E38-F38 -> 199.01
A39: 45658 | G39: =G38+E39-F39 -> 199.01
A40: 45663 | D40: Devolución Mantenimiento TD | E40: 13 | G40: =G39+E40-F40 -> 212.01
A41: 45678 | D41: Pago servicios mes de enero Remotefisrt SIL | E41: 8565.91 | G41: =G40+E41-F41 -> 8777.92
A42: 45678 | D42: Impuesto ITF | F42: 0.4 | G42: =G41+E42-F42 -> 8777.52
...

Sheet GASTOS SUCURSAL PERÚ
B2: Fecha | C2: Descripción | D2: Valor
B3: 45560 | C3: 50% Anticipo constitución | D3: 500
B4: 45560 | C4: IGV | D4: 90
B5: 45560 | C5: Apertura cuenta | D5: 150
B6: 45560 | C6: Comisión Bancaria | D6: 25
B7: 45566 | C7: 50% Saldo final constitución | D7: 500
B8: 45566 | C8: IGV | D8: 90
B9: 45566 | C9: Comisión Bancaria | D9: 25
B10: 45608 | C10: factura estudio fuentes 4734 Oct | D10: 348.1
B11: 45608 | C11: factura estudio fuentes 4853 Nov | D11: 1020.7
B12: 45608 | C12: Dinero Caja | D12: =2620-D10-D11 -> 1251.2
B13: 45623 | C13: Pago póliza vida seguro | D13: =629.51/'Diferencia Cambio S&P'!$S$26 -> #DIV/0!
B14: 45624 | C14: Pago Nómina Noviembre Gonzalo Gabriel Armas | D14: =6536.4/'Diferencia Cambio S&P'!$S$26 -> #DIV/0!
B15: 45638 | C15: Seguridad social noviembre | D15: =914.43/'Diferencia Cambio S&P'!$S$26 -> #DIV/0!
B16: 45638 | C16: Pago Gratificaciones y Bonificación de Perú Diciembre Gonzalo Gabriel Armas | D16: =3270/'Diferencia Cambio S&P'!$S$26 -> #DIV/0!
B17: 45642 | C17: Aporte Esauld | D17: =702/'Diferencia Cambio S&P'!$S$26 -> #DIV/0!
B18: 45646 | C18: factura estudio fuentes 5107 Dic | D18: 938.1
B19: 45646 | C19: Gastos Financieros soles | D19: =('BCP SOLES BCP'!$F$7+'BCP SOLES BCP'!$F$8+'BCP SOLES BCP'!$F$9+'BCP SOLES BCP'!$F$13+'BCP SOLES BCP'!$F$14+'BCP SOLES BCP'!$F$15+'BCP SOLES BCP'!$F$18+'BCP SOLES BCP'!$F$23+'BCP SOLES BCP'!$F$24+'BCP SOLES BCP'!$F$25+'BCP SOLES BCP'!$F$26+'BCP SOLES BCP'!$F$34+'BCP SOLES BCP'!$F$38)/'Diferencia Cambio S&P'!$S$26 -> #DIV/0!
B20: 45646 | C20: Gastos Financieros USD | D20: ='BCP USD BCP'!$F$6+'BCP USD BCP'!$F$7+'BCP USD BCP'!$F$12+'BCP USD BCP'!$F$14+'BCP USD BCP'!$F$15+'BCP USD BCP'!$F$17+'BCP USD BCP'!$F$20+'BCP USD BCP'!$F$21+'BCP USD BCP'!$F$22+'BCP USD BCP'!$F$25+'BCP USD BCP'!$F$26+'BCP USD BCP'!$F$31 -> 37.55
B21: 45653 | C21: Pago Nómina Noviembre Gonzalo Gabriel Armas | D21: ='BCP SOLES BCP'!F44/'Diferencia Cambio S&P'!$S$26 -> #DIV/0!
B22: 45653 | C22: Gastos Financieros USD | D22: =('BCP SOLES BCP'!$F$45+'BCP SOLES BCP'!$F$46)/'Diferencia Cambio S&P'!$S$26 -> #DIV/0!
B23: TOTAL | D23: =SUM(D3:D22) -> #DIV/0!

Sheet FLUJO CAJA MARZO
D1: 42400
D4: Fecha de Elaboración: | E4: 45719
C6: Tasa de cambio: | D6: 3.68 | J6: 12800.27
D7: MARZO | J7: 12729.47
D8: VALOR S/ Sol | E8: VALOR USD | J8: =J6-J7 -> 70.8
C9: BANCOS | D9: =SUBTOTAL(9,D10:D11) -> 38615.269 | E9: =SUBTOTAL(9,E10:E11) -> 10493.28
C10: Bancos S/ Soles | D10: ='BCP SOLES BCP'!$G$93+1521.83 -> 26725.925 | E10: =D10/$D$6 -> 7262.4796
C11: Bancos USD | D11: =E11*$D$6 -> 11889.344 | E11: ='BCP USD BCP'!$G$67 -> 3230.8
C12: CLIENTES | D12: =SUBTOTAL(9,D13:D15) -> 89149.454 | E12: =SUBTOTAL(9,E13:E15) -> 25084.56 | F12: Factura inicial | G12: Notas crédito | J12: Valor final real
B13: Pagado | C13: Client: Remorfist-Factura Nro 11-Abono | D13: =E13*3.54 -> 45312.956 | E13: =12729.47+70.8 -> 12800.27 | F13: =14132.55 -> 14132.55 | G13: =32.29+1300 -> 1332.29 | J13: =F13-G13 -> 12800.26
B14: Pagado | C14: Client: Eurportage-Factura Nro 12 | D14: =E14*3.54 -> 34633.555 | E14: 9783.49
B15: Pagado | C15: Client: Remorfist-Factura Nro 13-Offcycle | D15: =E15*3.68 -> 9202.944 | E15: 2500.8 | F15: 2571.6 | G15: =E15-F15 -> -70.8
C16: TOTAL INGRESOS | D16: =SUBTOTAL(9,D9:D14) -> 118561.78 | E16: =SUBTOTAL(9,E9:E14) -> 33077.04
B19: CUENTAS X PAGAR MES | D19: MARZO | F19: Fecha de Elaboración: | J19: 45717
B20: Factura | C20: PROVEEDOR | D20: VALOR S/Sol | E20: VALOR USD | F20: Fecha vencimiento | G20: Estado | J20: KPI
C21: SEGURIDAD IGSS | D21: =SUBTOTAL(9,D22:D24) -> 5005.54 | E21: =SUBTOTAL(9,E22:E24) -> 1360.2011
C22: Planilla de declaración y pago de aportes previsional-Gonzálo de armas | D22: 1964.78 | E22: =D22/$D$6 -> 533.90761 | F22: 45723 | G22: Cancelado | H22: =IF(OR(G22="Sin pagar",G22="Pagar"),_xlfn.SINGLE(NETWORKDAYS($J$19,F22,FestivosPerú!$A$2:$A$15)),0) -> 0 | I22: =NETWORKDAYS($J$19,F22,FestivosPerú!$A$2:$A$15) -> 5 | J22: =H22 -> 0
C23: Planilla de declaración y pago de aportes previsional-Braydi Yusset Vera Neyra | D23: 2313.08 | E23: =D23/$D$6 -> 628.55435 | F23: 45723 | G23: Cancelado | H23: =IF(OR(G23="Sin pagar",G23="Pagar"),_xlfn.SINGLE(NETWORKDAYS($J$19,F23,FestivosPerú!$A$2:$A$15)),0) -> 0 | I23: =NETWORKDAYS($J$19,F23,FestivosPerú!$A$2:$A$15) -> 5 | J23: =H23 -> 0
C24: Planilla de declaración y pago de aportes previsional Hector Andrés Zevallos Váquez | D24: 727.68 | E24: =D24/$D$6 -> 197.73913 | F24: 45723 | G24: Cancelado | H24: =IF(OR(G24="Sin pagar",G24="Pagar"),_xlfn.SINGLE(NETWORKDAYS($J$19,F24,FestivosPerú!$A$2:$A$15)),0) -> 0 | I24: =NETWORKDAYS($J$19,F24,FestivosPerú!$A$2:$A$15) -> 5 | J24: =H24 -> 0
C25: IMPUESTOS | D25: =SUBTOTAL(9,D26:D27) -> 12189 | E25: =SUBTOTAL(9,E26:E27) -> 3312.2283 | J25: =H25 -> 0
C26: PLAME Essalud y Renta de Quinta Categoría (Retención) | D26: 11110 | E26: =D26/$D$6 -> 3019.0217 | F26: 45728 | G26: Cancelado | H26: =IF(OR(G26="Sin pagar",G26="Pagar"),_xlfn.SINGLE(NETWORKDAYS($J$19,F26,FestivosPerú!$A$2:$A$15)),0) -> 0 | I26: =NETWORKDAYS($J$19,F26,FestivosPerú!$A$2:$A$15) -> 8 | J26: =H26 -> 0
C27: Pago de renta IGV | D27: 1079 | E27: =D27/$D$6 -> 293.20652 | F27: 45733 | G27: Cancelado | H27: =IF(OR(G27="Sin pagar",G27="Pagar"),_xlfn.SINGLE(NETWORKDAYS($J$19,F27,FestivosPerú!$A$2:$A$15)),0) -> 0 | I27: =NETWORKDAYS($J$19,F27,FestivosPerú!$A$2:$A$15) -> 11 | J27: =H27 -> 0
C28: SERVICIOS OUTSORCING CONTABLE | D28: =SUBTOTAL(9,D29:D29) -> 1281.008 | E28: =SUBTOTAL(9,E29:E29) -> 348.1 | J28: =H28 -> 0
B29: 5628 | C29: Estudio fuentes servicios marzo | D29: =$E$29*$D$6 -> 1281.008 | E29: 348.1 | F29: 45743 | G29: Cancelado | H29: =IF(OR(G29="Sin pagar",G29="Pagar"),_xlfn.SINGLE(NETWORKDAYS($J$19,F29,FestivosPerú!$A$2:$A$15)),0) -> 0 | I29: =NETWORKDAYS($J$19,F29,FestivosPerú!$A$2:$A$15) -> 19 | J29: =H29 -> 0
C30: PÓLIZAS DE VIDA Y SEGUROS MÉDICO | D30: =SUBTOTAL(9,D31:D31) -> 1254 | E30: =SUBTOTAL(9,E31:E31) -> 340.76087
C31: Póliza de salud Braidy Vera- pago 12 meses -1er mes | D31: 1254 | E31: =D31/D6 -> 340.76087 | F31: 45727 | G31: Sin Pagar | H31: =IF(OR(G31="Sin pagar",G31="Pagar"),_xlfn.SINGLE(NETWORKDAYS($J$19,F31,FestivosPerú!$A$2:$A$15)),0) -> 7 | I31: =NETWORKDAYS($J$19,F31,FestivosPerú!$A$2:$A$15) -> 7 | J31: =H31 -> 7
C32: COSTOS FINANCIEROS | D32: =SUBTOTAL(9,D33:D33) -> 116.16261 | E32: =SUBTOTAL(9,E33:E33) -> 31.565926
C33: COSTOS FINANCIEROS | D33: =('BCP SOLES BCP'!$F$98+'BCP SOLES BCP'!$F$105+'BCP SOLES BCP'!$F$108+'BCP SOLES BCP'!$F$113+'BCP SOLES BCP'!$F$115+'BCP SOLES BCP'!$F$117+'BCP SOLES BCP'!$F$119+'BCP SOLES BCP'!$F$122+'BCP SOLES BCP'!$F$124+'BCP SOLES BCP'!$F$126+'BCP SOLES BCP'!$F$127)+(('BCP USD BCP'!$F$66+'BCP USD BCP'!$F$67+'BCP USD BCP'!$F$68+'BCP USD BCP'!$F$70+'BCP USD BCP'!$F$73+'BCP USD BCP'!$F$76+'BCP USD BCP'!$F$79+'BCP USD BCP'!$F$80+'BCP USD BCP'!$F$81)/$D$6) -> 116.16261 | E33: =D33/D6 -> 31.565926 | F33: 45747 | G33: Cancelado | H33: =IF(OR(G33="Sin pagar",G33="Pagar"),_xlfn.SINGLE(NETWORKDAYS($J$19,F33,FestivosPerú!$A$2:$A$15)),0) -> 0 | I33: =NETWORKDAYS($J$19,F33,FestivosPerú!$A$2:$A$15) -> 21 | J33: =H33 -> 0
C34: NÓMINAS | D34: =SUBTOTAL(9,D35:D38) -> 47268.854 | E34: =SUBTOTAL(9,E35:E38) -> 12844.797
C35: Gonzalo Gabriel Armas-Remofisrt | D35: 13204.759 | E35: =D35/$D$6 -> 3588.2498 | F35: 45744 | G35: Cancelado | H35: =IF(OR(G35="Sin pagar",G35="Pagar"),_xlfn.SINGLE(NETWORKDAYS($J$19,F35,FestivosPerú!$A$2:$A$15)),0) -> 0 | I35: =NETWORKDAYS($J$19,F35,FestivosPerú!$A$2:$A$15) -> 20 | J35: =H35 -> 0
C36: Héctor Andrés Zevallos Vasquez-Remotefirst | D36: 12481.715 | E36: =D36/$D$6 -> 3391.7704 | F36: 45744 | G36: Cancelado | H36: =IF(OR(G36="Sin pagar",G36="Pagar"),_xlfn.SINGLE(NETWORKDAYS($J$19,F36,FestivosPerú!$A$2:$A$15)),0) -> 0 | I36: =NETWORKDAYS($J$19,F36,FestivosPerú!$A$2:$A$15) -> 20 | J36: =H36 -> 0
C37: Braydi Yusset Vera Neira-Europortage | D37: 13725.33 | E37: =D37/$D$6 -> 3729.7092 | F37: 45744 | G37: Cancelado | H37: =IF(OR(G37="Sin pagar",G37="Pagar"),_xlfn.SINGLE(NETWORKDAYS($J$19,F37,FestivosPerú!$A$2:$A$15)),0) -> 0 | I37: =NETWORKDAYS($J$19,F37,FestivosPerú!$A$2:$A$15) -> 20 | J37: =H37 -> 0
C38: Cristhian Portugal Segovia -Europortage | D38: 7857.05 | E38: =D38/$D$6 -> 2135.0679 | F38: 45744 | G38: Cancelado | H38: =IF(OR(G38="Sin pagar",G38="Pagar"),_xlfn.SINGLE(NETWORKDAYS($J$19,F38,FestivosPerú!$A$2:$A$15)),0) -> 0 | I38: =NETWORKDAYS($J$19,F38,FestivosPerú!$A$2:$A$15) -> 20 | J38: =H38 -> 0
C39: REEMBOLSO | D39: =SUBTOTAL(9,D40:D42) -> 17893.41 | E39: =SUBTOTAL(9,E40:E42) -> 4862.3397
C40: Reembolso Braydi Yusset Vera Neira-Europortage | D40: 7044.25 | E40: =D40/$D$6 -> 1914.1984 | F40: 45744 | G40: Cancelado | H40: =IF(OR(G40="Sin pagar",G40="Pagar"),_xlfn.SINGLE(NETWORKDAYS($J$19,F40,FestivosPerú!$A$2:$A$15)),0) -> 0 | I40: =NETWORKDAYS($J$19,F40,FestivosPerú!$A$2:$A$15) -> 20 | J40: =H40 -> 0
C41: Reembolso Gonzalo Gabriel Armas-Remofisrt | D41: 10437.22 | E41: =D41/$D$6 -> 2836.2011 | F41: 45744 | G41: Cancelado | H41: =IF(OR(G41="Sin pagar",G41="Pagar"),_xlfn.SINGLE(NETWORKDAYS($J$19,F41,FestivosPerú!$A$2:$A$15)),0) -> 0 | I41: =NETWORKDAYS($J$19,F41,FestivosPerú!$A$2:$A$15) -> 20 | J41: =H41 -> 0
C42: Reembolso Héctor Andrés Zevallos Vasquez-Remotefirst | D42: 411.94 | E42: =D42/$D$6 -> 111.94022 | F42: 45744 | G42: Cancelado | H42: =IF(OR(G42="Sin pagar",G42="Pagar"),_xlfn.SINGLE(NETWORKDAYS($J$19,F42,FestivosPerú!$A$2:$A$15)),0) -> 0 | I42: =NETWORKDAYS($J$19,F42,FestivosPerú!$A$2:$A$15) -> 20 | J42: =H42 -> 0
C43: IMPREVISTO | D43: =SUBTOTAL(9,D44:D47) -> 587.3 | E43: =SUBTOTAL(9,E44:E47) -> 128.73913
B44: F001 - 0013697 | C44: Pago examen médico ocupacional de ingreso Christian Portugal Europortage | D44: 327 | E44: =D44/$D$6 -> 88.858696 | F44: 45724 | G44: Cancelado | H44: =IF(OR(G44="Sin pagar",G44="Pagar"),_xlfn.SINGLE(NETWORKDAYS($J$19,F44,FestivosPerú!$A$2:$A$15)),0) -> 0 | I44: =NETWORKDAYS($J$19,F44,FestivosPerú!$A$2:$A$15) -> 5 | J44: =H44 -> 0
C45: Pago seguro complementario de trabajo riesgo salud-Obreros alto riesgo- Recibo Nro 159141649 | D45: 116.95 | E45: =D45/$D$6 -> 31.779891 | F45: 45724 | G45: Cancelado | H45: =IF(OR(G45="Sin pagar",G45="Pagar"),_xlfn.SINGLE(NETWORKDAYS($J$19,F45,FestivosPerú!$A$2:$A$15)),0) -> 0 | I45: =NETWORKDAYS($J$19,F45,FestivosPerú!$A$2:$A$15) -> 5 | J45: =H45 -> 0
...

Sheet FLUJO CAJA ABRIL
D1: 42400
D4: Fecha de Elaboración: | E4: 45748
C6: Tasa de cambio: | D6: 3.68
D7: ABRIL
D8: VALOR S/ Sol | E8: VALOR USD
C9: BANCOS | D9: =SUBTOTAL(9,D10:D11) -> 54720.342 | E9: =SUBTOTAL(9,E10:E11) -> 14869.658
C10: Bancos S/ Soles | D10: ='BCP SOLES BCP'!$G$128 -> 32966.501 | E10: =D10/$D$6 -> 8958.2883
C11: Bancos USD | D11: =E11*$D$6 -> 21753.842 | E11: ='BCP USD BCP'!$G$82 -> 5911.37
C12: CLIENTES | D12: =SUBTOTAL(9,D13:D15) -> 72838.86 | E12: =SUBTOTAL(9,E13:E15) -> 19869.11
B13: Pagado | C13: Client: Remorfist-Factura Nro 15 | D13: 20189.153 | E13: =D13/3.63 -> 5561.75
B14: Pagado | C14: Client: Remorfist-Factura Nro 17 | D14: 100.0065 | E14: =D14/3.63 -> 27.55
B15: Pagado | C15: Client: Eurportage-Factura Nro 16-18 | D15: =$E$15*$D$6 -> 52549.701 | E15: 14279.81
C16: TOTAL INGRESOS | D16: =SUBTOTAL(9,D9:D15) -> 127559.2 | E16: =SUBTOTAL(9,E9:E15) -> 34738.768
B19: CUENTAS X PAGAR MES | D19: ABRIL | F19: Fecha de Elaboración: | J19: 45748
B20: Factura | C20: PROVEEDOR | D20: VALOR S/Sol | E20: VALOR USD | F20: Fecha vencimiento | G20: Estado | J20: KPI
C21: SEGURIDAD IGSS | D21: =SUBTOTAL(9,D22:D24) -> 7339.8 | E21: =SUBTOTAL(9,E22:E24) -> 1994.5109
C22: Planilla de declaración y pago de aportes previsional-Gonzálo de armas | D22: 1964.78 | E22: =D22/$D$6 -> 533.90761 | F22: 45755 | G22: Cancelado | H22: =IF(OR(G22="Sin pagar",G22="Pagar"),_xlfn.SINGLE(NETWORKDAYS($J$19,F22,FestivosPerú!$A$2:$A$15)),0) -> 0 | I22: =NETWORKDAYS($J$19,F22,FestivosPerú!$A$2:$A$15) -> 6 | J22: =H22 -> 0
C23: Planilla de declaración y pago de aportes previsional-Braydi Yusset Vera Neyra | D23: 2339.18 | E23: =D23/$D$6 -> 635.64674 | F23: 45755 | G23: Cancelado | H23: =IF(OR(G23="Sin pagar",G23="Pagar"),_xlfn.SINGLE(NETWORKDAYS($J$19,F23,FestivosPerú!$A$2:$A$15)),0) -> 0 | I23: =NETWORKDAYS($J$19,F23,FestivosPerú!$A$2:$A$15) -> 6 | J23: =H23 -> 0
C24: Planilla de declaración y pago de aportes previsional Hector Andrés Zevallos Váquez | D24: 3035.84 | E24: =D24/$D$6 -> 824.95652 | F24: 45755 | G24: Cancelado | H24: =IF(OR(G24="Sin pagar",G24="Pagar"),_xlfn.SINGLE(NETWORKDAYS($J$19,F24,FestivosPerú!$A$2:$A$15)),0) -> 0 | I24: =NETWORKDAYS($J$19,F24,FestivosPerú!$A$2:$A$15) -> 6 | J24: =H24 -> 0
C25: IMPUESTOS | D25: =SUBTOTAL(9,D26:D27) -> 14903 | E25: =SUBTOTAL(9,E26:E27) -> 4049.7283 | J25: =H25 -> 0
C26: PLAME Essalud y Renta de Quinta Categoría (Retención) | D26: 13330 | E26: =D26/$D$6 -> 3622.2826 | F26: 45761 | G26: Cancelado | H26: =IF(OR(G26="Sin pagar",G26="Pagar"),_xlfn.SINGLE(NETWORKDAYS($J$19,F26,FestivosPerú!$A$2:$A$15)),0) -> 0 | I26: =NETWORKDAYS($J$19,F26,FestivosPerú!$A$2:$A$15) -> 10 | J26: =H26 -> 0
C27: Pago de renta IGV | D27: 1573 | E27: =D27/$D$6 -> 427.44565 | F27: 45762 | G27: Cancelado | H27: =IF(OR(G27="Sin pagar",G27="Pagar"),_xlfn.SINGLE(NETWORKDAYS($J$19,F27,FestivosPerú!$A$2:$A$15)),0) -> 0 | I27: =NETWORKDAYS($J$19,F27,FestivosPerú!$A$2:$A$15) -> 11 | J27: =H27 -> 0 | M27: Estudio Fuentes
C28: SERVICIOS OUTSORCING CONTABLE | D28: =SUBTOTAL(9,D29:D29) -> 1281.008 | E28: =SUBTOTAL(9,E29:E29) -> 348.1 | J28: =H28 -> 0
B29: 5752 | C29: Estudio fuentes servicios Abril | D29: =$E$29*$D$6 -> 1281.008 | E29: 348.1 | F29: 45776 | G29: Cancelado | H29: =IF(OR(G29="Sin pagar",G29="Pagar"),_xlfn.SINGLE(NETWORKDAYS($J$19,F29,FestivosPerú!$A$2:$A$15)),0) -> 0 | I29: =NETWORKDAYS($J$19,F29,FestivosPerú!$A$2:$A$15) -> 20 | J29: =H29 -> 0
C30: PÓLIZAS DE VIDA Y SEGUROS MÉDICO | D30: =SUBTOTAL(9,D31:D34) -> 1832.17 | E30: =SUBTOTAL(9,E31:E34) -> 497.87228
B31: 159827721 | C31: Seguros de vida complementario ley, SCTS y SCTP Héctor Andréz Zevallos | D31: 227.08 | E31: =D31/$D$6 -> 61.706522 | F31: 45749 | G31: Cancelado | H31: =IF(OR(G31="Sin pagar",G31="Pagar"),_xlfn.SINGLE(NETWORKDAYS($J$19,F31,FestivosPerú!$A$2:$A$15)),0) -> 0 | I31: =NETWORKDAYS($J$19,F31,FestivosPerú!$A$2:$A$15) -> 2 | J31: =H31 -> 0
B32: 159827700 | C32: Seguros de vida complementario ley, SCTS y SCTP Braidy Yuseet vera Neyra | D32: 233.89 | E32: =D32/$D$6 -> 63.557065 | F32: 45749 | G32: Cancelado | H32: =IF(OR(G32="Sin pagar",G32="Pagar"),_xlfn.SINGLE(NETWORKDAYS($J$19,F32,FestivosPerú!$A$2:$A$15)),0) -> 0 | I32: =NETWORKDAYS($J$19,F32,FestivosPerú!$A$2:$A$15) -> 2 | J32: =H32 -> 0
B33: 159827866 | C33: Seguros de vida complementario ley, SCTS y SCTP Christian Portugal Segovia | D33: 118 | E33: =D33/$D$6 -> 32.065217 | F33: 45749 | G33: Cancelado | H33: =IF(OR(G33="Sin pagar",G33="Pagar"),_xlfn.SINGLE(NETWORKDAYS($J$19,F33,FestivosPerú!$A$2:$A$15)),0) -> 0 | I33: =NETWORKDAYS($J$19,F33,FestivosPerú!$A$2:$A$15) -> 2 | J33: =H33 -> 0
C34: Póliza de salud Braidy Vera- Couta 6 meses fraccionada | D34: 1253.2 | E34: =D34/D6 -> 340.54348 | F34: 45776 | G34: Cancelado | H34: =IF(OR(G34="Sin pagar",G34="Pagar"),_xlfn.SINGLE(NETWORKDAYS($J$19,F34,FestivosPerú!$A$2:$A$15)),0) -> 0 | I34: =NETWORKDAYS($J$19,F34,FestivosPerú!$A$2:$A$15) -> 20 | J34: =H34 -> 0
C35: COSTOS FINANCIEROS | D35: =SUBTOTAL(9,D36:D36) -> 478.0212 | E35: =SUBTOTAL(9,E36:E36) -> 129.89707
C36: COSTOS FINANCIEROS | D36: 478.0212 | E36: =$D$36/$D$6 -> 129.89707 | F36: 45777 | G36: Cancelado | H36: =IF(OR(G36="Sin pagar",G36="Pagar"),_xlfn.SINGLE(NETWORKDAYS($J$19,F36,FestivosPerú!$A$2:$A$15)),0) -> 0 | I36: =NETWORKDAYS($J$19,F36,FestivosPerú!$A$2:$A$15) -> 21 | J36: =H36 -> 0
C37: NÓMINAS | D37: =SUBTOTAL(9,D38:D41) -> 56729.82 | E37: =SUBTOTAL(9,E38:E41) -> 15415.712
C38: Gonzalo Gabriel Armas-Remofisrt ( Liquidación) | D38: 24477.58 | E38: =D38/$D$6 -> 6651.5163 | F38: 45769 | G38: Cancelado | H38: =IF(OR(G38="Sin pagar",G38="Pagar"),_xlfn.SINGLE(NETWORKDAYS($J$19,F38,FestivosPerú!$A$2:$A$15)),0) -> 0 | I38: =NETWORKDAYS($J$19,F38,FestivosPerú!$A$2:$A$15) -> 15 | J38: =H38 -> 0
C39: Héctor Andrés Zevallos Vasquez-Remotefirst ( Liquidación) | D39: 8135.5 | E39: =D39/$D$6 -> 2210.7337 | F39: 45770 | G39: Cancelado | H39: =IF(OR(G39="Sin pagar",G39="Pagar"),_xlfn.SINGLE(NETWORKDAYS($J$19,F39,FestivosPerú!$A$2:$A$15)),0) -> 0 | I39: =NETWORKDAYS($J$19,F39,FestivosPerú!$A$2:$A$15) -> 16 | J39: =H39 -> 0
C40: Braydi Yusset Vera Neira-Europortage | D40: 13725.33 | E40: =D40/$D$6 -> 3729.7092 | F40: 45775 | G40: Cancelado | H40: =IF(OR(G40="Sin pagar",G40="Pagar"),_xlfn.SINGLE(NETWORKDAYS($J$19,F40,FestivosPerú!$A$2:$A$15)),0) -> 0 | I40: =NETWORKDAYS($J$19,F40,FestivosPerú!$A$2:$A$15) -> 19 | J40: =H40 -> 0
C41: Cristhian Portugal Segovia -Europortage | D41: 10391.41 | E41: =D41/$D$6 -> 2823.7527 | F41: 45776 | G41: Cancelado | H41: =IF(OR(G41="Sin pagar",G41="Pagar"),_xlfn.SINGLE(NETWORKDAYS($J$19,F41,FestivosPerú!$A$2:$A$15)),0) -> 0 | I41: =NETWORKDAYS($J$19,F41,FestivosPerú!$A$2:$A$15) -> 20 | J41: =H41 -> 0
C42: REEMBOLSO | D42: =SUBTOTAL(9,D43:D44) -> 4341.36 | E42: =SUBTOTAL(9,E43:E44) -> 1179.7174
C43: Reembolso Braydi Yusset Vera Neira-Europortage | D43: 3642.99 | E43: =D43/$D$6 -> 989.94293 | F43: 45775 | G43: Cancelado | H43: =IF(OR(G43="Sin pagar",G43="Pagar"),_xlfn.SINGLE(NETWORKDAYS($J$19,F43,FestivosPerú!$A$2:$A$15)),0) -> 0 | I43: =NETWORKDAYS($J$19,F43,FestivosPerú!$A$2:$A$15) -> 19 | J43: =H43 -> 0
C44: Reembolso Cristhian Portugal Segovia -Europortage | D44: 698.37 | E44: =D44/$D$6 -> 189.77446 | F44: 45776 | G44: Cancelado | H44: =IF(OR(G44="Sin pagar",G44="Pagar"),_xlfn.SINGLE(NETWORKDAYS($J$19,F44,FestivosPerú!$A$2:$A$15)),0) -> 0 | I44: =NETWORKDAYS($J$19,F44,FestivosPerú!$A$2:$A$15) -> 20 | J44: =H44 -> 0
C45: IMPREVISTO | D45: =SUBTOTAL(9,D46:D46) -> 301.97 | E45: =SUBTOTAL(9,E46:E46) -> 82.057065
...

Sheet FLUJO CAJA MAYO
D1: 42400
D4: Fecha de Elaboración: | E4: 45778
C6: Tasa de cambio: | D6: 3.66
D7: MAYO
D8: VALOR S/ Sol | E8: VALOR USD
C9: BANCOS | D9: =SUBTOTAL(9,D10:D11) -> 40299.372 | E9: =SUBTOTAL(9,E10:E11) -> 11010.757
C10: Bancos S/ Soles | D10: ='BCP SOLES BCP'!$G$168 -> 30657.981 | E10: =D10/$D$6 -> 8376.4975
C11: Bancos USD | D11: =E11*$D$6 -> 9641.3916 | E11: ='BCP USD BCP'!$G$99 -> 2634.26
C12: CLIENTES | D12: =SUBTOTAL(9,D13:D13) -> #REF! | E12: =SUBTOTAL(9,E13:E13) -> #REF!
B13: Pagado | C13: Client: Eurportage-Factura Nro 19 | D13: =$E$13*'Diferencia Cambio S&P'!#REF! -> #REF! | E13: ='Diferencia Cambio S&P'!#REF! -> #REF!
C14: TOTAL INGRESOS | D14: =SUBTOTAL(9,D9:D13) -> #REF! | E14: =SUBTOTAL(9,E9:E13) -> #REF!
B17: CUENTAS X PAGAR MES | D17: ABRIL | F17: Fecha de Elaboración: | J17: 45778
B18: Factura | C18: PROVEEDOR | D18: VALOR S/Sol | E18: VALOR USD | F18: Fecha vencimiento | G18: Estado | J18: KPI
C19: SEGURIDAD IGSS | D19: =SUBTOTAL(9,D20:D22) -> 5518.22 | E19: =SUBTOTAL(9,E20:E22) -> 1507.7104
C20: Planilla de declaración y pago de aportes previsional-Gonzálo de armas | D20: 1199.54 | E20: =D20/$D$6 -> 327.74317 | F20: 45785 | G20: Cancelado | H20: =IF(OR(G20="Sin pagar",G20="Pagar"),_xlfn.SINGLE(NETWORKDAYS($J$17,F20,FestivosPerú!$A$2:$A$15)),0) -> 0 | I20: =NETWORKDAYS($J$17,F20,FestivosPerú!$A$2:$A$15) -> 5 | J20: =H20 -> 0
C21: Planilla de declaración y pago de aportes previsional-Braydi Yusset Vera Neyra | D21: 2161.35 | E21: =D21/$D$6 -> 590.53279 | F21: 45785 | G21: Cancelado | H21: =IF(OR(G21="Sin pagar",G21="Pagar"),_xlfn.SINGLE(NETWORKDAYS($J$17,F21,FestivosPerú!$A$2:$A$15)),0) -> 0 | I21: =NETWORKDAYS($J$17,F21,FestivosPerú!$A$2:$A$15) -> 5 | J21: =H21 -> 0
C22: Planilla de declaración y pago de aportes previsional Hector Andrés Zevallos Váquez | D22: 2157.33 | E22: =D22/$D$6 -> 589.43443 | F22: 45785 | G22: Cancelado | H22: =IF(OR(G22="Sin pagar",G22="Pagar"),_xlfn.SINGLE(NETWORKDAYS($J$17,F22,FestivosPerú!$A$2:$A$15)),0) -> 0 | I22: =NETWORKDAYS($J$17,F22,FestivosPerú!$A$2:$A$15) -> 5 | J22: =H22 -> 0
C23: IMPUESTOS | D23: =SUBTOTAL(9,D24:D25) -> 13769 | E23: =SUBTOTAL(9,E24:E25) -> 3762.0219 | J23: =H23 -> 0
C24: PLAME Essalud y Renta de Quinta Categoría (Retención) | D24: 12653 | E24: =D24/$D$6 -> 3457.1038 | F24: 45790 | G24: Cancelado | H24: =IF(OR(G24="Sin pagar",G24="Pagar"),_xlfn.SINGLE(NETWORKDAYS($J$17,F24,FestivosPerú!$A$2:$A$15)),0) -> 0 | I24: =NETWORKDAYS($J$17,F24,FestivosPerú!$A$2:$A$15) -> 8 | J24: =H24 -> 0
C25: Pago de renta IGV Abril | D25: 1116 | E25: =D25/$D$6 -> 304.91803 | F25: 45793 | G25: Cancelado | H25: =IF(OR(G25="Sin pagar",G25="Pagar"),_xlfn.SINGLE(NETWORKDAYS($J$17,F25,FestivosPerú!$A$2:$A$15)),0) -> 0 | I25: =NETWORKDAYS($J$17,F25,FestivosPerú!$A$2:$A$15) -> 11 | J25: =H25 -> 0 | M25: Outsorcing contable
C26: SERVICIOS OUTSORCING CONTABLE | D26: =SUBTOTAL(9,D27:D31) -> 3617.054 | E26: =SUBTOTAL(9,E27:E31) -> 988.26612 | J26: =H26 -> 0
B27: 5984 | C27: Estudio fuentes servicios mayo | D27: =E27*$D$6 -> 1317.234 | E27: 359.9 | F27: 45806 | G27: Cancelado | H27: =IF(OR(G27="Sin pagar",G27="Pagar"),_xlfn.SINGLE(NETWORKDAYS($J$17,F27,FestivosPerú!$A$2:$A$15)),0) -> 0 | I27: =NETWORKDAYS($J$17,F27,FestivosPerú!$A$2:$A$15) -> 20 | J27: =H27 -> 0
B28: 6035 | C28: Estudio fuentes servicios mayo | D28: =E28*$D$6 -> 647.82 | E28: 177 | F28: 45806 | G28: Cancelado | H28: =IF(OR(G28="Sin pagar",G28="Pagar"),_xlfn.SINGLE(NETWORKDAYS($J$17,F28,FestivosPerú!$A$2:$A$15)),0) -> 0 | I28: =NETWORKDAYS($J$17,F28,FestivosPerú!$A$2:$A$15) -> 20 | J28: =H28 -> 0
B29: 5984 | C29: Estudio fuentes servicio cambio gerente general | D29: =(E29*$D$6)*0 -> 0 | E29: =472*0 -> 0 | F29: 45814 | G29: Sin Pagar | H29: =IF(OR(G29="Sin pagar",G29="Pagar"),_xlfn.SINGLE(NETWORKDAYS($J$17,F29,FestivosPerú!$A$2:$A$15)),0) -> 26 | I29: =NETWORKDAYS($J$17,F29,FestivosPerú!$A$2:$A$15) -> 26 | J29: =H29 -> 26
B30: E001-584 | C30: Outsourcing contable servicio abril Avanza | D30: =700*1.18 -> 826 | E30: =$D$30/$D$6 -> 225.68306 | F30: 45806 | G30: Cancelado | H30: =IF(OR(G30="Sin pagar",G30="Pagar"),_xlfn.SINGLE(NETWORKDAYS($J$17,F30,FestivosPerú!$A$2:$A$15)),0) -> 0 | I30: =NETWORKDAYS($J$17,F30,FestivosPerú!$A$2:$A$15) -> 20 | J30: =H30 -> 0
B31: E001-602 | C31: Outsourcing contable servicio abril Avanza | D31: =700*1.18 -> 826 | E31: =$D$30/$D$6 -> 225.68306 | F31: 45811 | G31: Cancelado | H31: =IF(OR(G31="Sin pagar",G31="Pagar"),_xlfn.SINGLE(NETWORKDAYS($J$17,F31,FestivosPerú!$A$2:$A$15)),0) -> 0 | I31: =NETWORKDAYS($J$17,F31,FestivosPerú!$A$2:$A$15) -> 23 | J31: =H31 -> 0
C32: PÓLIZAS DE VIDA Y SEGUROS MÉDICO | D32: =SUBTOTAL(9,D33:D41) -> 3244.52 | E32: =SUBTOTAL(9,E33:E41) -> 886.48087
B33: F052-01723822 | C33: Seguros de vida recibo 160793407 | D33: 118 | E33: =D33/$D$6 -> 32.240437 | F33: 45786 | G33: Cancelado | H33: =IF(OR(G33="Sin pagar",G33="Pagar"),_xlfn.SINGLE(NETWORKDAYS($J$17,F33,FestivosPerú!$A$2:$A$15)),0) -> 0 | I33: =NETWORKDAYS($J$17,F33,FestivosPerú!$A$2:$A$15) -> 6 | J33: =H33 -> 0
B34: F052-01723823 | C34: SCTR Pensiones recibo 160793127 | D34: 354.04 | E34: =D34/$D$6 -> 96.73224 | F34: 45786 | G34: Cancelado | H34: =IF(OR(G34="Sin pagar",G34="Pagar"),_xlfn.SINGLE(NETWORKDAYS($J$17,F34,FestivosPerú!$A$2:$A$15)),0) -> 0 | I34: =NETWORKDAYS($J$17,F34,FestivosPerú!$A$2:$A$15) -> 6 | J34: =H34 -> 0
B35: F052-01534951 | C35: SCTR Salud recibo 160793128 | D35: 343.73 | E35: =D35/$D$6 -> 93.915301 | F35: 45786 | G35: Cancelado | H35: =IF(OR(G35="Sin pagar",G35="Pagar"),_xlfn.SINGLE(NETWORKDAYS($J$17,F35,FestivosPerú!$A$2:$A$15)),0) -> 0 | I35: =NETWORKDAYS($J$17,F35,FestivosPerú!$A$2:$A$15) -> 6 | J35: =H35 -> 0
C36: Póliza de salud Davis Oporto-Primera cuota | D36: 1613 | E36: =D36/D6 -> 440.71038 | F36: 45806 | G36: Cancelado | H36: =IF(OR(G36="Sin pagar",G36="Pagar"),_xlfn.SINGLE(NETWORKDAYS($J$17,F36,FestivosPerú!$A$2:$A$15)),0) -> 0 | I36: =NETWORKDAYS($J$17,F36,FestivosPerú!$A$2:$A$15) -> 20 | J36: =H36 -> 0
C37: Póliza de salud Braidy Vera- Cuota 6 meses fraccionada | D37: =1253.2*0 -> 0 | E37: =$D$37/$D$6 -> 0 | F37: 45808 | G37: Cancelado | H37: =IF(OR(G37="Sin pagar",G37="Pagar"),_xlfn.SINGLE(NETWORKDAYS($J$17,F37,FestivosPerú!$A$2:$A$15)),0) -> 0 | I37: =NETWORKDAYS($J$17,F37,FestivosPerú!$A$2:$A$15) -> 21 | J37: =H37 -> 0
B38: S/N | C38: Seguros de vida Ley recibo 161448077 | D38: =118 -> 118 | E38: =D38/$D$6 -> 32.240437 | F38: 45811 | G38: Cancelado | H38: =IF(OR(G38="Sin pagar",G38="Pagar"),_xlfn.SINGLE(NETWORKDAYS($J$17,F38,FestivosPerú!$A$2:$A$15)),0) -> 0 | I38: =NETWORKDAYS($J$17,F38,FestivosPerú!$A$2:$A$15) -> 23 | J38: =H38 -> 0
B39: S/N | C39: SCTR Pensiones recibo 161447562 | D39: =354.03 -> 354.03 | E39: =D39/$D$6 -> 96.729508 | F39: 45811 | G39: Cancelado | H39: =IF(OR(G39="Sin pagar",G39="Pagar"),_xlfn.SINGLE(NETWORKDAYS($J$17,F39,FestivosPerú!$A$2:$A$15)),0) -> 0 | I39: =NETWORKDAYS($J$17,F39,FestivosPerú!$A$2:$A$15) -> 23 | J39: =H39 -> 0
B40: S/N | C40: SCTR Salud recibo 161447573 | D40: =343.72 -> 343.72 | E40: =D40/$D$6 -> 93.912568 | F40: 45811 | G40: Cancelado | H40: =IF(OR(G40="Sin pagar",G40="Pagar"),_xlfn.SINGLE(NETWORKDAYS($J$17,F40,FestivosPerú!$A$2:$A$15)),0) -> 0 | I40: =NETWORKDAYS($J$17,F40,FestivosPerú!$A$2:$A$15) -> 23 | J40: =H40 -> 0
B41: S/N | C41: Póliza de salud Braidy Vera-Mes de abril y mayo | D41: =2508*0 -> 0 | E41: =$D$41/$D$6 -> 0 | F41: 45811 | G41: Sin Pagar | H41: =IF(OR(G41="Sin pagar",G41="Pagar"),_xlfn.SINGLE(NETWORKDAYS($J$17,F41,FestivosPerú!$A$2:$A$15)),0) -> 23 | I41: =NETWORKDAYS($J$17,F41,FestivosPerú!$A$2:$A$15) -> 23 | J41: =H41 -> 23
C42: COSTOS FINANCIEROS | D42: =SUBTOTAL(9,D43:D43) -> 3740.87 | E42: =SUBTOTAL(9,E43:E43) -> 1022.0956
C43: COSTOS FINANCIEROS | D43: =('BCP SOLES BCP'!$F$173+'BCP SOLES BCP'!$F$179+'BCP SOLES BCP'!$F$181+'BCP SOLES BCP'!$F$185+'BCP SOLES BCP'!$F$188+'BCP SOLES BCP'!$F$190+'BCP SOLES BCP'!$F$192+'BCP SOLES BCP'!$F$194+'BCP SOLES BCP'!$F$199+'BCP SOLES BCP'!$F$200+'BCP SOLES BCP'!$F$201)+(('BCP USD BCP'!F99+'BCP USD BCP'!F101+'BCP USD BCP'!F102+'BCP USD BCP'!F106+'BCP USD BCP'!F107*$D$6))+3517.81 -> 3740.87 | E43: =$D$43/$D$6 -> 1022.0956 | F43: 45808 | G43: Cancelado | H43: =IF(OR(G43="Sin pagar",G43="Pagar"),_xlfn.SINGLE(NETWORKDAYS($J$17,F43,FestivosPerú!$A$2:$A$15)),0) -> 0 | I43: =NETWORKDAYS($J$17,F43,FestivosPerú!$A$2:$A$15) -> 21 | J43: =H43 -> 0
C44: NÓMINAS | D44: =SUBTOTAL(9,D45:D47) -> 35146.754 | E44: =SUBTOTAL(9,E45:E47) -> 9602.9382
C45: Braydi Yusset Vera Neira-Europortage | D45: 13447.124 | E45: =D45/$D$6 -> 3674.0775 | F45: 45805 | G45: Cancelado | H45: =IF(OR(G45="Sin pagar",G45="Pagar"),_xlfn.SINGLE(NETWORKDAYS($J$17,F45,FestivosPerú!$A$2:$A$15)),0) -> 0 | I45: =NETWORKDAYS($J$17,F45,FestivosPerú!$A$2:$A$15) -> 19 | J45: =H45 -> 0
...

Sheet FLUJO CAJA JUNIO
D1: 42400
D4: Fecha de Elaboración: | E4: 45809
C6: Tasa de cambio: | D6: 3.62
D7: JUNIO
D8: VALOR S/ Sol | E8: VALOR USD
C9: BANCOS | D9: =SUBTOTAL(9,D10:D11) -> 37709.259 | E9: =SUBTOTAL(9,E10:E11) -> 10416.922
C10: Bancos S/ Soles | D10: ='BCP SOLES BCP'!$G$207-3014.44+508.02+505.02 -> 32467.137 | E10: =D10/$D$6 -> 8968.8224
C11: Bancos USD | D11: =E11*$D$6 -> 5242.122 | E11: ='BCP USD BCP'!$G$108 -> 1448.1
C12: CLIENTES | D12: =SUBTOTAL(9,D13:D13) -> 99548.157 | E12: =SUBTOTAL(9,E13:E13) -> 28304.85
B13: Pagado | C13: Client: Europortage-Factura Nro EB01-20 | D13: =$E$13*'Diferencia Cambio S&P'!$K$22 -> 99548.157 | E13: ='Diferencia Cambio S&P'!$J$22 -> 28304.85
C14: TOTAL INGRESOS | D14: =SUBTOTAL(9,D9:D13) -> 137257.42 | E14: =SUBTOTAL(9,E9:E13) -> 38721.772
B17: CUENTAS X PAGAR MES | D17: ABRIL | F17: Fecha de Elaboración: | J17: 45809
B18: Factura | C18: PROVEEDOR | D18: VALOR S/Sol | E18: VALOR USD | F18: Fecha vencimiento | G18: Estado | J18: KPI
C19: SEGURIDAD IGSS | D19: =SUBTOTAL(9,D20:D21) -> 5688.08 | E19: =SUBTOTAL(9,E20:E21) -> 1571.2928
C20: Planilla de declaración y pago de aportes previsional-Braydi Yusset Vera Neyra y Davis Cesar Oporto Figueroa | D20: =3274.57+623.23 -> 3897.8 | E20: =D20/$D$6 -> 1076.7403 | F20: 45817 | G20: Cancelado | H20: =IF(OR(G20="Sin pagar",G20="Pagar"),_xlfn.SINGLE(NETWORKDAYS($J$17,F20,FestivosPerú!$A$2:$A$15)),0) -> 0 | I20: =NETWORKDAYS($J$17,F20,FestivosPerú!$A$2:$A$15) -> 6 | J20: =H20 -> 0
C21: Planilla de declaración y pago de aportes previsional Christian Portugal Segovia | D21: 1790.28 | E21: =D21/$D$6 -> 494.55249 | F21: 45817 | G21: Cancelado | H21: =IF(OR(G21="Sin pagar",G21="Pagar"),_xlfn.SINGLE(NETWORKDAYS($J$17,F21,FestivosPerú!$A$2:$A$15)),0) -> 0 | I21: =NETWORKDAYS($J$17,F21,FestivosPerú!$A$2:$A$15) -> 6 | J21: =H21 -> 0
C22: IMPUESTOS | D22: =SUBTOTAL(9,D23:D24) -> 11084 | E22: =SUBTOTAL(9,E23:E24) -> 3061.8785 | J22: =H22 -> 0
C23: Plame Essalud y Renta de Quinta Categoría (Retención) | D23: 9857 | E23: =D23/$D$6 -> 2722.9282 | F23: 45820 | G23: Cancelado | H23: =IF(OR(G23="Sin pagar",G23="Pagar"),_xlfn.SINGLE(NETWORKDAYS($J$17,F23,FestivosPerú!$A$2:$A$15)),0) -> 0 | I23: =NETWORKDAYS($J$17,F23,FestivosPerú!$A$2:$A$15) -> 9 | J23: =H23 -> 0
C24: Pago de renta IGV Mayo | D24: 1227 | E24: =D24/$D$6 -> 338.95028 | F24: 45824 | G24: Cancelado | H24: =IF(OR(G24="Sin pagar",G24="Pagar"),_xlfn.SINGLE(NETWORKDAYS($J$17,F24,FestivosPerú!$A$2:$A$15)),0) -> 0 | I24: =NETWORKDAYS($J$17,F24,FestivosPerú!$A$2:$A$15) -> 11 | J24: =H24 -> 0 | M24: Outsorcing contable
C25: SERVICIOS OUTSORCING CONTABLE | D25: =SUBTOTAL(9,D26:D28) -> 3786.738 | E25: =SUBTOTAL(9,E26:E28) -> 1046.0602 | J25: =H25 -> 0
B26: F001 - 00006024 | C26: Estudio fuentes servicio cambio gerente general | D26: =(E26*$D$6) -> 1708.64 | E26: =472 -> 472 | F26: 45817 | G26: Cancelado | H26: =IF(OR(G26="Sin pagar",G26="Pagar"),_xlfn.SINGLE(NETWORKDAYS($J$17,F26,FestivosPerú!$A$2:$A$15)),0) -> 0 | I26: =NETWORKDAYS($J$17,F26,FestivosPerú!$A$2:$A$15) -> 6 | J26: =H26 -> 0
B27: F001 - 00006148 | C27: Servicio de apersonamiento CTS BBVA y Servicio dirección fiscal junio 2025 | D27: =E27*D6 -> 662.098 | E27: 182.9 | F27: 45834 | G27: Cancelado | H27: =IF(OR(G27="Sin pagar",G27="Pagar"),_xlfn.SINGLE(NETWORKDAYS($J$17,F27,FestivosPerú!$A$2:$A$15)),0) -> 0 | I27: =NETWORKDAYS($J$17,F27,FestivosPerú!$A$2:$A$15) -> 19 | J27: =H27 -> 0
B28: E001-584 | C28: Outsourcing contable servicio Junio Avanza | D28: 1416 | E28: =$D$28/$D$6 -> 391.16022 | F28: 45834 | G28: Cancelado | H28: =IF(OR(G28="Sin pagar",G28="Pagar"),_xlfn.SINGLE(NETWORKDAYS($J$17,F28,FestivosPerú!$A$2:$A$15)),0) -> 0 | I28: =NETWORKDAYS($J$17,F28,FestivosPerú!$A$2:$A$15) -> 19 | J28: =H28 -> 0
C29: PÓLIZAS DE VIDA Y SEGUROS MÉDICO | D29: =SUBTOTAL(9,D30:D34) -> 8339.75 | E29: =SUBTOTAL(9,E30:E34) -> 2996.616
B30: F052-01751987 | C30: Seguros de vida Ley recibo 161448077 | D30: =118 -> 118 | E30: =D30/$D$6 -> 32.596685 | F30: 45810 | G30: Cancelado | H30: =IF(OR(G30="Sin pagar",G30="Pagar"),_xlfn.SINGLE(NETWORKDAYS($J$17,F30,FestivosPerú!$A$2:$A$15)),0) -> 0 | I30: =NETWORKDAYS($J$17,F30,FestivosPerú!$A$2:$A$15) -> 1 | J30: =H30 -> 0
B31: F052-01751988 | C31: SCTR Pensiones recibo 161447562 | D31: =354.03 -> 354.03 | E31: =D31/$D$6 -> 97.798343 | F31: 45810 | G31: Cancelado | H31: =IF(OR(G31="Sin pagar",G31="Pagar"),_xlfn.SINGLE(NETWORKDAYS($J$17,F31,FestivosPerú!$A$2:$A$15)),0) -> 0 | I31: =NETWORKDAYS($J$17,F31,FestivosPerú!$A$2:$A$15) -> 1 | J31: =H31 -> 0
B32: F052-01558203 | C32: SCTR Salud recibo 161447573 | D32: =343.72 -> 343.72 | E32: =D32/$D$6 -> 94.950276 | F32: 45810 | G32: Cancelado | H32: =IF(OR(G32="Sin pagar",G32="Pagar"),_xlfn.SINGLE(NETWORKDAYS($J$17,F32,FestivosPerú!$A$2:$A$15)),0) -> 0 | I32: =NETWORKDAYS($J$17,F32,FestivosPerú!$A$2:$A$15) -> 1 | J32: =H32 -> 0
B33: S/N | C33: Póliza de salud Braidy Vera-Mes de abril y mayo | D33: =2508*2 -> 5016 | E33: =$D$33/$D$6 -> 1385.6354 | F33: 45813 | G33: Cancelado | H33: =IF(OR(G33="Sin pagar",G33="Pagar"),_xlfn.SINGLE(NETWORKDAYS($J$17,F33,FestivosPerú!$A$2:$A$15)),0) -> 0 | I33: =NETWORKDAYS($J$17,F33,FestivosPerú!$A$2:$A$15) -> 4 | J33: =H33 -> 0
B34: S/N | C34: Póliza de salud Braidy Vera-Mes de Junio-Doble débito | D34: 2508 | E34: =$D$33/$D$6 -> 1385.6354 | F34: 45821 | G34: Cancelado | H34: =IF(OR(G34="Sin pagar",G34="Pagar"),_xlfn.SINGLE(NETWORKDAYS($J$17,F34,FestivosPerú!$A$2:$A$15)),0) -> 0 | I34: =NETWORKDAYS($J$17,F34,FestivosPerú!$A$2:$A$15) -> 10 | J34: =H34 -> 0
C35: COSTOS FINANCIEROS | D35: =SUBTOTAL(9,D36:D36) -> 292.5242 | E35: =SUBTOTAL(9,E36:E36) -> 80.807789
C36: COSTOS FINANCIEROS | D36: =('BCP SOLES BCP'!$F$209+'BCP SOLES BCP'!$F$211+'BCP SOLES BCP'!$F$213+'BCP SOLES BCP'!$F$216+'BCP SOLES BCP'!$F$218+'BCP SOLES BCP'!$F$221+'BCP SOLES BCP'!$F$223+'BCP SOLES BCP'!$F$224+'BCP SOLES BCP'!$F$232+'BCP SOLES BCP'!$F$234+'BCP SOLES BCP'!$F$236+'BCP SOLES BCP'!$F$238+'BCP SOLES BCP'!$F$240+'BCP SOLES BCP'!$F$242+'BCP SOLES BCP'!$F$243+'BCP SOLES BCP'!$F$244+'BCP SOLES BCP'!$F$245)+('BCP USD BCP'!F114+'BCP USD BCP'!F118+'BCP USD BCP'!F119+'BCP USD BCP'!F120*$D$6) -> 292.5242 | E36: =$D$36/$D$6 -> 80.807789 | F36: 45838 | G36: Cancelado | H36: =IF(OR(G36="Sin pagar",G36="Pagar"),_xlfn.SINGLE(NETWORKDAYS($J$17,F36,FestivosPerú!$A$2:$A$15)),0) -> 0 | I36: =NETWORKDAYS($J$17,F36,FestivosPerú!$A$2:$A$15) -> 21 | J36: =H36 -> 0
C37: NÓMINAS | D37: =SUBTOTAL(9,D38:D40) -> 34849.09 | E37: =SUBTOTAL(9,E38:E40) -> 9626.8205
C38: Braydi Yusset Vera Neira-Europortage | D38: 13319.616 | E38: =D38/$D$6 -> 3679.452 | F38: 45834 | G38: Cancelado | H38: =IF(OR(G38="Sin pagar",G38="Pagar"),_xlfn.SINGLE(NETWORKDAYS($J$17,F38,FestivosPerú!$A$2:$A$15)),0) -> 0 | I38: =NETWORKDAYS($J$17,F38,FestivosPerú!$A$2:$A$15) -> 19 | J38: =H38 -> 0
C39: Cristhian Portugal Segovia -Europortage | D39: 10717.393 | E39: =D39/$D$6 -> 2960.6058 | F39: 45834 | G39: Cancelado | H39: =IF(OR(G39="Sin pagar",G39="Pagar"),_xlfn.SINGLE(NETWORKDAYS($J$17,F39,FestivosPerú!$A$2:$A$15)),0) -> 0 | I39: =NETWORKDAYS($J$17,F39,FestivosPerú!$A$2:$A$15) -> 19 | J39: =H39 -> 0
C40: Davis Cesar oporto figueroa -Europortage | D40: 10812.081 | E40: =D40/$D$6 -> 2986.7628 | F40: 45834 | G40: Cancelado | H40: =IF(OR(G40="Sin pagar",G40="Pagar"),_xlfn.SINGLE(NETWORKDAYS($J$17,F40,FestivosPerú!$A$2:$A$15)),0) -> 0 | I40: =NETWORKDAYS($J$17,F40,FestivosPerú!$A$2:$A$15) -> 19 | J40: =H40 -> 0
C41: REEMBOLSO | D41: =SUBTOTAL(9,D42:D44) -> 32819.93 | E41: =SUBTOTAL(9,E42:E44) -> 9066.279
C42: Reembolso Braydi Yusset Vera Neira-Europortage | D42: 14539.09 | E42: =D42/$D$6 -> 4016.3232 | F42: 45834 | G42: Cancelado | H42: =IF(OR(G42="Sin pagar",G42="Pagar"),_xlfn.SINGLE(NETWORKDAYS($J$17,F42,FestivosPerú!$A$2:$A$15)),0) -> 0 | I42: =NETWORKDAYS($J$17,F42,FestivosPerú!$A$2:$A$15) -> 19 | J42: =H42 -> 0
C43: Reembolso Cristhian Portugal Segovia -Europortage | D43: 9067.27 | E43: =D43/$D$6 -> 2504.7707 | F43: 45835 | G43: Cancelado | H43: =IF(OR(G43="Sin pagar",G43="Pagar"),_xlfn.SINGLE(NETWORKDAYS($J$17,F43,FestivosPerú!$A$2:$A$15)),0) -> 0 | I43: =NETWORKDAYS($J$17,F43,FestivosPerú!$A$2:$A$15) -> 20 | J43: =H43 -> 0
C44: Reembolso Davis Cesar oporto figueroa -Europortage | D44: 9213.57 | E44: =D44/$D$6 -> 2545.1851 | F44: 45835 | G44: Cancelado | H44: =IF(OR(G44="Sin pagar",G44="Pagar"),_xlfn.SINGLE(NETWORKDAYS($J$17,F44,FestivosPerú!$A$2:$A$15)),0) -> 0 | I44: =NETWORKDAYS($J$17,F44,FestivosPerú!$A$2:$A$15) -> 20 | J44: =H44 -> 0
C45: IMPREVISTO | D45: =SUBTOTAL(9,D46:D48) -> 3592.26 | E45: =SUBTOTAL(9,E46:E48) -> 987.73481
...

Sheet FLUJO CAJA JULIO
D1: 42400
D4: Fecha de Elaboración: | E4: 45839
C6: Tasa de cambio: | D6: 3.5552
D7: JULIO
D8: VALOR S/ Sol | E8: VALOR USD
C9: BANCOS | D9: =SUBTOTAL(9,D10:D12) -> 40586.61 | E9: =SUBTOTAL(9,E10:E12) -> 11416.126
C10: Bancos S/ Soles | D10: ='BCP SOLES BCP'!$G$246-9955.17 -> 19668.951 | E10: =D10/$D$6 -> 5532.4457
C11: Bancos USD | D11: =E11*$D$6 -> 7052.3791 | E11: ='BCP USD BCP'!$G$121 -> 1983.68
C12: Préstamo S&P Colombia | D12: =E12*$D$6 -> 13865.28 | E12: 3900
C13: CLIENTES | D13: =SUBTOTAL(9,D14:D18) -> 140880.48 | E13: =SUBTOTAL(9,E14:E18) -> 40139.5
B14: Pagado | C14: Client: Europortage-Factura Nro EB01-21 | D14: =$E$14*'Diferencia Cambio S&P'!$K$23 -> 92937.955 | E14: ='BCP USD BCP'!E134 -> 26478.05
B15: Pagado | C15: Client: Yonyou xinfushe cloud technology co., limited-Factura Nro EB01-22 | D15: =$E$15*'Diferencia Cambio S&P'!$K$24 -> 18854.246 | E15: ='BCP USD BCP'!E132 -> 5371.58
B16: Pagado | C16: Client: Remotepass-Factura Nro EB01-23 | D16: =$E$16*'Diferencia Cambio S&P'!$K$25 -> 23734.55 | E16: ='BCP USD BCP'!E133 -> 6761.98
B17: Pagado | C17: Client: Safeguard-Factura Nro EB01-01 ( Cliente) | D17: =E17*3.504 -> 5353.7266 | E17: ='BCP USD BCP'!E129 -> 1527.89
B18: Sin Pagar | C18: Client: Safeguard-Factura Nro EB01-02 ( Cliente) | D18: =E18*3.44 -> 0 | E18: =1282.87*0 -> 0
C19: TOTAL INGRESOS | D19: =SUBTOTAL(9,D9:D18) -> 181467.09 | E19: =SUBTOTAL(9,E9:E18) -> 51555.626
B22: CUENTAS X PAGAR MES | D22: ABRIL | F22: Fecha de Elaboración: | J22: 45809
B23: Factura | C23: PROVEEDOR | D23: VALOR S/Sol | E23: VALOR USD | F23: Fecha vencimiento | G23: Estado | J23: KPI
C24: SEGURIDAD IGSS | D24: =SUBTOTAL(9,D25:D26) -> 5517.91 | E24: =SUBTOTAL(9,E25:E26) -> 1552.0674
B25: 2220819158 | C25: Planilla de declaración y pago de aportes previsional-Braydi Yusset Vera Neyra y Davis Cesar Oporto Figueroa | D25: 3727.63 | E25: =D25/$D$6 -> 1048.5008 | F25: 45842 | G25: Cancelado | H25: =IF(OR(G25="Sin pagar",G25="Pagar"),_xlfn.SINGLE(NETWORKDAYS($J$22,F25,FestivosPerú!$A$2:$A$15)),0) -> 0 | I25: =NETWORKDAYS($J$22,F25,FestivosPerú!$A$2:$A$15) -> 25 | J25: =H25 -> 0
B26: 2516822828 | C26: Planilla de declaración y pago de aportes previsional Christian Portugal Segovia | D26: 1790.28 | E26: =D26/$D$6 -> 503.56661 | F26: 45842 | G26: Cancelado | H26: =IF(OR(G26="Sin pagar",G26="Pagar"),_xlfn.SINGLE(NETWORKDAYS($J$22,F26,FestivosPerú!$A$2:$A$15)),0) -> 0 | I26: =NETWORKDAYS($J$22,F26,FestivosPerú!$A$2:$A$15) -> 25 | J26: =H26 -> 0
C27: IMPUESTOS | D27: =SUBTOTAL(9,D28:D29) -> 11486.35 | E27: =SUBTOTAL(9,E28:E29) -> 3230.859 | J27: =H27 -> 0
C28: Plame Essalud y Renta de Quinta Categoría (Retención) | D28: 9946 | E28: =D28/$D$6 -> 2797.5923 | F28: 45847 | G28: Cancelado | H28: =IF(OR(G28="Sin pagar",G28="Pagar"),_xlfn.SINGLE(NETWORKDAYS($J$22,F28,FestivosPerú!$A$2:$A$15)),0) -> 0 | I28: =NETWORKDAYS($J$22,F28,FestivosPerú!$A$2:$A$15) -> 28 | J28: =H28 -> 0
C29: Pago de renta IGV Junio | D29: 1540.35 | E29: =D29/$D$6 -> 433.26676 | F29: 45854 | G29: Cancelado | H29: =IF(OR(G29="Sin pagar",G29="Pagar"),_xlfn.SINGLE(NETWORKDAYS($J$22,F29,FestivosPerú!$A$2:$A$15)),0) -> 0 | I29: =NETWORKDAYS($J$22,F29,FestivosPerú!$A$2:$A$15) -> 33 | J29: =H29 -> 0 | M29: Outsorcing contable
C30: SERVICIOS OUTSORCING CONTABLE | D30: =SUBTOTAL(9,D31:D34) -> 3422 | E30: =SUBTOTAL(9,E31:E34) -> 647.22097 | J30: =H30 -> 0
B31: E001-637 | C31: Outsourcing contable servicio Julio a S&P- Avanza | D31: 1416 | E31: =$D$31/$D$6 -> 398.28983 | F31: 45867 | G31: Cancelado | H31: =IF(OR(G31="Sin pagar",G31="Pagar"),_xlfn.SINGLE(NETWORKDAYS($J$22,F31,FestivosPerú!$A$2:$A$15)),0) -> 0 | I31: =NETWORKDAYS($J$22,F31,FestivosPerú!$A$2:$A$15) -> 40 | J31: =H31 -> 0
B32: E001-641 | C32: Outsourcing contable servicio mayo a SG- Avanza | D32: 295 | E32: =$D$32/$D$6 -> 82.977048 | F32: 45867 | G32: Cancelado | H32: =IF(OR(G32="Sin pagar",G32="Pagar"),_xlfn.SINGLE(NETWORKDAYS($J$22,F32,FestivosPerú!$A$2:$A$15)),0) -> 0 | I32: =NETWORKDAYS($J$22,F32,FestivosPerú!$A$2:$A$15) -> 40 | J32: =H32 -> 0
B33: E001-642 | C33: Outsourcing contable servicio junio a SG- Avanza | D33: 295 | E33: =$D$32/$D$6 -> 82.977048 | F33: 45867 | G33: Cancelado | H33: =IF(OR(G33="Sin pagar",G33="Pagar"),_xlfn.SINGLE(NETWORKDAYS($J$22,F33,FestivosPerú!$A$2:$A$15)),0) -> 0 | I33: =NETWORKDAYS($J$22,F33,FestivosPerú!$A$2:$A$15) -> 40 | J33: =H33 -> 0
B34: E001-643 | C34: Outsourcing contable servicio julio a SG- Avanza | D34: 1416 | E34: =$D$32/$D$6 -> 82.977048 | F34: 45867 | G34: Cancelado | H34: =IF(OR(G34="Sin pagar",G34="Pagar"),_xlfn.SINGLE(NETWORKDAYS($J$22,F34,FestivosPerú!$A$2:$A$15)),0) -> 0 | I34: =NETWORKDAYS($J$22,F34,FestivosPerú!$A$2:$A$15) -> 40 | J34: =H34 -> 0
C35: PÓLIZAS DE VIDA Y SEGUROS MÉDICO | D35: =SUBTOTAL(9,D36:D45) -> 5216.7 | E35: =SUBTOTAL(9,E36:E45) -> 1467.3436
B36: F052-01751987 | C36: Seguros de vida Rimac -Davis oporto | D36: 1613 | E36: =D36/$D$6 -> 453.70162 | F36: 45840 | G36: Cancelado | H36: =IF(OR(G36="Sin pagar",G36="Pagar"),_xlfn.SINGLE(NETWORKDAYS($J$22,F36,FestivosPerú!$A$2:$A$15)),0) -> 0 | I36: =NETWORKDAYS($J$22,F36,FestivosPerú!$A$2:$A$15) -> 23 | J36: =H36 -> 0
B37: F052-01791304 | C37: Seguros de vida Ley recibo 162427159 | D37: =118 -> 118 | E37: =D37/$D$6 -> 33.190819 | F37: 45842 | G37: Cancelado | H37: =IF(OR(G37="Sin pagar",G37="Pagar"),_xlfn.SINGLE(NETWORKDAYS($J$22,F37,FestivosPerú!$A$2:$A$15)),0) -> 0 | I37: =NETWORKDAYS($J$22,F37,FestivosPerú!$A$2:$A$15) -> 25 | J37: =H37 -> 0
B38: F052-01791305 | C38: SCTR Pensiones recibo 162413259 | D38: =354.03 -> 354.03 | E38: =D38/$D$6 -> 99.580896 | F38: 45842 | G38: Cancelado | H38: =IF(OR(G38="Sin pagar",G38="Pagar"),_xlfn.SINGLE(NETWORKDAYS($J$22,F38,FestivosPerú!$A$2:$A$15)),0) -> 0 | I38: =NETWORKDAYS($J$22,F38,FestivosPerú!$A$2:$A$15) -> 25 | J38: =H38 -> 0
B39: F052-01590916 | C39: SCTR Salud recibo 162413267 | D39: =343.72 -> 343.72 | E39: =D39/$D$6 -> 96.680918 | F39: 45842 | G39: Cancelado | H39: =IF(OR(G39="Sin pagar",G39="Pagar"),_xlfn.SINGLE(NETWORKDAYS($J$22,F39,FestivosPerú!$A$2:$A$15)),0) -> 0 | I39: =NETWORKDAYS($J$22,F39,FestivosPerú!$A$2:$A$15) -> 25 | J39: =H39 -> 0
B40: F052-01791306 | C40: SCTR Salud recibo 162427441- Ingreso Yon you | D40: 179.6 | E40: =D40/$D$6 -> 50.517552 | F40: 45842 | G40: Cancelado | H40: =IF(OR(G40="Sin pagar",G40="Pagar"),_xlfn.SINGLE(NETWORKDAYS($J$22,F40,FestivosPerú!$A$2:$A$15)),0) -> 0 | I40: =NETWORKDAYS($J$22,F40,FestivosPerú!$A$2:$A$15) -> 25 | J40: =H40 -> 0
B41: S/N | C41: Seguros de vida Rimac -Davis oporto | D41: 1613 | E41: =D41/$D$6 -> 453.70162 | F41: 45871 | G41: Cancelado | H41: =IF(OR(G41="Sin pagar",G41="Pagar"),_xlfn.SINGLE(NETWORKDAYS($J$22,F41,FestivosPerú!$A$2:$A$15)),0) -> 0 | I41: =NETWORKDAYS($J$22,F41,FestivosPerú!$A$2:$A$15) -> 43 | J41: =H41 -> 0
B42: S/N | C42: SCTR Pensiones recibo 162413259 | D42: =354.03 -> 354.03 | E42: =D42/$D$6 -> 99.580896 | F42: 45873 | G42: Cancelado | H42: =IF(OR(G42="Sin pagar",G42="Pagar"),_xlfn.SINGLE(NETWORKDAYS($J$22,F42,FestivosPerú!$A$2:$A$15)),0) -> 0 | I42: =NETWORKDAYS($J$22,F42,FestivosPerú!$A$2:$A$15) -> 44 | J42: =H42 -> 0
B43: S/N | C43: SCTR Salud recibo 162413267 | D43: =343.72 -> 343.72 | E43: =D43/$D$6 -> 96.680918 | F43: 45873 | G43: Cancelado | H43: =IF(OR(G43="Sin pagar",G43="Pagar"),_xlfn.SINGLE(NETWORKDAYS($J$22,F43,FestivosPerú!$A$2:$A$15)),0) -> 0 | I43: =NETWORKDAYS($J$22,F43,FestivosPerú!$A$2:$A$15) -> 44 | J43: =H43 -> 0
B44: S/N | C44: Seguros de vida Ley recibo 162427159 | D44: =118 -> 118 | E44: =D44/$D$6 -> 33.190819 | F44: 45873 | G44: Cancelado | H44: =IF(OR(G44="Sin pagar",G44="Pagar"),_xlfn.SINGLE(NETWORKDAYS($J$22,F44,FestivosPerú!$A$2:$A$15)),0) -> 0 | I44: =NETWORKDAYS($J$22,F44,FestivosPerú!$A$2:$A$15) -> 44 | J44: =H44 -> 0
B45: S/N | C45: SCTR Salud recibo 162427441- Ingreso Yon you | D45: 179.6 | E45: =D45/$D$6 -> 50.517552 | F45: 45873 | G45: Cancelado | H45: =IF(OR(G45="Sin pagar",G45="Pagar"),_xlfn.SINGLE(NETWORKDAYS($J$22,F45,FestivosPerú!$A$2:$A$15)),0) -> 0 | I45: =NETWORKDAYS($J$22,F45,FestivosPerú!$A$2:$A$15) -> 44 | J45: =H45 -> 0
...

Sheet FLUJO CAJA AGOSTO
D1: 42400
D4: Fecha de Elaboración: | E4: 45870
C6: Tasa de cambio: | D6: 3.52
D7: AGOSTO
D8: VALOR S/ Sol | E8: VALOR USD
C9: BANCOS | D9: =SUBTOTAL(9,D10:D12) -> 50375.276 | E9: =SUBTOTAL(9,E10:E12) -> 14311.158
C10: Bancos S/ Soles | D10: ='BCP SOLES BCP'!$G$309 -> 40117.433 | E10: =D10/$D$6 -> 11396.998
C11: Bancos USD | D11: =E11*$D$6 -> 10187.443 | E11: ='BCP USD BCP'!$G$144 -> 2894.16
C12: Devolución de dinero Delivery | D12: =E12*$D$6 -> 70.4 | E12: 20
C13: CLIENTES | D13: =SUBTOTAL(9,D14:D20) -> 215690.38 | E13: =SUBTOTAL(9,E14:E20) -> 61866.332
B14: Pagado | C14: Client: Safeguard-Factura Nro EB01-02 ( Cliente) | D14: =E14*3.44 -> 4413.0728 | E14: =1282.87 -> 1282.87 | G14: =E14+E15+E16 -> 22849.1
B15: Pagado | C15: Client: Safeguard-Factura Nro EB01-03 ( Cliente) | D15: =E15*3.44 -> 60586.966 | E15: 17612.49
B16: Pagado | C16: Client: Safeguard-Factura Nro EB01-04 ( Cliente) | D16: =E16*3.44 -> 13600.866 | E16: 3953.74
D17: =6249.86-181.07+41.34 -> 6110.13 | E17: =D17/D6 -> 1735.8324
B18: Pagado | C18: Client: Europortage-Factura Nro EB01-24 | D18: =$E$18*'Diferencia Cambio S&P'!$K$23 -> 88163.618 | E18: 25117.84
B19: Pagado | C19: Client: Remotepass-Factura Nro EB01-25 | D19: =E19*$D$6 -> 23907.77 | E19: 6791.98
B20: Sin Pagar | C20: Client: Yonyou xinfushe cloud technology co., limited-Factura Nro EB01-26 | D20: =E20*$D$6 -> 18907.962 | E20: 5371.58
C21: TOTAL INGRESOS | D21: =SUBTOTAL(9,D9:D20) -> 266065.66 | E21: =SUBTOTAL(9,E9:E20) -> 76177.49
B24: CUENTAS X PAGAR MES | D24: AGOSTO | F24: Fecha de Elaboración: | J24: 45870
B25: Factura | C25: PROVEEDOR | D25: VALOR S/Sol | E25: VALOR USD | F25: Fecha vencimiento | G25: Estado | J25: KPI
C26: SEGURIDAD IGSS | D26: =SUBTOTAL(9,D27:D29) -> 9411.88 | E26: =SUBTOTAL(9,E27:E29) -> 2673.8295
B27: 2220819158 | C27: Planilla de declaración y pago de aportes previsional-Braydi Yusset Vera Neyra y Davis Cesar Oporto Figueroa | D27: =3271.3+623.91 -> 3895.21 | E27: =D27/$D$6 -> 1106.5938 | F27: 45875 | G27: Cancelado | H27: =IF(OR(G27="Sin pagar",G27="Pagar"),_xlfn.SINGLE(NETWORKDAYS($J$24,F27,FestivosPerú!$A$2:$A$15)),0) -> 0 | I27: =NETWORKDAYS($J$24,F27,FestivosPerú!$A$2:$A$15) -> 3 | J27: =H27 -> 0
B28: 2516822828 | C28: Planilla de declaración y pago de aportes previsional Christian Portugal Segovia y Luis renato Sanchez Martinez | D28: =1654.07+410.08 -> 2064.15 | E28: =D28/$D$6 -> 586.40625 | F28: 45875 | G28: Cancelado | H28: =IF(OR(G28="Sin pagar",G28="Pagar"),_xlfn.SINGLE(NETWORKDAYS($J$24,F28,FestivosPerú!$A$2:$A$15)),0) -> 0 | I28: =NETWORKDAYS($J$24,F28,FestivosPerú!$A$2:$A$15) -> 3 | J28: =H28 -> 0
B29: 2609515342 | C29: Planilla de declaración y pago de aportes previsional Christiams Hebert Valle Gomez -Remotepass | D29: =2688.5+764.02 -> 3452.52 | E29: =D29/$D$6 -> 980.82955 | F29: 45875 | G29: Cancelado | H29: =IF(OR(G29="Sin pagar",G29="Pagar"),_xlfn.SINGLE(NETWORKDAYS($J$24,F29,FestivosPerú!$A$2:$A$15)),0) -> 0 | I29: =NETWORKDAYS($J$24,F29,FestivosPerú!$A$2:$A$15) -> 3 | J29: =H29 -> 0
C30: IMPUESTOS | D30: =SUBTOTAL(9,D31:D32) -> 15813 | E30: =SUBTOTAL(9,E31:E32) -> 4492.3295 | J30: =H30 -> 0
C31: Plame Essalud y Renta de Quinta Categoría (Retención) | D31: 13751 | E31: =D31/$D$6 -> 3906.5341 | F31: 45882 | G31: Cancelado | H31: =IF(OR(G31="Sin pagar",G31="Pagar"),_xlfn.SINGLE(NETWORKDAYS($J$24,F31,FestivosPerú!$A$2:$A$15)),0) -> 0 | I31: =NETWORKDAYS($J$24,F31,FestivosPerú!$A$2:$A$15) -> 8 | J31: =H31 -> 0
