Workbook
Name Fact: #REF!
Name Fact: #REF!
Name Marca: '[1]Facturas Pagadas y Pendientes'!#REF!
Name Marca: '[1]Facturas Pagadas y Pendientes'!#REF!
Name Marca1: '[1]Facturas Pagadas y Pendientes'!#REF!
Name Marca1: '[1]Facturas Pagadas y Pendientes'!#REF!
Name Marcas: '[1]Facturas Pagadas y Pendientes'!#REF!
Name Marcas: '[1]Facturas Pagadas y Pendientes'!#REF!
Name Valor: '[1]Facturas Pagadas y Pendientes'!#REF!
Name Valor: '[1]Facturas Pagadas y Pendientes'!#REF!
Name Value: '[1]Facturas Pagadas y Pendientes'!#REF!
Name Value: '[1]Facturas Pagadas y Pendientes'!#REF!
Name values: '[1]Facturas Pagadas y Pendientes'!#REF!

Sheet Hoja1
B2: No. | C2: Tipo de Gasto | D2: Fecha | E2: Gastos | F2: Ingreso | G2: Saldo
B3: 1 | C3: Transferencia recibida $. 371.65 | D3: 44974 | E3: 0 | F3: 2697.47 | G3: =F3 -> 2697.47
B4: 2 | C4: Gastos Tramites legales SAT, IGSS | D4: 44974 | E4: -2697.47 | F4: 0 | G4: =G3+E4 -> 0
B5: 3 | C5: Compra de Computadora Macbook 14 | D5: 44988 | E5: -19999.99 | F5: 0 | G5: =G4+E5 -> -19999.99
B6: 4 | C6: Apertura de cuenta y Gastos Administrativos | D6: 44991 | F6: 1000 | G6: =F6+E6 -> 1000
B7: 5 | C7: Transferencia recibida $. 150.00 | D7: 45000 | F7: 1487.85 | G7: =G6+F7 -> 2487.85
B8: 6 | C8: Devolucion apertura de cuenta y movilizacion | D8: 45003 | E8: -1500 | G8: =G7+E8 -> 987.85
B9: 7 | C9: Transferencia recibida | D9: 45015 | F9: 35063.13 | G9: =G8+F9 -> 36050.98
B10: 8 | C10: Pago de salario mes de marzo 2023 | D10: 45016 | E10: -18236.9 | G10: =G9+E10 -> 17814.08
B11: 9 | C11: Anticipo honorarios febrero a marzo 2023 | D11: 45038 | E11: -2000 | G11: =G10+E11 -> 15814.08
C12: TOTAL | E12: =SUM(E3:E11) -> -44434.36 | F12: =SUM(F3:F11) -> 40248.45 | G12: =G11 -> 15814.08

Sheet RESUMEN
A1: RESUMEN INGRESOS Y GASTOS
A2: SOLUTIONS & PAYROLL, S. A.
A3: SUCURSAL GUATEMALA
A4: No | B4: DESCRIPCION | C4: INGRESOS | D4: GASTOS
A5: 1 | B5: TRANSFERENCIAS RECIBIDAS A LA CUENTA
A6: 1.1 | B6: SALDO INCIAL | C6: 20477.39
A7: 1.2 | B7: TRANSFERENCIAS RECIBIDAS ENERO 2024 | C7: 295632.14
A9: 2 | B9: GASTOS EFECTUADOS
A10: 2.1 | B10: EGRESOS MES ENERO 2024 | D10: 32633.16
B12: SUBTOTAL | C12: =SUM(C6:C8) -> 316109.53 | D12: =SUM(D6:D10) -> 32633.16
B13: SALDO SEGÚN LIBROS | D13: =C12-D12 -> 283476.37
B14: TOTAL FINAL | C14: =SUM(C12) -> 316109.53 | D14: =SUM(D12:D13) -> 316109.53

Sheet Caja USD
B1: LIBRO DE CAJA
B2: SOLUTIONS & PAYROLL, S. A.
B3: SUCURSAL GUATEMALA USD
C4: INGRESOS | G4: EGRESOS
B5: FECHA | C5: CONCEPTO | D5: TOTAL | F5: FECHA | G5: CONCEPTO | H5: TOTAL
B6: 45292 | C6: Saldo Inicial | D6: 100 | F6: 45321 | G6: Pago Póliza Salud | H6: 1039.74
B7: 45321 | C7: transf fondos pagos Póliza | D7: 1040
C8: TOTAL INGRESOS ENERO | D8: =SUM(D6:D7) -> 1140 | G8: TOTAL EGRESOS ENERO | H8: =SUM(H6:H7) -> 1039.74
G9: SALDO DE CAJA ENERO | H9: =(D8-H8) -> 100.26
B11: FECHA | C11: CONCEPTO | D11: TOTAL | F11: FECHA | G11: CONCEPTO | H11: TOTAL
B12: 45323 | C12: Saldo Inicial | D12: =H9 -> 100.26 | F12: 45323 | G12: Pago Reembolso Ronny Quan | H12: 821.65
B13: 45323 | C13: Transf fondos Pago Reembol | D13: 821.65 | F13: 45323 | G13: Pago Póliza Vida | H13: 519.87
B14: 45349 | C14: Transf fondos Pago Póliza Salud | D14: 499.74
C15: TOTAL INGRESOS FEBRERO | D15: =SUM(D12:D14) -> 1421.65 | G15: TOTAL EGRESOS FEBRERO | H15: =SUM(H12:H14) -> 1341.52
G16: SALDO DE CAJA MARZO | H16: =D15-H15 -> 80.13
B18: FECHA | C18: CONCEPTO | D18: TOTAL | F18: FECHA | G18: CONCEPTO | H18: TOTAL
B19: 45352 | C19: Saldo Inicial | D19: =H16 -> 80.13 | F19: 45358 | G19: Pago reembolso Ronny Quan USD | H19: 979.7
B20: 45323 | C20: Transf fondos Pago Reembol | D20: 1000
C21: TOTAL INGRESOS MARZO | D21: =SUM(D19:D20) -> 1080.13 | G21: TOTAL EGRESOS MARZO | H21: =SUM(H19:H20) -> 979.7
G22: SALDO DE CAJA MARZO | H22: =D21-H21 -> 100.43
B25: FECHA | C25: CONCEPTO | D25: TOTAL | F25: FECHA | G25: CONCEPTO | H25: TOTAL
B26: 45383 | C26: Saldo Inicial | D26: =H22 -> 100.43 | F26: 45384 | G26: Pago reembolso Ronny Quan USD | H26: 753.91
B27: 45383 | C27: Transf fondos Pago Reembol | D27: 2017.06 | F27: 45384 | G27: Pago reembolso Iván Estuardo Chávez Morales | H27: 1263.15
B28: 45405 | C28: Transf fondos Pago Póliza vida abril | D28: 420.79 | F28: 45405 | G28: Pago Póliza Vida | H28: 519.87
C30: TOTAL INGRESOS ABRIL | D30: =SUM(D26:D29) -> 2538.28 | G30: TOTAL EGRESOS ABRIL | H30: =SUM(H26:H29) -> 2536.93
G31: SALDO DE CAJA ABRIL | H31: =D30-H30 -> 1.35
B34: FECHA | C34: CONCEPTO | D34: TOTAL | F34: FECHA | G34: CONCEPTO | H34: TOTAL
B35: 45413 | C35: Saldo Inicial | D35: =H31 -> 1.35 | F35: 45440 | G35: Pago Póliza Vida | H35: 519.87
B36: 45440 | C36: Transf fondos Pago Póliza vida MAYO | D36: 571.07 | F36: 45441 | G36: Pago reembolso Ronny Quan USD | H36: 1434.21
B37: 45441 | C37: Transf fondos Pago reembolsos mayo | D37: 2600 | F37: 45441 | G37: Pago reembolso Iván Estuardo Chávez Morales | H37: 1088.35
C39: TOTAL INGRESOS MAYO | D39: =SUM(D35:D38) -> 3172.42 | G39: TOTAL EGRESOS MAYO | H39: =SUM(H35:H38) -> 3042.43
G40: SALDO DE CAJA MAYO | H40: =D39-H39 -> 129.99
B45: FECHA | C45: CONCEPTO | D45: TOTAL | F45: FECHA | G45: CONCEPTO | H45: TOTAL
B46: 45444 | C46: Saldo Inicial | D46: =$H$40 -> 129.99 | F46: 45450 | G46: Pago reembolso jerry García USD | H46: =1088.35 -> 1088.35
B47: 45447 | C47: Devolución de Dinero Ivan Estuardo Chavez | D47: 1088.35 | F47: 45457 | G47: Pago reembolso Ronny Quan USD | H47: =1065.86 -> 1065.86
B48: 45449 | C48: Transf pagos facturas enero a may S&P Col | D48: 5280.45 | F48: 45471 | G48: Póliza de vida Ivan Estuardo Chavez Morales | H48: =55.07*$J$46 -> 0
F49: 45471 | G49: Poliza de vida Rony Eduardo Quan Lam | H49: =259.47*$J$46 -> 0
C50: TOTAL INGRESOS JUNIO | D50: =SUM(D46:D49) -> 6498.79 | F50: 45471 | G50: Poliza de vida Jerry García Carillo | H50: =205.33*$J$46 -> 0
G52: TOTAL EGRESOS JUNIO | H52: =SUM(H46:H51) -> 2154.21
G53: SALDO DE CAJA JUNIO | H53: =D50-H52 -> 4344.58
...

Sheet Caja QTQ
B1: LIBRO DE CAJA
B2: SOLUTIONS & PAYROLL, S. A.
B3: SUCURSAL GUATEMALA USD
C4: INGRESOS | G4: EGRESOS
B5: FECHA | C5: CONCEPTO | D5: TOTAL | F5: FECHA | G5: CONCEPTO | H5: TOTAL
B6: 45292 | C6: SALDO INICIAL | D6: 20477.39 | F6: 45296 | G6: Emisión estados de cuenta | H6: 15
B7: 45303 | C7: Marta Xicay -GFC-202401 | D7: 18270.77 | F7: 45296 | G7: Emisión estados de cuenta | H7: 15
B8: 45322 | C8: Ivan Ch-Jerry G-Ronny Q-Energyzer 202401 | D8: 277361.37 | F8: 45296 | G8: Emisión estados de cuenta | H8: 15
F9: 45307 | G9: pago ISR asalariados 2023 | H9: 1892.89
F10: 45308 | G10: Pago planilla igss dic 2023 | H10: 3159.63
F11: 45320 | G11: Pago salario marta xicay en 2024 | H11: 17507.04
F12: 45321 | G12: Compra $. 1,039.74 traslado cta dolares | H12: 8236.8
F13: 45321 | G13: Pago seguro mes enero y febrero 2024 | H13: 1791.8
C16: TOTAL INGRESOS ENERO | D16: =SUM(D6:D15) -> 316109.53 | G16: TOTAL EGRESOS ENERO | H16: =SUM(H6:H15) -> 32633.16
G17: SALDO DE CAJA ENERO | H17: =(D16-H16) -> 283476.37
B19: FECHA | C19: CONCEPTO | D19: TOTAL | F19: FECHA | G19: CONCEPTO | H19: TOTAL
B20: 45323 | C20: Saldo Inicial | D20: =H17 -> 283476.37 | F20: 45323 | G20: Jerry Garcia Carrillo Enero 2024 | H20: 69020.57
B21: 45334 | C21: ACH City Bank Penny Test (SG) | D21: 25 | F21: 45323 | G21: Ronny Eduardo Quan Lam Enero 24 | H21: 80877.89
B22: 45335 | C22: Marta Xicay -GFC-202401 | D22: 22574.81 | F22: 45323 | G22: Ivan Eduardo Chavez Morales En 2024 | H22: 39790.21
F23: 45323 | G23: Reembolso Ronny Quan | H23: 5386.76
F24: 45323 | G24: Reembolso Ronny Quan | H24: 6507.47
F25: 45336 | G25: Declaraguate ISR Asalariados Enero 2024 | H25: 12314.65
F26: 45341 | G26: Pago planilla IGSS Mes enero 2024 | H26: 30448.42
F27: 45349 | G27: Traslado cuenta dolares pago PANAMERICAN LIFE | H27: 3952.94
F28: 45349 | G28: Pago Seguro salud Marzo 2024 | H28: 1792.2
F29: 45351 | G29: Pago Salario Marta Xicay Feb 2024 | H29: 17507.04
C30: TOTAL INGRESOS FEBRERO | D30: =SUM(D20:D29) -> 306076.18 | G30: TOTAL EGRESOS FEBRERO | H30: =SUM(H20:H29) -> 267598.15
G31: SALDO DE CAJA FEBRERO | H31: =D30-H30 -> 38478.03
B33: FECHA | C33: CONCEPTO | D33: TOTAL | F33: FECHA | G33: CONCEPTO | H33: TOTAL
B34: 45352 | C34: Saldo Inicial | D34: =H31 -> 38478.03 | F34: 45352 | G34: Jerry Garcia Carrillo Febrero 2024 | H34: 54332.57
B35: 45352 | C35: Ivan Ch-Jerry G-Ronny Q-Energyzer 202401 | D35: 225566.58 | F35: 45352 | G35: Ronny Eduardo Quan Lam Febrero 24 | H35: 66189.9
B36: 45362 | C36: Client:Global For Children-Marta Xicay 202402-Termination | D36: 17468.75 | F36: 45352 | G36: Ivan Eduardo Chavez Morales febrero 2024 | H36: 24970.21
B37: 45366 | C37: Client:Kairos-Ivan Chavez-Ruth Carolina Vasquez 202403 | D37: 7172.5 | F37: 45355 | G37: Reembolso Gtos Ivan chavez enero 2024 | H37: 4381.18
B38: 45371 | C38: Client:Energyzer-Ivan Chavez-Jerry García-Ronny Quan 202403 | D38: 288267.58 | F38: 45357 | G38: Servicios honorarios Juan Santiago enero | H38: 945
B39: 45377 | C39: Client: Czarnikow- Sthepanie Rodriguez Lopez 202403 | D39: 77876.16 | F39: 45358 | G39: Reembolso Ronny Quan Marzo | H39: 1868.42
F40: 45358 | G40: Traslado cuenta dolares pago Reembolso Ronny Quan | H40: 7910
F41: 45364 | G41: Declaraguate ISR Asalariados Febrero 2024 | H41: 9710.64
C42: TOTAL INGRESOS MARZO | D42: =SUM(D34:D41) -> 654829.6 | F42: 45366 | G42: Liquidación Marta Xicay | H42: =16550.42 -> 16550.42
F43: 45369 | G43: Cobro emisión estado cuenta | H43: 15
F44: 45369 | G44: Cobro emisión estado cuenta | H44: 15
...

Sheet Flujo Caja Noviembre 2025
D1: 42400
D4: Fecha de Elaboración: | E4: 45962
C6: Tasa de cambio: | D6: 7.46
D7: NOVIEMBRE
D8: VALOR QTQ | E8: VALOR USD
C9: BANCOS | D9: =SUBTOTAL(9,D10:D11) -> 461596.24 | E9: =SUBTOTAL(9,E10:E11) -> 61876.171
C10: Bancos QTQ | D10: ='Caja QTQ'!$J$822+31241.13 -> 447415.67 | E10: =D10/$D$6 -> 59975.291
C11: Bancos USD | D11: =E11*D6 -> 14180.565 | E11: ='Caja USD'!$H$260 -> 1900.88
C12: CLIENTES | D12: =SUBTOTAL(9,D13:D29) -> 1519234.7 | E12: =SUBTOTAL(9,E13:E29) -> 199963.21
B13: Pagado | C13: Client: NotableGrowth, Inc-Remotefist | D13: ='Diferencia en cambio'!I187 -> 50408.41 | E13: =D13/'Diferencia en cambio'!$L$187 -> 6633.77 | G13: 232387.56 | J13: =G13/$D$6 -> 31151.147
B14: Pagado | C14: Client: Bilingual Bridges, Inc-Remotefist | D14: ='Diferencia en cambio'!I188 -> 12594.789 | E14: =D14/'Diferencia en cambio'!$L$188 -> 1657.48 | G14: 59616.41 | J14: =G14/$D$6 -> 7991.4759
B15: Pagado | C15: Client: :Iberia Foods LLC -Remotefist | D15: ='Diferencia en cambio'!I189 -> 28246.938 | E15: =D15/'Diferencia en cambio'!$L$189 -> 3717.31
B16: Pagado | C16: Client: Vinmar International,-Liza Marlene Torres valdes 202508-Remofirst | D16: ='Diferencia en cambio'!I190 -> 20247.953 | E16: =D16/'Diferencia en cambio'!$L$190 -> 2664.64
B17: Pagado | C17: Client: Czarnikow- Sthepanie Rodriguez Lopez-Remotefist | D17: ='Diferencia en cambio'!I191 -> 18416.425 | E17: =D17/'Diferencia en cambio'!L191 -> 2423.61
B18: Pagado | C18: Client: Soul Innovations-Remotefist | D18: ='Diferencia en cambio'!I192 -> 102473.05 | E18: =D18/'Diferencia en cambio'!$L$192 -> 13485.5
B19: Pagado | C19: Client:Energyzer-Safeguard | D19: ='Diferencia en cambio'!I193 -> 425268.22 | E19: =$D$19/'Diferencia en cambio'!$L$193 -> 55740.43
B20: Pagado | C20: Client:Kairos- Safeguard | D20: ='Diferencia en cambio'!$I$194 -> 23739.41 | E20: =D20/'Diferencia en cambio'!$L$194 -> 3174.48
B21: Pagado | C21: Client: Opportunity-Safeguard | D21: ='Diferencia en cambio'!I195 -> 42797.111 | E21: =D21/'Diferencia en cambio'!$L$195 -> 5609.47
B22: Pagado | C22: Client: Panthera, Inc-Safeguard | D22: ='Diferencia en cambio'!I196 -> 33691.756 | E22: =D22/'Diferencia en cambio'!$L$196 -> 4416.02
B23: Pagado | C23: Client: :Careercircle, LLC-Safeguard | D23: ='Diferencia en cambio'!I197 -> 69708.449 | E23: =D23/'Diferencia en cambio'!$L$197 -> 9219.28
B24: Pagado | C24: Client: :Highspring, LLC-Safeguard | D24: ='Diferencia en cambio'!I198 -> 17297.159 | E24: =D24/'Diferencia en cambio'!$L$198 -> 2267.16
B25: Pagado | C25: Client: :Archewll, LLC-Safeguard | D25: ='Diferencia en cambio'!I199 -> 143579.24 | E25: =D25/'Diferencia en cambio'!$L$199 -> 18989.05
B26: Pagado | C26: Client:Global Expansion | D26: ='Diferencia en cambio'!I186 -> 121412.13 | E26: =D26/'Diferencia en cambio'!L186 -> 15938.35
B27: Pagado | C27: Client: Safeguard expenses | D27: ='Diferencia en cambio'!I185 -> 38638.95 | E27: =D27/'Diferencia en cambio'!L185 -> 5150
B28: Pagado | C28: Client: Safeguard Nomina directa | D28: ='Diferencia en cambio'!I200 -> 311098.25 | E28: =D28/'Diferencia en cambio'!L200 -> 40885.18
B29: Pagado | C29: Client: Safeguard Nomina directa-Valor duplicado | D29: 59616.45 | E29: =D29/D6 -> 7991.4812
C30: TOTAL INGRESOS | D30: =SUBTOTAL(9,D9:D29) -> 1980830.9 | E30: =SUBTOTAL(9,E9:E29) -> 261839.38
B33: CUENTAS X PAGAR MES | D33: NOVIEMBRE
B34: Factura | C34: PROVEEDOR | D34: VALOR QTQ | E34: VALOR USD | F34: Fecha vencimiento | G34: Estado | J34: KPI
C35: SEGURIDAD IGSS | D35: =SUBTOTAL(9,D36:D36) -> 119631.47 | E35: =SUBTOTAL(9,E36:E36) -> 16036.39
B36: 5794688 | C36: Pago planilla IGSS Octubre | D36: 119631.47 | E36: =D36/$D$6 -> 16036.39 | F36: 45975 | G36: Cancelado | H36: =IF(OR(G36="Sin pagar",G36="Pagar"),NETWORKDAYS($E$4,F36,'Festivos Guatemala'!$A$3:$A$15),0) -> 0 | I36: =NETWORKDAYS($E$4,F36,'Festivos Guatemala'!$A$3:$A$15) -> 10 | J36: =H36 -> 0
C37: IMPUESTOS | D37: =SUBTOTAL(9,D38:D40) -> 29911.35 | E37: =SUBTOTAL(9,E38:E40) -> 4009.5643 | J37: =H37 -> 0
B38: 49088379970 | C38: Declaraguate ISR Septiembre | D38: 25414.84 | E38: =D38/$D$6 -> 3406.815 | F38: 45975 | G38: Cancelado | H38: =IF(OR(G38="Sin pagar",G38="Pagar"),NETWORKDAYS($E$4,F38,'Festivos Guatemala'!$A$3:$A$15),0) -> 0 | I38: =NETWORKDAYS($E$4,F38,'Festivos Guatemala'!$A$3:$A$15) -> 10 | J38: =H38 -> 0
B39: 49088577105 | C39: Declaraguate ISR no residentes facturación Col Factura 601 Octubre (15%) | D39: 3462.99 | E39: =D39/$D$6 -> 464.20777 | F39: 45975 | G39: Cancelado | H39: =IF(OR(G39="Sin pagar",G39="Pagar"),NETWORKDAYS($E$4,F39,'Festivos Guatemala'!$A$3:$A$15),0) -> 0 | I39: =NETWORKDAYS($E$4,F39,'Festivos Guatemala'!$A$3:$A$15) -> 10 | J39: =H39 -> 0
B40: 4904205174 | C40: Declaraguate ISR No Residentes / Grupo CGR Lawyer | D40: 1033.52 | E40: =D40/$D$6 -> 138.54155 | F40: 45975 | G40: Cancelado | H40: =IF(OR(G40="Sin pagar",G40="Pagar"),NETWORKDAYS($E$4,F40,'Festivos Guatemala'!$A$3:$A$15),0) -> 0 | I40: =NETWORKDAYS($E$4,F40,'Festivos Guatemala'!$A$3:$A$15) -> 10 | J40: =H40 -> 0
C41: SERVICIOS PROFESIONALES -REPRESENTACIÓN LEGAL -GASTOS DE OFICINA | D41: =SUBTOTAL(9,D42:D46) -> 17617.89 | E41: =SUBTOTAL(9,E42:E46) -> 2361.6475 | J41: =H41 -> 0
B42: E320000000007 | C42: Servicio de representación, diligencia de alta TSS y ministerio Grupo CGR Lawyer | D42: =$E$42*$D$6 -> 10071 | E42: 1350 | F42: 45968 | G42: Cancelado | H42: =IF(OR(G42="Sin pagar",G42="Pagar"),NETWORKDAYS($E$4,F42,'Festivos Guatemala'!$A$3:$A$15),0) -> 0 | I42: =NETWORKDAYS($E$4,F42,'Festivos Guatemala'!$A$3:$A$15) -> 5 | J42: =H42 -> 0
B43: 752578 | C43: Inbers contadores Servicios contables con entrega de información financiera correspondiente al periodo de octubre 2025 | D43: =4673.2 -> 4673.2 | E43: =D43/$D$6 -> 626.43432 | F43: 45982 | G43: Cancelado | H43: =IF(OR(G43="Sin pagar",G43="Pagar"),NETWORKDAYS($E$4,F43,'Festivos Guatemala'!$A$3:$A$15),0) -> 0 | I43: =NETWORKDAYS($E$4,F43,'Festivos Guatemala'!$A$3:$A$15) -> 15 | J43: =H43 -> 0
B44: 2888256700 | C44: Servicios prestados por representación entidad Global Guatemala Nov. 2025 | D44: 1368.42 | E44: =D44/$D$6 -> 183.43432 | F44: 45982 | G44: Cancelado | H44: =IF(OR(G44="Sin pagar",G44="Pagar"),NETWORKDAYS($E$4,F44,'Festivos Guatemala'!$A$3:$A$15),0) -> 0 | I44: =NETWORKDAYS($E$4,F44,'Festivos Guatemala'!$A$3:$A$15) -> 15 | J44: =H44 -> 0
B45: 1089948594 | C45: Servicios prestados de representación mes de Octubre de 2025 | D45: 926.32 | E45: =D45/$D$6 -> 124.17158 | F45: 45982 | G45: Cancelado | H45: =IF(OR(G45="Sin pagar",G45="Pagar"),NETWORKDAYS($E$4,F45,'Festivos Guatemala'!$A$3:$A$15),0) -> 0 | I45: =NETWORKDAYS($E$4,F45,'Festivos Guatemala'!$A$3:$A$15) -> 15 | J45: =H45 -> 0
...

Sheet Flujo Caja Diciembre 2025
D1: 42400
D4: Fecha de Elaboración: | E4: 45992
C6: Tasa de cambio: | D6: 7.46
D7: DICIEMBRE
D8: VALOR QTQ | E8: VALOR USD
C9: BANCOS | D9: =SUBTOTAL(9,D10:D12) -> 503122.91 | E9: =SUBTOTAL(9,E10:E12) -> 67442.75
C10: Bancos QTQ | D10: ='Caja QTQ'!$D$826+7012.4 -> 433717.46 | E10: =D10/$D$6 -> 58139.07
C11: Bancos USD | D11: =E11*D6 -> 36420.69 | E11: ='Caja USD'!$D$290 -> 4882.13
C12: Devolución de dinero Roony Quan por pago doble reembolso | D12: =E12*D6 -> 32984.763 | E12: 4421.55
C13: CLIENTES | D13: =SUBTOTAL(9,D14:D31) -> 1100545.3 | E13: =SUBTOTAL(9,E14:E31) -> 144950.03
B14: Pagado | C14: Client: NotableGrowth, Inc-Remotefist | D14: ='Diferencia en cambio'!I201 -> 50276.328 | E14: =D14/'Diferencia en cambio'!L201 -> 6633.77
B15: Pagado | C15: Client: Bilingual Bridges, Inc-Remotefist | D15: ='Diferencia en cambio'!I202 -> 12562.242 | E15: =D15/'Diferencia en cambio'!L202 -> 1657.54
B16: Pagado | C16: Client: :Iberia Foods LLC -Remotefist | D16: ='Diferencia en cambio'!I203 -> 28172.924 | E16: =D16/'Diferencia en cambio'!L203 -> 3717.31
B17: Pagado | C17: Client: Vinmar International,-Liza Marlene Torres valdes 202508-Remofirst | D17: ='Diferencia en cambio'!I204 -> 20194.899 | E17: =D17/'Diferencia en cambio'!L204 -> 2664.64
B18: Pagado | C18: Client: Czarnikow- Sthepanie Rodriguez Lopez-Remotefist | D18: ='Diferencia en cambio'!I205 -> 42031.831 | E18: =D18/'Diferencia en cambio'!L205 -> 5545.94
B19: Pagado | C19: Client: Soul Innovations-Remotefist | D19: ='Diferencia en cambio'!I206 -> 95878.326 | E19: =D19/'Diferencia en cambio'!L206 -> 12650.78
B20: Sin Pagar | C20: Client:Energyzer-Safeguard | D20: =E20*$D$6 -> 0 | E20: ='Diferencia en cambio'!F207*0 -> 0
B21: Pagado | C21: Client:Kairos- Safeguard | D21: ='Diferencia en cambio'!I208 -> 11102.886 | E21: =D21/'Diferencia en cambio'!L208 -> 1465.01
B22: Pagado | C22: Client: Opportunity-Safeguard | D22: ='Diferencia en cambio'!I209 -> 27323.372 | E22: =D22/'Diferencia en cambio'!L209 -> 3605.28
D23: 2059 | E23: =D23/D6 -> 276.00536
B25: Pagado | C25: Client: Panthera, Inc-Safeguard | D25: ='Diferencia en cambio'!I210 -> 18300.69 | E25: =D25/'Diferencia en cambio'!L210 -> 2414.75
B26: Pagado | C26: Client: :Careercircle, LLC-Safeguard | D26: ='Diferencia en cambio'!I211 -> 45390.562 | E26: =D26/'Diferencia en cambio'!L211 -> 5989.22
B27: Pagado | C27: Client: :Highspring, LLC-Safeguard | D27: ='Diferencia en cambio'!I212 -> 107775.17 | E27: =D27/'Diferencia en cambio'!L212 -> 14220.78
B28: Pagado | C28: Client: :Archewll, LLC-Safeguard | D28: ='Diferencia en cambio'!I213 -> 12749.512 | E28: =D28/'Diferencia en cambio'!L213 -> 1682.28
B29: Pagado | C29: Client:Global Expansion | D29: ='Diferencia en cambio'!I215 -> 121412.05 | E29: =$D$29/'Diferencia en cambio'!$L$215 -> 15938.34
B30: Pagado | C30: Client: Safeguard Nomina directa-Aguinaldo | D30: ='Diferencia en cambio'!I214 -> 117321.19 | E30: =$D$30/'Diferencia en cambio'!$L$214 -> 15564.84
B31: Pagado | C31: Client: Safeguard Nomina directa | D31: ='Diferencia en cambio'!I216 -> 387994.35 | E31: =$D$31/'Diferencia en cambio'!$L$216 -> 50923.54
C32: TOTAL INGRESOS | D32: =SUBTOTAL(9,D9:D31) -> 1603668.2 | E32: =SUBTOTAL(9,E9:E31) -> 212392.78
B35: CUENTAS X PAGAR MES | D35: DICIEMBRE
B36: Factura | C36: PROVEEDOR | D36: VALOR QTQ | E36: VALOR USD | F36: Fecha vencimiento | G36: Estado | J36: KPI
C37: SEGURIDAD IGSS | D37: =SUBTOTAL(9,D38:D38) -> 106546.18 | E37: =SUBTOTAL(9,E38:E38) -> 14282.33
B38: 5794688 | C38: Pago planilla IGSS Noviembre | D38: 106546.18 | E38: =D38/$D$6 -> 14282.33 | F38: 46006 | G38: Cancelado | H38: =IF(OR(G38="Sin pagar",G38="Pagar"),NETWORKDAYS($E$4,F38,'Festivos Guatemala'!$A$3:$A$15),0) -> 0 | I38: =NETWORKDAYS($E$4,F38,'Festivos Guatemala'!$A$3:$A$15) -> 11 | J38: =H38 -> 0
C39: IMPUESTOS | D39: =SUBTOTAL(9,D40:D42) -> 31765.83 | E39: =SUBTOTAL(9,E40:E42) -> 4258.1542 | J39: =H39 -> 0
B40: 49380053011 | C40: Declaraguate ISR Septiembre | D40: 28513.4 | E40: =D40/$D$6 -> 3822.1716 | F40: 46003 | G40: Cancelado | H40: =IF(OR(G40="Sin pagar",G40="Pagar"),NETWORKDAYS($E$4,F40,'Festivos Guatemala'!$A$3:$A$15),0) -> 0 | I40: =NETWORKDAYS($E$4,F40,'Festivos Guatemala'!$A$3:$A$15) -> 10 | J40: =H40 -> 0
B41: 49375016788 | C41: Declaraguate ISR no residentes facturación Col Factura Noviembre (15%) | D41: 1703 | E41: =D41/$D$6 -> 228.28418 | F41: 46003 | G41: Cancelado | H41: =IF(OR(G41="Sin pagar",G41="Pagar"),NETWORKDAYS($E$4,F41,'Festivos Guatemala'!$A$3:$A$15),0) -> 0 | I41: =NETWORKDAYS($E$4,F41,'Festivos Guatemala'!$A$3:$A$15) -> 10 | J41: =H41 -> 0
B42: 49375134303 | C42: Declaraguate ISR No Residentes / Grupo CGR Lawyer | D42: 1549.43 | E42: =D42/$D$6 -> 207.69839 | F42: 46003 | G42: Cancelado | H42: =IF(OR(G42="Sin pagar",G42="Pagar"),NETWORKDAYS($E$4,F42,'Festivos Guatemala'!$A$3:$A$15),0) -> 0 | I42: =NETWORKDAYS($E$4,F42,'Festivos Guatemala'!$A$3:$A$15) -> 10 | J42: =H42 -> 0
C43: SERVICIOS PROFESIONALES -REPRESENTACIÓN LEGAL -GASTOS DE OFICINA | D43: =SUBTOTAL(9,D44:D48) -> 31485.94 | E43: =SUBTOTAL(9,E44:E48) -> 3470.6354 | J43: =H43 -> 0
B44: E320000000008 | C44: Servicio de representación, diligencia de alta TSS y ministerio Grupo CGR Lawyer | D44: =$E$44*$D$6 -> 12309 | E44: 1650 | F44: 45995 | G44: Cancelado | H44: =IF(OR(G44="Sin pagar",G44="Pagar"),NETWORKDAYS($E$4,F44,'Festivos Guatemala'!$A$3:$A$15),0) -> 0 | I44: =NETWORKDAYS($E$4,F44,'Festivos Guatemala'!$A$3:$A$15) -> 4 | J44: =H44 -> 0
B45: 12557 | C45: Inbers contadores Servicios contables con entrega de información financiera correspondiente al periodo de Noviembre 2025 | D45: =4673.2-100 -> 4573.2 | E45: =D45/$D$6 -> 613.02949 | F45: 46010 | G45: Cancelado | H45: =IF(OR(G45="Sin pagar",G45="Pagar"),NETWORKDAYS($E$4,F45,'Festivos Guatemala'!$A$3:$A$15),0) -> 0 | I45: =NETWORKDAYS($E$4,F45,'Festivos Guatemala'!$A$3:$A$15) -> 15 | J45: =H45 -> 0
B46: 2888256700 | C46: Servicios prestados por representación entidad Global Guatemala Diciembre 2025 | D46: 1368.42 | E46: =D46/$D$6 -> 183.43432 | F46: 46010 | G46: Cancelado | H46: =IF(OR(G46="Sin pagar",G46="Pagar"),NETWORKDAYS($E$4,F46,'Festivos Guatemala'!$A$3:$A$15),0) -> 0 | I46: =NETWORKDAYS($E$4,F46,'Festivos Guatemala'!$A$3:$A$15) -> 15 | J46: =H46 -> 0
...

Sheet RECURSOS
B1: INGRESO
B2: MES | C2: CLIENTE | D2: FACTURA | E2: FEE
B3: Enero | C3: Energyzer | D3: 4258350666 | E3: 1708.86
B4: Enero | C4: Global for children | D4: 1904100714 | E4: 125.43
B5: Febrero | C5: =+C4 -> Global for children | D5: 2820099227 | E5: 120.09
B6: Febrero | C6: =+C5 -> Global for children | D6: 4150543673 | E6: 155.11
B7: Febrero | C7: =+C3 -> Energyzer | D7: 2018594064 | E7: 1389.79
B8: Marzo | C8: =+C7 -> Energyzer | D8: 614157553 | E8: 1778.35
B9: Marzo | C9: Opportunity | D9: 1264599604 | E9: 75.06
B10: Marzo | C10: Kairos | D10: 112609088 | E10: 45.18
B11: Total ingresos operacionales | E11: =SUM(E3:E10) -> 5397.87
B13: COSTOS
B14: MES | C14: PROVEEDOR | D14: FACTURA | E14: VALOR
B15: Enero | C15: S&P | D15: 4640 | E15: 917.15
B16: Enero | C16: JUAN Y ARNOLDO | E16: 256 | F16: 2000
B17: Febrero | C17: =+C15 -> S&P | D17: 4641 | E17: 832.5
B18: Febrero | C18: =+C16 -> JUAN Y ARNOLDO | E18: =+E16 -> 256 | F18: 2000
B19: Marzo | C19: =+C17 -> S&P | D19: PENDIENTE | E19: 949.295 | H19: 120 | I19: =E18-H19 -> 136
B20: Marzo | C20: =+C18 -> JUAN Y ARNOLDO | D20: PENDIENTE | E20: =+E18 -> 256 | F20: =+F18 -> 2000
B21: Marzo | C21: Representación legal | D21: PENDIENTE | E21: 217 | F21: 1700 | H21: =E21*7.91 -> 1716.47
B22: Total egresos operacionales | E22: =SUM(E15:E21) -> 3683.945
B24: Saldo | E24: =+E11-E22 -> 1713.925 | F24: =+E24*7.81 -> 13385.754

Sheet Flujo caja Abril
D1: 42400
D4: Fecha de Elaboración: | E4: 45385
C6: Tasa de cambio: | D6: 7.55
D7: ABRIL
D8: VALOR QTQ | E8: VALOR USD
C9: BANCOS | D9: =SUBTOTAL(9,D10:D11) -> 174210.98 | E9: =SUBTOTAL(9,E10:E11) -> 23074.302
C10: Bancos QTQ | D10: 173452.73 | E10: =D10/$D$6 -> 22973.872
C11: Bancos USD | D11: 758.2465 | E11: =D11/$D$6 -> 100.43
C12: CLIENTES | D12: =SUBTOTAL(9,D13:D16) -> 429182.71 | E12: =SUBTOTAL(9,E13:E16) -> 56845.393
C13: Client: Czarnikow- Sthepanie Rodriguez Lopez-TC 7.55 | D13: 46149.77 | E13: =D13/$D$6 -> 6112.5523
C14: Client:Energyzer-Ivan Chavez-Jerry García-Ronny Quan-TC 7.55 | D14: 362565.53 | E14: =D14/$D$6 -> 48021.924
C15: Client:Kairos-Ivan Chavez-Ruth Carolina Vasquez-TC 7.55 | D15: 7191.534 | E15: =D15/$D$6 -> 952.52106
C16: Client: Opportunity-Edlin Ivette Poitan-TC 7.55 | D16: 13275.885 | E16: =D16/$D$6 -> 1758.3954
C17: TOTAL INGRESOS | D17: =SUBTOTAL(9,D9:D16) -> 603393.69 | E17: =SUBTOTAL(9,E9:E16) -> 79919.694
B20: CUENTAS X PAGAR MES | D20: ABRIL
B21: Factura | C21: PROVEEDOR | D21: VALOR QTQ | E21: VALOR USD | F21: Fecha vencimiento | G21: Estado | J21: KPI
C22: SEGURIDAD IGSS | D22: =SUBTOTAL(9,D23:D24) -> 77479.56 | E22: =SUBTOTAL(9,E23:E24) -> 8065.8066
B23: 176206200 | C23: Pago planilla IGSS Febrero | D23: ='Caja QTQ'!H60+'Caja QTQ'!H61 -> 32463.39 | E23: =30448.42/$D$6 -> 4032.9033 | F23: 45392 | G23: Cancelado | H23: =IF(OR(G23="Sin pagar",G23="Pagar"),NETWORKDAYS($E$4,F23,'Festivos Guatemala'!$A$3:$A$15),0) -> 0 | I23: =NETWORKDAYS($E$4,F23,'Festivos Guatemala'!$A$3:$A$15) -> 6 | J23: =H23 -> 0
B24: 176206200 | C24: Pago planilla IGSS Marzo | D24: 45016.17 | E24: =30448.42/$D$6 -> 4032.9033 | F24: 45397 | G24: Cancelado | H24: =IF(OR(G24="Sin pagar",G24="Pagar"),NETWORKDAYS($E$4,F24,'Festivos Guatemala'!$A$3:$A$15),0) -> 0 | I24: =NETWORKDAYS($E$4,F24,'Festivos Guatemala'!$A$3:$A$15) -> 9 | J24: =H24 -> 0
C25: IMPUESTOS | D25: =SUBTOTAL(9,D26:D28) -> 18928.22 | E25: =SUBTOTAL(9,E26:E28) -> 2507.049 | J25: =H25 -> 0
C26: Declaraguate ISR Marzo | D26: 17191.61 | E26: =D26/$D$6 -> 2277.0344 | F26: 45394 | G26: Cancelado | H26: =IF(OR(G26="Sin pagar",G26="Pagar"),NETWORKDAYS($E$4,F26,'Festivos Guatemala'!$A$3:$A$15),0) -> 0 | I26: =NETWORKDAYS($E$4,F26,'Festivos Guatemala'!$A$3:$A$15) -> 8 | J26: =H26 -> 0
C27: ISR en concepto de la factura 4700 | D27: 1178.23 | E27: =D27/$D$6 -> 156.05695 | F27: 45394 | G27: Cancelado | H27: =IF(OR(G27="Sin pagar",G27="Pagar"),NETWORKDAYS($E$4,F27,'Festivos Guatemala'!$A$3:$A$15),0) -> 0 | I27: =NETWORKDAYS($E$4,F27,'Festivos Guatemala'!$A$3:$A$15) -> 8 | J27: =H27 -> 0
C28: Impuesto de Solidaridad (ISO) | D28: 558.38 | E28: =D28/$D$6 -> 73.957616 | F28: 45406 | G28: Cancelado | H28: =IF(OR(G28="Sin pagar",G28="Pagar"),NETWORKDAYS($E$4,F28,'Festivos Guatemala'!$A$3:$A$15),0) -> 0 | I28: =NETWORKDAYS($E$4,F28,'Festivos Guatemala'!$A$3:$A$15) -> 16 | J28: =H28 -> 0
C29: SERVICIOS PROFESIONALES -REPRESENTACIÓN LEGAL | D29: =SUBTOTAL(9,D30:D36) -> 3380 | E29: =SUBTOTAL(9,E30:E36) -> 447.68212 | J29: =H29 -> 0
C30: Servicios profesionales Juan-Servicios prestados- mes Febrero | D30: 840 | E30: =D30/$D$6 -> 111.25828 | F30: 45393 | G30: Cancelado | H30: =IF(OR(G30="Sin pagar",G30="Pagar"),NETWORKDAYS($E$4,F30,'Festivos Guatemala'!$A$3:$A$15),0) -> 0 | I30: =NETWORKDAYS($E$4,F30,'Festivos Guatemala'!$A$3:$A$15) -> 7 | J30: =H30 -> 0
C31: Servicios profesionales Juan-Servicios prestados-Marzo | D31: 840 | E31: =D31/$D$6 -> 111.25828 | F31: 45393 | G31: Cancelado | H31: =IF(OR(G31="Sin pagar",G31="Pagar"),NETWORKDAYS($E$4,F31,'Festivos Guatemala'!$A$3:$A$15),0) -> 0 | I31: =NETWORKDAYS($E$4,F31,'Festivos Guatemala'!$A$3:$A$15) -> 7 | J31: =H31 -> 0
B32: S/N | C32: 81% Gestión de representación legal 2024­-2027 | D32: 1700 | E32: =D32/$D$6 -> 225.16556 | F32: 45393 | G32: Cancelado | H32: =IF(OR(G32="Sin pagar",G32="Pagar"),NETWORKDAYS($E$4,F32,'Festivos Guatemala'!$A$3:$A$15),0) -> 0 | I32: =NETWORKDAYS($E$4,F32,'Festivos Guatemala'!$A$3:$A$15) -> 7 | J32: =H32 -> 0
B33: S/N | C33: Servicios profesionales Arnoldo prestados en Enero | D33: =1200*0 -> 0 | E33: =D33/$D$6 -> 0 | F33: 45412 | G33: Sin Pagar | H33: =IF(OR(G33="Sin pagar",G33="Pagar"),NETWORKDAYS($E$4,F33,'Festivos Guatemala'!$A$3:$A$15),0) -> 20 | I33: =NETWORKDAYS($E$4,F33,'Festivos Guatemala'!$A$3:$A$15) -> 20 | J33: =H33 -> 20
B34: S/N | C34: Servicios profesionales Arnoldo prestados en Febrero | D34: =1200*0 -> 0 | E34: =D34/$D$6 -> 0 | F34: 45412 | G34: Sin Pagar | H34: =IF(OR(G34="Sin pagar",G34="Pagar"),NETWORKDAYS($E$4,F34,'Festivos Guatemala'!$A$3:$A$15),0) -> 20 | I34: =NETWORKDAYS($E$4,F34,'Festivos Guatemala'!$A$3:$A$15) -> 20 | J34: =H34 -> 20
B35: S/N | C35: Servicios profesionales Arnoldo prestados en Marzo | D35: =1200*0 -> 0 | E35: =D35/$D$6 -> 0 | F35: 45412 | G35: Sin Pagar | H35: =IF(OR(G35="Sin pagar",G35="Pagar"),NETWORKDAYS($E$4,F35,'Festivos Guatemala'!$A$3:$A$15),0) -> 20 | I35: =NETWORKDAYS($E$4,F35,'Festivos Guatemala'!$A$3:$A$15) -> 20 | J35: =H35 -> 20
B36: S/N | C36: Servicio cambios de socio | D36: =11200*0 -> 0 | E36: =D36/$D$6 -> 0 | F36: 45416 | G36: Sin Pagar | H36: =IF(OR(G36="Sin pagar",G36="Pagar"),NETWORKDAYS($E$4,F36,'Festivos Guatemala'!$A$3:$A$15),0) -> 23 | I36: =NETWORKDAYS($E$4,F36,'Festivos Guatemala'!$A$3:$A$15) -> 23 | J36: =H36 -> 23
C37: PÓLIZAS Y SEGUROS | D37: =SUBTOTAL(9,D38:D43) -> 6631.1885 | E37: =SUBTOTAL(9,E38:E43) -> 878.30311
C38: Póliza de vida Ivan Estuardo Chavez Morales-USD-Póliza Vida | D38: =E38*$D$6 -> 1958.9985 | E38: 259.47 | F38: 45405 | G38: Cancelado | H38: =IF(OR(G38="Sin pagar",G38="Pagar"),NETWORKDAYS($E$4,F38,'Festivos Guatemala'!$A$3:$A$15),0) -> 0 | I38: =NETWORKDAYS($E$4,F38,'Festivos Guatemala'!$A$3:$A$15) -> 15 | J38: =H38 -> 0
C39: Poliza de vida Rony Eduardo Quan Lam-USD-Póliza Vida | D39: =E39*$D$6 -> 415.7785 | E39: 55.07 | F39: 45405 | G39: Cancelado | H39: =IF(OR(G39="Sin pagar",G39="Pagar"),NETWORKDAYS($E$4,F39,'Festivos Guatemala'!$A$3:$A$15),0) -> 0 | I39: =NETWORKDAYS($E$4,F39,'Festivos Guatemala'!$A$3:$A$15) -> 15 | J39: =H39 -> 0
C40: Poliza de vida Jerry García Carillo -USD-Póliza Vida | D40: =E40*$D$6 -> 1550.2415 | E40: 205.33 | F40: 45405 | G40: Cancelado | H40: =IF(OR(G40="Sin pagar",G40="Pagar"),NETWORKDAYS($E$4,F40,'Festivos Guatemala'!$A$3:$A$15),0) -> 0 | I40: =NETWORKDAYS($E$4,F40,'Festivos Guatemala'!$A$3:$A$15) -> 15 | J40: =H40 -> 0
C41: Póliza de vida Ivan Estuardo Chavez Morales-QTZ-GM | D41: 888.15 | E41: =D41/$D$6 -> 117.63576 | F41: 45405 | G41: Cancelado | H41: =IF(OR(G41="Sin pagar",G41="Pagar"),NETWORKDAYS($E$4,F41,'Festivos Guatemala'!$A$3:$A$15),0) -> 0 | I41: =NETWORKDAYS($E$4,F41,'Festivos Guatemala'!$A$3:$A$15) -> 15 | J41: =H41 -> 0
C42: Poliza de vida Rony Eduardo Quan Lam-QTQ-GM | D42: 903.72 | E42: =D42/$D$6 -> 119.69801 | F42: 45405 | G42: Cancelado | H42: =IF(OR(G42="Sin pagar",G42="Pagar"),NETWORKDAYS($E$4,F42,'Festivos Guatemala'!$A$3:$A$15),0) -> 0 | I42: =NETWORKDAYS($E$4,F42,'Festivos Guatemala'!$A$3:$A$15) -> 15 | J42: =H42 -> 0
C43: Poliza de vida Jerry García Carillo -QTQ-GM | D43: 914.3 | E43: =D43/$D$6 -> 121.09934 | F43: 45405 | G43: Cancelado | H43: =IF(OR(G43="Sin pagar",G43="Pagar"),NETWORKDAYS($E$4,F43,'Festivos Guatemala'!$A$3:$A$15),0) -> 0 | I43: =NETWORKDAYS($E$4,F43,'Festivos Guatemala'!$A$3:$A$15) -> 15 | J43: =H43 -> 0
C44: COBROS ENTRE SUCURSALES | D44: =SUBTOTAL(9,D45:D49) -> 0 | E44: =SUBTOTAL(9,E45:E49) -> 0
B45: 4640 | C45: Cobro S&P a sucursal Guatemala -Enero | D45: =E45*$D$6 -> 0 | E45: =917.15*0 -> 0 | F45: 45411 | G45: Sin Pagar | H45: =IF(OR(G45="Sin pagar",G45="Pagar"),NETWORKDAYS($E$4,F45,'Festivos Guatemala'!$A$3:$A$15),0) -> 19 | I45: =NETWORKDAYS($E$4,F45,'Festivos Guatemala'!$A$3:$A$15) -> 19 | J45: =H45 -> 19
...

Sheet Flujo caja Mayo
D1: 42400
D4: Fecha de Elaboración: | E4: 45413
C6: Tasa de cambio: | D6: 7.88
D7: ABRIL
D8: VALOR QTQ | E8: VALOR USD
C9: BANCOS | D9: =SUBTOTAL(9,D10:D11) -> 148167.93 | E9: =SUBTOTAL(9,E10:E11) -> 18803.037
C10: Bancos QTQ | D10: ='Caja QTQ'!$H$83-20720 -> 148157.29 | E10: =D10/$D$6 -> 18801.687
C11: Bancos USD | D11: ='Caja USD'!$H$31*'Flujo caja Mayo'!$D$6 -> 10.638 | E11: =D11/$D$6 -> 1.35
C12: CLIENTES | D12: =SUBTOTAL(9,D13:D16) -> 330738.31 | E12: =SUBTOTAL(9,E13:E16) -> 41971.867
C13: Client: Czarnikow- Sthepanie Rodriguez Lopez-TC 7.55 | D13: 41146.97 | E13: =D13/$D$6 -> 5221.6967
C14: Client:Energyzer-Ivan Chavez-Jerry García-Ronny Quan-TC 7.55 | D14: ='Diferencia en cambio'!$I$17 -> 269107.6 | E14: =D14/$D$6 -> 34150.711
C15: Client:Kairos-Ivan Chavez-Ruth Carolina Vasquez-TC 7.55 | D15: ='Diferencia en cambio'!I18 -> 7197.2643 | E15: =D15/$D$6 -> 913.35841
C16: Client: Opportunity-Edlin Ivette Poitan-TC 7.55 | D16: ='Diferencia en cambio'!$I$19 -> 13286.476 | E16: =D16/$D$6 -> 1686.101
C17: TOTAL INGRESOS | D17: =SUBTOTAL(9,D9:D16) -> 478906.24 | E17: =SUBTOTAL(9,E9:E16) -> 60774.903
B20: CUENTAS X PAGAR MES | D20: ABRIL
B21: Factura | C21: PROVEEDOR | D21: VALOR QTQ | E21: VALOR USD | F21: Fecha vencimiento | G21: Estado | J21: KPI
C22: SEGURIDAD IGSS | D22: =SUBTOTAL(9,D23:D23) -> 48442.26 | E22: =SUBTOTAL(9,E23:E23) -> 3864.0127
B23: 176206200 | C23: Pago planilla IGSS Abril | D23: 48442.26 | E23: =30448.42/$D$6 -> 3864.0127 | F23: 45426 | G23: Cancelado | H23: =IF(OR(G23="Sin pagar",G23="Pagar"),NETWORKDAYS($E$4,F23,'Festivos Guatemala'!$A$3:$A$15),0) -> 0 | I23: =NETWORKDAYS($E$4,F23,'Festivos Guatemala'!$A$3:$A$15) -> 10 | J23: =H23 -> 0
C24: IMPUESTOS | D24: =SUBTOTAL(9,D25:D27) -> 17579.69 | E24: =SUBTOTAL(9,E25:E27) -> 2230.9251 | J24: =H24 -> 0
B25: 42629341546 | C25: Declaraguate ISR Abril | D25: 15808 | E25: =D25/$D$6 -> 2006.0914 | F25: 45426 | G25: Cancelado | H25: =IF(OR(G25="Sin pagar",G25="Pagar"),NETWORKDAYS($E$4,F25,'Festivos Guatemala'!$A$3:$A$15),0) -> 0 | I25: =NETWORKDAYS($E$4,F25,'Festivos Guatemala'!$A$3:$A$15) -> 10 | J25: =H25 -> 0
B26: 426295952621 | C26: Declaraguate ISR Abril | D26: 1771.69 | E26: =D26/$D$6 -> 224.83376 | F26: 45426 | G26: Cancelado | H26: =IF(OR(G26="Sin pagar",G26="Pagar"),NETWORKDAYS($E$4,F26,'Festivos Guatemala'!$A$3:$A$15),0) -> 0 | I26: =NETWORKDAYS($E$4,F26,'Festivos Guatemala'!$A$3:$A$15) -> 10 | J26: =H26 -> 0
B27: 42780261927 | C27: Declaraguate IVA mes de abril | D27: 0 | E27: =D27/$D$6 -> 0 | F27: 45443 | G27: Cancelado | H27: =IF(OR(G27="Sin pagar",G27="Pagar"),NETWORKDAYS($E$4,F27,'Festivos Guatemala'!$A$3:$A$15),0) -> 0 | I27: =NETWORKDAYS($E$4,F27,'Festivos Guatemala'!$A$3:$A$15) -> 23 | J27: =H27 -> 0
C28: SERVICIOS PROFESIONALES -REPRESENTACIÓN LEGAL | D28: =SUBTOTAL(9,D29:D34) -> 5640 | E28: =SUBTOTAL(9,E29:E34) -> 715.73604 | J28: =H28 -> 0
C29: Servicios profesionales Juan-Servicios prestados-Abril | D29: 840 | E29: =D29/$D$6 -> 106.59898 | F29: 45420 | G29: Cancelado | H29: =IF(OR(G29="Sin pagar",G29="Pagar"),NETWORKDAYS($E$4,F29,'Festivos Guatemala'!$A$3:$A$15),0) -> 0 | I29: =NETWORKDAYS($E$4,F29,'Festivos Guatemala'!$A$3:$A$15) -> 6 | J29: =H29 -> 0
B30: 790 | C30: Servicios profesionales Arnoldo prestados en Enero | D30: =1200 -> 1200 | E30: =D30/$D$6 -> 152.28426 | F30: 45428 | G30: Cancelado | H30: =IF(OR(G30="Sin pagar",G30="Pagar"),NETWORKDAYS($E$4,F30,'Festivos Guatemala'!$A$3:$A$15),0) -> 0 | I30: =NETWORKDAYS($E$4,F30,'Festivos Guatemala'!$A$3:$A$15) -> 12 | J30: =H30 -> 0
B31: 780 | C31: Servicios profesionales Arnoldo prestados en Febrero | D31: =1200 -> 1200 | E31: =D31/$D$6 -> 152.28426 | F31: 45428 | G31: Cancelado | H31: =IF(OR(G31="Sin pagar",G31="Pagar"),NETWORKDAYS($E$4,F31,'Festivos Guatemala'!$A$3:$A$15),0) -> 0 | I31: =NETWORKDAYS($E$4,F31,'Festivos Guatemala'!$A$3:$A$15) -> 12 | J31: =H31 -> 0
B32: 830 | C32: Servicios profesionales Arnoldo prestados en Marzo | D32: =1200 -> 1200 | E32: =D32/$D$6 -> 152.28426 | F32: 45428 | G32: Cancelado | H32: =IF(OR(G32="Sin pagar",G32="Pagar"),NETWORKDAYS($E$4,F32,'Festivos Guatemala'!$A$3:$A$15),0) -> 0 | I32: =NETWORKDAYS($E$4,F32,'Festivos Guatemala'!$A$3:$A$15) -> 12 | J32: =H32 -> 0
B33: 921 | C33: Servicios profesionales Arnoldo prestados en Abril | D33: =1200 -> 1200 | E33: =D33/$D$6 -> 152.28426 | F33: 45467 | G33: Cancelado | H33: =IF(OR(G33="Sin pagar",G33="Pagar"),NETWORKDAYS($E$4,F33,'Festivos Guatemala'!$A$3:$A$15),0) -> 0 | I33: =NETWORKDAYS($E$4,F33,'Festivos Guatemala'!$A$3:$A$15) -> 39 | J33: =H33 -> 0
B34: 922 | C34: Servicios profesionales Arnoldo prestados en Mayo | D34: =1200*0 -> 0 | E34: =D34/$D$6 -> 0 | F34: 45473 | G34: Cancelado | H34: =IF(OR(G34="Sin pagar",G34="Pagar"),NETWORKDAYS($E$4,F34,'Festivos Guatemala'!$A$3:$A$15),0) -> 0 | I34: =NETWORKDAYS($E$4,F34,'Festivos Guatemala'!$A$3:$A$15) -> 43 | J34: =H34 -> 0
C35: PÓLIZAS Y SEGUROS | D35: =SUBTOTAL(9,D36:D41) -> 7717.0456 | E35: =SUBTOTAL(9,E36:E41) -> 979.32051
B36: Valores previstos | C36: Póliza de vida Ivan Estuardo Chavez Morales-USD-Póliza Vida | D36: =E36*$D$6 -> 2044.6236 | E36: 259.47 | F36: 45440 | G36: Cancelado | H36: =IF(OR(G36="Sin pagar",G36="Pagar"),NETWORKDAYS($E$4,F36,'Festivos Guatemala'!$A$3:$A$15),0) -> 0 | I36: =NETWORKDAYS($E$4,F36,'Festivos Guatemala'!$A$3:$A$15) -> 20 | J36: =H36 -> 0
C37: Poliza de vida Rony Eduardo Quan Lam-USD-Póliza Vida | D37: =E37*$D$6 -> 433.9516 | E37: 55.07 | F37: 45440 | G37: Cancelado | H37: =IF(OR(G37="Sin pagar",G37="Pagar"),NETWORKDAYS($E$4,F37,'Festivos Guatemala'!$A$3:$A$15),0) -> 0 | I37: =NETWORKDAYS($E$4,F37,'Festivos Guatemala'!$A$3:$A$15) -> 20 | J37: =H37 -> 0
C38: Poliza de vida Jerry García Carillo -USD-Póliza Vida | D38: =E38*$D$6 -> 1618.0004 | E38: 205.33 | F38: 45440 | G38: Cancelado | H38: =IF(OR(G38="Sin pagar",G38="Pagar"),NETWORKDAYS($E$4,F38,'Festivos Guatemala'!$A$3:$A$15),0) -> 0 | I38: =NETWORKDAYS($E$4,F38,'Festivos Guatemala'!$A$3:$A$15) -> 20 | J38: =H38 -> 0
C39: Póliza de vida Ivan Estuardo Chavez Morales-QTQ-GM | D39: 888.15 | E39: =D39/$D$6 -> 112.70939 | F39: 45440 | G39: Cancelado | H39: =IF(OR(G39="Sin pagar",G39="Pagar"),NETWORKDAYS($E$4,F39,'Festivos Guatemala'!$A$3:$A$15),0) -> 0 | I39: =NETWORKDAYS($E$4,F39,'Festivos Guatemala'!$A$3:$A$15) -> 20 | J39: =H39 -> 0
C40: Poliza de vida Rony Eduardo Quan Lam-QTQ-GM | D40: 903.72 | E40: =D40/$D$6 -> 114.68528 | F40: 45440 | G40: Cancelado | H40: =IF(OR(G40="Sin pagar",G40="Pagar"),NETWORKDAYS($E$4,F40,'Festivos Guatemala'!$A$3:$A$15),0) -> 0 | I40: =NETWORKDAYS($E$4,F40,'Festivos Guatemala'!$A$3:$A$15) -> 20 | J40: =H40 -> 0
C41: Poliza de vida Jerry García Carillo -QTQ-GM-Claudia Marisol Mayorga Ayala | D41: 1828.6 | E41: =D41/$D$6 -> 232.05584 | F41: 45441 | G41: Cancelado | H41: =IF(OR(G41="Sin pagar",G41="Pagar"),NETWORKDAYS($E$4,F41,'Festivos Guatemala'!$A$3:$A$15),0) -> 0 | I41: =NETWORKDAYS($E$4,F41,'Festivos Guatemala'!$A$3:$A$15) -> 21 | J41: =H41 -> 0
C42: COBROS ENTRE SUCURSALES | D42: =SUBTOTAL(9,D43:D48) -> 0 | E42: =SUBTOTAL(9,E43:E48) -> 0
B43: 4640 | C43: Cobro S&P a sucursal Guatemala -Enero | D43: =E43*$D$6 -> 0 | E43: =917.15*0 -> 0 | F43: 45443 | G43: Cancelado | H43: =IF(OR(G43="Sin pagar",G43="Pagar"),NETWORKDAYS($E$4,F43,'Festivos Guatemala'!$A$3:$A$15),0) -> 0 | I43: =NETWORKDAYS($E$4,F43,'Festivos Guatemala'!$A$3:$A$15) -> 23 | J43: =H43 -> 0
B44: 4641 | C44: Cobro S&P a sucursal Guatemala -febrero | D44: =E44*$D$6 -> 0 | E44: =832.5*0 -> 0 | F44: 45443 | G44: Cancelado | H44: =IF(OR(G44="Sin pagar",G44="Pagar"),NETWORKDAYS($E$4,F44,'Festivos Guatemala'!$A$3:$A$15),0) -> 0 | I44: =NETWORKDAYS($E$4,F44,'Festivos Guatemala'!$A$3:$A$15) -> 23 | J44: =H44 -> 0
B45: 4700 | C45: Cobro S&P a sucursal Guatemala -Marzo | D45: =E45*$D$6 -> 0 | E45: =1009.3*0 -> 0 | F45: 45443 | G45: Cancelado | H45: =IF(OR(G45="Sin pagar",G45="Pagar"),NETWORKDAYS($E$4,F45,'Festivos Guatemala'!$A$3:$A$15),0) -> 0 | I45: =NETWORKDAYS($E$4,F45,'Festivos Guatemala'!$A$3:$A$15) -> 23 | J45: =H45 -> 0
...

Sheet Flujo caja Junio 
D1: 42400
D4: Fecha de Elaboración: | E4: 45447
C6: Tasa de cambio: | D6: 7.55
D7: ABRIL
D8: VALOR QTQ | E8: VALOR USD
C9: BANCOS | D9: =SUBTOTAL(9,D10:D12) -> 229471.41 | E9: =SUBTOTAL(9,E10:E12) -> 30393.564
C10: Bancos QTQ | D10: ='Caja QTQ'!$H$111+43089.5890499999 -> 220272.94 | E10: =D10/$D$6 -> 29175.224
C11: Bancos USD | D11: ='Caja USD'!H40*$D$6 -> 981.4245 | E11: =D11/$D$6 -> 129.99
C12: Devolución de Dinero Ivan Estuardo Chavez | D12: ='Caja USD'!$D$47*D6 -> 8217.0425 | E12: =D12/$D$6 -> 1088.35
C13: CLIENTES | D13: =SUBTOTAL(9,D14:D18) -> 450741.79 | E13: =SUBTOTAL(9,E14:E18) -> 59675.833
C14: Client: Czarnikow- Sthepanie Rodriguez Lopez-TC 7.55 | D14: 41200.42 | E14: =D14/7.55 -> 5457.0093
C15: Client:Energyzer-Ivan Chavez-Jerry García-Ronny Quan-TC 7.55 | D15: 341220.02 | E15: =D15/7.55 -> 45194.705
C16: Client:Kairos-Ivan Chavez-Ruth Carolina Vasquez-TC 7.55 | D16: 9387.8072 | E16: =D16/7.55 -> 1243.4182
C17: Client: Opportunity-Edlin Ivette Poitan-TC 7.55 | D17: 15861.723 | E17: =D17/7.55 -> 2100.8905
C18: Client: NotableGrowth, Inc-TC 7.55 | D18: 43071.81 | E18: 5679.81
C19: TOTAL INGRESOS | D19: =SUBTOTAL(9,D9:D18) -> 680213.19 | E19: =SUBTOTAL(9,E9:E18) -> 90069.397
B22: CUENTAS X PAGAR MES | D22: ABRIL
B23: Factura | C23: PROVEEDOR | D23: VALOR QTQ | E23: VALOR USD | F23: Fecha vencimiento | G23: Estado | J23: KPI
C24: SEGURIDAD IGSS | D24: =SUBTOTAL(9,D25:D25) -> 39252.51 | E24: =SUBTOTAL(9,E25:E25) -> 4032.9033
B25: 176206200 | C25: Pago planilla IGSS Mayo | D25: 39252.51 | E25: =30448.42/$D$6 -> 4032.9033 | F25: 45456 | G25: Cancelado | H25: =IF(OR(G25="Sin pagar",G25="Pagar"),NETWORKDAYS($E$4,F25,'Festivos Guatemala'!$A$3:$A$15),0) -> 0 | I25: =NETWORKDAYS($E$4,F25,'Festivos Guatemala'!$A$3:$A$15) -> 8 | J25: =H25 -> 0
C26: IMPUESTOS | D26: =SUBTOTAL(9,D27:D29) -> 13238.19 | E26: =SUBTOTAL(9,E27:E29) -> 1753.4026 | J26: =H26 -> 0
B27: 42629341546 | C27: Declaraguate ISR Mayo | D27: 11895.04 | E27: =D27/$D$6 -> 1575.502 | F27: 45457 | G27: Cancelado | H27: =IF(OR(G27="Sin pagar",G27="Pagar"),NETWORKDAYS($E$4,F27,'Festivos Guatemala'!$A$3:$A$15),0) -> 0 | I27: =NETWORKDAYS($E$4,F27,'Festivos Guatemala'!$A$3:$A$15) -> 9 | J27: =H27 -> 0
B28: 426295952621 | C28: Declaraguate ISR Mayo facturación Col | D28: 1343.15 | E28: =D28/$D$6 -> 177.90066 | F28: 45457 | G28: Cancelado | H28: =IF(OR(G28="Sin pagar",G28="Pagar"),NETWORKDAYS($E$4,F28,'Festivos Guatemala'!$A$3:$A$15),0) -> 0 | I28: =NETWORKDAYS($E$4,F28,'Festivos Guatemala'!$A$3:$A$15) -> 9 | J28: =H28 -> 0
B29: 42780261927 | C29: Declaraguate IVA mes de abril | D29: 0 | E29: =D29/$D$6 -> 0 | F29: 45473 | G29: Cancelado | H29: =IF(OR(G29="Sin pagar",G29="Pagar"),NETWORKDAYS($E$4,F29,'Festivos Guatemala'!$A$3:$A$15),0) -> 0 | I29: =NETWORKDAYS($E$4,F29,'Festivos Guatemala'!$A$3:$A$15) -> 19 | J29: =H29 -> 0
C30: SERVICIOS PROFESIONALES -REPRESENTACIÓN LEGAL | D30: =SUBTOTAL(9,D31:D32) -> 840 | E30: =SUBTOTAL(9,E31:E32) -> 111.25828 | J30: =H30 -> 0
C31: Servicios profesionales Juan-Servicios prestados-Mayo | D31: 840 | E31: =D31/$D$6 -> 111.25828 | F31: 45450 | G31: Cancelado | H31: =IF(OR(G31="Sin pagar",G31="Pagar"),NETWORKDAYS($E$4,F31,'Festivos Guatemala'!$A$3:$A$15),0) -> 0 | I31: =NETWORKDAYS($E$4,F31,'Festivos Guatemala'!$A$3:$A$15) -> 4 | J31: =H31 -> 0
B32: 922 | C32: Servicios profesionales Arnoldo prestados en Mayo | D32: =1200*0 -> 0 | E32: =D32/$D$6 -> 0 | F32: 45464 | G32: Cancelado | H32: =IF(OR(G32="Sin pagar",G32="Pagar"),NETWORKDAYS($E$4,F32,'Festivos Guatemala'!$A$3:$A$15),0) -> 0 | I32: =NETWORKDAYS($E$4,F32,'Festivos Guatemala'!$A$3:$A$15) -> 14 | J32: =H32 -> 0
C33: PÓLIZAS Y SEGUROS | D33: =SUBTOTAL(9,D34:D39) -> 7545.4885 | E33: =SUBTOTAL(9,E34:E39) -> 999.40245
C34: Póliza de vida Ivan Estuardo Chavez Morales-USD-Póliza Vida | D34: =E34*$D$6 -> 415.7785 | E34: =55.07 -> 55.07 | F34: 45471 | G34: Cancelado | H34: =IF(OR(G34="Sin pagar",G34="Pagar"),NETWORKDAYS($E$4,F34,'Festivos Guatemala'!$A$3:$A$15),0) -> 0 | I34: =NETWORKDAYS($E$4,F34,'Festivos Guatemala'!$A$3:$A$15) -> 19 | J34: =H34 -> 0
C35: Poliza de vida Rony Eduardo Quan Lam-USD-Póliza Vida | D35: =E35*$D$6 -> 1958.9985 | E35: =259.47 -> 259.47 | F35: 45471 | G35: Cancelado | H35: =IF(OR(G35="Sin pagar",G35="Pagar"),NETWORKDAYS($E$4,F35,'Festivos Guatemala'!$A$3:$A$15),0) -> 0 | I35: =NETWORKDAYS($E$4,F35,'Festivos Guatemala'!$A$3:$A$15) -> 19 | J35: =H35 -> 0
C36: Poliza de vida Jerry García Carillo -USD-Póliza Vida | D36: =E36*$D$6 -> 1550.2415 | E36: =205.33 -> 205.33 | F36: 45471 | G36: Cancelado | H36: =IF(OR(G36="Sin pagar",G36="Pagar"),NETWORKDAYS($E$4,F36,'Festivos Guatemala'!$A$3:$A$15),0) -> 0 | I36: =NETWORKDAYS($E$4,F36,'Festivos Guatemala'!$A$3:$A$15) -> 19 | J36: =H36 -> 0
C37: Póliza de vida Ivan Estuardo Chavez Morales-QTQ-GM | D37: =888.15 -> 888.15 | E37: =D37/$D$6 -> 117.63576 | F37: 45471 | G37: Cancelado | H37: =IF(OR(G37="Sin pagar",G37="Pagar"),NETWORKDAYS($E$4,F37,'Festivos Guatemala'!$A$3:$A$15),0) -> 0 | I37: =NETWORKDAYS($E$4,F37,'Festivos Guatemala'!$A$3:$A$15) -> 19 | J37: =H37 -> 0
C38: Poliza de vida Rony Eduardo Quan Lam-QTQ-GM | D38: =903.72 -> 903.72 | E38: =D38/$D$6 -> 119.69801 | F38: 45471 | G38: Cancelado | H38: =IF(OR(G38="Sin pagar",G38="Pagar"),NETWORKDAYS($E$4,F38,'Festivos Guatemala'!$A$3:$A$15),0) -> 0 | I38: =NETWORKDAYS($E$4,F38,'Festivos Guatemala'!$A$3:$A$15) -> 19 | J38: =H38 -> 0
C39: Poliza de vida Jerry García Carillo -QTQ-GM-Claudia Marisol Mayorga Ayala | D39: =1828.6 -> 1828.6 | E39: =D39/$D$6 -> 242.19868 | F39: 45471 | G39: Cancelado | H39: =IF(OR(G39="Sin pagar",G39="Pagar"),NETWORKDAYS($E$4,F39,'Festivos Guatemala'!$A$3:$A$15),0) -> 0 | I39: =NETWORKDAYS($E$4,F39,'Festivos Guatemala'!$A$3:$A$15) -> 19 | J39: =H39 -> 0
C40: COBROS ENTRE SUCURSALES | D40: =SUBTOTAL(9,D41:D47) -> 48575.265 | E40: =SUBTOTAL(9,E41:E47) -> 6433.81 | M40: =SUM(M41:M47) -> 42965403 | N40: =11000*4145.1 -> 45596100
B41: 4640 | C41: Cobro S&P a sucursal Guatemala -Enero | D41: =E41*$D$6 -> 6924.4825 | E41: =917.15 -> 917.15 | F41: 45449 | G41: Cancelado | H41: =IF(OR(G41="Sin pagar",G41="Pagar"),NETWORKDAYS($E$4,F41,'Festivos Guatemala'!$A$3:$A$15),0) -> 0 | I41: =NETWORKDAYS($E$4,F41,'Festivos Guatemala'!$A$3:$A$15) -> 3 | J41: =H41 -> 0 | M41: =E41*3933.56 -> 3607664.6
B42: 4641 | C42: Cobro S&P a sucursal Guatemala -febrero | D42: =E42*$D$6 -> 6285.375 | E42: =832.5 -> 832.5 | F42: 45449 | G42: Cancelado | H42: =IF(OR(G42="Sin pagar",G42="Pagar"),NETWORKDAYS($E$4,F42,'Festivos Guatemala'!$A$3:$A$15),0) -> 0 | I42: =NETWORKDAYS($E$4,F42,'Festivos Guatemala'!$A$3:$A$15) -> 3 | J42: =H42 -> 0 | M42: =E42*3933.56 -> 3274688.7
B43: 4700 | C43: Cobro S&P a sucursal Guatemala -Marzo | D43: =E43*$D$6 -> 7620.215 | E43: =1009.3 -> 1009.3 | F43: 45449 | G43: Cancelado | H43: =IF(OR(G43="Sin pagar",G43="Pagar"),NETWORKDAYS($E$4,F43,'Festivos Guatemala'!$A$3:$A$15),0) -> 0 | I43: =NETWORKDAYS($E$4,F43,'Festivos Guatemala'!$A$3:$A$15) -> 3 | J43: =H43 -> 0 | M43: =E43*3888.02 -> 3924178.6
B44: 4707 | C44: Cobro S&P a sucursal Guatemala -Marzo | D44: =E44*$D$6 -> 7550 | E44: =1000 -> 1000 | F44: 45449 | G44: Cancelado | H44: =IF(OR(G44="Sin pagar",G44="Pagar"),NETWORKDAYS($E$4,F44,'Festivos Guatemala'!$A$3:$A$15),0) -> 0 | I44: =NETWORKDAYS($E$4,F44,'Festivos Guatemala'!$A$3:$A$15) -> 3 | J44: =H44 -> 0 | M44: =E44*3865.97 -> 3865970
B45: 4776 | C45: Cobro S&P a sucursal Guatemala -Abril | D45: =E45*$D$6 -> 11487.325 | E45: =1521.5 -> 1521.5 | F45: 45449 | G45: Cancelado | H45: =IF(OR(G45="Sin pagar",G45="Pagar"),NETWORKDAYS($E$4,F45,'Festivos Guatemala'!$A$3:$A$15),0) -> 0 | I45: =NETWORKDAYS($E$4,F45,'Festivos Guatemala'!$A$3:$A$15) -> 3 | J45: =H45 -> 0 | M45: =E45*3924.82 -> 5971613.6
...

Sheet Flujo caja Julio
D1: 42400
D4: Fecha de Elaboración: | E4: 45475
C6: Tasa de cambio: | D6: 7.55
D7: JULIO
D8: VALOR QTQ | E8: VALOR USD
C9: BANCOS | D9: =SUBTOTAL(9,D10:D11) -> 170811.57 | E9: =SUBTOTAL(9,E10:E11) -> 26393.188
C10: Bancos QTQ | D10: ='Caja QTQ'!$D$142 -> 166466.99 | E10: =D10/$D$6 -> 22048.608
C11: Bancos USD | D11: ='Caja USD'!$H$53 -> 4344.58 | E11: ='Caja USD'!D58 -> 4344.58
C12: CLIENTES | D12: =SUBTOTAL(9,D13:D17) -> 389916.26 | E12: =SUBTOTAL(9,E13:E17) -> 51644.538
C13: Client: Czarnikow- Sthepanie Rodriguez Lopez-TC 7.55 | D13: ='Diferencia en cambio'!$I$25 -> 41329.252 | E13: =D13/$D$6 -> 5474.0732
C14: Client:Energyzer-Ivan Chavez-Jerry García-Ronny Quan-TC 7.55 | D14: ='Diferencia en cambio'!$I$26 -> 284899.12 | E14: =D14/$D$6 -> 37734.983
C15: Client:Kairos-Ivan Chavez-Ruth Carolina Vasquez-TC 7.55 | D15: ='Diferencia en cambio'!$I$27 -> 7197.2643 | E15: =D15/$D$6 -> 953.28004
C16: Client: Opportunity-Edlin Ivette Poitan-TC 7.55 | D16: ='Diferencia en cambio'!$I$28 -> 13286.476 | E16: =D16/$D$6 -> 1759.7981
C17: Client: NotableGrowth, Inc-TC 7.55 | D17: ='Diferencia en cambio'!$I$29 -> 43204.148 | E17: =D17/$D$6 -> 5722.4037
C18: TOTAL INGRESOS | D18: =SUBTOTAL(9,D9:D17) -> 560727.83 | E18: =SUBTOTAL(9,E9:E17) -> 78037.726
B21: CUENTAS X PAGAR MES | D21: ABRIL
B22: Factura | C22: PROVEEDOR | D22: VALOR QTQ | E22: VALOR USD | F22: Fecha vencimiento | G22: Estado | J22: KPI
C23: SEGURIDAD IGSS | D23: =SUBTOTAL(9,D24:D24) -> 43669.12 | E23: =SUBTOTAL(9,E24:E24) -> 4032.9033
B24: 176206200 | C24: Pago planilla IGSS Junio | D24: =43669.12 -> 43669.12 | E24: =30448.42/$D$6 -> 4032.9033 | F24: 45483 | G24: Cancelado | H24: =IF(OR(G24="Sin pagar",G24="Pagar"),NETWORKDAYS($E$4,F24,'Festivos Guatemala'!$A$3:$A$15),0) -> 0 | I24: =NETWORKDAYS($E$4,F24,'Festivos Guatemala'!$A$3:$A$15) -> 7 | J24: =H24 -> 0
C25: IMPUESTOS | D25: =SUBTOTAL(9,D26:D30) -> 15152.01 | E25: =SUBTOTAL(9,E26:E30) -> 2006.8887 | J25: =H25 -> 0
B26: 42629341546 | C26: Declaraguate ISR Junio | D26: 12837.81 | E26: =D26/$D$6 -> 1700.3722 | F26: 45488 | G26: Cancelado | H26: =IF(OR(G26="Sin pagar",G26="Pagar"),NETWORKDAYS($E$4,F26,'Festivos Guatemala'!$A$3:$A$15),0) -> 0 | I26: =NETWORKDAYS($E$4,F26,'Festivos Guatemala'!$A$3:$A$15) -> 10 | J26: =H26 -> 0
B27: 426295952621 | C27: Declaraguate ISR Julio facturación Col | D27: 1755.82 | E27: =D27/$D$6 -> 232.55894 | F27: 45488 | G27: Cancelado | H27: =IF(OR(G27="Sin pagar",G27="Pagar"),NETWORKDAYS($E$4,F27,'Festivos Guatemala'!$A$3:$A$15),0) -> 0 | I27: =NETWORKDAYS($E$4,F27,'Festivos Guatemala'!$A$3:$A$15) -> 10 | J27: =H27 -> 0
B28: 43589111783 | C28: Declaraguate IVA mes de Junio | D28: 0 | E28: =D28/$D$6 -> 0 | F28: 45504 | G28: Cancelado | H28: =IF(OR(G28="Sin pagar",G28="Pagar"),NETWORKDAYS($E$4,F28,'Festivos Guatemala'!$A$3:$A$15),0) -> 0 | I28: =NETWORKDAYS($E$4,F28,'Festivos Guatemala'!$A$3:$A$15) -> 22 | J28: =H28 -> 0
B29: 43631922735 | C29: Declaraguate Pago ISO | D29: 558.38 | E29: =D29/$D$6 -> 73.957616 | F29: 45504 | G29: Cancelado | H29: =IF(OR(G29="Sin pagar",G29="Pagar"),NETWORKDAYS($E$4,F29,'Festivos Guatemala'!$A$3:$A$15),0) -> 0 | I29: =NETWORKDAYS($E$4,F29,'Festivos Guatemala'!$A$3:$A$15) -> 22 | J29: =H29 -> 0
B30: 43640140958 | C30: Declaraguate declaración de ISR 2do trimestre 2024 | D30: 0 | E30: =D30/$D$6 -> 0 | F30: 45504 | G30: Cancelado | H30: =IF(OR(G30="Sin pagar",G30="Pagar"),NETWORKDAYS($E$4,F30,'Festivos Guatemala'!$A$3:$A$15),0) -> 0 | I30: =NETWORKDAYS($E$4,F30,'Festivos Guatemala'!$A$3:$A$15) -> 22 | J30: =H30 -> 0
C31: SERVICIOS PROFESIONALES -REPRESENTACIÓN LEGAL | D31: =SUBTOTAL(9,D32:D33) -> 2040 | E31: =SUBTOTAL(9,E32:E33) -> 270.19868 | J31: =H31 -> 0
C32: Servicios profesionales Juan-Servicios prestados-Junio | D32: 840 | E32: =D32/$D$6 -> 111.25828 | F32: 45483 | G32: Cancelado | H32: =IF(OR(G32="Sin pagar",G32="Pagar"),NETWORKDAYS($E$4,F32,'Festivos Guatemala'!$A$3:$A$15),0) -> 0 | I32: =NETWORKDAYS($E$4,F32,'Festivos Guatemala'!$A$3:$A$15) -> 7 | J32: =H32 -> 0
B33: 922 | C33: Servicios profesionales Arnoldo prestados en Mayo | D33: =1200 -> 1200 | E33: =D33/$D$6 -> 158.9404 | F33: 45485 | G33: Cancelado | H33: =IF(OR(G33="Sin pagar",G33="Pagar"),NETWORKDAYS($E$4,F33,'Festivos Guatemala'!$A$3:$A$15),0) -> 0 | I33: =NETWORKDAYS($E$4,F33,'Festivos Guatemala'!$A$3:$A$15) -> 9 | J33: =H33 -> 0
C34: PÓLIZAS Y SEGUROS | D34: =SUBTOTAL(9,D35:D43) -> 11165.959 | E34: =SUBTOTAL(9,E35:E43) -> 1478.9349
C35: Poliza de vida Jerry García Carillo -QTQ-GM-Claudia Marisol Mayorga Ayala | D35: 1828.6 | E35: =D35/$D$6 -> 242.19868 | F35: 45475 | G35: Cancelado | H35: =IF(OR(G35="Sin pagar",G35="Pagar"),NETWORKDAYS($E$4,F35,'Festivos Guatemala'!$A$3:$A$15),0) -> 0 | I35: =NETWORKDAYS($E$4,F35,'Festivos Guatemala'!$A$3:$A$15) -> 1 | J35: =H35 -> 0
C36: Póliza de vida Ivan Estuardo Chavez Morales-QTQ-GM | D36: 888.15 | E36: =D36/$D$6 -> 117.63576 | F36: 45475 | G36: Cancelado | H36: =IF(OR(G36="Sin pagar",G36="Pagar"),NETWORKDAYS($E$4,F36,'Festivos Guatemala'!$A$3:$A$15),0) -> 0 | I36: =NETWORKDAYS($E$4,F36,'Festivos Guatemala'!$A$3:$A$15) -> 1 | J36: =H36 -> 0
C37: Poliza de vida Rony Eduardo Quan Lam-QTQ-GM | D37: 903.72 | E37: =D37/$D$6 -> 119.69801 | F37: 45475 | G37: Cancelado | H37: =IF(OR(G37="Sin pagar",G37="Pagar"),NETWORKDAYS($E$4,F37,'Festivos Guatemala'!$A$3:$A$15),0) -> 0 | I37: =NETWORKDAYS($E$4,F37,'Festivos Guatemala'!$A$3:$A$15) -> 1 | J37: =H37 -> 0
C38: Póliza de vida Ivan Estuardo Chavez Morales-USD-Póliza Vida | D38: =E38*$D$6 -> 415.7785 | E38: 55.07 | F38: 45496 | G38: Cancelado | H38: =IF(OR(G38="Sin pagar",G38="Pagar"),NETWORKDAYS($E$4,F38,'Festivos Guatemala'!$A$3:$A$15),0) -> 0 | I38: =NETWORKDAYS($E$4,F38,'Festivos Guatemala'!$A$3:$A$15) -> 16 | J38: =H38 -> 0
C39: Poliza de vida Rony Eduardo Quan Lam-USD-Póliza Vida | D39: =E39*$D$6 -> 1958.9985 | E39: 259.47 | F39: 45496 | G39: Cancelado | H39: =IF(OR(G39="Sin pagar",G39="Pagar"),NETWORKDAYS($E$4,F39,'Festivos Guatemala'!$A$3:$A$15),0) -> 0 | I39: =NETWORKDAYS($E$4,F39,'Festivos Guatemala'!$A$3:$A$15) -> 16 | J39: =H39 -> 0
C40: Poliza de vida Jerry García Carillo -USD-Póliza Vida | D40: =E40*$D$6 -> 1550.2415 | E40: 205.33 | F40: 45496 | G40: Cancelado | H40: =IF(OR(G40="Sin pagar",G40="Pagar"),NETWORKDAYS($E$4,F40,'Festivos Guatemala'!$A$3:$A$15),0) -> 0 | I40: =NETWORKDAYS($E$4,F40,'Festivos Guatemala'!$A$3:$A$15) -> 16 | J40: =H40 -> 0
C41: Póliza de vida Ivan Estuardo Chavez Morales-QTQ-GM | D41: 888.15 | E41: =D41/$D$6 -> 117.63576 | F41: 45496 | G41: Cancelado | H41: =IF(OR(G41="Sin pagar",G41="Pagar"),NETWORKDAYS($E$4,F41,'Festivos Guatemala'!$A$3:$A$15),0) -> 0 | I41: =NETWORKDAYS($E$4,F41,'Festivos Guatemala'!$A$3:$A$15) -> 16 | J41: =H41 -> 0
C42: Poliza de vida Rony Eduardo Quan Lam-QTQ-GM | D42: 903.72 | E42: =D42/$D$6 -> 119.69801 | F42: 45496 | G42: Cancelado | H42: =IF(OR(G42="Sin pagar",G42="Pagar"),NETWORKDAYS($E$4,F42,'Festivos Guatemala'!$A$3:$A$15),0) -> 0 | I42: =NETWORKDAYS($E$4,F42,'Festivos Guatemala'!$A$3:$A$15) -> 16 | J42: =H42 -> 0
C43: Poliza de vida Jerry García Carillo -QTQ-GM-Claudia Marisol Mayorga Ayala | D43: 1828.6 | E43: =D43/$D$6 -> 242.19868 | F43: 45496 | G43: Cancelado | H43: =IF(OR(G43="Sin pagar",G43="Pagar"),NETWORKDAYS($E$4,F43,'Festivos Guatemala'!$A$3:$A$15),0) -> 0 | I43: =NETWORKDAYS($E$4,F43,'Festivos Guatemala'!$A$3:$A$15) -> 16 | J43: =H43 -> 0
C44: COBROS ENTRE SUCURSALES | D44: =SUBTOTAL(9,D45:D46) -> 0 | E44: =SUBTOTAL(9,E45:E46) -> 0 | M44: =SUM(M45:M45) -> 17820150 | N44: =11000*4145.1 -> 45596100
B45: 4944 | C45: Cobro S&P a sucursal Guatemala -Junio | D45: =E45*$D$6 -> 0 | E45: =((1507.5)*0) -> 0 | F45: 45499 | G45: Cancelado | H45: =IF(OR(G45="Sin pagar",G45="Pagar"),NETWORKDAYS($E$4,F45,'Festivos Guatemala'!$A$3:$A$15),0) -> 0 | I45: =NETWORKDAYS($E$4,F45,'Festivos Guatemala'!$A$3:$A$15) -> 19 | J45: =H45 -> 0 | M45: =(11000-6433.81)*3902.63 -> 17820150
...

Sheet Flujo caja Agosto
D1: 42400
D4: Fecha de Elaboración: | E4: 45506
C6: Tasa de cambio: | D6: 7.58
D7: AGOSTO
D8: VALOR QTQ | E8: VALOR USD
C9: BANCOS | D9: =SUBTOTAL(9,D10:D12) -> 215137.73 | E9: =SUBTOTAL(9,E10:E12) -> 28382.286
C10: Bancos QTQ | D10: ='Caja QTQ'!$H$167 -> 183654.45 | E10: =D10/$D$6 -> 24228.82
C11: Bancos USD | D11: =E11*D6 -> 6427.1578 | E11: 847.91
C12: Ajuste a ingreso | D12: 25056.12 | E12: =D12/D6 -> 3305.5567
C13: CLIENTES | D13: =SUBTOTAL(9,D14:D20) -> 350253.08 | E13: =SUBTOTAL(9,E14:E20) -> 45885.614
C14: Client: Czarnikow- Sthepanie Rodriguez Lopez | D14: ='Diferencia en cambio'!$I$30 -> 41118.301 | E14: =D14/'Diferencia en cambio'!$L$30 -> 5412.3008
C15: Client:Energyzer-Ivan Chavez-Jerry García-Ronny Quan | D15: ='Diferencia en cambio'!$I$31 -> 220045.98 | E15: =D15/'Diferencia en cambio'!$L$31 -> 28731.467
C16: Client:Kairos-Ivan Chavez-Ruth Carolina Vasquez | D16: ='Diferencia en cambio'!$I$32 -> 7266.2065 | E16: =D16/'Diferencia en cambio'!$L$32 -> 948.75066
C17: Client: Opportunity-Edlin Ivette Poitan | D17: ='Caja QTQ'!$D$172 -> 13203.01 | E17: =D17/'Diferencia en cambio'!$L$33 -> 1751.4367
C18: Client: NotableGrowth, Inc | D18: ='Diferencia en cambio'!$I$34 -> 42983.472 | E18: =D18/'Diferencia en cambio'!$L$34 -> 5657.8087
C19: Client: Panthera, Inc | D19: ='Diferencia en cambio'!$I$35 -> 6832.27 | E19: =D19/'Diferencia en cambio'!$L$35 -> 908.7473
C20: Client: Bilingual Bridges, Inc | D20: ='Diferencia en cambio'!$I$36 -> 18803.838 | E20: =D20/'Diferencia en cambio'!$L$36 -> 2475.1029
C21: TOTAL INGRESOS | D21: =SUBTOTAL(9,D9:D18) -> 539754.7 | E21: =SUBTOTAL(9,E9:E18) -> 70884.05
B24: CUENTAS X PAGAR MES | D24: AGOSTO
B25: Factura | C25: PROVEEDOR | D25: VALOR QTQ | E25: VALOR USD | F25: Fecha vencimiento | G25: Estado | J25: KPI
C26: SEGURIDAD IGSS | D26: =SUBTOTAL(9,D27:D27) -> 48735.99 | E26: =SUBTOTAL(9,E27:E27) -> 4016.942
B27: 176206200 | C27: Pago planilla IGSS Julio | D27: 48735.99 | E27: =30448.42/$D$6 -> 4016.942 | F27: 45513 | G27: Cancelado | H27: =IF(OR(G27="Sin pagar",G27="Pagar"),NETWORKDAYS($E$4,F27,'Festivos Guatemala'!$A$3:$A$15),0) -> 0 | I27: =NETWORKDAYS($E$4,F27,'Festivos Guatemala'!$A$3:$A$15) -> 6 | J27: =H27 -> 0
C28: IMPUESTOS | D28: =SUBTOTAL(9,D29:D31) -> 16396.43 | E28: =SUBTOTAL(9,E29:E31) -> 2163.1174 | J28: =H28 -> 0
B29: 43809986140 | C29: Declaraguate ISR Julio | D29: 14909.47 | E29: =D29/$D$6 -> 1966.9485 | F29: 45518 | G29: Cancelado | H29: =IF(OR(G29="Sin pagar",G29="Pagar"),NETWORKDAYS($E$4,F29,'Festivos Guatemala'!$A$3:$A$15),0) -> 0 | I29: =NETWORKDAYS($E$4,F29,'Festivos Guatemala'!$A$3:$A$15) -> 9 | J29: =H29 -> 0
B30: 43802212905 | C30: Declaraguate ISR Agosto facturación Col Factura 5027 | D30: 1486.96 | E30: =D30/$D$6 -> 196.16887 | F30: 45517 | G30: Cancelado | H30: =IF(OR(G30="Sin pagar",G30="Pagar"),NETWORKDAYS($E$4,F30,'Festivos Guatemala'!$A$3:$A$15),0) -> 0 | I30: =NETWORKDAYS($E$4,F30,'Festivos Guatemala'!$A$3:$A$15) -> 8 | J30: =H30 -> 0
B31: 43589111783 | C31: Declaraguate IVA mes de Julio | D31: 0 | E31: =D31/$D$6 -> 0 | F31: 45535 | G31: Cancelado | H31: =IF(OR(G31="Sin pagar",G31="Pagar"),NETWORKDAYS($E$4,F31,'Festivos Guatemala'!$A$3:$A$15),0) -> 0 | I31: =NETWORKDAYS($E$4,F31,'Festivos Guatemala'!$A$3:$A$15) -> 21 | J31: =H31 -> 0
C32: SERVICIOS PROFESIONALES -REPRESENTACIÓN LEGAL | D32: =SUBTOTAL(9,D33:D37) -> 1682.11 | E32: =SUBTOTAL(9,E33:E37) -> 221.91425 | J32: =H32 -> 0
C33: Servicios profesionales Juan-Servicios prestados-Julio | D33: 840 | E33: =D33/$D$6 -> 110.81794 | F33: 45513 | G33: Cancelado | H33: =IF(OR(G33="Sin pagar",G33="Pagar"),NETWORKDAYS($E$4,F33,'Festivos Guatemala'!$A$3:$A$15),0) -> 0 | I33: =NETWORKDAYS($E$4,F33,'Festivos Guatemala'!$A$3:$A$15) -> 6 | J33: =H33 -> 0
C34: Servicios prestados por audiencias IGSS el día 11 y 31 de julio | D34: 842.11 | E34: =D34/$D$6 -> 111.09631 | F34: 45513 | G34: Cancelado | H34: =IF(OR(G34="Sin pagar",G34="Pagar"),NETWORKDAYS($E$4,F34,'Festivos Guatemala'!$A$3:$A$15),0) -> 0 | I34: =NETWORKDAYS($E$4,F34,'Festivos Guatemala'!$A$3:$A$15) -> 6 | J34: =H34 -> 0
B35: 954 | C35: Servicios profesionales Arnoldo prestados en Junio | D35: =1250*0 -> 0 | E35: =D35/$D$6 -> 0 | F35: 45534 | G35: Cancelado | H35: =IF(OR(G35="Sin pagar",G35="Pagar"),NETWORKDAYS($E$4,F35,'Festivos Guatemala'!$A$3:$A$15),0) -> 0 | I35: =NETWORKDAYS($E$4,F35,'Festivos Guatemala'!$A$3:$A$15) -> 21 | J35: =H35 -> 0 | M35: Sin radicar
